Workbook
Name MW_IT: Assumptions!$D$5
Name KW_IT: Assumptions!$D$6
Name PUE: Assumptions!$D$7
Name CaseNo: Assumptions!$D$9
Name ConstrMonths: Assumptions!$D$10
Name OpsMonthsY2: Assumptions!$D$11
Name ModCostPerMW: Assumptions!$D$14
Name LiquidPrem: Assumptions!$D$15
Name ModuleScope: Assumptions!$D$16
Name RatePerKw: Assumptions!$D$19
Name RentEscal: Assumptions!$D$20
Name LeaseTermYrs: Assumptions!$D$21
Name VacancyPct: Assumptions!$D$22
Name MgmtFeePct: Assumptions!$D$23
Name Insurance: Assumptions!$D$24
Name CapReservePerKw: Assumptions!$D$25
Name LandlordGA: Assumptions!$D$26
Name OpexEscal: Assumptions!$D$27
Name LTC: Assumptions!$D$30
Name SOFR: Assumptions!$D$31
Name SnrRate: Assumptions!$D$33
Name OrigFee: Assumptions!$D$34
Name SnrTerm: Assumptions!$D$35
Name MidPeriod: Assumptions!$D$36
Name PacePct: Assumptions!$D$39
Name PaceRate: Assumptions!$D$40
Name PaceAmortYrs: Assumptions!$D$41
Name StabCapRate: Assumptions!$D$44
Name PermLTV: Assumptions!$D$45
Name PermLTC: Assumptions!$D$46
Name MinDSCR: Assumptions!$D$47
Name PermRate: Assumptions!$D$48
Name PermAmortYrs: Assumptions!$D$49
Name RefiFeePct: Assumptions!$D$50
Name ExitCapRate: Assumptions!$D$53
Name SellCostPct: Assumptions!$D$54
Name TargetSpread: Assumptions!$D$55
Name LPShare: Assumptions!$D$56
Name GPShare: Assumptions!$D$57
Name PrefReturn: Assumptions!$D$58
Name Hurdle2: Assumptions!$D$59
Name Promote2: Assumptions!$D$60
Name Promote3: Assumptions!$D$61
Name EqpAdvance: Assumptions!$D$64
Name EqpRate: Assumptions!$D$65
Name EqpIdcPct: Assumptions!$D$66
Name LTC_B: Assumptions!$D$67
Name SpreadB: Assumptions!$D$68
Name PCBF: 'Uses of Funds'!$H$26
Name TotalProjectCost: 'Uses of Funds'!$H$34
Name LowCaseTPC: 'Uses of Funds'!$D$34
Name HighCaseTPC: 'Uses of Funds'!$F$34
Name SelModules: 'Uses of Funds'!$H$12
Name SelSnrFee: 'Uses of Funds'!$H$29
Name SelIdcSenior: 'Uses of Funds'!$H$30
Name SelIdcPace: 'Uses of Funds'!$H$31
Name SelContPct: 'Uses of Funds'!$H$22
Name SelModEsc: 'Uses of Funds'!$H$11
Name SelLand: 'Uses of Funds'!$H$6
Name SnrCommitment: 'Sources of Funds'!$D$10

Sheet Summary
B1: 5 MW MODULAR DATA CENTER | DEVELOPMENT AND FINANCING MODEL
B2: Powered industrial site acquisition, modular delivery at the OEM quote, triple net wholesale lease and a ten year stabilised hold. All figures are driven by the Assumptions tab.
B4: PROJECT SNAPSHOT
B5: Critical IT Load (MW) | D5: =MW_IT
B6: Gross Utility Demand at the Design PUE (MW) | D6: =MW_IT*PUE
B7: Cost Case Selected | D7: =CHOOSE(CaseNo,"Low","Base","High")
B8: Construction Period | D8: =ConstrMonths
B9: Module Cost per MW, OEM Quote | D9: =ModCostPerMW
B11: TOTAL PROJECT COST
B12: Project Cost Before Financing Costs | D12: =PCBF
B13: Financing Costs, Fee and Capitalised Interest | D13: =TotalProjectCost-PCBF
B14: TOTAL PROJECT COST | D14: =TotalProjectCost
B15: Total Project Cost per MW | D15: =TotalProjectCost/MW_IT
B16: Total Project Cost per kW | D16: =TotalProjectCost/KW_IT
B17: Low Case Total Project Cost | D17: =LowCaseTPC
B18: High Case Total Project Cost | D18: =HighCaseTPC
B19: Low to High Cost Range per MW | D19: =(HighCaseTPC-LowCaseTPC)/MW_IT
B21: CAPITAL STACK, STRUCTURE A
B22: Senior Construction Commitment | D22: =SnrCommitment
B23: C-PACE Assessment Commitment | D23: =PaceCommitment
B24: Total Equity | D24: =TotalEquityA
B25: Leverage on Total Project Cost | D25: =(SnrCommitment+PaceCommitment)/TotalProjectCost
B26: Blended Cost of Debt | D26: =BlendedDebtCostA
B27: Equity Cheque under Structure B | D27: =EquityB
B28: Equity Saving under Structure B | D28: =TotalEquityA-EquityB
B30: OPERATIONS AND CREDIT
B31: Contracted Rate per kW per Month | D31: =RatePerKw
B32: Stabilised Net Operating Income | D32: =StabilisedNOI
B33: Stabilised NOI per kW per Month | D33: =StabilisedNOI/KW_IT/12
B34: Yield on Total Project Cost | D34: =StabilisedNOI/TotalProjectCost
B35: Development Spread over the Exit Cap Rate | D35: =(StabilisedNOI/TotalProjectCost-ExitCapRate)*10000
B36: Permanent Loan Proceeds at Stabilisation | D36: =PermLoan
B37: Permanent Loan to Cost at Refinancing | D37: =PermLoan/TotalProjectCost
B38: Binding Sizing Constraint | D38: =BindingConstraint
B39: Stabilised DSCR | D39: =StabDSCR
B40: Stabilised Debt Yield | D40: =StabDebtYield
B42: ASSUMPTION CALIBRATION
B43: Development Spread over the Exit Cap Rate | D43: =(StabilisedNOI/TotalProjectCost-ExitCapRate)*10000 | F43: =IF(D43>600,"Above the observable market band of 300 bps to 600 bps. Reduce the rate per kW per month or widen the exit cap rate.",IF(D43<200,"Below the band. The spread does not compensate for construction and interconnection risk.","Inside the observable market band."))
B44: Stabilised Value as a Multiple of Total Project Cost | D44: =StabilisedNOI/ExitCapRate/TotalProjectCost
B45: Rate per kW per Month Implying the Target Development Spread | D45: =((ExitCapRate+TargetSpread/10000)*TotalProjectCost+(Insurance+CapReservePerKw*KW_IT+LandlordGA)*(1+OpexEscal))/(KW_IT*12*(1+RentEscal)*(1-VacancyPct)*(1-MgmtFeePct))
...

Sheet Assumptions
B1: ASSUMPTIONS
B2: Green figures are hardcoded inputs. Black figures are calculated on this sheet. Blue figures link to another schedule.
B4: CAPACITY AND PROGRAMME
B5: Critical IT Load (MW) | D5: 5 | F5: Contracted white space capacity sold to the tenant
B6: Critical IT Load (kW) | D6: =Assumptions!$D$5*1000
B7: Design PUE (x) | D7: 1.3 | F7: Blended annualised power usage effectiveness
B8: Gross Utility Demand (MW) | D8: =Assumptions!$D$5*Assumptions!$D$7 | F8: Size the interconnection off this figure, not off critical load
B9: Cost Case (1 = Low, 2 = Base, 3 = High) | D9: 2 | F9: Drives the selected column on Uses of Funds
B10: Construction Period (months) | D10: 18 | F10: Site mobilisation through field commissioning
B11: Months of Operation in Year 2 | D11: 6 | F11: Rent commences at completion under a signed lease
B13: MODULE AND COST DRIVERS
B14: Module Cost per MW ($) | D14: 7500000 | F14: OEM indicative quote for the prefabricated units, delivered and set
B15: Liquid Cooling Ready Premium (% of module) | D15: 0 | F15: CDU footprint, secondary loop stubs and floor loading for direct to chip
B16: Module Scope, Base Specification | D16: =Assumptions!$D$5*Assumptions!$D$14*(1+Assumptions!$D$15)
B18: LEASE AND OPERATIONS
B19: Rate per kW per Month ($) | D19: 160 | F19: Wholesale triple net. Tier one markets $150 to $200, secondary markets $110 to $160
B20: Annual Rent Escalation (%) | D20: 0.03 | F20: Contractual bump inside the lease
B21: Lease Term (years) | D21: 15 | F21: Initial term before extension options
B22: Structural Vacancy and Credit Loss (%) | D22: 0.03 | F22: Applied to gross potential rent
B23: Management Fee (% of EGR) | D23: 0.015
B24: Insurance ($ per year) | D24: 120000 | F24: Property and liability retained by the landlord
B25: Capital Reserve ($ per kW per year) | D25: 8
B26: Landlord G&A ($ per year) | D26: 100000
B27: Operating Cost Escalation (%) | D27: 0.025
B29: SENIOR CONSTRUCTION DEBT
B30: Loan to Cost (%) | D30: 0.55 | F30: Applied to project cost before financing costs
B31: SOFR (%) | D31: 0.035 | F31: Indicative. Confirm against the live curve before committing
B32: Credit Spread (bps) | D32: 425 | F32: Bank pricing with a signed lease in hand. Debt funds price 500 to 750 bps
B33: All In Coupon (%) | D33: =Assumptions!$D$31+Assumptions!$D$32/10000
B34: Origination Fee (% of commitment) | D34: 0.0125
B35: Term to Refinance (months) | D35: 24 | F35: Construction period plus stabilisation. Interest is capitalised throughout
B36: Mid Period Draw Convention (%) | D36: 0.5 | F36: Share of the current month funding that accrues interest in that month
B38: C-PACE ASSESSMENT FINANCING
B39: C-PACE (% of cost) | D39: 0.15 | F39: Efficiency and resiliency eligible mechanical and electrical scope
B40: C-PACE Coupon (%) | D40: 0.075 | F40: Fixed for the full assessment term and non recourse
B41: C-PACE Amortisation (years) | D41: 25
B43: PERMANENT DEBT AT STABILISATION
B44: Stabilised Valuation Cap Rate (%) | D44: 0.065 | F44: Used to size the takeout loan
B45: Permanent LTV Cap (%) | D45: 0.6
B46: Permanent Loan to Cost Cap (%) | D46: 0.75 | F46: Lenders cap the takeout against cost basis, which binds on a wide development spread
...

Sheet Uses of Funds
B1: USES OF FUNDS | TOTAL PROJECT COST
B2: Three scenario columns. The Selected column is driven by the Cost Case input on the Assumptions tab.
B4: Cost Line | D4: Low | E4: Base | F4: High | H4: Selected | I4: $ per MW | J4: % of Total
B5: SITE ACQUISITION AND PRE DEVELOPMENT
B6: Land or Industrial Building Acquisition | D6: 1000000 | E6: 2500000 | F6: 10000000 | H6: =INDEX(D6:F6,CaseNo) | I6: =H6/MW_IT | J6: =H6/TotalProjectCost
B7: Pre Development Diligence | D7: 400000 | E7: 600000 | F7: 1200000 | H7: =INDEX(D7:F7,CaseNo) | I7: =H7/MW_IT | J7: =H7/TotalProjectCost
B8: HARD COST
B9: Site Work and Civil | D9: 1200000 | E9: 2000000 | F9: 3500000 | H9: =INDEX(D9:F9,CaseNo) | I9: =H9/MW_IT | J9: =H9/TotalProjectCost
B10: Utility Interconnection and MV Yard | D10: 500000 | E10: 1500000 | F10: 6000000 | H10: =INDEX(D10:F10,CaseNo) | I10: =H10/MW_IT | J10: =H10/TotalProjectCost
B11: Module Price Escalation (% of base scope) | D11: 0 | E11: 0 | F11: 0.09 | H11: =INDEX(D11:F11,CaseNo)
B12: Modular Data Center Units | D12: =ModuleScope*(1+D11) | E12: =ModuleScope*(1+E11) | F12: =ModuleScope*(1+F11) | H12: =INDEX(D12:F12,CaseNo) | I12: =H12/MW_IT | J12: =H12/TotalProjectCost
B13: Fiber and Network Entry | D13: 400000 | E13: 1000000 | F13: 2000000 | H13: =INDEX(D13:F13,CaseNo) | I13: =H13/MW_IT | J13: =H13/TotalProjectCost
B14: Security Systems, FF&E and NOC Fit Out | D14: 300000 | E14: 500000 | F14: 800000 | H14: =INDEX(D14:F14,CaseNo) | I14: =H14/MW_IT | J14: =H14/TotalProjectCost
B15: Total Hard Cost | D15: =D9+D10+D12+D13+D14 | E15: =E9+E10+E12+E13+E14 | F15: =F9+F10+F12+F13+F14 | H15: =H9+H10+H12+H13+H14 | I15: =H15/MW_IT | J15: =H15/TotalProjectCost
B16: SOFT COST
B17: A&E, Owner's Costs and Development Management | D17: 700000 | E17: 1000000 | F17: 1800000 | H17: =INDEX(D17:F17,CaseNo) | I17: =H17/MW_IT | J17: =H17/TotalProjectCost
B18: Permits, Impact Fees and Utility Deposits | D18: 300000 | E18: 500000 | F18: 1000000 | H18: =INDEX(D18:F18,CaseNo) | I18: =H18/MW_IT | J18: =H18/TotalProjectCost
B19: Closing Costs, Title, Builder's Risk and Taxes | D19: 500000 | E19: 800000 | F19: 1200000 | H19: =INDEX(D19:F19,CaseNo) | I19: =H19/MW_IT | J19: =H19/TotalProjectCost
B20: Total Soft Cost | D20: =D17+D18+D19 | E20: =E17+E18+E19 | F20: =F17+F18+F19 | H20: =H17+H18+H19 | I20: =H20/MW_IT | J20: =H20/TotalProjectCost
B21: CONTINGENCY AND RESERVES
B22: Contingency (% of hard cost) | D22: 0.08 | E22: 0.1 | F22: 0.12 | H22: =INDEX(D22:F22,CaseNo)
B23: Construction Contingency | D23: =D15*D22 | E23: =E15*E22 | F23: =F15*F22 | H23: =INDEX(D23:F23,CaseNo) | I23: =H23/MW_IT | J23: =H23/TotalProjectCost
B24: Operating and Lease Up Reserve | D24: 500000 | E24: 1000000 | F24: 1500000 | H24: =INDEX(D24:F24,CaseNo) | I24: =H24/MW_IT | J24: =H24/TotalProjectCost
B26: PROJECT COST BEFORE FINANCING COSTS | D26: =D6+D7+D15+D20+D23+D24 | E26: =E6+E7+E15+E20+E23+E24 | F26: =F6+F7+F15+F20+F23+F24 | H26: =H6+H7+H15+H20+H23+H24 | I26: =H26/MW_IT | J26: =H26/TotalProjectCost
B28: FINANCING COSTS, CAPITALISED INTO THE LOAN COMMITMENTS
B29: Senior Origination Fee | D29: =D26*LTC*OrigFee | E29: =E26*LTC*OrigFee | F29: =F26*LTC*OrigFee | H29: =INDEX(D29:F29,CaseNo) | I29: =H29/MW_IT | J29: =H29/TotalProjectCost
B30: Senior Interest During Construction | D30: =IdcFactorSnr*D26 | E30: =IdcFactorSnr*E26 | F30: =IdcFactorSnr*F26 | H30: =INDEX(D30:F30,CaseNo) | I30: =H30/MW_IT | J30: =H30/TotalProjectCost
B31: C-PACE Capitalised Interest During Construction | D31: =IdcFactorPace*D26 | E31: =IdcFactorPace*E26 | F31: =IdcFactorPace*F26 | H31: =INDEX(D31:F31,CaseNo) | I31: =H31/MW_IT | J31: =H31/TotalProjectCost
B32: Total Financing Costs | D32: =D29+D30+D31 | E32: =E29+E30+E31 | F32: =F29+F30+F31 | H32: =H29+H30+H31 | I32: =H32/MW_IT | J32: =H32/TotalProjectCost
B34: TOTAL PROJECT COST | D34: =D26+D32 | E34: =E26+E32 | F34: =F26+F32 | H34: =H26+H32 | I34: =H34/MW_IT | J34: =H34/TotalProjectCost
B36: MEMO
B37: Total Project Cost per MW of Critical IT Load | H37: =H34/MW_IT
B38: Total Project Cost per kW of Critical IT Load | H38: =H34/KW_IT
B39: Module Scope as a % of Total Project Cost | H39: =H12/H34
B40: Hard Cost as a % of Total Project Cost | H40: =H15/H34
B41: Contingency as a % of Total Project Cost | H41: =H23/H34
B42: Low Case Total Project Cost per MW | H42: =D34/MW_IT
B43: High Case Total Project Cost per MW | H43: =F34/MW_IT
B45: Source: OEM indicative quote for the module scope at $7.5M per MW. All other lines are desk estimates benchmarked to 2025 and 2026 wholesale and modular build pricing of $9.0M to $15.0M per MW all in, excluding IT hardware.
B46: Excluded from this build: tenant IT hardware. A 5 MW fleet of current generation AI accelerators runs $150M to $250M and a general purpose enterprise fleet runs $40M to $80M, in both cases a multiple of the facility cost above.
...

Sheet Sources of Funds
B1: SOURCES OF FUNDS | CAPITAL STACK ALTERNATIVES
B2: Structure A is the real estate led stack and is the structure carried through the Debt Schedule and Returns tabs. Structure B is presented for comparison only.
D4: STRUCTURE A REAL ESTATE LED | H4: STRUCTURE B EQUIPMENT FINANCE LED
B5: Source | D5: Amount | E5: % of Cost | F5: Pricing | H5: Amount | I5: % of Cost | J5: Pricing
B6: SENIOR SECURED DEBT
B7: Construction Loan on Cost | D7: =PCBF*LTC | E7: =D7/TotalProjectCost | F7: SOFR + 425 bps | H7: =RealPropertyCost*LTC_B | I7: =H7/TotalProjectCost | J7: SOFR + 400 bps
B8: Add: Capitalised Origination Fee | D8: =SelSnrFee | E8: =D8/TotalProjectCost | F8: 1.25% of commitment | H8: =H7*OrigFee | I8: =H8/TotalProjectCost | J8: 1.25% of commitment
B9: Add: Capitalised Interest Reserve | D9: =SelIdcSenior | E9: =D9/TotalProjectCost | F9: Interest only to refinance | H9: =H7*IdcFactorSnr/LTC | I9: =H9/TotalProjectCost | J9: Interest only to refinance
B10: Total Senior Commitment | D10: =SUM(D7:D9) | E10: =D10/TotalProjectCost | H10: =SUM(H7:H9) | I10: =H10/TotalProjectCost
B12: SUBORDINATE AND ASSET LEVEL DEBT
B13: C-PACE Assessment | D13: =PCBF*PacePct | E13: =D13/TotalProjectCost | F13: 7.50% fixed, 25 years | J13: n/a
B14: Add: Capitalised Interest | D14: =SelIdcPace | E14: =D14/TotalProjectCost | F14: Capitalised to completion | J14: n/a
B15: Total C-PACE Commitment | D15: =D13+D14 | E15: =D15/TotalProjectCost | H15: =0 | I15: =H15/TotalProjectCost
B17: Equipment Finance on Module Scope | D17: =0 | E17: =D17/TotalProjectCost | F17: n/a | H17: =SelModules*EqpAdvance | I17: =H17/TotalProjectCost | J17: 10.0%, 7 years
B18: Add: Capitalised Interest | D18: =0 | E18: =D18/TotalProjectCost | F18: n/a | H18: =H17*EqpIdcPct | I18: =H18/TotalProjectCost | J18: Short delivery carry
B19: Total Equipment Finance | D19: =0 | E19: =D19/TotalProjectCost | H19: =H17+H18 | I19: =H19/TotalProjectCost
B21: TOTAL DEBT | D21: =D10+D15+D19 | E21: =D21/TotalProjectCost | H21: =H10+H15+H19 | I21: =H21/TotalProjectCost
B23: EQUITY
B24: Limited Partner Equity | D24: =PCBF*(1-LTC-PacePct)*LPShare | E24: =D24/TotalProjectCost | F24: 9% pref, 70/30 then 60/40 | H24: =(TotalProjectCost-H21)*LPShare | I24: =H24/TotalProjectCost | J24: 9% pref, 70/30 then 60/40
B25: Sponsor Co-invest Equity | D25: =PCBF*(1-LTC-PacePct)*GPShare | E25: =D25/TotalProjectCost | F25: Promote above the hurdles | H25: =(TotalProjectCost-H21)*GPShare | I25: =H25/TotalProjectCost | J25: Promote above the hurdles
B26: TOTAL EQUITY | D26: =D24+D25 | E26: =D26/TotalProjectCost | H26: =H24+H25 | I26: =H26/TotalProjectCost
B28: TOTAL SOURCES | D28: =D21+D26 | E28: =D28/TotalProjectCost | H28: =H21+H26 | I28: =H28/TotalProjectCost
B29: Check: Total Sources less Total Project Cost | D29: =D28-TotalProjectCost | H29: =H28-TotalProjectCost
B31: STRUCTURE COMPARISON
B32: Equity Cheque Required | D32: =D26 | H32: =H26
B33: Equity as a % of Total Project Cost | D33: =D26/TotalProjectCost | H33: =H26/TotalProjectCost
B34: Total Leverage on Cost | D34: =D21/TotalProjectCost | H34: =H21/TotalProjectCost
B35: Equity Saving versus Structure A | D35: =0 | H35: =D26-H26
B36: Blended Cost of Debt | D36: =BlendedDebtCostA | H36: =BlendedDebtCostB
B38: WORKINGS
B39: Structure A Blended Cost of Debt | D39: =(D7*SnrRate+D13*PaceRate)/(D7+D13)
B40: Structure B Blended Cost of Debt | D40: =(H7*(SOFR+SpreadB/10000)+H17*EqpRate)/(H7+H17)
B41: Real Property Cost Base, Total Cost less Module Scope | D41: =PCBF-SelModules
B43: Note: Structure A keeps a single collateral pool and one intercreditor relationship. Structure B cuts the equity cheque materially but splits collateral across a mortgage lender and an equipment lessor, which requires an intercreditor agreement and carries a faster amortisation schedule.
B44: Note: no senior debt is available on a speculative basis at this size. Both structures assume a signed lease or a letter of intent with a creditworthy tenant is in place at loan closing. Structure B is compared against the same total project cost for a like for like equity comparison, so its equity line absorbs the difference in financing costs.
B45: Not modelled as a source but available in most jurisdictions: a sales and use tax exemption on data center equipment worth 4% to 8% of the module scope, property tax abatement, and a transferable 30% investment tax credit on any on site solar, storage or fuel cell capacity.

Sheet Draw Schedule
B1: CONSTRUCTION DRAW SCHEDULE | MONTHLY, EQUITY FUNDED FIRST
B2: Drawn on the Selected cost case. Equity funds the opening cost curve in full, then the senior loan and the C-PACE assessment fund pro rata to their commitments. Interest is capitalised into each commitment.
B4: Month | D4: 0 | E4: 1 | F4: 2 | G4: 3 | H4: 4 | I4: 5 | J4: 6 | K4: 7 | L4: 8 | M4: 9 | N4: 10 | O4: 11 | P4: 12 | Q4: 13 | R4: 14 | S4: 15 | T4: 16 | U4: 17 | V4: 18 | W4: 19 | X4: 20 | Y4: 21 | Z4: 22 | AA4: 23 | AB4: 24
B6: COST CURVE
B7: Draw Curve (% of project cost before financing) | D7: 0.1 | E7: 0.03 | F7: 0.03 | G7: 0.03 | H7: 0.05 | I7: 0.05 | J7: 0.05 | K7: 0.07 | L7: 0.07 | M7: 0.07 | N7: 0.07 | O7: 0.07 | P7: 0.07 | Q7: 0.05 | R7: 0.05 | S7: 0.05 | T7: 0.03 | U7: 0.03 | V7: 0.03 | W7: 0 | X7: 0 | Y7: 0 | Z7: 0 | AA7: 0 | AB7: 0
B8: Project Cost Draw | D8: =D7*PCBF | E8: =E7*PCBF | F8: =F7*PCBF | G8: =G7*PCBF | H8: =H7*PCBF | I8: =I7*PCBF | J8: =J7*PCBF | K8: =K7*PCBF | ... AB8: =AB7*PCBF
B9: Cumulative Project Cost Draw | D9: =0+D8 | E9: =D9+E8 | F9: =E9+F8 | G9: =F9+G8 | H9: =G9+H8 | I9: =H9+I8 | J9: =I9+J8 | K9: =J9+K8 | L9: =K9+L8 | ... AB9: =AA9+AB8
B11: FUNDING SEQUENCE
B12: Equity Draw | D12: =MIN(D8,MAX(0,TotalEquityA-0)) | E12: =MIN(E8,MAX(0,TotalEquityA-D13)) | F12: =MIN(F8,MAX(0,TotalEquityA-E13)) | G12: =MIN(G8,MAX(0,TotalEquityA-F13)) | H12: =MIN(H8,MAX(0,TotalEquityA-G13)) | I12: =MIN(I8,MAX(0,TotalEquityA-H13)) | J12: =MIN(J8,MAX(0,TotalEquityA-I13)) | K12: =MIN(K8,MAX(0,TotalEquityA-J13)) | L12: =MIN(L8,MAX(0,TotalEquityA-K13)) | ... AB12: =MIN(AB8,MAX(0,TotalEquityA-AA13))
B13: Cumulative Equity Draw | D13: =0+D12 | E13: =D13+E12 | F13: =E13+F12 | G13: =F13+G12 | H13: =G13+H12 | I13: =H13+I12 | J13: =I13+J12 | K13: =J13+K12 | L13: =K13+L12 | ... AB13: =AA13+AB12
B14: Debt Draw Required | D14: =D8-D12 | E14: =E8-E12 | F14: =F8-F12 | G14: =G8-G12 | H14: =H8-H12 | I14: =I8-I12 | J14: =J8-J12 | K14: =K8-K12 | ... AB14: =AB8-AB12
B15: Senior Loan Draw on Cost | D15: =D14*LTC/(LTC+PacePct) | E15: =E14*LTC/(LTC+PacePct) | F15: =F14*LTC/(LTC+PacePct) | G15: =G14*LTC/(LTC+PacePct) | H15: =H14*LTC/(LTC+PacePct) | I15: =I14*LTC/(LTC+PacePct) | J15: =J14*LTC/(LTC+PacePct) | K15: =K14*LTC/(LTC+PacePct) | ... AB15: =AB14*LTC/(LTC+PacePct)
B16: Senior Origination Fee Funded at Closing | D16: =SelSnrFee | E16: =0 | F16: =0 | G16: =0 | H16: =0 | I16: =0 | J16: =0 | K16: =0 | L16: =0 | ... AB16: =0
B17: Total Senior Funding | D17: =D15+D16 | E17: =E15+E16 | F17: =F15+F16 | G17: =G15+G16 | H17: =H15+H16 | I17: =I15+I16 | J17: =J15+J16 | K17: =K15+K16 | ... AB17: =AB15+AB16
B18: C-PACE Draw | D18: =D14*PacePct/(LTC+PacePct) | E18: =E14*PacePct/(LTC+PacePct) | F18: =F14*PacePct/(LTC+PacePct) | G18: =G14*PacePct/(LTC+PacePct) | H18: =H14*PacePct/(LTC+PacePct) | I18: =I14*PacePct/(LTC+PacePct) | J18: =J14*PacePct/(LTC+PacePct) | K18: =K14*PacePct/(LTC+PacePct) | ... AB18: =AB14*PacePct/(LTC+PacePct)
B20: SENIOR LOAN BALANCE, INTEREST CAPITALISED
B21: Balance, Beginning of Month | D21: =0 | E21: =D23 | F21: =E23 | G21: =F23 | H21: =G23 | I21: =H23 | J21: =I23 | K21: =J23 | L21: =K23 | ... AB21: =AA23
B22: Interest Accrued and Capitalised | D22: =(D21+D17*MidPeriod)*SnrRate/12 | E22: =(E21+E17*MidPeriod)*SnrRate/12 | F22: =(F21+F17*MidPeriod)*SnrRate/12 | G22: =(G21+G17*MidPeriod)*SnrRate/12 | H22: =(H21+H17*MidPeriod)*SnrRate/12 | I22: =(I21+I17*MidPeriod)*SnrRate/12 | J22: =(J21+J17*MidPeriod)*SnrRate/12 | K22: =(K21+K17*MidPeriod)*SnrRate/12 | ... AB22: =(AB21+AB17*MidPeriod)*SnrRate/12
B23: Balance, End of Month | D23: =D21+D17+D22 | E23: =E21+E17+E22 | F23: =F21+F17+F22 | G23: =G21+G17+G22 | H23: =H21+H17+H22 | I23: =I21+I17+I22 | J23: =J21+J17+J22 | K23: =K21+K17+K22 | ... AB23: =AB21+AB17+AB22
B25: C-PACE BALANCE, INTEREST CAPITALISED
B26: Balance, Beginning of Month | D26: =0 | E26: =D28 | F26: =E28 | G26: =F28 | H26: =G28 | I26: =H28 | J26: =I28 | K26: =J28 | L26: =K28 | ... AB26: =AA28
B27: Interest Accrued and Capitalised | D27: =(D26+D18*MidPeriod)*PaceRate/12 | E27: =(E26+E18*MidPeriod)*PaceRate/12 | F27: =(F26+F18*MidPeriod)*PaceRate/12 | G27: =(G26+G18*MidPeriod)*PaceRate/12 | H27: =(H26+H18*MidPeriod)*PaceRate/12 | I27: =(I26+I18*MidPeriod)*PaceRate/12 | J27: =(J26+J18*MidPeriod)*PaceRate/12 | K27: =(K26+K18*MidPeriod)*PaceRate/12 | ... AB27: =(AB26+AB18*MidPeriod)*PaceRate/12
B28: Balance, End of Month | D28: =D26+D18+D27 | E28: =E26+E18+E27 | F28: =F26+F18+F27 | G28: =G26+G18+G27 | H28: =H26+H18+H27 | I28: =I26+I18+I27 | J28: =J26+J18+J27 | K28: =K26+K18+K27 | ... AB28: =AB26+AB18+AB27
B31: OUTPUTS
B32: Total Senior Interest During Construction | D32: =SUM(D22:AB22)
B33: Total C-PACE Capitalised Interest | D33: =SUM(D27:AB27)
B34: Senior IDC per $1 of Project Cost Before Financing | D34: =D32/PCBF
B35: C-PACE IDC per $1 of Project Cost Before Financing | D35: =D33/PCBF
B36: Senior Balance at Month 0 | D36: =D23
B37: Senior Balance at Month 12 | D37: =P23
B38: Senior Balance at Month 24 | D38: =AB23
B39: C-PACE Balance at Month 0 | D39: =D28
B40: C-PACE Balance at Month 12 | D40: =P28
B41: C-PACE Balance at Month 24 | D41: =AB28
B42: Peak Equity Funded | D42: =AB13
B44: CHECKS
B45: Draw curve sums to 100% | D45: =SUM(D7:AB7)
B46: Cumulative draw less project cost before financing | D46: =AB9-PCBF
B47: Senior balance at month 24 less senior commitment | D47: =D38-SnrCommitment
B48: C-PACE balance at month 24 less C-PACE commitment | D48: =D41-PaceCommitment
...

Sheet Operating Model
B1: OPERATING MODEL | STABILISED NET OPERATING INCOME
B2: Triple net wholesale lease. The tenant pays power directly, so the landlord retains only management, insurance, reserves and G&A.
B4: Period | D4: 0 | E4: 1 | F4: 2 | G4: 3 | H4: 4 | I4: 5 | J4: 6 | K4: 7 | L4: 8 | M4: 9 | N4: 10 | O4: 11 | P4: 12 | Q4: 13
B6: TIMELINE AND PRICING
B7: Operating Months in Period | D7: =IF(0<2,0,IF(0=2,OpsMonthsY2,12)) | E7: =IF(1<2,0,IF(1=2,OpsMonthsY2,12)) | F7: =IF(2<2,0,IF(2=2,OpsMonthsY2,12)) | G7: =IF(3<2,0,IF(3=2,OpsMonthsY2,12)) | H7: =IF(4<2,0,IF(4=2,OpsMonthsY2,12)) | I7: =IF(5<2,0,IF(5=2,OpsMonthsY2,12)) | J7: =IF(6<2,0,IF(6=2,OpsMonthsY2,12)) | K7: =IF(7<2,0,IF(7=2,OpsMonthsY2,12)) | L7: =IF(8<2,0,IF(8=2,OpsMonthsY2,12)) | M7: =IF(9<2,0,IF(9=2,OpsMonthsY2,12)) | N7: =IF(10<2,0,IF(10=2,OpsMonthsY2,12)) | O7: =IF(11<2,0,IF(11=2,OpsMonthsY2,12)) | P7: =IF(12<2,0,IF(12=2,OpsMonthsY2,12)) | Q7: =IF(13<2,0,IF(13=2,OpsMonthsY2,12))
B8: Rent Escalation Index | D8: =IF(0<2,0,(1+RentEscal)^(0-2)) | E8: =IF(1<2,0,(1+RentEscal)^(1-2)) | F8: =IF(2<2,0,(1+RentEscal)^(2-2)) | G8: =IF(3<2,0,(1+RentEscal)^(3-2)) | H8: =IF(4<2,0,(1+RentEscal)^(4-2)) | I8: =IF(5<2,0,(1+RentEscal)^(5-2)) | J8: =IF(6<2,0,(1+RentEscal)^(6-2)) | K8: =IF(7<2,0,(1+RentEscal)^(7-2)) | L8: =IF(8<2,0,(1+RentEscal)^(8-2)) | M8: =IF(9<2,0,(1+RentEscal)^(9-2)) | N8: =IF(10<2,0,(1+RentEscal)^(10-2)) | O8: =IF(11<2,0,(1+RentEscal)^(11-2)) | P8: =IF(12<2,0,(1+RentEscal)^(12-2)) | Q8: =IF(13<2,0,(1+RentEscal)^(13-2))
B9: Rate per kW per Month | D9: =RatePerKw*D8 | E9: =RatePerKw*E8 | F9: =RatePerKw*F8 | G9: =RatePerKw*G8 | H9: =RatePerKw*H8 | I9: =RatePerKw*I8 | J9: =RatePerKw*J8 | K9: =RatePerKw*K8 | ... Q9: =RatePerKw*Q8
B10: Operating Cost Escalation Index | D10: =IF(0<2,0,(1+OpexEscal)^(0-2)) | E10: =IF(1<2,0,(1+OpexEscal)^(1-2)) | F10: =IF(2<2,0,(1+OpexEscal)^(2-2)) | G10: =IF(3<2,0,(1+OpexEscal)^(3-2)) | H10: =IF(4<2,0,(1+OpexEscal)^(4-2)) | I10: =IF(5<2,0,(1+OpexEscal)^(5-2)) | J10: =IF(6<2,0,(1+OpexEscal)^(6-2)) | K10: =IF(7<2,0,(1+OpexEscal)^(7-2)) | L10: =IF(8<2,0,(1+OpexEscal)^(8-2)) | M10: =IF(9<2,0,(1+OpexEscal)^(9-2)) | N10: =IF(10<2,0,(1+OpexEscal)^(10-2)) | O10: =IF(11<2,0,(1+OpexEscal)^(11-2)) | P10: =IF(12<2,0,(1+OpexEscal)^(12-2)) | Q10: =IF(13<2,0,(1+OpexEscal)^(13-2))
B12: REVENUE
B13: Gross Potential Rent | D13: =KW_IT*D9*D7 | E13: =KW_IT*E9*E7 | F13: =KW_IT*F9*F7 | G13: =KW_IT*G9*G7 | H13: =KW_IT*H9*H7 | I13: =KW_IT*I9*I7 | J13: =KW_IT*J9*J7 | K13: =KW_IT*K9*K7 | ... Q13: =KW_IT*Q9*Q7
B14: Less: Structural Vacancy and Credit Loss | D14: =-D13*VacancyPct | E14: =-E13*VacancyPct | F14: =-F13*VacancyPct | G14: =-G13*VacancyPct | H14: =-H13*VacancyPct | I14: =-I13*VacancyPct | J14: =-J13*VacancyPct | K14: =-K13*VacancyPct | ... Q14: =-Q13*VacancyPct
B15: Effective Gross Revenue | D15: =D13+D14 | E15: =E13+E14 | F15: =F13+F14 | G15: =G13+G14 | H15: =H13+H14 | I15: =I13+I14 | J15: =J13+J14 | K15: =K13+K14 | ... Q15: =Q13+Q14
B17: LANDLORD RETAINED OPERATING COST
B18: Management Fee | D18: =-D15*MgmtFeePct | E18: =-E15*MgmtFeePct | F18: =-F15*MgmtFeePct | G18: =-G15*MgmtFeePct | H18: =-H15*MgmtFeePct | I18: =-I15*MgmtFeePct | J18: =-J15*MgmtFeePct | K18: =-K15*MgmtFeePct | ... Q18: =-Q15*MgmtFeePct
B19: Insurance | D19: =-Insurance*D10*D7/12 | E19: =-Insurance*E10*E7/12 | F19: =-Insurance*F10*F7/12 | G19: =-Insurance*G10*G7/12 | H19: =-Insurance*H10*H7/12 | I19: =-Insurance*I10*I7/12 | J19: =-Insurance*J10*J7/12 | K19: =-Insurance*K10*K7/12 | ... Q19: =-Insurance*Q10*Q7/12
B20: Capital Reserve | D20: =-CapReservePerKw*KW_IT*D10*D7/12 | E20: =-CapReservePerKw*KW_IT*E10*E7/12 | F20: =-CapReservePerKw*KW_IT*F10*F7/12 | G20: =-CapReservePerKw*KW_IT*G10*G7/12 | H20: =-CapReservePerKw*KW_IT*H10*H7/12 | I20: =-CapReservePerKw*KW_IT*I10*I7/12 | J20: =-CapReservePerKw*KW_IT*J10*J7/12 | K20: =-CapReservePerKw*KW_IT*K10*K7/12 | ... Q20: =-CapReservePerKw*KW_IT*Q10*Q7/12
B21: Landlord G&A | D21: =-LandlordGA*D10*D7/12 | E21: =-LandlordGA*E10*E7/12 | F21: =-LandlordGA*F10*F7/12 | G21: =-LandlordGA*G10*G7/12 | H21: =-LandlordGA*H10*H7/12 | I21: =-LandlordGA*I10*I7/12 | J21: =-LandlordGA*J10*J7/12 | K21: =-LandlordGA*K10*K7/12 | ... Q21: =-LandlordGA*Q10*Q7/12
B22: Total Landlord Retained Operating Cost | D22: =SUM(D18:D21) | E22: =SUM(E18:E21) | F22: =SUM(F18:F21) | G22: =SUM(G18:G21) | H22: =SUM(H18:H21) | I22: =SUM(I18:I21) | J22: =SUM(J18:J21) | K22: =SUM(K18:K21) | ... Q22: =SUM(Q18:Q21)
B24: NET OPERATING INCOME | D24: =D15+D22 | E24: =E15+E22 | F24: =F15+F22 | G24: =G15+G22 | H24: =H15+H22 | I24: =I15+I22 | J24: =J15+J22 | K24: =K15+K22 | ... Q24: =Q15+Q22
B27: MEMO
B28: NOI Margin (% of EGR) | D28: =IF(D15=0,0,D24/D15) | E28: =IF(E15=0,0,E24/E15) | F28: =IF(F15=0,0,F24/F15) | G28: =IF(G15=0,0,G24/G15) | H28: =IF(H15=0,0,H24/H15) | I28: =IF(I15=0,0,I24/I15) | J28: =IF(J15=0,0,J24/J15) | K28: =IF(K15=0,0,K24/K15) | ... Q28: =IF(Q15=0,0,Q24/Q15)
B29: NOI per kW per Month | D29: =IF(D7=0,0,D24/KW_IT/D7) | E29: =IF(E7=0,0,E24/KW_IT/E7) | F29: =IF(F7=0,0,F24/KW_IT/F7) | G29: =IF(G7=0,0,G24/KW_IT/G7) | H29: =IF(H7=0,0,H24/KW_IT/H7) | I29: =IF(I7=0,0,I24/KW_IT/I7) | J29: =IF(J7=0,0,J24/KW_IT/J7) | K29: =IF(K7=0,0,K24/KW_IT/K7) | ... Q29: =IF(Q7=0,0,Q24/KW_IT/Q7)
B30: Yield on Total Project Cost (annualised) | D30: =IF(D7=0,0,D24/(D7/12)/TotalProjectCost) | E30: =IF(E7=0,0,E24/(E7/12)/TotalProjectCost) | F30: =IF(F7=0,0,F24/(F7/12)/TotalProjectCost) | G30: =IF(G7=0,0,G24/(G7/12)/TotalProjectCost) | H30: =IF(H7=0,0,H24/(H7/12)/TotalProjectCost) | I30: =IF(I7=0,0,I24/(I7/12)/TotalProjectCost) | J30: =IF(J7=0,0,J24/(J7/12)/TotalProjectCost) | K30: =IF(K7=0,0,K24/(K7/12)/TotalProjectCost) | ... Q30: =IF(Q7=0,0,Q24/(Q7/12)/TotalProjectCost)
B31: Inside the Initial Lease Term | D31: =IF(0<2,"n/a",IF(0-2<LeaseTermYrs,"Yes","Rollover")) | E31: =IF(1<2,"n/a",IF(1-2<LeaseTermYrs,"Yes","Rollover")) | F31: =IF(2<2,"n/a",IF(2-2<LeaseTermYrs,"Yes","Rollover")) | G31: =IF(3<2,"n/a",IF(3-2<LeaseTermYrs,"Yes","Rollover")) | H31: =IF(4<2,"n/a",IF(4-2<LeaseTermYrs,"Yes","Rollover")) | I31: =IF(5<2,"n/a",IF(5-2<LeaseTermYrs,"Yes","Rollover")) | J31: =IF(6<2,"n/a",IF(6-2<LeaseTermYrs,"Yes","Rollover")) | K31: =IF(7<2,"n/a",IF(7-2<LeaseTermYrs,"Yes","Rollover")) | L31: =IF(8<2,"n/a",IF(8-2<LeaseTermYrs,"Yes","Rollover")) | M31: =IF(9<2,"n/a",IF(9-2<LeaseTermYrs,"Yes","Rollover")) | N31: =IF(10<2,"n/a",IF(10-2<LeaseTermYrs,"Yes","Rollover")) | O31: =IF(11<2,"n/a",IF(11-2<LeaseTermYrs,"Yes","Rollover")) | P31: =IF(12<2,"n/a",IF(12-2<LeaseTermYrs,"Yes","Rollover")) | Q31: =IF(13<2,"n/a",IF(13-2<LeaseTermYrs,"Yes","Rollover"))
B34: Source: rate per kW per month benchmarked to 2025 and 2026 wholesale colocation leasing. Powered shell product prices at $60 to $100 per kW per month and is not comparable to the fully fitted modular delivery modelled here.
B35: Note: Year 2 carries a partial year at the months of operation input. Rent commences at completion under the assumed signed lease, so no absorption ramp is modelled. A speculative build would require a lease up curve and would not support senior debt at closing.

Sheet Debt Schedule
B1: DEBT SCHEDULE | CONSTRUCTION FACILITY, TAKEOUT SIZING AND AMORTISATION
B2: Structure A. The construction facility capitalises interest to the end of Year 2 and is then refinanced into permanent debt sized off stabilised net operating income.
B4: Period | D4: 0 | E4: 1 | F4: 2 | G4: 3 | H4: 4 | I4: 5 | J4: 6 | K4: 7 | L4: 8 | M4: 9 | N4: 10 | O4: 11 | P4: 12 | Q4: 13
B6: SENIOR CONSTRUCTION FACILITY
B7: Balance, Beginning of Year | D7: =0 | E7: =D10 | F7: =E10 | G7: =F10 | H7: =G10 | I7: =H10 | J7: =I10 | K7: =J10 | L7: =K10 | ... Q7: =P10
B8: Funding and Capitalised Interest in the Year | D8: =SnrBalM0 | E8: =SnrBalM12-SnrBalM0 | F8: =SnrBalM24-SnrBalM12 | G8: =0 | H8: =0 | I8: =0 | J8: =0 | K8: =0 | L8: =0 | M8: =0 | N8: =0 | ... Q8: =0
B9: Repayment at Refinancing | D9: =0 | E9: =0 | F9: =-(F7+F8) | G9: =0 | H9: =0 | I9: =0 | J9: =0 | K9: =0 | L9: =0 | M9: =0 | N9: =0 | ... Q9: =0
B10: Balance, End of Year | D10: =D7+D8+D9 | E10: =E7+E8+E9 | F10: =F7+F8+F9 | G10: =G7+G8+G9 | H10: =H7+H8+H9 | I10: =I7+I8+I9 | J10: =J7+J8+J9 | K10: =K7+K8+K9 | ... Q10: =Q7+Q8+Q9
B13: PERMANENT DEBT SIZING AT THE END OF YEAR 2
B14: Stabilised NOI, First Full Operating Year | D14: =StabilisedNOI
B15: Stabilised Value at the Valuation Cap Rate | D15: =D14/StabCapRate
B16: C-PACE Annual Assessment Payment | D16: =PMT(PaceRate,PaceAmortYrs,-PaceCommitment)
B17: Permanent Debt Service Constant per $1 | D17: =PMT(PermRate,PermAmortYrs,-1)
B18: Sizing Test 1: LTV Cap | D18: =D15*PermLTV
B19: Sizing Test 2: Minimum DSCR | D19: =MAX(0,(D14/MinDSCR-D16)/D17)
B20: Sizing Test 3: Loan to Cost Cap | D20: =TotalProjectCost*PermLTC
B21: Permanent Loan Proceeds | D21: =MIN(D18,D19,D20)
B22: Binding Constraint | D22: =IF(D21=D18,"LTV Cap",IF(D21=D19,"Minimum DSCR","Loan to Cost Cap"))
B23: Resulting Loan to Value | D23: =D21/D15
B24: Less: Refinancing Fee | D24: =-D21*RefiFeePct
B25: Less: Construction Facility Payoff | D25: =-SnrCommitment
B26: Net Refinancing Proceeds to Equity | D26: =D21+D24+D25
B29: PERMANENT LOAN AMORTISATION
B30: Balance, Beginning of Year | D30: =0 | E30: =0 | F30: =0 | G30: =PermLoan | H30: =G34 | I30: =H34 | J30: =I34 | K30: =J34 | L30: =K34 | M30: =L34 | N30: =M34 | O30: =N34 | ... Q30: =P34
B31: Total Debt Service | D31: =0 | E31: =0 | F31: =0 | G31: =PermLoan*PermConstant | H31: =PermLoan*PermConstant | I31: =PermLoan*PermConstant | J31: =PermLoan*PermConstant | K31: =PermLoan*PermConstant | L31: =PermLoan*PermConstant | M31: =PermLoan*PermConstant | N31: =PermLoan*PermConstant | ... Q31: =PermLoan*PermConstant
B32: Interest Component | D32: =0 | E32: =0 | F32: =0 | G32: =G30*PermRate | H32: =H30*PermRate | I32: =I30*PermRate | J32: =J30*PermRate | K32: =K30*PermRate | L32: =L30*PermRate | M32: =M30*PermRate | N32: =N30*PermRate | ... Q32: =Q30*PermRate
B33: Principal Component | D33: =0 | E33: =0 | F33: =0 | G33: =G31-G32 | H33: =H31-H32 | I33: =I31-I32 | J33: =J31-J32 | K33: =K31-K32 | L33: =L31-L32 | M33: =M31-M32 | N33: =N31-N32 | ... Q33: =Q31-Q32
B34: Balance, End of Year | D34: =0 | E34: =0 | F34: =0 | G34: =G30-G33 | H34: =H30-H33 | I34: =I30-I33 | J34: =J30-J33 | K34: =K30-K33 | L34: =L30-L33 | M34: =M30-M33 | N34: =N30-N33 | ... Q34: =Q30-Q33
B37: C-PACE ASSESSMENT AMORTISATION
B38: Balance, Beginning of Year | D38: =0 | E38: =PaceBalM0 | F38: =PaceBalM12 | G38: =PaceCommitment | H38: =G42 | I38: =H42 | J38: =I42 | K38: =J42 | L38: =K42 | M38: =L42 | N38: =M42 | O38: =N42 | ... Q38: =P42
B39: Annual Assessment Payment | D39: =0 | E39: =0 | F39: =0 | G39: =PaceConstant | H39: =PaceConstant | I39: =PaceConstant | J39: =PaceConstant | K39: =PaceConstant | L39: =PaceConstant | M39: =PaceConstant | N39: =PaceConstant | ... Q39: =PaceConstant
B40: Interest Component | D40: =0 | E40: =0 | F40: =0 | G40: =G38*PaceRate | H40: =H38*PaceRate | I40: =I38*PaceRate | J40: =J38*PaceRate | K40: =K38*PaceRate | L40: =L38*PaceRate | M40: =M38*PaceRate | N40: =N38*PaceRate | ... Q40: =Q38*PaceRate
B41: Principal Component | D41: =0 | E41: =0 | F41: =0 | G41: =G39-G40 | H41: =H39-H40 | I41: =I39-I40 | J41: =J39-J40 | K41: =K39-K40 | L41: =L39-L40 | M41: =M39-M40 | N41: =N39-N40 | ... Q41: =Q39-Q40
B42: Balance, End of Year | D42: =PaceBalM0 | E42: =PaceBalM12 | F42: =PaceBalM24 | G42: =G38-G41 | H42: =H38-H41 | I42: =I38-I41 | J42: =J38-J41 | K42: =K38-K41 | L42: =L38-L41 | M42: =M38-M41 | N42: =N38-N41 | ... Q42: =Q38-Q41
B45: CREDIT METRICS
B46: Total Cash Debt Service | D46: =D31+D39 | E46: =E31+E39 | F46: =F31+F39 | G46: =G31+G39 | H46: =H31+H39 | I46: =I31+I39 | J46: =J31+J39 | K46: =K31+K39 | ... Q46: =Q31+Q39
B47: Total Debt Outstanding | D47: =D10+D42 | E47: =E10+E42 | F47: =F10+F42 | G47: =G34+G42 | H47: =H34+H42 | I47: =I34+I42 | J47: =J34+J42 | K47: =K34+K42 | L47: =L34+L42 | M47: =M34+M42 | N47: =N34+N42 | ... Q47: =Q34+Q42
B48: DSCR | D48: =IF(D46=0,0,'Operating Model'!D24/D46) | E48: =IF(E46=0,0,'Operating Model'!E24/E46) | F48: =IF(F46=0,0,'Operating Model'!F24/F46) | G48: =IF(G46=0,0,'Operating Model'!G24/G46) | H48: =IF(H46=0,0,'Operating Model'!H24/H46) | I48: =IF(I46=0,0,'Operating Model'!I24/I46) | J48: =IF(J46=0,0,'Operating Model'!J24/J46) | K48: =IF(K46=0,0,'Operating Model'!K24/K46) | ... Q48: =IF(Q46=0,0,'Operating Model'!Q24/Q46)
B49: Debt Yield on Total Debt | D49: =IF(D47=0,0,'Operating Model'!D24/D47) | E49: =IF(E47=0,0,'Operating Model'!E24/E47) | F49: =IF(F47=0,0,'Operating Model'!F24/F47) | G49: =IF(G47=0,0,'Operating Model'!G24/G47) | H49: =IF(H47=0,0,'Operating Model'!H24/H47) | I49: =IF(I47=0,0,'Operating Model'!I24/I47) | J49: =IF(J47=0,0,'Operating Model'!J24/J47) | K49: =IF(K47=0,0,'Operating Model'!K24/K47) | ... Q49: =IF(Q47=0,0,'Operating Model'!Q24/Q47)
B50: Loan to Value at the Exit Cap Rate | D50: =IF(OR(D47=0,'Operating Model'!D24=0),0,D47/('Operating Model'!D24/ExitCapRate)) | E50: =IF(OR(E47=0,'Operating Model'!E24=0),0,E47/('Operating Model'!E24/ExitCapRate)) | F50: =IF(OR(F47=0,'Operating Model'!F24=0),0,F47/('Operating Model'!F24/ExitCapRate)) | G50: =IF(OR(G47=0,'Operating Model'!G24=0),0,G47/('Operating Model'!G24/ExitCapRate)) | H50: =IF(OR(H47=0,'Operating Model'!H24=0),0,H47/('Operating Model'!H24/ExitCapRate)) | I50: =IF(OR(I47=0,'Operating Model'!I24=0),0,I47/('Operating Model'!I24/ExitCapRate)) | J50: =IF(OR(J47=0,'Operating Model'!J24=0),0,J47/('Operating Model'!J24/ExitCapRate)) | K50: =IF(OR(K47=0,'Operating Model'!K24=0),0,K47/('Operating Model'!K24/ExitCapRate)) | ... Q50: =IF(OR(Q47=0,'Operating Model'!Q24=0),0,Q47/('Operating Model'!Q24/ExitCapRate))
...

Sheet Returns
B1: RETURNS | UNLEVERED, LEVERED AND THE PROMOTE WATERFALL
B2: Two years of construction followed by a ten year stabilised hold. The exit occurs at the end of Year 12 on the forward year NOI.
B4: Period | D4: 0 | E4: 1 | F4: 2 | G4: 3 | H4: 4 | I4: 5 | J4: 6 | K4: 7 | L4: 8 | M4: 9 | N4: 10 | O4: 11 | P4: 12 | Q4: 13
B6: UNLEVERED PROJECT CASH FLOW
B7: Project Cost Outflow | D7: =-'Draw Schedule'!D53 | E7: =-'Draw Schedule'!E53 | F7: =-'Draw Schedule'!F53 | G7: =0 | H7: =0 | I7: =0 | J7: =0 | K7: =0 | L7: =0 | M7: =0 | N7: =0 | ... P7: =0
B8: Net Operating Income | D8: ='Operating Model'!D24 | E8: ='Operating Model'!E24 | F8: ='Operating Model'!F24 | G8: ='Operating Model'!G24 | H8: ='Operating Model'!H24 | I8: ='Operating Model'!I24 | J8: ='Operating Model'!J24 | K8: ='Operating Model'!K24 | ... P8: ='Operating Model'!P24
B9: Net Sale Proceeds | D9: =0 | E9: =0 | F9: =0 | G9: =0 | H9: =0 | I9: =0 | J9: =0 | K9: =0 | ... O9: =0 | P9: ='Operating Model'!Q24/ExitCapRate*(1-SellCostPct)
B10: Unlevered Cash Flow | D10: =SUM(D7:D9) | E10: =SUM(E7:E9) | F10: =SUM(F7:F9) | G10: =SUM(G7:G9) | H10: =SUM(H7:H9) | I10: =SUM(I7:I9) | J10: =SUM(J7:J9) | K10: =SUM(K7:K9) | ... P10: =SUM(P7:P9)
B12: Unlevered IRR | D12: =IRR(D10:P10)
B13: Unlevered Multiple on Invested Capital | D13: =SUMIF(D10:P10,">0")/-SUMIF(D10:P10,"<0")
B14: Total Unlevered Profit | D14: =SUM(D10:P10)
B15: Yield on Cost at Stabilisation | D15: =StabilisedNOI/TotalProjectCost
B16: Development Spread over the Exit Cap Rate | D16: =(D15-ExitCapRate)*10000
B17: Stabilised Value at the Exit Cap Rate | D17: =StabilisedNOI/ExitCapRate
B18: Value Creation over Total Project Cost | D18: =D17-TotalProjectCost
B19: Profit on Cost | D19: =D18/TotalProjectCost
B21: LEVERED EQUITY CASH FLOW
B22: Equity Contributions | D22: =-'Draw Schedule'!D54 | E22: =-'Draw Schedule'!E54 | F22: =-'Draw Schedule'!F54 | G22: =0 | H22: =0 | I22: =0 | J22: =0 | K22: =0 | L22: =0 | M22: =0 | N22: =0 | ... P22: =0
B23: Net Operating Income | D23: ='Operating Model'!D24 | E23: ='Operating Model'!E24 | F23: ='Operating Model'!F24 | G23: ='Operating Model'!G24 | H23: ='Operating Model'!H24 | I23: ='Operating Model'!I24 | J23: ='Operating Model'!J24 | K23: ='Operating Model'!K24 | ... P23: ='Operating Model'!P24
B24: Less: Total Cash Debt Service | D24: =-'Debt Schedule'!D46 | E24: =-'Debt Schedule'!E46 | F24: =-'Debt Schedule'!F46 | G24: =-'Debt Schedule'!G46 | H24: =-'Debt Schedule'!H46 | I24: =-'Debt Schedule'!I46 | J24: =-'Debt Schedule'!J46 | K24: =-'Debt Schedule'!K46 | ... P24: =-'Debt Schedule'!P46
B25: Net Refinancing Proceeds | D25: =0 | E25: =0 | F25: ='Debt Schedule'!D26 | G25: =0 | H25: =0 | I25: =0 | J25: =0 | K25: =0 | L25: =0 | M25: =0 | N25: =0 | ... P25: =0
B26: Net Sale Proceeds | D26: =0 | E26: =0 | F26: =0 | G26: =0 | H26: =0 | I26: =0 | J26: =0 | K26: =0 | ... O26: =0 | P26: ='Operating Model'!Q24/ExitCapRate*(1-SellCostPct)
B27: Less: Debt Payoff at Exit | D27: =0 | E27: =0 | F27: =0 | G27: =0 | H27: =0 | I27: =0 | J27: =0 | K27: =0 | ... O27: =0 | P27: =-('Debt Schedule'!P34+'Debt Schedule'!P42)
B28: Levered Equity Cash Flow | D28: =SUM(D22:D27) | E28: =SUM(E22:E27) | F28: =SUM(F22:F27) | G28: =SUM(G22:G27) | H28: =SUM(H22:H27) | I28: =SUM(I22:I27) | J28: =SUM(J22:J27) | K28: =SUM(K22:K27) | ... P28: =SUM(P22:P27)
B30: Levered Equity IRR | D30: =IRR(D28:P28)
B31: Equity Multiple | D31: =SUMIF(D28:P28,">0")/-SUMIF(D28:P28,"<0")
B32: Peak Equity Invested | D32: =-SUMIF(D28:P28,"<0")
B33: Total Distributions to Equity | D33: =SUMIF(D28:P28,">0")
B34: Total Levered Profit | D34: =SUM(D28:P28)
B36: DISTRIBUTION WATERFALL, HURDLE BALANCE METHOD
B37: Total Equity Cash Flow | D37: =D28 | E37: =E28 | F37: =F28 | G37: =G28 | H37: =H28 | I37: =I28 | J37: =J28 | K37: =K28 | ... P37: =P28
B38: Capital Contributions | D38: =-MIN(0,D37) | E38: =-MIN(0,E37) | F38: =-MIN(0,F37) | G38: =-MIN(0,G37) | H38: =-MIN(0,H37) | I38: =-MIN(0,I37) | J38: =-MIN(0,J37) | K38: =-MIN(0,K37) | ... P38: =-MIN(0,P37)
B39: Cash Available to Distribute | D39: =MAX(0,D37) | E39: =MAX(0,E37) | F39: =MAX(0,F37) | G39: =MAX(0,G37) | H39: =MAX(0,H37) | I39: =MAX(0,I37) | J39: =MAX(0,J37) | K39: =MAX(0,K37) | ... P39: =MAX(0,P37)
B41: Tier 1: Return of Capital and the Preferred Return
B42: Hurdle Balance, Beginning of Year | D42: =0 | E42: =D46 | F42: =E46 | G42: =F46 | H42: =G46 | I42: =H46 | J42: =I46 | K42: =J46 | L42: =K46 | ... P42: =O46
B43: Accrual at the Preferred Return | D43: =D42*PrefReturn | E43: =E42*PrefReturn | F43: =F42*PrefReturn | G43: =G42*PrefReturn | H43: =H42*PrefReturn | I43: =I42*PrefReturn | J43: =J42*PrefReturn | K43: =K42*PrefReturn | ... P43: =P42*PrefReturn
B44: Hurdle Balance before Distributions | D44: =MAX(0,D42+D43+D38) | E44: =MAX(0,E42+E43+E38) | F44: =MAX(0,F42+F43+F38) | G44: =MAX(0,G42+G43+G38) | H44: =MAX(0,H42+H43+H38) | I44: =MAX(0,I42+I43+I38) | J44: =MAX(0,J42+J43+J38) | K44: =MAX(0,K42+K43+K38) | ... P44: =MAX(0,P42+P43+P38)
B45: Tier 1 Distribution | D45: =MIN(D39,D44) | E45: =MIN(E39,E44) | F45: =MIN(F39,F44) | G45: =MIN(G39,G44) | H45: =MIN(H39,H44) | I45: =MIN(I39,I44) | J45: =MIN(J39,J44) | K45: =MIN(K39,K44) | ... P45: =MIN(P39,P44)
B46: Hurdle Balance, End of Year | D46: =D44-D45 | E46: =E44-E45 | F46: =F44-F45 | G46: =G44-G45 | H46: =H44-H45 | I46: =I44-I45 | J46: =J44-J45 | K46: =K44-K45 | ... P46: =P44-P45
B48: Tier 2: Pro Rata to the Second Hurdle
...

Sheet Sensitivities
B1: SENSITIVITIES | HEAT MAPPED, BASE CASE MARKED WITH A DASHED BOX
B2: Each grid recomputes stabilised NOI and total project cost in closed form, so the figures are exact rather than interpolated.
B4: WORKINGS
B5: Stabilised NOI per $1 of Rate per kW per Month | D5: =KW_IT*12*(1+RentEscal)*(1-VacancyPct)*(1-MgmtFeePct)
B6: Stabilised NOI Fixed Cost Component | D6: =-(Insurance+CapReservePerKw*KW_IT+LandlordGA)*(1+OpexEscal)
B7: Check: modelled stabilised NOI less the closed form | D7: =StabilisedNOI-(D5*RatePerKw+D6)
B8: Financing Gross Up Factor | D8: =1+LTC*OrigFee+IdcFactorSnr+IdcFactorPace
B9: Cost Gross Up Factor for Contingency and Financing | D9: =(1+SelContPct)*D8
B10: Module Quantity Basis (MW adjusted for specification) | D10: =MW_IT*(1+LiquidPrem)*(1+SelModEsc)
B12: GRID 1 YIELD ON COST BY RATE PER KW AND MODULE COST PER MW
B13: Rate per kW per Month | D13: 6500000 | E13: 7000000 | F13: 7500000 | G13: 8000000 | H13: 8500000
B14: 100 | D14: =($D$5*$B14+$D$6)/(TotalProjectCost+(D$13-ModCostPerMW)*$D$10*$D$9) | E14: =($D$5*$B14+$D$6)/(TotalProjectCost+(E$13-ModCostPerMW)*$D$10*$D$9) | F14: =($D$5*$B14+$D$6)/(TotalProjectCost+(F$13-ModCostPerMW)*$D$10*$D$9) | G14: =($D$5*$B14+$D$6)/(TotalProjectCost+(G$13-ModCostPerMW)*$D$10*$D$9) | H14: =($D$5*$B14+$D$6)/(TotalProjectCost+(H$13-ModCostPerMW)*$D$10*$D$9)
B15: 120 | D15: =($D$5*$B15+$D$6)/(TotalProjectCost+(D$13-ModCostPerMW)*$D$10*$D$9) | E15: =($D$5*$B15+$D$6)/(TotalProjectCost+(E$13-ModCostPerMW)*$D$10*$D$9) | F15: =($D$5*$B15+$D$6)/(TotalProjectCost+(F$13-ModCostPerMW)*$D$10*$D$9) | G15: =($D$5*$B15+$D$6)/(TotalProjectCost+(G$13-ModCostPerMW)*$D$10*$D$9) | H15: =($D$5*$B15+$D$6)/(TotalProjectCost+(H$13-ModCostPerMW)*$D$10*$D$9)
B16: 140 | D16: =($D$5*$B16+$D$6)/(TotalProjectCost+(D$13-ModCostPerMW)*$D$10*$D$9) | E16: =($D$5*$B16+$D$6)/(TotalProjectCost+(E$13-ModCostPerMW)*$D$10*$D$9) | F16: =($D$5*$B16+$D$6)/(TotalProjectCost+(F$13-ModCostPerMW)*$D$10*$D$9) | G16: =($D$5*$B16+$D$6)/(TotalProjectCost+(G$13-ModCostPerMW)*$D$10*$D$9) | H16: =($D$5*$B16+$D$6)/(TotalProjectCost+(H$13-ModCostPerMW)*$D$10*$D$9)
B17: 160 | D17: =($D$5*$B17+$D$6)/(TotalProjectCost+(D$13-ModCostPerMW)*$D$10*$D$9) | E17: =($D$5*$B17+$D$6)/(TotalProjectCost+(E$13-ModCostPerMW)*$D$10*$D$9) | F17: =($D$5*$B17+$D$6)/(TotalProjectCost+(F$13-ModCostPerMW)*$D$10*$D$9) | G17: =($D$5*$B17+$D$6)/(TotalProjectCost+(G$13-ModCostPerMW)*$D$10*$D$9) | H17: =($D$5*$B17+$D$6)/(TotalProjectCost+(H$13-ModCostPerMW)*$D$10*$D$9)
B18: 180 | D18: =($D$5*$B18+$D$6)/(TotalProjectCost+(D$13-ModCostPerMW)*$D$10*$D$9) | E18: =($D$5*$B18+$D$6)/(TotalProjectCost+(E$13-ModCostPerMW)*$D$10*$D$9) | F18: =($D$5*$B18+$D$6)/(TotalProjectCost+(F$13-ModCostPerMW)*$D$10*$D$9) | G18: =($D$5*$B18+$D$6)/(TotalProjectCost+(G$13-ModCostPerMW)*$D$10*$D$9) | H18: =($D$5*$B18+$D$6)/(TotalProjectCost+(H$13-ModCostPerMW)*$D$10*$D$9)
B19: 200 | D19: =($D$5*$B19+$D$6)/(TotalProjectCost+(D$13-ModCostPerMW)*$D$10*$D$9) | E19: =($D$5*$B19+$D$6)/(TotalProjectCost+(E$13-ModCostPerMW)*$D$10*$D$9) | F19: =($D$5*$B19+$D$6)/(TotalProjectCost+(F$13-ModCostPerMW)*$D$10*$D$9) | G19: =($D$5*$B19+$D$6)/(TotalProjectCost+(G$13-ModCostPerMW)*$D$10*$D$9) | H19: =($D$5*$B19+$D$6)/(TotalProjectCost+(H$13-ModCostPerMW)*$D$10*$D$9)
B20: Yield on total project cost at stabilisation. Exit cap rates for leased data center product run 6.0% to 7.5%, so anything above roughly 9.0% carries a development spread worth underwriting.
B23: GRID 2 STABILISED VALUE PER MW BY RATE PER KW AND EXIT CAP RATE
B24: Rate per kW per Month | D24: 0.0575 | E24: 0.0625 | F24: 0.0675 | G24: 0.0725 | H24: 0.0775
B25: 100 | D25: =($D$5*$B25+$D$6)/D$24/MW_IT | E25: =($D$5*$B25+$D$6)/E$24/MW_IT | F25: =($D$5*$B25+$D$6)/F$24/MW_IT | G25: =($D$5*$B25+$D$6)/G$24/MW_IT | H25: =($D$5*$B25+$D$6)/H$24/MW_IT
B26: 120 | D26: =($D$5*$B26+$D$6)/D$24/MW_IT | E26: =($D$5*$B26+$D$6)/E$24/MW_IT | F26: =($D$5*$B26+$D$6)/F$24/MW_IT | G26: =($D$5*$B26+$D$6)/G$24/MW_IT | H26: =($D$5*$B26+$D$6)/H$24/MW_IT
B27: 140 | D27: =($D$5*$B27+$D$6)/D$24/MW_IT | E27: =($D$5*$B27+$D$6)/E$24/MW_IT | F27: =($D$5*$B27+$D$6)/F$24/MW_IT | G27: =($D$5*$B27+$D$6)/G$24/MW_IT | H27: =($D$5*$B27+$D$6)/H$24/MW_IT
B28: 160 | D28: =($D$5*$B28+$D$6)/D$24/MW_IT | E28: =($D$5*$B28+$D$6)/E$24/MW_IT | F28: =($D$5*$B28+$D$6)/F$24/MW_IT | G28: =($D$5*$B28+$D$6)/G$24/MW_IT | H28: =($D$5*$B28+$D$6)/H$24/MW_IT
B29: 180 | D29: =($D$5*$B29+$D$6)/D$24/MW_IT | E29: =($D$5*$B29+$D$6)/E$24/MW_IT | F29: =($D$5*$B29+$D$6)/F$24/MW_IT | G29: =($D$5*$B29+$D$6)/G$24/MW_IT | H29: =($D$5*$B29+$D$6)/H$24/MW_IT
B30: 200 | D30: =($D$5*$B30+$D$6)/D$24/MW_IT | E30: =($D$5*$B30+$D$6)/E$24/MW_IT | F30: =($D$5*$B30+$D$6)/F$24/MW_IT | G30: =($D$5*$B30+$D$6)/G$24/MW_IT | H30: =($D$5*$B30+$D$6)/H$24/MW_IT
B31: Gross stabilised value per MW of critical IT load, before selling costs. Compare against total project cost per MW on the Uses of Funds tab.
B34: GRID 3 PROFIT ON COST BY RATE PER KW AND EXIT CAP RATE
B35: Rate per kW per Month | D35: 0.0575 | E35: 0.0625 | F35: 0.0675 | G35: 0.0725 | H35: 0.0775
B36: 100 | D36: =(($D$5*$B36+$D$6)/D$35*(1-SellCostPct)-TotalProjectCost)/TotalProjectCost | E36: =(($D$5*$B36+$D$6)/E$35*(1-SellCostPct)-TotalProjectCost)/TotalProjectCost | F36: =(($D$5*$B36+$D$6)/F$35*(1-SellCostPct)-TotalProjectCost)/TotalProjectCost | G36: =(($D$5*$B36+$D$6)/G$35*(1-SellCostPct)-TotalProjectCost)/TotalProjectCost | H36: =(($D$5*$B36+$D$6)/H$35*(1-SellCostPct)-TotalProjectCost)/TotalProjectCost
B37: 120 | D37: =(($D$5*$B37+$D$6)/D$35*(1-SellCostPct)-TotalProjectCost)/TotalProjectCost | E37: =(($D$5*$B37+$D$6)/E$35*(1-SellCostPct)-TotalProjectCost)/TotalProjectCost | F37: =(($D$5*$B37+$D$6)/F$35*(1-SellCostPct)-TotalProjectCost)/TotalProjectCost | G37: =(($D$5*$B37+$D$6)/G$35*(1-SellCostPct)-TotalProjectCost)/TotalProjectCost | H37: =(($D$5*$B37+$D$6)/H$35*(1-SellCostPct)-TotalProjectCost)/TotalProjectCost
B38: 140 | D38: =(($D$5*$B38+$D$6)/D$35*(1-SellCostPct)-TotalProjectCost)/TotalProjectCost | E38: =(($D$5*$B38+$D$6)/E$35*(1-SellCostPct)-TotalProjectCost)/TotalProjectCost | F38: =(($D$5*$B38+$D$6)/F$35*(1-SellCostPct)-TotalProjectCost)/TotalProjectCost | G38: =(($D$5*$B38+$D$6)/G$35*(1-SellCostPct)-TotalProjectCost)/TotalProjectCost | H38: =(($D$5*$B38+$D$6)/H$35*(1-SellCostPct)-TotalProjectCost)/TotalProjectCost
B39: 160 | D39: =(($D$5*$B39+$D$6)/D$35*(1-SellCostPct)-TotalProjectCost)/TotalProjectCost | E39: =(($D$5*$B39+$D$6)/E$35*(1-SellCostPct)-TotalProjectCost)/TotalProjectCost | F39: =(($D$5*$B39+$D$6)/F$35*(1-SellCostPct)-TotalProjectCost)/TotalProjectCost | G39: =(($D$5*$B39+$D$6)/G$35*(1-SellCostPct)-TotalProjectCost)/TotalProjectCost | H39: =(($D$5*$B39+$D$6)/H$35*(1-SellCostPct)-TotalProjectCost)/TotalProjectCost
B40: 180 | D40: =(($D$5*$B40+$D$6)/D$35*(1-SellCostPct)-TotalProjectCost)/TotalProjectCost | E40: =(($D$5*$B40+$D$6)/E$35*(1-SellCostPct)-TotalProjectCost)/TotalProjectCost | F40: =(($D$5*$B40+$D$6)/F$35*(1-SellCostPct)-TotalProjectCost)/TotalProjectCost | G40: =(($D$5*$B40+$D$6)/G$35*(1-SellCostPct)-TotalProjectCost)/TotalProjectCost | H40: =(($D$5*$B40+$D$6)/H$35*(1-SellCostPct)-TotalProjectCost)/TotalProjectCost
B41: 200 | D41: =(($D$5*$B41+$D$6)/D$35*(1-SellCostPct)-TotalProjectCost)/TotalProjectCost | E41: =(($D$5*$B41+$D$6)/E$35*(1-SellCostPct)-TotalProjectCost)/TotalProjectCost | F41: =(($D$5*$B41+$D$6)/F$35*(1-SellCostPct)-TotalProjectCost)/TotalProjectCost | G41: =(($D$5*$B41+$D$6)/G$35*(1-SellCostPct)-TotalProjectCost)/TotalProjectCost | H41: =(($D$5*$B41+$D$6)/H$35*(1-SellCostPct)-TotalProjectCost)/TotalProjectCost
B42: Net of selling costs and measured against the selected total project cost. A merchant build is normally underwritten to a minimum of 20% profit on cost to absorb schedule and cost overrun risk.
B45: GRID 4 DEVELOPMENT SPREAD IN BASIS POINTS BY RATE PER KW AND EXIT CAP RATE
B46: Rate per kW per Month | D46: 0.0575 | E46: 0.0625 | F46: 0.0675 | G46: 0.0725 | H46: 0.0775
B47: 100 | D47: =(($D$5*$B47+$D$6)/TotalProjectCost-D$46)*10000 | E47: =(($D$5*$B47+$D$6)/TotalProjectCost-E$46)*10000 | F47: =(($D$5*$B47+$D$6)/TotalProjectCost-F$46)*10000 | G47: =(($D$5*$B47+$D$6)/TotalProjectCost-G$46)*10000 | H47: =(($D$5*$B47+$D$6)/TotalProjectCost-H$46)*10000
B48: 120 | D48: =(($D$5*$B48+$D$6)/TotalProjectCost-D$46)*10000 | E48: =(($D$5*$B48+$D$6)/TotalProjectCost-E$46)*10000 | F48: =(($D$5*$B48+$D$6)/TotalProjectCost-F$46)*10000 | G48: =(($D$5*$B48+$D$6)/TotalProjectCost-G$46)*10000 | H48: =(($D$5*$B48+$D$6)/TotalProjectCost-H$46)*10000
...
