Workbook
Name ABF_Legal_Form: #REF!
Name AccountPurpose: #REF!
Name AccountType: #REF!
Name CustomerType: #REF!
Name Energy_Infra: #REF!
Name IQ_CH: 110000
Name IQ_CQ: 5000
Name IQ_CY: 10000
Name IQ_DAILY: 500000
Name IQ_FH: 100000
Name IQ_FQ: 500
Name IQ_FY: 1000
Name IQ_LTM: 2000
Name IQ_MONTH: 15000
Name IQ_NTM: 6000
Name IQ_WEEK: 50000
Name IQ_YTD: 3000
Name Legal_Form_Asset_Type: #REF!
Name YesNo: #REF!

Sheet JS Lookup
B4: Property Type | C4: Collateral Type (from Position Report) | D4: Loan Type | E4: Investment Type | F4: Legal Form | G4: Legal Form (from Position Report) | H4: Subordinate Debt | I4: Position Leverage | J4: Capital Stack Position | K4: Reporting Type | L4: Insurance Reporting Schedule | M4: Fund Type
B5: Multifamily | C5: CRE Agriculture | D5: Acquisition | E5: Origination | F5: Mortgage | G5: Asset Purchase Levered | H5: B-Note | I5: Structural | J5: Senior Mortgage | K5: UW In-Place | L5: Schedule A - Real Estate | M5: FI+
B6: Industrial | C6: CRE Entitled Land | D6: Construction | E6: Loan Acquisition | F6: B-Note | G6: Asset Purchase Unlevered | H6: Mezzanine Loan | I6: Repo/Warehouse | J6: Repo/Warehouse | K6: UW Stabilized Untrended | L6: Schedule B - Commercial Mortgages | M6: Opportunistic
B7: Retail | C7: CRE Ground Lease | D7: Refinance | E7: Financing | F7: CUSIP | G7: CUSIP IG | H7: Preferred Equity | I7: Note on Note | J7: Note on Note | K7: UW Stabilized Trended | L7: Schedule B - Residential Mortgages | M7: Enhanced Core
B8: Hospitality | C8: CRE Hotel | D8: Bridge | E8: CUSIP - New Issue | F8: Mezzanine Loan | G8: CUSIP Non-IG | H8: HRR | I8: Senior Mortgage | J8: Senior Bonds | K8: Most Recent | L8: Schedule D - Non-Financial ABS | M8: FI+ / Opportunistic
B9: Data Center | C9: CRE Industrial | D9: Note-on-Note | E9: CUSIP - Secondary | F9: Preferred Equity | G9: Debt/Platform | H9: Other | I9: N/A - Unlevered | J9: Junior Bonds | K9: 2nd Most Recent | L9: Schedule D - Financial ABS
B10: Office | C10: CRE Mixed Asset Loan Pool | D10: Financing | E10: Syndication | F10: Structured Equity | G10: Equity/Platform | H10: N/A | J10: B-Note | K10: 3rd Most Recent | L10: Schedule D - Other
B11: Mixed Use | C11: CRE Mixed Use | D11: Recapitalization | E11: Levered Whole Loan | F11: Common Equity | G11: Financing Junior | J11: Retained WL Equity | L11: Schedule BA - Residual Tranche
B12: Student Housing | C12: CRE Multi Family | D12: Platform | E12: Forward Flow | F12: Other | G12: Financing Senior | J12: Mezzanine | L12: Schedule BA - Interest in JV, LP or LLC (Bonds)
B13: Senior Housing | C13: CRE Office | D13: Various | E13: Loan Pool Acquisition | G13: CRE Loan Senior | J13: Senior Mezzanine | L13: Schedule BA - Interest in JV, LP or LLC (Common Stocks)
B14: Condo | C14: CRE Retail | D14: N/A | E14: Preferred Equity | G14: CRE Loan Junior | J14: Junior Mezzanine | L14: Schedule BA - Interest in JV, LP or LLC (Preferred Stocks)
B15: Manufactured Housing | C15: CRE Senior Housing | E15: Equity | G15: Asset Purchase Levered -JV/Asset Co | J15: Preferred Equity | L15: Schedule BA - Interest in JV, LP or LLC (Real Estate)
B16: Residential - For Sale Development | C16: CRE Student Housing | E16: Mezzanine | G16: Asset Purchase Unlevered - JV/Asset Co | J16: Common Equity | L16: Schedule BA - Interest in JV, LP or LLC (Mortgage Loans)
B17: Single Family Rental (SFR) | C17: CRE Construction Loans | J17: Other | L17: Schedule BA - Other
B18: BTR | C18: CRE Storage | L18: Schedule DA - Short-Term Investments
B19: Horizontal Land Development | C19: CRE Mobile Home Parks | L19: Schedule DB- PART A - Options, Caps, Floors, Collars, Swaps and Forwards
B20: Agricultural Land | C20: CRE Portfolio | L20: Schedule DB- PART B - Futures Contracts
B21: Land | L21: Schedule DB - PART C - Replication (Synthetic Asset) Transactions Open as of Current Statement Date
B22: Land Banking | L22: Schedule E - (Cash Equivalents)
B23: Lot Servicing | L23: N/A
B24: Medical Office
B25: Life Science
B26: Self Storage
B27: Ground Lease
B28: NNN - Office
B29: NNN - Industrial
B30: NNN - Retail
B31: Various

Sheet Comment Summary
B3: Comment Detail
B4: # | C4: Tab | D4: Cell | E4: Header / Field | F4: Category | G4: Comment
B5: =ROW()-4 -> 1 | C5: Capital Stack | D5: D2 | E5: Debt Stack Type | F5: Suggestion | G5: Consider replacing with Investment Type to the right
B6: =ROW()-4 -> 2 | C6: Capital Stack | D6: E2 | E6: SSP Investment Type | F6: Suggestion | G6: Added what I think categories should be. Could replace Origination Type
B7: =ROW()-4 -> 3 | C7: Capital Stack | D7: F2 | E7: Legal Form | F7: Discussion Point | G7: Currently pulling my view on options for drop-down
B8: =ROW()-4 -> 4 | C8: Capital Stack | D8: G2 | E8: Legal Form (Position Report) | F8: Discussion Point | G8: Curren drop-down options from the position report, should discuss which to use or if to include both
B9: =ROW()-4 -> 5 | C9: Capital Stack | D9: M2 | E9: SSP Total Invested Capital | F9: Discussion Point | G9: Copied initial for now, but needs to be updated Need to discuss how to capture original invested amounts and current invested amounts over time
B10: =ROW()-4 -> 6 | C10: Capital Stack | D10: N2 | E10: SSP Total Invested Capital | F10: Discussion Point | G10: Copied initial for now, but needs to be updated Need to discuss how to capture original invested amounts and current invested amounts over time
B11: =ROW()-4 -> 7 | C11: Capital Stack | D11: O2 | E11: SSP Last Dollar Exposure | F11: Suggestion | G11: Could be calc'd so maybe doesn’t need to be in this tape but think it would be helpful to see at least
B12: =ROW()-4 -> 8 | C12: Capital Stack | D12: P2 | E12: Investment Level Leverage | F12: Definition / Guidance | G12: Meant to capture if there is leverage on our position, either structurally or through us borrowing
B13: =ROW()-4 -> 9 | C13: Capital Stack | D13: Q2 | E13: Leverage Provider | F13: Definition / Guidance | G13: Who is giving us the leverage? Like GS on BLT and Hearthstone, Apollo on Royalton Levered, Santander on anything on our warehouse line, etc.
B14: =ROW()-4 -> 10 | C14: Capital Stack | D14: R2 | E14: Total Deal Size | F14: Discussion Point | G14: Total deal capitalization. To discuss what layer to include down to for CML. Current thought is to include through collateral value which inherently includes borrower equity, thought being we can then calc subordination, etc. Or maybe have multiple columns that capture total cost, appraised value, underwritten value so we can look multiple ways
B15: =ROW()-4 -> 11 | C15: Capital Stack | D15: S2 | E15: Total Cost | F15: Discussion Point | G15: Same comment as R2 (Total Deal Size)
B16: =ROW()-4 -> 12 | C16: Capital Stack | D16: T2 | E16: Total Appraised Value | F16: Discussion Point | G16: Same comment as R2 (Total Deal Size)
... B71: =ROW()-4 -> 67 | C71: Allocations & Returns | D71: AS2 | E71: Capital Charge | F71: Question | G71: Can we have this calc automatically based on inputs?

Sheet INPUTS ->

Sheet Property UW
A2: Mash-ID | B2: Deal Code | C2: Loan Name | D2: Reporting Type | E2: As of | F2: Occupancy | G2: Revenues | H2: Expenses | I2: NOI | J2: Reporting Type | K2: As of | L2: Occupancy | M2: Revenues | N2: Expenses | O2: NOI | P2: Reporting Type | Q2: As of | R2: Occupancy | S2: Revenues | T2: Expenses | U2: NOI | V2: Reporting Type | W2: As of | X2: Occupancy | Y2: Revenues | Z2: Expenses | AA2: NOI | AB2: Reporting Type | AC2: As of | AD2: Occupancy | AE2: Revenues | AF2: Expenses | AG2: NOI | AH2: Reporting Type | AI2: As of | AJ2: Occupancy | AK2: Revenues | AL2: Expenses | AM2: NOI
A3: MaSH-3410443 | B3: 67692 | C3: Project Sequoia | D3: UW In-Place | E3: 45016 | F3: 0.92620307 | G3: 1.5991943e+08 | H3: 36199451 | I3: 1.2371998e+08 | J3: UW Stabilized Untrended | K3: 45016 | L3: 0.93412893 | M3: 1.8295511e+08 | N3: 38684138 | O3: 1.4427097e+08 | P3: UW Stabilized Trended | Q3: 45016 | R3: 0.93412893 | S3: 2.0591759e+08 | T3: 43539338 | U3: 1.6237825e+08 | V3: Most Recent | W3: 46203 | AB3: 2nd Most Recent | AC3: 46112 | AH3: 3rd Most Recent | AI3: 46022
A4: MaSH-3256633 | B4: 61883 | C4: Project Royale | D4: UW In-Place | E4: 44804 | F4: 0.97 | G4: 41792640 | H4: 21146929 | I4: 20645711 | J4: UW Stabilized Untrended | K4: 44804 | L4: 0.94 | M4: 41810031 | N4: 23644217 | O4: 18165814 | P4: UW Stabilized Trended | Q4: 44804 | R4: 0.94 | S4: 49070783 | T4: 23862039 | U4: 25208744 | V4: Most Recent | W4: 46203 | AB4: 2nd Most Recent | AC4: 46112 | AH4: 3rd Most Recent | AI4: 46022
A5: MaSH-3258016 | B5: 61973 | C5: Lakefront North | D5: UW In-Place | E5: 44865 | F5: =223920/258031 -> 0.86780271 | G5: 9822780 | H5: 4304747 | I5: =G5-H5 -> 5518033 | J5: UW Stabilized Untrended | P5: UW Stabilized Trended | Q5: 48518 | R5: 0.9 | S5: 12507327 | T5: 5607424 | U5: =S5-T5 -> 6899903 | V5: Most Recent | W5: 46203 | AB5: 2nd Most Recent | AC5: 46112 | AH5: 3rd Most Recent | AI5: 46022
A6: MaSH-3339577 | B6: 64734 | C6: Project Balboa | D6: UW In-Place | E6: 44896 | F6: 0.94742094 | G6: 6141504 | H6: 1978989 | I6: =G6-H6 -> 4162515 | J6: UW Stabilized Untrended | P6: UW Stabilized Trended | Q6: 47118 | R6: 0.9 | S6: 7387940 | T6: 2242930 | U6: =S6-T6 -> 5145010 | V6: Most Recent | W6: 46203 | AB6: 2nd Most Recent | AC6: 46112 | AH6: 3rd Most Recent | AI6: 46022
A7: MaSH-3534532 | B7: 102039 | C7: Project Cubic | D7: UW In-Place | E7: 45223 | F7: 0.94181037 | G7: 85629602 | H7: 18034079 | I7: 67595522 | J7: UW Stabilized Untrended | K7: =E7 -> 45223 | L7: 0.93059688 | M7: 96150116 | N7: 20062287 | O7: 76087829 | P7: UW Stabilized Trended | Q7: =E7 -> 45223 | R7: 0.93059688 | S7: 1.0633695e+08 | T7: 23285648 | U7: 83051307 | V7: Most Recent | W7: 46203 | AB7: 2nd Most Recent | AC7: 46112 | AH7: 3rd Most Recent | AI7: 46022
A8: MaSH-3337170 | B8: 64681 | C8: Project Eyas | D8: UW In-Place | E8: 44926 | F8: 0.8357 | G8: 38426648 | H8: 23123380 | I8: 15303268 | J8: UW Stabilized Untrended | K8: =E8 -> 44926 | L8: 0.9 | M8: 41091692 | N8: 25960832 | O8: 15130860 | P8: UW Stabilized Trended | Q8: 46752 | R8: 0.9 | S8: 48459755 | T8: 26181874 | U8: 22277881 | V8: Most Recent | W8: 46203 | AB8: 2nd Most Recent | AC8: 46112 | AH8: 3rd Most Recent | AI8: 46022
A9: MaSH-3340378 | B9: 64777 | C9: Project Stripe | D9: UW In-Place | E9: 44926 | F9: 0.938454 | G9: 51011504 | H9: 19135416 | I9: 31876088 | J9: UW Stabilized Untrended | K9: =E9 -> 44926 | L9: 0.945 | M9: 52118176 | N9: 21018433 | O9: 31099743 | P9: UW Stabilized Trended | Q9: 46752 | R9: 0.945 | S9: 60345855 | T9: 21244695 | U9: 39101160 | V9: Most Recent | W9: 46203 | AB9: 2nd Most Recent | AC9: 46112 | AH9: 3rd Most Recent | AI9: 46022
A10: MaSH-3687981 | B10: 255488 | C10: Project Bellevue | D10: UW In-Place | E10: 45688 | F10: 0.5054 | G10: 31282158 | H10: 22916597 | I10: 8365560.6 | J10: UW Stabilized Untrended | K10: =E10 -> 45688 | L10: 0.8114 | M10: 46759937 | N10: 27373488 | O10: 19386448 | P10: UW Stabilized Trended | Q10: 46387 | R10: 0.8001 | S10: 46980437 | T10: 27579522 | U10: 19400915 | V10: Most Recent | W10: 46203 | AB10: 2nd Most Recent | AC10: 46112 | AH10: 3rd Most Recent | AI10: 46022
A11: MaSH-3773167 | B11: 340674 | C11: Project Fayetteville 2-Pack | D11: UW In-Place | E11: 45991 | F11: 0.900641 | G11: 4804718.5 | H11: 1436022.5 | I11: 3368696 | J11: UW Stabilized Untrended | K11: 45991 | L11: 0.935 | M11: 4760346.5 | N11: 1434691.4 | O11: 3325655.1 | P11: UW Stabilized Trended | Q11: 47452 | R11: 0.93 | S11: 4881228.1 | T11: 1546115.1 | U11: 3335113 | V11: Most Recent | W11: 46203 | AB11: 2nd Most Recent | AC11: 46112 | AH11: 3rd Most Recent | AI11: 46022
A12: MaSH-3774814 | B12: 342321 | C12: Mosaic Apartments | D12: UW In-Place | E12: 45930 | F12: 0.90131579 | G12: 7037303.6 | H12: 2700684.3 | I12: 4336619.3 | J12: UW Stabilized Untrended | K12: 45930 | L12: 0.9 | M12: 6895728.7 | N12: 2700684.3 | O12: 4195044.4 | P12: UW Stabilized Trended | Q12: 47757 | R12: 0.9 | S12: 7322831.2 | T12: 3047156.6 | U12: 4275674.6 | V12: Most Recent | W12: 46203 | AB12: 2nd Most Recent | AC12: 46112 | AH12: 3rd Most Recent | AI12: 46022
A13: MaSH-3774820 | B13: 342327 | C13: Project Arista | D13: UW In-Place | E13: 45991 | F13: 0.91740882 | G13: 5673443.5 | H13: 1978718 | I13: 3694725.4 | J13: UW Stabilized Untrended | K13: 45991 | L13: 0.93592317 | M13: 5781629.4 | N13: 2399712.5 | O13: 3381916.9 | P13: UW Stabilized Trended | Q13: 46037 | R13: 0.945 | S13: 6606139.7 | T13: 2502369.6 | U13: 4103770.1 | V13: Most Recent | W13: 46203 | AB13: 2nd Most Recent | AC13: 46112 | AH13: 3rd Most Recent | AI13: 46022
A14: MaSH-3700986 | B14: 268493 | C14: Project Grand Bay Hotel San Francisco | D14: UW In-Place | E14: 45930 | F14: 0.5676439 | G14: 26141990 | H14: 22985235 | I14: 3156755.3 | J14: UW Stabilized Untrended | K14: 45930 | L14: 0.74867258 | M14: 39646844 | N14: 29818293 | O14: 9828550.7 | P14: UW Stabilized Trended | Q14: 47118 | R14: 0.78089457 | S14: 44901113 | T14: 33779704 | U14: 11121409 | V14: Most Recent | W14: 46203 | AB14: 2nd Most Recent | AC14: 46112 | AH14: 3rd Most Recent | AI14: 46022
A15: MaSH-3776991 | B15: 344498 | C15: Crystal Springs Resort | D15: UW In-Place | E15: 46022 | F15: 0.52007062 | G15: 1.0600131e+08 | H15: 80998881 | I15: 25002425 | J15: UW Stabilized Untrended | K15: 46163 | L15: 0.525 | M15: 1.0740813e+08 | N15: 82816119 | O15: 24592009 | P15: UW Stabilized Trended | Q15: 46538 | R15: 0.523 | S15: 1.0204269e+08 | T15: 81733834 | U15: 20308861 | V15: Most Recent | W15: 46203 | AB15: 2nd Most Recent | AC15: 46112 | AH15: 3rd Most Recent | AI15: 46022
A16: MaSH-3776993 | B16: 344500 | C16: Alpine Village | D16: UW In-Place | E16: 46216 | F16: 0.9522293 | G16: 7451883.4 | H16: 3609556.6 | I16: 3842326.8 | J16: UW Stabilized Untrended | K16: =E16 -> 46216 | L16: 0.94 | M16: 7682070.5 | N16: 3573497.6 | O16: 4108572.8 | P16: UW Stabilized Trended | Q16: 47695 | R16: 0.94 | S16: 8038033.6 | T16: 3831520.9 | U16: 4206512.7 | V16: Most Recent | W16: 46203 | AB16: 2nd Most Recent | AC16: 46112 | AH16: 3rd Most Recent | AI16: 46022
A17: MaSH-3773094 | B17: 340601 | C17: Project Highland Portfolio | D17: UW In-Place | E17: 46203 | F17: 0.68166557 | G17: 2.3383749e+08 | H17: 1.6855565e+08 | I17: 65281844 | J17: UW Stabilized Untrended | K17: 47483 | L17: 0.70030842 | M17: 2.687151e+08 | N17: 1.9101047e+08 | O17: 77704632 | P17: UW Stabilized Trended | Q17: 47848 | R17: 0.70030842 | S17: 2.7645728e+08 | T17: 1.9637732e+08 | U17: 80079959 | V17: Most Recent | W17: 46203 | AB17: 2nd Most Recent | AC17: 46112 | AH17: 3rd Most Recent | AI17: 46022
A18: MaSH-3780342 | B18: 347849 | C18: Project Prime Care Portfolio Senior Financing | D18: UW In-Place | E18: 46173 | F18: 0.872 | G18: 95712083 | H18: 75010856 | I18: 20701227 | J18: UW Stabilized Untrended | K18: 46265 | L18: 0.9236 | M18: 1.0391541e+08 | N18: 79291076 | O18: 24624335 | P18: UW Stabilized Trended | Q18: 47726 | R18: 0.9236 | S18: 1.1753539e+08 | T18: 87044257 | U18: 30491136 | V18: Most Recent | W18: 46203 | AB18: 2nd Most Recent | AC18: 46112 | AH18: 3rd Most Recent | AI18: 46022
A19: MaSH-3768501 | B19: 336008 | C19: Project Scarlet Bay | D19: UW In-Place | J19: UW Stabilized Untrended | K19: 45991 | L19: =(5216400*0.95+330470*0.9+10201200*0.94+813735*0.85)/(5216400+330470+10201200+813735) -> 0.93792952 | M19: =5626296+11414557 -> 17040853 | N19: =(1705478-33000)+(3640215-91500) -> 5221193 | O19: =M19-N19 -> 11819660 | P19: UW Stabilized Trended | Q19: 47634 | R19: =(5637471*0.95+357146*0.9+11188794*0.94+892514*0.85)/(5637471+357146+11188794+892514) -> 0.93788462 | S19: =6080453+12519618 -> 18600071 | T19: =(1846448-35664)+(4001946-100358) -> 5712372 | U19: =S19-T19 -> 12887699 | V19: Most Recent | W19: 46203 | AB19: 2nd Most Recent | AC19: 46112 | AH19: 3rd Most Recent | AI19: 46022
A20: MaSH-3773946 | B20: 342718 | C20: Project Royalton Whole Loan | D20: UW In-Place | E20: 46022 | F20: 0.8548 | G20: 37773260 | H20: 30524460 | I20: 7248800 | J20: UW Stabilized Untrended | K20: 46022 | L20: 0.8 | M20: 71751230 | N20: 51555820 | O20: 20195410 | P20: UW Stabilized Trended | Q20: 47483 | R20: 0.8 | S20: 86747820 | T20: 61305790 | U20: 25442030 | V20: Most Recent | W20: 46203 | AB20: 2nd Most Recent | AC20: 46112 | AH20: 3rd Most Recent | AI20: 46022
C21: Project Royalton Levered | D21: UW In-Place | E21: =E$20 -> 46022 | F21: =F$20 -> 0.8548 | G21: =G$20 -> 37773260 | H21: =H$20 -> 30524460 | I21: =I$20 -> 7248800 | J21: UW Stabilized Untrended | K21: =K$20 -> 46022 | L21: =L$20 -> 0.8 | M21: =M$20 -> 71751230 | N21: =N$20 -> 51555820 | O21: =O$20 -> 20195410 | P21: UW Stabilized Trended | Q21: =Q$20 -> 47483 | R21: =R$20 -> 0.8 | S21: =S$20 -> 86747820 | T21: =T$20 -> 61305790 | U21: =U$20 -> 25442030 | V21: Most Recent | W21: 46203 | AB21: 2nd Most Recent | AC21: 46112 | AH21: 3rd Most Recent | AI21: 46022
A22: MaSH-3570618 | B22: 138125 | C22: Project Hearthstone Land | D22: UW In-Place | J22: UW Stabilized Untrended | P22: UW Stabilized Trended | V22: Most Recent | W22: 46203 | AB22: 2nd Most Recent | AC22: 46112 | AH22: 3rd Most Recent | AI22: 46022
A23: MaSH-3777002 | B23: 344509 | C23: HLTN 2026-DPLO - Class B | D23: UW In-Place | E23: 46081 | F23: 0.65609589 | G23: 1.8180281e+08 | H23: 1.2889299e+08 | I23: 52909817 | J23: UW Stabilized Untrended | K23: 46081 | L23: 0.725 | M23: 2.1121719e+08 | N23: 1.4071191e+08 | O23: 70505283 | P23: UW Stabilized Trended | Q23: 46387 | R23: 0.74 | S23: 214165926 | T23: =214165926-70751619 -> 143414307 | U23: =S23-T23 -> 70751619 | V23: Most Recent | W23: 46203 | AB23: 2nd Most Recent | AC23: 46112 | AH23: 3rd Most Recent | AI23: 46022
A24: MaSH-3777002 | B24: 344509 | C24: HLTN 2026-DPLO - Class C | D24: UW In-Place | E24: =E$23 -> 46081 | F24: =F$23 -> 0.65609589 | G24: =G$23 -> 1.8180281e+08 | H24: =H$23 -> 1.2889299e+08 | I24: =I$23 -> 52909817 | J24: UW Stabilized Untrended | K24: =K$23 -> 46081 | L24: =L$23 -> 0.725 | M24: =M$23 -> 2.1121719e+08 | N24: =N$23 -> 1.4071191e+08 | O24: =O$23 -> 70505283 | P24: UW Stabilized Trended | Q24: =Q$23 -> 46387 | R24: =R$23 -> 0.74 | S24: =S$23 -> 214165926 | T24: =T$23 -> 143414307 | U24: =U$23 -> 70751619 | V24: Most Recent | W24: 46203 | AB24: 2nd Most Recent | AC24: 46112 | AH24: 3rd Most Recent | AI24: 46022
A25: MaSH-3777002 | B25: 344509 | C25: HLTN 2026-DPLO - Class D | D25: UW In-Place | E25: =E$23 -> 46081 | F25: =F$23 -> 0.65609589 | G25: =G$23 -> 1.8180281e+08 | H25: =H$23 -> 1.2889299e+08 | I25: =I$23 -> 52909817 | J25: UW Stabilized Untrended | K25: =K$23 -> 46081 | L25: =L$23 -> 0.725 | M25: =M$23 -> 2.1121719e+08 | N25: =N$23 -> 1.4071191e+08 | O25: =O$23 -> 70505283 | P25: UW Stabilized Trended | Q25: =Q$23 -> 46387 | R25: =R$23 -> 0.74 | S25: =S$23 -> 214165926 | T25: =T$23 -> 143414307 | U25: =U$23 -> 70751619 | V25: Most Recent | W25: 46203 | AB25: 2nd Most Recent | AC25: 46112 | AH25: 3rd Most Recent | AI25: 46022
A26: MaSH-3777674 | B26: 345181 | C26: KSL 2026-HT3 - Class B | D26: UW In-Place | E26: 46081 | F26: 0.78382656 | G26: 265516315 | H26: 1.7408766e+08 | I26: 91428653 | J26: UW Stabilized Untrended | K26: 46081 | L26: 0.78107338 | M26: 2.6518861e+08 | N26: 1.7563452e+08 | O26: 89554098 | P26: UW Stabilized Trended | Q26: 46387 | R26: 0.784 | S26: 272884617 | T26: =272884617-92323109 -> 180561508 | U26: =S26-T26 -> 92323109 | V26: Most Recent | W26: 46203 | AB26: 2nd Most Recent | AC26: 46112 | AH26: 3rd Most Recent | AI26: 46022
A27: MaSH-3777674 | B27: 345181 | C27: KSL 2026-HT3 - Class C | D27: UW In-Place | E27: =E$26 -> 46081 | F27: =F$26 -> 0.78382656 | G27: =G$26 -> 265516315 | H27: =H$26 -> 1.7408766e+08 | I27: =I$26 -> 91428653 | J27: UW Stabilized Untrended | K27: =K$26 -> 46081 | L27: =L$26 -> 0.78107338 | M27: =M$26 -> 2.6518861e+08 | N27: =N$26 -> 1.7563452e+08 | O27: =O$26 -> 89554098 | P27: UW Stabilized Trended | Q27: =Q$26 -> 46387 | R27: =R$26 -> 0.784 | S27: =S$26 -> 272884617 | T27: =T$26 -> 180561508 | U27: =U$26 -> 92323109 | V27: Most Recent | W27: 46203 | AB27: 2nd Most Recent | AC27: 46112 | AH27: 3rd Most Recent | AI27: 46022
A28: MaSH-3777674 | B28: 345181 | C28: KSL 2026-HT3 - Class D | D28: UW In-Place | E28: =E$26 -> 46081 | F28: =F$26 -> 0.78382656 | G28: =G$26 -> 265516315 | H28: =H$26 -> 1.7408766e+08 | I28: =I$26 -> 91428653 | J28: UW Stabilized Untrended | K28: =K$26 -> 46081 | L28: =L$26 -> 0.78107338 | M28: =M$26 -> 2.6518861e+08 | N28: =N$26 -> 1.7563452e+08 | O28: =O$26 -> 89554098 | P28: UW Stabilized Trended | Q28: =Q$26 -> 46387 | R28: =R$26 -> 0.784 | S28: =S$26 -> 272884617 | T28: =T$26 -> 180561508 | U28: =U$26 -> 92323109 | V28: Most Recent | W28: 46203 | AB28: 2nd Most Recent | AC28: 46112 | AH28: 3rd Most Recent | AI28: 46022
A29: MaSH-3779335 | B29: 346842 | C29: AHPT 2026-ATRM - Class B | D29: UW In-Place | E29: 46173 | F29: 0.73351356 | G29: 2.4117197e+08 | H29: 1.7166238e+08 | I29: 69509594 | J29: UW Stabilized Untrended | K29: 46173 | L29: 0.72504047 | M29: 2.3848107e+08 | N29: 1.7203549e+08 | O29: 66445578 | P29: UW Stabilized Trended | Q29: 46387 | R29: 0.733 | S29: 244421636 | T29: =244421636-70813368 -> 173608268 | U29: =S29-T29 -> 70813368 | V29: Most Recent | W29: 46203 | AB29: 2nd Most Recent | AC29: 46112 | AH29: 3rd Most Recent | AI29: 46022
A30: MaSH-3779335 | B30: 346842 | C30: AHPT 2026-ATRM - Class C | D30: UW In-Place | E30: =E$29 -> 46173 | F30: =F$29 -> 0.73351356 | G30: =G$29 -> 2.4117197e+08 | H30: =H$29 -> 1.7166238e+08 | I30: =I$29 -> 69509594 | J30: UW Stabilized Untrended | K30: =K$29 -> 46173 | L30: =L$29 -> 0.72504047 | M30: =M$29 -> 2.3848107e+08 | N30: =N$29 -> 1.7203549e+08 | O30: =O$29 -> 66445578 | P30: UW Stabilized Trended | Q30: =Q$29 -> 46387 | R30: =R$29 -> 0.733 | S30: =S$29 -> 244421636 | T30: =T$29 -> 173608268 | U30: =U$29 -> 70813368 | V30: Most Recent | W30: 46203 | AB30: 2nd Most Recent | AC30: 46112 | AH30: 3rd Most Recent | AI30: 46022
A31: MaSH-3779335 | B31: 346842 | C31: AHPT 2026-ATRM - Class D | D31: UW In-Place | E31: =E$29 -> 46173 | F31: =F$29 -> 0.73351356 | G31: =G$29 -> 2.4117197e+08 | H31: =H$29 -> 1.7166238e+08 | I31: =I$29 -> 69509594 | J31: UW Stabilized Untrended | K31: =K$29 -> 46173 | L31: =L$29 -> 0.72504047 | M31: =M$29 -> 2.3848107e+08 | N31: =N$29 -> 1.7203549e+08 | O31: =O$29 -> 66445578 | P31: UW Stabilized Trended | Q31: =Q$29 -> 46387 | R31: =R$29 -> 0.733 | S31: =S$29 -> 244421636 | T31: =T$29 -> 173608268 | U31: =U$29 -> 70813368 | V31: Most Recent | W31: 46203 | AB31: 2nd Most Recent | AC31: 46112 | AH31: 3rd Most Recent | AI31: 46022
A32: MaSH-3779335 | B32: 346842 | C32: AHPT 2026-ATRM - Class E | D32: UW In-Place | E32: =E$29 -> 46173 | F32: =F$29 -> 0.73351356 | G32: =G$29 -> 2.4117197e+08 | H32: =H$29 -> 1.7166238e+08 | I32: =I$29 -> 69509594 | J32: UW Stabilized Untrended | K32: =K$29 -> 46173 | L32: =L$29 -> 0.72504047 | M32: =M$29 -> 2.3848107e+08 | N32: =N$29 -> 1.7203549e+08 | O32: =O$29 -> 66445578 | P32: UW Stabilized Trended | Q32: =Q$29 -> 46387 | R32: =R$29 -> 0.733 | S32: =S$29 -> 244421636 | T32: =T$29 -> 173608268 | U32: =U$29 -> 70813368 | V32: Most Recent | W32: 46203 | AB32: 2nd Most Recent | AC32: 46112 | AH32: 3rd Most Recent | AI32: 46022
A33: MaSH-3748736 | B33: 316243 | C33: Bridge Loan Trust | D33: UW In-Place | E33: 45900 | F33: =(184*0.446+240*0.192+222*0.856+312*0.84+160*0.348+312*0.8+162*0.915+110*0.473+276*0.42+178*0.195+75*0.938+174*0.92+514*0.145+254*0.0819999999999999+150*0.695+96*0.89+56*0.62)/3475 -> 0.5141364 | G33: 36481903 | H33: 17328987 | I33: =G33-H33 -> 19152916 | J33: UW Stabilized Untrended | K33: 45900 | L33: =1-6780925/70125728 -> 0.90330332 | M33: 65663328 | N33: 30804297 | O33: =M33-N33 -> 34859031 | P33: UW Stabilized Trended | Q33: 47726 | R33: =1-7709037/79783992 -> 0.90337614 | S33: 74559759 | T33: 34599209 | U33: =S33-T33 -> 39960550 | V33: Most Recent | W33: 46203 | AB33: 2nd Most Recent | AC33: 46112 | AH33: 3rd Most Recent | AI33: 46022
A34: MaSH-3748736 | B34: 316243 | C34: Bridge Loan Trust - Residual Class B | D34: UW In-Place | E34: =E$33 -> 45900 | F34: =F$33 -> 0.5141364 | G34: =G$33 -> 36481903 | H34: =H$33 -> 17328987 | I34: =I$33 -> 19152916 | J34: UW Stabilized Untrended | K34: =K$33 -> 45900 | L34: =L$33 -> 0.90330332 | M34: =M$33 -> 65663328 | N34: =N$33 -> 30804297 | O34: =O$33 -> 34859031 | P34: UW Stabilized Trended | Q34: =Q$33 -> 47726 | R34: =R$33 -> 0.90337614 | S34: =S$33 -> 74559759 | T34: =T$33 -> 34599209 | U34: =U$33 -> 39960550 | V34: Most Recent | W34: 46203 | AB34: 2nd Most Recent | AC34: 46112 | AH34: 3rd Most Recent | AI34: 46022

Sheet Capital Stack
A2: Mash-ID | B2: Deal Code | C2: Loan Name | D2: Debt Stack Type | E2: SSP Investment Type | F2: Legal Form | G2: Legal Form (Position Report) | H2: SSP Commitment Amount | I2: SSP Initial Loan Balance | J2: Funding Program | K2: Purchase Price | L2: SSP Invested Capital at Close | M2: SSP Total Invested Capital | N2: SSP Total Future Funding | O2: SSP Last Dollar Exposure | P2: Investment Level Leverage | Q2: Leverage Provider | R2: Total Debt | S2: Total Cost | T2: Total Appraised Value | U2: Total Underwritten Value | V2: Most Senior Position | W2: Most Senior Commitment | X2: Most Senior Detachment Point | Y2: Most Senior Attachment Point | Z2: Most Senior Advance Rate | AA2: Most Senior LTV | AB2: Most Senior Spread | AC2: 2nd Most Senior Position | AD2: 2nd Most Senior Commitment | AE2: 2nd Most Senior Detachment Point | AF2: 2nd Most Senior Attachment Point | AG2: 2nd Most Senior Advance Rate | AH2: 2nd Most Senior LTV | AI2: 2nd Most Senior Spread | AJ2: 3rd Most Senior Position | AK2: 3rd Most Senior Commitment | AL2: 3rd Most Senior Detachment Point | AM2: 3rd Most Senior Attachment Point | AN2: 3rd Most Senior Advance Rate | AO2: 3rd Most Senior LTV | AP2: 3rd Most Senior Spread | AQ2: 4th Most Senior Position | AR2: 4th Most Senior Commitment | AS2: 4th Most Senior Detachment Point | AT2: 4th Most Senior Attachment Point | AU2: 4th Most Senior Advance Rate | AV2: 4thMost Senior LTV | AW2: 4th Most Senior Spread
A3: MaSH-3410443 | B3: 67692 | C3: Project Sequoia | D3: A Note | E3: Syndication | F3: Mortgage | G3: CRE Loan Senior | H3: 154500000 | I3: 149600000 | J3: Multiple Funding | K3: 0.9303 | L3: =I3*K3 -> 139172880 | M3: =L3+N3 -> 144072880 | N3: =H3-I3 -> 4900000 | O3: =W3 -> 1962073941 | P3: N/A - Unlevered | Q3: N/A | R3: =IF(OR(V3="",V3="N/A",V3="Common Equity",V3="Builder Deposit / Equity"),0,N(W3))+IF(OR(AC3="",AC3="N/A",AC3="Common Equity",AC3="Builder Deposit / Equity"),0,N(AD3))+IF(OR(AJ3="",AJ3="N/A",AJ3="Common Equity",AJ3="Builder Deposit / Equity"),0,N(AK3))+IF(OR(AQ3="",AQ3="N/A",AQ3="Common Equity",AQ3="Builder Deposit / Equity"),0,N(AR3)) -> 1962073941 | S3: 3065449030 | T3: 3199100000 | U3: 2412300000 | V3: Senior Mortgage | W3: 1962073941 | X3: 0 | Y3: =IF(OR(V3="",V3="N/A",V3="Common Equity",V3="Builder Deposit / Equity",N($R3)=0),"N/A",SUM($W3)/$R3*100) -> 100 | Z3: =IF(OR(V3="",V3="N/A",V3="Common Equity",V3="Builder Deposit / Equity",N($R3)=0),"N/A",SUM($W3)/$R3*100) -> 100 | AA3: =IF(OR(V3="",V3="N/A",N($T3)=0),"N/A",SUM($W3)/$T3*100) -> 61.33206 | AB3: 0.024 | AC3: Common Equity | AD3: =T3-W3 -> 1237026059 | AE3: =IF(OR(AC3="",AC3="N/A"),"N/A",Y3) -> 100 | AF3: =IF(OR(AC3="",AC3="N/A",AC3="Common Equity",AC3="Builder Deposit / Equity",N($R3)=0),"N/A",SUM($W3,$AD3)/$R3*100) -> N/A | AG3: =IF(OR(AC3="",AC3="N/A",AC3="Common Equity",AC3="Builder Deposit / Equity",N($R3)=0),"N/A",SUM($W3,$AD3)/$R3*100) -> N/A | AH3: =IF(OR(AC3="",AC3="N/A",N($T3)=0),"N/A",SUM($W3,$AD3)/$T3*100) -> 100 | AI3: N/A
A4: MaSH-3256633 | B4: 61883 | C4: Project Royale | D4: A Note | E4: Syndication | F4: Mortgage | G4: CRE Loan Senior | H4: 98100000 | I4: 98100000 | J4: Single Funding | K4: 0.99 | L4: =I4*K4 -> 97119000 | M4: =L4+N4 -> 97119000 | N4: =H4-I4 -> 0 | O4: =W4 -> 248100000 | P4: N/A - Unlevered | Q4: N/A | R4: =IF(OR(V4="",V4="N/A",V4="Common Equity",V4="Builder Deposit / Equity"),0,N(W4))+IF(OR(AC4="",AC4="N/A",AC4="Common Equity",AC4="Builder Deposit / Equity"),0,N(AD4))+IF(OR(AJ4="",AJ4="N/A",AJ4="Common Equity",AJ4="Builder Deposit / Equity"),0,N(AK4))+IF(OR(AQ4="",AQ4="N/A",AQ4="Common Equity",AQ4="Builder Deposit / Equity"),0,N(AR4)) -> 300100000 | S4: 394100000 | T4: 400000000 | U4: 407287722 | V4: Senior Mortgage | W4: 248100000 | X4: 0 | Y4: =IF(OR(V4="",V4="N/A",V4="Common Equity",V4="Builder Deposit / Equity",N($R4)=0),"N/A",SUM($W4)/$R4*100) -> 82.672443 | Z4: =IF(OR(V4="",V4="N/A",V4="Common Equity",V4="Builder Deposit / Equity",N($R4)=0),"N/A",SUM($W4)/$R4*100) -> 82.672443 | AA4: =IF(OR(V4="",V4="N/A",N($T4)=0),"N/A",SUM($W4)/$T4*100) -> 62.025 | AB4: 0.0233 | AC4: Mezzanine | AD4: 52000000 | AE4: =IF(OR(AC4="",AC4="N/A"),"N/A",Y4) -> 82.672443 | AF4: =IF(OR(AC4="",AC4="N/A",AC4="Common Equity",AC4="Builder Deposit / Equity",N($R4)=0),"N/A",SUM($W4,$AD4)/$R4*100) -> 100 | AG4: =IF(OR(AC4="",AC4="N/A",AC4="Common Equity",AC4="Builder Deposit / Equity",N($R4)=0),"N/A",SUM($W4,$AD4)/$R4*100) -> 100 | AH4: =IF(OR(AC4="",AC4="N/A",N($T4)=0),"N/A",SUM($W4,$AD4)/$T4*100) -> 75.025 | AI4: 0.0535 | AJ4: Common Equity | AK4: =T4-W4-AD4 -> 99900000 | AL4: =IF(OR(AJ4="",AJ4="N/A"),"N/A",AF4) -> 100 | AM4: =IF(OR(AJ4="",AJ4="N/A",AJ4="Common Equity",AJ4="Builder Deposit / Equity",N($R4)=0),"N/A",SUM($W4,$AD4,$AK4)/$R4*100) -> N/A | AN4: =IF(OR(AJ4="",AJ4="N/A",AJ4="Common Equity",AJ4="Builder Deposit / Equity",N($R4)=0),"N/A",SUM($W4,$AD4,$AK4)/$R4*100) -> N/A | AO4: =IF(OR(AJ4="",AJ4="N/A",N($T4)=0),"N/A",SUM($W4,$AD4,$AK4)/$T4*100) -> 100 | AP4: N/A
A5: MaSH-3258016 | B5: 61973 | C5: Lakefront North | D5: A Note | E5: Origination | F5: Mortgage | G5: CRE Loan Senior | H5: 50000000 | I5: 50000000 | J5: Single Funding | K5: 1 | L5: =I5*K5 -> 50000000 | M5: =L5+N5 -> 50000000 | N5: =H5-I5 -> 0 | O5: =W5 -> 50000000 | P5: N/A - Unlevered | Q5: N/A | R5: =IF(OR(V5="",V5="N/A",V5="Common Equity",V5="Builder Deposit / Equity"),0,N(W5))+IF(OR(AC5="",AC5="N/A",AC5="Common Equity",AC5="Builder Deposit / Equity"),0,N(AD5))+IF(OR(AJ5="",AJ5="N/A",AJ5="Common Equity",AJ5="Builder Deposit / Equity"),0,N(AK5))+IF(OR(AQ5="",AQ5="N/A",AQ5="Common Equity",AQ5="Builder Deposit / Equity"),0,N(AR5)) -> 50000000 | S5: 94400000 | T5: 92100000 | U5: 80133338 | V5: Senior Mortgage | W5: 50000000 | X5: 0 | Y5: =IF(OR(V5="",V5="N/A",V5="Common Equity",V5="Builder Deposit / Equity",N($R5)=0),"N/A",SUM($W5)/$R5*100) -> 100 | Z5: =IF(OR(V5="",V5="N/A",V5="Common Equity",V5="Builder Deposit / Equity",N($R5)=0),"N/A",SUM($W5)/$R5*100) -> 100 | AA5: =IF(OR(V5="",V5="N/A",N($T5)=0),"N/A",SUM($W5)/$T5*100) -> 54.288817 | AB5: N/A | AC5: Common Equity | AD5: =T5-W5 -> 42100000 | AE5: =IF(OR(AC5="",AC5="N/A"),"N/A",Y5) -> 100 | AF5: =IF(OR(AC5="",AC5="N/A",AC5="Common Equity",AC5="Builder Deposit / Equity",N($R5)=0),"N/A",SUM($W5,$AD5)/$R5*100) -> N/A | AG5: =IF(OR(AC5="",AC5="N/A",AC5="Common Equity",AC5="Builder Deposit / Equity",N($R5)=0),"N/A",SUM($W5,$AD5)/$R5*100) -> N/A | AH5: =IF(OR(AC5="",AC5="N/A",N($T5)=0),"N/A",SUM($W5,$AD5)/$T5*100) -> 100 | AI5: N/A
A6: MaSH-3339577 | B6: 64734 | C6: Project Balboa | D6: A Note | E6: Syndication | F6: Mortgage | G6: CRE Loan Senior | H6: 41250000 | I6: 31995000 | J6: Multiple Funding | K6: 0.995 | L6: =I6*K6 -> 31835025 | M6: =L6+N6 -> 41090025 | N6: =H6-I6 -> 9255000 | O6: =W6 -> 41250000 | P6: N/A - Unlevered | Q6: N/A | R6: =IF(OR(V6="",V6="N/A",V6="Common Equity",V6="Builder Deposit / Equity"),0,N(W6))+IF(OR(AC6="",AC6="N/A",AC6="Common Equity",AC6="Builder Deposit / Equity"),0,N(AD6))+IF(OR(AJ6="",AJ6="N/A",AJ6="Common Equity",AJ6="Builder Deposit / Equity"),0,N(AK6))+IF(OR(AQ6="",AQ6="N/A",AQ6="Common Equity",AQ6="Builder Deposit / Equity"),0,N(AR6)) -> 55000000 | S6: 86500000 | T6: 105800000 | U6: 67005112 | V6: Senior Mortgage | W6: 41250000 | X6: 0 | Y6: =IF(OR(V6="",V6="N/A",V6="Common Equity",V6="Builder Deposit / Equity",N($R6)=0),"N/A",SUM($W6)/$R6*100) -> 75 | Z6: =IF(OR(V6="",V6="N/A",V6="Common Equity",V6="Builder Deposit / Equity",N($R6)=0),"N/A",SUM($W6)/$R6*100) -> 75 | AA6: =IF(OR(V6="",V6="N/A",N($T6)=0),"N/A",SUM($W6)/$T6*100) -> 38.988658 | AB6: 0.035 | AC6: B-Note | AD6: 13750000 | AE6: =IF(OR(AC6="",AC6="N/A"),"N/A",Y6) -> 75 | AF6: =IF(OR(AC6="",AC6="N/A",AC6="Common Equity",AC6="Builder Deposit / Equity",N($R6)=0),"N/A",SUM($W6,$AD6)/$R6*100) -> 100 | AG6: =IF(OR(AC6="",AC6="N/A",AC6="Common Equity",AC6="Builder Deposit / Equity",N($R6)=0),"N/A",SUM($W6,$AD6)/$R6*100) -> 100 | AH6: =IF(OR(AC6="",AC6="N/A",N($T6)=0),"N/A",SUM($W6,$AD6)/$T6*100) -> 51.984877 | AI6: N/A | AJ6: Common Equity | AK6: =T6-W6-AD6 -> 50800000 | AL6: =IF(OR(AJ6="",AJ6="N/A"),"N/A",AF6) -> 100 | AM6: =IF(OR(AJ6="",AJ6="N/A",AJ6="Common Equity",AJ6="Builder Deposit / Equity",N($R6)=0),"N/A",SUM($W6,$AD6,$AK6)/$R6*100) -> N/A | AN6: =IF(OR(AJ6="",AJ6="N/A",AJ6="Common Equity",AJ6="Builder Deposit / Equity",N($R6)=0),"N/A",SUM($W6,$AD6,$AK6)/$R6*100) -> N/A | AO6: =IF(OR(AJ6="",AJ6="N/A",N($T6)=0),"N/A",SUM($W6,$AD6,$AK6)/$T6*100) -> 100 | AP6: N/A
A7: MaSH-3534532 | B7: 102039 | C7: Project Cubic | D7: A Note | E7: Syndication | F7: Mortgage | G7: CRE Loan Senior | H7: 50100000 | I7: 50100000 | J7: Single Funding | K7: 0.9465 | L7: =I7*K7 -> 47419650 | M7: =L7+N7 -> 47419650 | N7: =H7-I7 -> 0 | O7: =W7 -> 1435000000 | P7: N/A - Unlevered | Q7: N/A | R7: =IF(OR(V7="",V7="N/A",V7="Common Equity",V7="Builder Deposit / Equity"),0,N(W7))+IF(OR(AC7="",AC7="N/A",AC7="Common Equity",AC7="Builder Deposit / Equity"),0,N(AD7))+IF(OR(AJ7="",AJ7="N/A",AJ7="Common Equity",AJ7="Builder Deposit / Equity"),0,N(AK7))+IF(OR(AQ7="",AQ7="N/A",AQ7="Common Equity",AQ7="Builder Deposit / Equity"),0,N(AR7)) -> 1850000000 | S7: 1850000000 | T7: 2480000000 | U7: 1432900000 | V7: Senior Mortgage | W7: 1435000000 | X7: 0 | Y7: =IF(OR(V7="",V7="N/A",V7="Common Equity",V7="Builder Deposit / Equity",N($R7)=0),"N/A",SUM($W7)/$R7*100) -> 77.567568 | Z7: =IF(OR(V7="",V7="N/A",V7="Common Equity",V7="Builder Deposit / Equity",N($R7)=0),"N/A",SUM($W7)/$R7*100) -> 77.567568 | AA7: =IF(OR(V7="",V7="N/A",N($T7)=0),"N/A",SUM($W7)/$T7*100) -> 57.862903 | AB7: 0.0169809 | AC7: Mezzanine | AD7: 415000000 | AE7: =IF(OR(AC7="",AC7="N/A"),"N/A",Y7) -> 77.567568 | AF7: =IF(OR(AC7="",AC7="N/A",AC7="Common Equity",AC7="Builder Deposit / Equity",N($R7)=0),"N/A",SUM($W7,$AD7)/$R7*100) -> 100 | AG7: =IF(OR(AC7="",AC7="N/A",AC7="Common Equity",AC7="Builder Deposit / Equity",N($R7)=0),"N/A",SUM($W7,$AD7)/$R7*100) -> 100 | AH7: =IF(OR(AC7="",AC7="N/A",N($T7)=0),"N/A",SUM($W7,$AD7)/$T7*100) -> 74.596774 | AI7: 0.0505 | AJ7: Common Equity | AK7: =T7-W7-AD7 -> 630000000 | AL7: =IF(OR(AJ7="",AJ7="N/A"),"N/A",AF7) -> 100 | AM7: =IF(OR(AJ7="",AJ7="N/A",AJ7="Common Equity",AJ7="Builder Deposit / Equity",N($R7)=0),"N/A",SUM($W7,$AD7,$AK7)/$R7*100) -> N/A | AN7: =IF(OR(AJ7="",AJ7="N/A",AJ7="Common Equity",AJ7="Builder Deposit / Equity",N($R7)=0),"N/A",SUM($W7,$AD7,$AK7)/$R7*100) -> N/A | AO7: =IF(OR(AJ7="",AJ7="N/A",N($T7)=0),"N/A",SUM($W7,$AD7,$AK7)/$T7*100) -> 100 | AP7: N/A
A8: MaSH-3337170 | B8: 64681 | C8: Project Eyas | D8: A Note | E8: Syndication | F8: Mortgage | G8: CRE Loan Senior | H8: 70700000 | I8: 67217966 | J8: Multiple Funding | K8: 0.9575 | L8: =I8*K8 -> 64361202 | M8: =L8+N8 -> 67843236 | N8: =H8-I8 -> 3482034.2 | O8: =W8 -> 2.2070177e+08 | P8: N/A - Unlevered | Q8: N/A | R8: =IF(OR(V8="",V8="N/A",V8="Common Equity",V8="Builder Deposit / Equity"),0,N(W8))+IF(OR(AC8="",AC8="N/A",AC8="Common Equity",AC8="Builder Deposit / Equity"),0,N(AD8))+IF(OR(AJ8="",AJ8="N/A",AJ8="Common Equity",AJ8="Builder Deposit / Equity"),0,N(AK8))+IF(OR(AQ8="",AQ8="N/A",AQ8="Common Equity",AQ8="Builder Deposit / Equity"),0,N(AR8)) -> 2.75729e+08 | S8: 368328856 | T8: 353800000 | U8: 310343107 | V8: Senior Mortgage | W8: 2.2070177e+08 | X8: 0 | Y8: =IF(OR(V8="",V8="N/A",V8="Common Equity",V8="Builder Deposit / Equity",N($R8)=0),"N/A",SUM($W8)/$R8*100) -> 80.043002 | Z8: =IF(OR(V8="",V8="N/A",V8="Common Equity",V8="Builder Deposit / Equity",N($R8)=0),"N/A",SUM($W8)/$R8*100) -> 80.043002 | AA8: =IF(OR(V8="",V8="N/A",N($T8)=0),"N/A",SUM($W8)/$T8*100) -> 62.380376 | AB8: 0.0228 | AC8: Mezzanine | AD8: 55027230 | AE8: =IF(OR(AC8="",AC8="N/A"),"N/A",Y8) -> 80.043002 | AF8: =IF(OR(AC8="",AC8="N/A",AC8="Common Equity",AC8="Builder Deposit / Equity",N($R8)=0),"N/A",SUM($W8,$AD8)/$R8*100) -> 100 | AG8: =IF(OR(AC8="",AC8="N/A",AC8="Common Equity",AC8="Builder Deposit / Equity",N($R8)=0),"N/A",SUM($W8,$AD8)/$R8*100) -> 100 | AH8: =IF(OR(AC8="",AC8="N/A",N($T8)=0),"N/A",SUM($W8,$AD8)/$T8*100) -> 77.933578 | AI8: 0.0575 | AJ8: Common Equity | AK8: =T8-W8-AD8 -> 78071000 | AL8: =IF(OR(AJ8="",AJ8="N/A"),"N/A",AF8) -> 100 | AM8: =IF(OR(AJ8="",AJ8="N/A",AJ8="Common Equity",AJ8="Builder Deposit / Equity",N($R8)=0),"N/A",SUM($W8,$AD8,$AK8)/$R8*100) -> N/A | AN8: =IF(OR(AJ8="",AJ8="N/A",AJ8="Common Equity",AJ8="Builder Deposit / Equity",N($R8)=0),"N/A",SUM($W8,$AD8,$AK8)/$R8*100) -> N/A | AO8: =IF(OR(AJ8="",AJ8="N/A",N($T8)=0),"N/A",SUM($W8,$AD8,$AK8)/$T8*100) -> 100 | AP8: N/A
A9: MaSH-3340378 | B9: 64777 | C9: Project Stripe | D9: A Note | E9: Syndication | F9: Mortgage | G9: CRE Loan Senior | H9: 96000000 | I9: 96000000 | J9: Single Funding | K9: 0.9225 | L9: =I9*K9 -> 88560000 | M9: =L9+N9 -> 88560000 | N9: =H9-I9 -> 0 | O9: =W9 -> 550600000 | P9: N/A - Unlevered | Q9: N/A | R9: =IF(OR(V9="",V9="N/A",V9="Common Equity",V9="Builder Deposit / Equity"),0,N(W9))+IF(OR(AC9="",AC9="N/A",AC9="Common Equity",AC9="Builder Deposit / Equity"),0,N(AD9))+IF(OR(AJ9="",AJ9="N/A",AJ9="Common Equity",AJ9="Builder Deposit / Equity"),0,N(AK9))+IF(OR(AQ9="",AQ9="N/A",AQ9="Common Equity",AQ9="Builder Deposit / Equity"),0,N(AR9)) -> 696000000 | S9: 870450000 | T9: 825300000 | U9: 688775190 | V9: Senior Mortgage | W9: 550600000 | X9: 0 | Y9: =IF(OR(V9="",V9="N/A",V9="Common Equity",V9="Builder Deposit / Equity",N($R9)=0),"N/A",SUM($W9)/$R9*100) -> 79.109195 | Z9: =IF(OR(V9="",V9="N/A",V9="Common Equity",V9="Builder Deposit / Equity",N($R9)=0),"N/A",SUM($W9)/$R9*100) -> 79.109195 | AA9: =IF(OR(V9="",V9="N/A",N($T9)=0),"N/A",SUM($W9)/$T9*100) -> 66.715134 | AB9: 0.018 | AC9: Mezzanine | AD9: 145400000 | AE9: =IF(OR(AC9="",AC9="N/A"),"N/A",Y9) -> 79.109195 | AF9: =IF(OR(AC9="",AC9="N/A",AC9="Common Equity",AC9="Builder Deposit / Equity",N($R9)=0),"N/A",SUM($W9,$AD9)/$R9*100) -> 100 | AG9: =IF(OR(AC9="",AC9="N/A",AC9="Common Equity",AC9="Builder Deposit / Equity",N($R9)=0),"N/A",SUM($W9,$AD9)/$R9*100) -> 100 | AH9: =IF(OR(AC9="",AC9="N/A",N($T9)=0),"N/A",SUM($W9,$AD9)/$T9*100) -> 84.33297 | AI9: 0.0515 | AJ9: Common Equity | AK9: =T9-W9-AD9 -> 129300000 | AL9: =IF(OR(AJ9="",AJ9="N/A"),"N/A",AF9) -> 100 | AM9: =IF(OR(AJ9="",AJ9="N/A",AJ9="Common Equity",AJ9="Builder Deposit / Equity",N($R9)=0),"N/A",SUM($W9,$AD9,$AK9)/$R9*100) -> N/A | AN9: =IF(OR(AJ9="",AJ9="N/A",AJ9="Common Equity",AJ9="Builder Deposit / Equity",N($R9)=0),"N/A",SUM($W9,$AD9,$AK9)/$R9*100) -> N/A | AO9: =IF(OR(AJ9="",AJ9="N/A",N($T9)=0),"N/A",SUM($W9,$AD9,$AK9)/$T9*100) -> 100 | AP9: N/A
A10: MaSH-3687981 | B10: 255488 | C10: Project Bellevue | D10: A Note | E10: Syndication | F10: Mortgage | G10: CRE Loan Senior | H10: 40000000 | I10: 40000000 | J10: Single Funding | K10: 0.994 | L10: =I10*K10 -> 39760000 | M10: =L10+N10 -> 39760000 | N10: =H10-I10 -> 0 | O10: =W10 -> 156500000 | P10: N/A - Unlevered | Q10: N/A | R10: =IF(OR(V10="",V10="N/A",V10="Common Equity",V10="Builder Deposit / Equity"),0,N(W10))+IF(OR(AC10="",AC10="N/A",AC10="Common Equity",AC10="Builder Deposit / Equity"),0,N(AD10))+IF(OR(AJ10="",AJ10="N/A",AJ10="Common Equity",AJ10="Builder Deposit / Equity"),0,N(AK10))+IF(OR(AQ10="",AQ10="N/A",AQ10="Common Equity",AQ10="Builder Deposit / Equity"),0,N(AR10)) -> 168500000 | S10: 377585009 | T10: 269950000 | U10: 220400000 | V10: Senior Mortgage | W10: 156500000 | X10: 0 | Y10: =IF(OR(V10="",V10="N/A",V10="Common Equity",V10="Builder Deposit / Equity",N($R10)=0),"N/A",SUM($W10)/$R10*100) -> 92.878338 | Z10: =IF(OR(V10="",V10="N/A",V10="Common Equity",V10="Builder Deposit / Equity",N($R10)=0),"N/A",SUM($W10)/$R10*100) -> 92.878338 | AA10: =IF(OR(V10="",V10="N/A",N($T10)=0),"N/A",SUM($W10)/$T10*100) -> 57.973699 | AB10: 0.04 | AC10: Preferred Equity | AD10: 12000000 | AE10: =IF(OR(AC10="",AC10="N/A"),"N/A",Y10) -> 92.878338 | AF10: =IF(OR(AC10="",AC10="N/A",AC10="Common Equity",AC10="Builder Deposit / Equity",N($R10)=0),"N/A",SUM($W10,$AD10)/$R10*100) -> 100 | AG10: =IF(OR(AC10="",AC10="N/A",AC10="Common Equity",AC10="Builder Deposit / Equity",N($R10)=0),"N/A",SUM($W10,$AD10)/$R10*100) -> 100 | AH10: =IF(OR(AC10="",AC10="N/A",N($T10)=0),"N/A",SUM($W10,$AD10)/$T10*100) -> 62.418966 | AI10: N/A | AJ10: Common Equity | AK10: =T10-W10-AD10 -> 101450000 | AL10: =IF(OR(AJ10="",AJ10="N/A"),"N/A",AF10) -> 100 | AM10: =IF(OR(AJ10="",AJ10="N/A",AJ10="Common Equity",AJ10="Builder Deposit / Equity",N($R10)=0),"N/A",SUM($W10,$AD10,$AK10)/$R10*100) -> N/A | AN10: =IF(OR(AJ10="",AJ10="N/A",AJ10="Common Equity",AJ10="Builder Deposit / Equity",N($R10)=0),"N/A",SUM($W10,$AD10,$AK10)/$R10*100) -> N/A | AO10: =IF(OR(AJ10="",AJ10="N/A",N($T10)=0),"N/A",SUM($W10,$AD10,$AK10)/$T10*100) -> 100 | AP10: N/A
A11: MaSH-3773167 | B11: 340674 | C11: Project Fayetteville 2-Pack | D11: A Note | E11: Syndication | F11: Mortgage | G11: CRE Loan Senior | H11: 40000000 | I11: 40000000 | J11: Single Funding | K11: 1 | L11: =I11*K11 -> 40000000 | M11: =L11+N11 -> 40000000 | N11: =H11-I11 -> 0 | O11: =W11 -> 40000000 | P11: N/A - Unlevered | Q11: N/A | R11: =IF(OR(V11="",V11="N/A",V11="Common Equity",V11="Builder Deposit / Equity"),0,N(W11))+IF(OR(AC11="",AC11="N/A",AC11="Common Equity",AC11="Builder Deposit / Equity"),0,N(AD11))+IF(OR(AJ11="",AJ11="N/A",AJ11="Common Equity",AJ11="Builder Deposit / Equity"),0,N(AK11))+IF(OR(AQ11="",AQ11="N/A",AQ11="Common Equity",AQ11="Builder Deposit / Equity"),0,N(AR11)) -> 40000000 | S11: 40000000 | T11: 57300000 | U11: 54100000 | V11: Senior Mortgage | W11: 40000000 | X11: 0 | Y11: =IF(OR(V11="",V11="N/A",V11="Common Equity",V11="Builder Deposit / Equity",N($R11)=0),"N/A",SUM($W11)/$R11*100) -> 100 | Z11: =IF(OR(V11="",V11="N/A",V11="Common Equity",V11="Builder Deposit / Equity",N($R11)=0),"N/A",SUM($W11)/$R11*100) -> 100 | AA11: =IF(OR(V11="",V11="N/A",N($T11)=0),"N/A",SUM($W11)/$T11*100) -> 69.808028 | AB11: 0.0251 | AC11: Common Equity | AD11: =T11-W11 -> 17300000 | AE11: =IF(OR(AC11="",AC11="N/A"),"N/A",Y11) -> 100 | AF11: =IF(OR(AC11="",AC11="N/A",AC11="Common Equity",AC11="Builder Deposit / Equity",N($R11)=0),"N/A",SUM($W11,$AD11)/$R11*100) -> N/A | AG11: =IF(OR(AC11="",AC11="N/A",AC11="Common Equity",AC11="Builder Deposit / Equity",N($R11)=0),"N/A",SUM($W11,$AD11)/$R11*100) -> N/A | AH11: =IF(OR(AC11="",AC11="N/A",N($T11)=0),"N/A",SUM($W11,$AD11)/$T11*100) -> 100 | AI11: N/A
A12: MaSH-3774814 | B12: 342321 | C12: Mosaic Apartments | D12: A Note | E12: Syndication | F12: Mortgage | G12: CRE Loan Senior | H12: 48400000 | I12: 48400000 | J12: Single Funding | K12: 1 | L12: =I12*K12 -> 48400000 | M12: =L12+N12 -> 48400000 | N12: =H12-I12 -> 0 | O12: =W12 -> 48400000 | P12: N/A - Unlevered | Q12: N/A | R12: =IF(OR(V12="",V12="N/A",V12="Common Equity",V12="Builder Deposit / Equity"),0,N(W12))+IF(OR(AC12="",AC12="N/A",AC12="Common Equity",AC12="Builder Deposit / Equity"),0,N(AD12))+IF(OR(AJ12="",AJ12="N/A",AJ12="Common Equity",AJ12="Builder Deposit / Equity"),0,N(AK12))+IF(OR(AQ12="",AQ12="N/A",AQ12="Common Equity",AQ12="Builder Deposit / Equity"),0,N(AR12)) -> 48400000 | S12: 48400000 | T12: 78800000 | U12: 68000000 | V12: Senior Mortgage | W12: 48400000 | X12: 0 | Y12: =IF(OR(V12="",V12="N/A",V12="Common Equity",V12="Builder Deposit / Equity",N($R12)=0),"N/A",SUM($W12)/$R12*100) -> 100 | Z12: =IF(OR(V12="",V12="N/A",V12="Common Equity",V12="Builder Deposit / Equity",N($R12)=0),"N/A",SUM($W12)/$R12*100) -> 100 | AA12: =IF(OR(V12="",V12="N/A",N($T12)=0),"N/A",SUM($W12)/$T12*100) -> 61.42132 | AB12: 0.0251 | AC12: Common Equity | AD12: =T12-W12 -> 30400000 | AE12: =IF(OR(AC12="",AC12="N/A"),"N/A",Y12) -> 100 | AF12: =IF(OR(AC12="",AC12="N/A",AC12="Common Equity",AC12="Builder Deposit / Equity",N($R12)=0),"N/A",SUM($W12,$AD12)/$R12*100) -> N/A | AG12: =IF(OR(AC12="",AC12="N/A",AC12="Common Equity",AC12="Builder Deposit / Equity",N($R12)=0),"N/A",SUM($W12,$AD12)/$R12*100) -> N/A | AH12: =IF(OR(AC12="",AC12="N/A",N($T12)=0),"N/A",SUM($W12,$AD12)/$T12*100) -> 100 | AI12: N/A
A13: MaSH-3774820 | B13: 342327 | C13: Project Arista | D13: A Note | E13: Syndication | F13: Mortgage | G13: CRE Loan Senior | H13: 48000000 | I13: 48000000 | J13: Single Funding | K13: 1 | L13: =I13*K13 -> 48000000 | M13: =L13+N13 -> 48000000 | N13: =H13-I13 -> 0 | O13: =W13 -> 48000000 | P13: N/A - Unlevered | Q13: N/A | R13: =IF(OR(V13="",V13="N/A",V13="Common Equity",V13="Builder Deposit / Equity"),0,N(W13))+IF(OR(AC13="",AC13="N/A",AC13="Common Equity",AC13="Builder Deposit / Equity"),0,N(AD13))+IF(OR(AJ13="",AJ13="N/A",AJ13="Common Equity",AJ13="Builder Deposit / Equity"),0,N(AK13))+IF(OR(AQ13="",AQ13="N/A",AQ13="Common Equity",AQ13="Builder Deposit / Equity"),0,N(AR13)) -> 52000000 | S13: 52000000 | T13: 78910000 | U13: 66000000 | V13: Senior Mortgage | W13: 48000000 | X13: 0 | Y13: =IF(OR(V13="",V13="N/A",V13="Common Equity",V13="Builder Deposit / Equity",N($R13)=0),"N/A",SUM($W13)/$R13*100) -> 92.307692 | Z13: =IF(OR(V13="",V13="N/A",V13="Common Equity",V13="Builder Deposit / Equity",N($R13)=0),"N/A",SUM($W13)/$R13*100) -> 92.307692 | AA13: =IF(OR(V13="",V13="N/A",N($T13)=0),"N/A",SUM($W13)/$T13*100) -> 60.828792 | AB13: 0.0235 | AC13: B-Note | AD13: 4000000 | AE13: =IF(OR(AC13="",AC13="N/A"),"N/A",Y13) -> 92.307692 | AF13: =IF(OR(AC13="",AC13="N/A",AC13="Common Equity",AC13="Builder Deposit / Equity",N($R13)=0),"N/A",SUM($W13,$AD13)/$R13*100) -> 100 | AG13: =IF(OR(AC13="",AC13="N/A",AC13="Common Equity",AC13="Builder Deposit / Equity",N($R13)=0),"N/A",SUM($W13,$AD13)/$R13*100) -> 100 | AH13: =IF(OR(AC13="",AC13="N/A",N($T13)=0),"N/A",SUM($W13,$AD13)/$T13*100) -> 65.897858 | AI13: 0.12 | AJ13: Common Equity | AK13: =T13-W13-AD13 -> 26910000 | AL13: =IF(OR(AJ13="",AJ13="N/A"),"N/A",AF13) -> 100 | AM13: =IF(OR(AJ13="",AJ13="N/A",AJ13="Common Equity",AJ13="Builder Deposit / Equity",N($R13)=0),"N/A",SUM($W13,$AD13,$AK13)/$R13*100) -> N/A | AN13: =IF(OR(AJ13="",AJ13="N/A",AJ13="Common Equity",AJ13="Builder Deposit / Equity",N($R13)=0),"N/A",SUM($W13,$AD13,$AK13)/$R13*100) -> N/A | AO13: =IF(OR(AJ13="",AJ13="N/A",N($T13)=0),"N/A",SUM($W13,$AD13,$AK13)/$T13*100) -> 100 | AP13: N/A
A14: MaSH-3700986 | B14: 268493 | C14: Project Grand Bay Hotel San Francisco | D14: A Note | E14: Origination | F14: Mortgage | G14: CRE Loan Senior | H14: 69500000 | I14: 59500000 | J14: Multiple Funding | K14: 1 | L14: =I14*K14 -> 59500000 | M14: =L14+N14 -> 69500000 | N14: =H14-I14 -> 10000000 | O14: =W14+AD14 -> 69500000 | P14: Repo/Warehouse | Q14: Santander | R14: =IF(OR(V14="",V14="N/A",V14="Common Equity",V14="Builder Deposit / Equity"),0,N(W14))+IF(OR(AC14="",AC14="N/A",AC14="Common Equity",AC14="Builder Deposit / Equity"),0,N(AD14))+IF(OR(AJ14="",AJ14="N/A",AJ14="Common Equity",AJ14="Builder Deposit / Equity"),0,N(AK14))+IF(OR(AQ14="",AQ14="N/A",AQ14="Common Equity",AQ14="Builder Deposit / Equity"),0,N(AR14)) -> 91000000 | S14: 97000000 | T14: 1.9688385e+08 | U14: 122500000 | V14: Repo/Warehouse | W14: =41650000+7000000 -> 48650000 | X14: 0 | Y14: =IF(OR(V14="",V14="N/A",V14="Common Equity",V14="Builder Deposit / Equity",N($R14)=0),"N/A",SUM($W14)/$R14*100) -> 53.461538 | Z14: =IF(OR(V14="",V14="N/A",V14="Common Equity",V14="Builder Deposit / Equity",N($R14)=0),"N/A",SUM($W14)/$R14*100) -> 53.461538 | AA14: =IF(OR(V14="",V14="N/A",N($T14)=0),"N/A",SUM($W14)/$T14*100) -> 24.71 | AB14: 0.0175 | AC14: Whole Loan (SSP Retained) | AD14: =H14-W14 -> 20850000 | AE14: =IF(OR(AC14="",AC14="N/A"),"N/A",Y14) -> 53.461538 | AF14: =IF(OR(AC14="",AC14="N/A",AC14="Common Equity",AC14="Builder Deposit / Equity",N($R14)=0),"N/A",SUM($W14,$AD14)/$R14*100) -> 76.373626 | AG14: =IF(OR(AC14="",AC14="N/A",AC14="Common Equity",AC14="Builder Deposit / Equity",N($R14)=0),"N/A",SUM($W14,$AD14)/$R14*100) -> 76.373626 | AH14: =IF(OR(AC14="",AC14="N/A",N($T14)=0),"N/A",SUM($W14,$AD14)/$T14*100) -> 35.3 | AI14: 0.0515 | AJ14: Preferred Equity | AK14: =12500000+9000000 -> 21500000 | AL14: =IF(OR(AJ14="",AJ14="N/A"),"N/A",AF14) -> 76.373626 | AM14: =IF(OR(AJ14="",AJ14="N/A",AJ14="Common Equity",AJ14="Builder Deposit / Equity",N($R14)=0),"N/A",SUM($W14,$AD14,$AK14)/$R14*100) -> 100 | AN14: =IF(OR(AJ14="",AJ14="N/A",AJ14="Common Equity",AJ14="Builder Deposit / Equity",N($R14)=0),"N/A",SUM($W14,$AD14,$AK14)/$R14*100) -> 100 | AO14: =IF(OR(AJ14="",AJ14="N/A",N($T14)=0),"N/A",SUM($W14,$AD14,$AK14)/$T14*100) -> 46.220144 | AP14: 0.08 | AQ14: Common Equity | AR14: =T14-SUM(W14,AD14,AK14) -> 1.0588385e+08 | AS14: =IF(OR(AQ14="",AQ14="N/A"),"N/A",AM14) -> 100 | AT14: =IF(OR(AQ14="",AQ14="N/A",AQ14="Common Equity",AQ14="Builder Deposit / Equity",N($R14)=0),"N/A",SUM($W14,$AD14,$AK14,$AR14)/$R14*100) -> N/A | AU14: =IF(OR(AQ14="",AQ14="N/A",AQ14="Common Equity",AQ14="Builder Deposit / Equity",N($R14)=0),"N/A",SUM($W14,$AD14,$AK14,$AR14)/$R14*100) -> N/A | AV14: =IF(OR(AQ14="",AQ14="N/A",N($T14)=0),"N/A",SUM($W14,$AD14,$AK14,$AR14)/$T14*100) -> 100 | AW14: N/A
A15: MaSH-3776991 | B15: 344498 | C15: Crystal Springs Resort | D15: A Note | E15: Origination | F15: Mortgage | G15: CRE Loan Senior | H15: 131000000 | I15: =H15 -> 131000000 | J15: Single Funding | K15: 0.9925 | L15: =I15*K15 -> 130017500 | M15: =L15+N15 -> 130017500 | N15: =H15-I15 -> 0 | O15: =W15 -> 131000000 | P15: N/A - Unlevered | Q15: N/A | R15: =IF(OR(V15="",V15="N/A",V15="Common Equity",V15="Builder Deposit / Equity"),0,N(W15))+IF(OR(AC15="",AC15="N/A",AC15="Common Equity",AC15="Builder Deposit / Equity"),0,N(AD15))+IF(OR(AJ15="",AJ15="N/A",AJ15="Common Equity",AJ15="Builder Deposit / Equity"),0,N(AK15))+IF(OR(AQ15="",AQ15="N/A",AQ15="Common Equity",AQ15="Builder Deposit / Equity"),0,N(AR15)) -> 154000000 | S15: 268000000 | T15: 232000000 | U15: 204950000 | V15: Senior Mortgage | W15: 131000000 | X15: 0 | Y15: =IF(OR(V15="",V15="N/A",V15="Common Equity",V15="Builder Deposit / Equity",N($R15)=0),"N/A",SUM($W15)/$R15*100) -> 85.064935 | Z15: =IF(OR(V15="",V15="N/A",V15="Common Equity",V15="Builder Deposit / Equity",N($R15)=0),"N/A",SUM($W15)/$R15*100) -> 85.064935 | AA15: =IF(OR(V15="",V15="N/A",N($T15)=0),"N/A",SUM($W15)/$T15*100) -> 56.465517 | AB15: 0.024 | AC15: Mezzanine | AD15: 23000000 | AE15: =IF(OR(AC15="",AC15="N/A"),"N/A",Y15) -> 85.064935 | AF15: =IF(OR(AC15="",AC15="N/A",AC15="Common Equity",AC15="Builder Deposit / Equity",N($R15)=0),"N/A",SUM($W15,$AD15)/$R15*100) -> 100 | AG15: =IF(OR(AC15="",AC15="N/A",AC15="Common Equity",AC15="Builder Deposit / Equity",N($R15)=0),"N/A",SUM($W15,$AD15)/$R15*100) -> 100 | AH15: =IF(OR(AC15="",AC15="N/A",N($T15)=0),"N/A",SUM($W15,$AD15)/$T15*100) -> 66.37931 | AI15: 0.074 | AJ15: Common Equity | AK15: =T15-W15-AD15 -> 78000000 | AL15: =IF(OR(AJ15="",AJ15="N/A"),"N/A",AF15) -> 100 | AM15: =IF(OR(AJ15="",AJ15="N/A",AJ15="Common Equity",AJ15="Builder Deposit / Equity",N($R15)=0),"N/A",SUM($W15,$AD15,$AK15)/$R15*100) -> N/A | AN15: =IF(OR(AJ15="",AJ15="N/A",AJ15="Common Equity",AJ15="Builder Deposit / Equity",N($R15)=0),"N/A",SUM($W15,$AD15,$AK15)/$R15*100) -> N/A | AO15: =IF(OR(AJ15="",AJ15="N/A",N($T15)=0),"N/A",SUM($W15,$AD15,$AK15)/$T15*100) -> 100 | AP15: N/A
A16: MaSH-3776993 | B16: 344500 | C16: Alpine Village | D16: A Note | E16: Origination | F16: Mortgage | G16: CRE Loan Senior | H16: 54250000 | I16: =H16 -> 54250000 | J16: Single Funding | K16: 1 | L16: =I16*K16 -> 54250000 | M16: =L16+N16 -> 54250000 | N16: =H16-I16 -> 0 | O16: =W16 -> 54250000 | P16: N/A - Unlevered | Q16: N/A | R16: =IF(OR(V16="",V16="N/A",V16="Common Equity",V16="Builder Deposit / Equity"),0,N(W16))+IF(OR(AC16="",AC16="N/A",AC16="Common Equity",AC16="Builder Deposit / Equity"),0,N(AD16))+IF(OR(AJ16="",AJ16="N/A",AJ16="Common Equity",AJ16="Builder Deposit / Equity"),0,N(AK16))+IF(OR(AQ16="",AQ16="N/A",AQ16="Common Equity",AQ16="Builder Deposit / Equity"),0,N(AR16)) -> 69000000 | S16: 71020944 | T16: 83000000 | U16: 76900000 | V16: Senior Mortgage | W16: 54250000 | X16: 0 | Y16: =IF(OR(V16="",V16="N/A",V16="Common Equity",V16="Builder Deposit / Equity",N($R16)=0),"N/A",SUM($W16)/$R16*100) -> 78.623188 | Z16: =IF(OR(V16="",V16="N/A",V16="Common Equity",V16="Builder Deposit / Equity",N($R16)=0),"N/A",SUM($W16)/$R16*100) -> 78.623188 | AA16: =IF(OR(V16="",V16="N/A",N($T16)=0),"N/A",SUM($W16)/$T16*100) -> 65.361446 | AB16: 0.0235 | AC16: Mezzanine | AD16: 14750000 | AE16: =IF(OR(AC16="",AC16="N/A"),"N/A",Y16) -> 78.623188 | AF16: =IF(OR(AC16="",AC16="N/A",AC16="Common Equity",AC16="Builder Deposit / Equity",N($R16)=0),"N/A",SUM($W16,$AD16)/$R16*100) -> 100 | AG16: =IF(OR(AC16="",AC16="N/A",AC16="Common Equity",AC16="Builder Deposit / Equity",N($R16)=0),"N/A",SUM($W16,$AD16)/$R16*100) -> 100 | AH16: =IF(OR(AC16="",AC16="N/A",N($T16)=0),"N/A",SUM($W16,$AD16)/$T16*100) -> 83.13253 | AI16: 0.1125 | AJ16: Common Equity | AK16: =T16-W16-AD16 -> 14000000 | AL16: =IF(OR(AJ16="",AJ16="N/A"),"N/A",AF16) -> 100 | AM16: =IF(OR(AJ16="",AJ16="N/A",AJ16="Common Equity",AJ16="Builder Deposit / Equity",N($R16)=0),"N/A",SUM($W16,$AD16,$AK16)/$R16*100) -> N/A | AN16: =IF(OR(AJ16="",AJ16="N/A",AJ16="Common Equity",AJ16="Builder Deposit / Equity",N($R16)=0),"N/A",SUM($W16,$AD16,$AK16)/$R16*100) -> N/A | AO16: =IF(OR(AJ16="",AJ16="N/A",N($T16)=0),"N/A",SUM($W16,$AD16,$AK16)/$T16*100) -> 100 | AP16: N/A
A17: MaSH-3773094 | B17: 340601 | C17: Project Highland Portfolio | D17: Mezz | E17: Mezzanine | F17: Mezzanine Loan | G17: CRE Loan Junior | H17: 80000000 | I17: 80000000 | J17: Single Funding | K17: 0.98485302 | L17: =I17*K17 -> 78788241 | M17: =L17+N17 -> 78788241 | N17: =H17-I17 -> 0 | O17: =W17+H17 -> 525000000 | P17: N/A - Unlevered | Q17: N/A | R17: =IF(OR(V17="",V17="N/A",V17="Common Equity",V17="Builder Deposit / Equity"),0,N(W17))+IF(OR(AC17="",AC17="N/A",AC17="Common Equity",AC17="Builder Deposit / Equity"),0,N(AD17))+IF(OR(AJ17="",AJ17="N/A",AJ17="Common Equity",AJ17="Builder Deposit / Equity"),0,N(AK17))+IF(OR(AQ17="",AQ17="N/A",AQ17="Common Equity",AQ17="Builder Deposit / Equity"),0,N(AR17)) -> 525000000 | S17: 533751241 | T17: 807692000 | U17: 616000000 | V17: Senior Mortgage | W17: 445000000 | X17: 0 | Y17: =IF(OR(V17="",V17="N/A",V17="Common Equity",V17="Builder Deposit / Equity",N($R17)=0),"N/A",SUM($W17)/$R17*100) -> 84.761905 | Z17: =IF(OR(V17="",V17="N/A",V17="Common Equity",V17="Builder Deposit / Equity",N($R17)=0),"N/A",SUM($W17)/$R17*100) -> 84.761905 | AA17: =IF(OR(V17="",V17="N/A",N($T17)=0),"N/A",SUM($W17)/$T17*100) -> 55.095259 | AB17: 0.04 | AC17: Mezzanine | AD17: 80000000 | AE17: =IF(OR(AC17="",AC17="N/A"),"N/A",Y17) -> 84.761905 | AF17: =IF(OR(AC17="",AC17="N/A",AC17="Common Equity",AC17="Builder Deposit / Equity",N($R17)=0),"N/A",SUM($W17,$AD17)/$R17*100) -> 100 | AG17: =IF(OR(AC17="",AC17="N/A",AC17="Common Equity",AC17="Builder Deposit / Equity",N($R17)=0),"N/A",SUM($W17,$AD17)/$R17*100) -> 100 | AH17: =IF(OR(AC17="",AC17="N/A",N($T17)=0),"N/A",SUM($W17,$AD17)/$T17*100) -> 65.000025 | AI17: 0.125 | AJ17: Common Equity | AK17: =T17-W17-AD17 -> 282692000 | AL17: =IF(OR(AJ17="",AJ17="N/A"),"N/A",AF17) -> 100 | AM17: =IF(OR(AJ17="",AJ17="N/A",AJ17="Common Equity",AJ17="Builder Deposit / Equity",N($R17)=0),"N/A",SUM($W17,$AD17,$AK17)/$R17*100) -> N/A | AN17: =IF(OR(AJ17="",AJ17="N/A",AJ17="Common Equity",AJ17="Builder Deposit / Equity",N($R17)=0),"N/A",SUM($W17,$AD17,$AK17)/$R17*100) -> N/A | AO17: =IF(OR(AJ17="",AJ17="N/A",N($T17)=0),"N/A",SUM($W17,$AD17,$AK17)/$T17*100) -> 100 | AP17: N/A
A18: MaSH-3780342 | B18: 347849 | C18: Project Prime Care Portfolio Senior Financing | D18: A Note | E18: Syndication | F18: Mortgage | G18: CRE Loan Senior | H18: 55000000 | I18: 55000000 | J18: Single Funding | K18: 0.99 | L18: =I18*K18 -> 54450000 | M18: =L18+N18 -> 54450000 | N18: =H18-I18 -> 0 | O18: =W18 -> 205000000 | P18: N/A - Unlevered | Q18: N/A | R18: =IF(OR(V18="",V18="N/A",V18="Common Equity",V18="Builder Deposit / Equity"),0,N(W18))+IF(OR(AC18="",AC18="N/A",AC18="Common Equity",AC18="Builder Deposit / Equity"),0,N(AD18))+IF(OR(AJ18="",AJ18="N/A",AJ18="Common Equity",AJ18="Builder Deposit / Equity"),0,N(AK18))+IF(OR(AQ18="",AQ18="N/A",AQ18="Common Equity",AQ18="Builder Deposit / Equity"),0,N(AR18)) -> 300000000 | S18: 300000000 | T18: 355000000 | U18: 327000000 | V18: Senior Mortgage | W18: 205000000 | X18: 0 | Y18: =IF(OR(V18="",V18="N/A",V18="Common Equity",V18="Builder Deposit / Equity",N($R18)=0),"N/A",SUM($W18)/$R18*100) -> 68.333333 | Z18: =IF(OR(V18="",V18="N/A",V18="Common Equity",V18="Builder Deposit / Equity",N($R18)=0),"N/A",SUM($W18)/$R18*100) -> 68.333333 | AA18: =IF(OR(V18="",V18="N/A",N($T18)=0),"N/A",SUM($W18)/$T18*100) -> 57.746479 | AB18: 0.025 | AC18: Mezzanine | AD18: 95000000 | AE18: =IF(OR(AC18="",AC18="N/A"),"N/A",Y18) -> 68.333333 | AF18: =IF(OR(AC18="",AC18="N/A",AC18="Common Equity",AC18="Builder Deposit / Equity",N($R18)=0),"N/A",SUM($W18,$AD18)/$R18*100) -> 100 | AG18: =IF(OR(AC18="",AC18="N/A",AC18="Common Equity",AC18="Builder Deposit / Equity",N($R18)=0),"N/A",SUM($W18,$AD18)/$R18*100) -> 100 | AH18: =IF(OR(AC18="",AC18="N/A",N($T18)=0),"N/A",SUM($W18,$AD18)/$T18*100) -> 84.507042 | AI18: 0.07 | AJ18: Common Equity | AK18: =T18-W18-AD18 -> 55000000 | AL18: =IF(OR(AJ18="",AJ18="N/A"),"N/A",AF18) -> 100 | AM18: =IF(OR(AJ18="",AJ18="N/A",AJ18="Common Equity",AJ18="Builder Deposit / Equity",N($R18)=0),"N/A",SUM($W18,$AD18,$AK18)/$R18*100) -> N/A | AN18: =IF(OR(AJ18="",AJ18="N/A",AJ18="Common Equity",AJ18="Builder Deposit / Equity",N($R18)=0),"N/A",SUM($W18,$AD18,$AK18)/$R18*100) -> N/A | AO18: =IF(OR(AJ18="",AJ18="N/A",N($T18)=0),"N/A",SUM($W18,$AD18,$AK18)/$T18*100) -> 100 | AP18: N/A
