Workbook
Name \a: #N/A
Name \b: #REF!
Name \c: #REF!
Name \d: #N/A
Name \e: #REF!
Name \F: #REF!
Name \i: #REF!
Name \m: #REF!
Name \o: #REF!
Name \p: #REF!
Name \q: #REF!
Name \R: #REF!
Name \s: #REF!
Name \T: #REF!
Name \x: #REF!
Name \Z: #REF!
Name ___CO_PROJ: #REF!
Name __blg300: #REF!
Name __Dumpster: 0
Name _001_LOC_APPLICATION_SOURCE: #REF!
Name _010_LETTER_OF_CREDIT_SOURCE: #REF!
Name _1_: #REF!
Name _1_1: #REF!
Name _10AC: #REF!
Name _11AUG_98: #REF!
Name _12CASH_REC: #REF!
Name _13CSH: #REF!
Name _14DECEMBER_98: #REF!
Name _15E: #REF!
Name _16NOVEMBER_98: #REF!
Name _17OCTOBER_98: #REF!
Name _18PL: #REF!
Name _19Module2_.PRINT_BCCAM: #N/A
Name _19SEPTEMBER_98: #REF!
Name _1Module2_.PRINT_BCCAM: #N/A
Name _1REPLA: #REF!
Name _2_: #REF!
Name _20__GS_Margin: #REF!
Name _2004: #REF!
Name _2005: #REF!
Name _2006: #REF!
Name _2007: #REF!
Name _2008: #REF!
Name _2009: #REF!
Name _2010: #REF!
Name _2011: #REF!
Name _2012: #REF!
Name _2013: #REF!
Name _2013_: #REF!
Name _2014: #REF!
Name _2015: #REF!
Name _20SUBPL: #REF!
Name _22505.5471: #REF!
Name _22505.5472: #REF!
Name _22505.5473: #REF!
Name _22505.5474: #REF!
Name _22505.5475: #REF!
Name _22505.5477: #REF!
Name _22505.5479: #REF!
Name _22510.5471: #REF!

Sheet Cover
D10: Private and Confidential
D20: KKR RECOP I LP Secondary Opportunity

Sheet Fwd Returns
N1: Projected Investment Returns(A)
B3: Cutoff Month | I3: ='HTM Output'!G2 -> 46203
B4: Projected Transaction Date | I4: ='HTM Output'!G3 -> 46388
B6: Promote Assumed | C6: =IF(D6=0,"UW life of fund cash flows do not meet "&TEXT('HTM WF'!$D$28,"0.0%")&" promote hurdle","") -> UW life of fund cash flows do not meet 8.0% promote hurdle | I6: ='HTM WF'!$GS$84 -> 0
B7: IM Fee Assumed | C7: Fees are offset from SS fees received | I7: =Assumptions!$E$8 -> 0.0125
B8: Selling Investor % of Fund | I8: =Assumptions!$D$5 -> 0.3539823
U9: =SUMIFS('HTM Output'!$K$37:$GS$37,'HTM Output'!$K$6:$GS$6,">"&'HTM Output'!$G$3)*$I$8=SUM(U42:HB42) -> FALSE
C10: Bpiece Curr UPB | D10: Current Mark Px | U10: =YEAR(U11) -> 2027 | V10: =YEAR(V11) -> 2027 | W10: =YEAR(W11) -> 2027 | X10: =YEAR(X11) -> 2027 | Y10: =YEAR(Y11) -> 2027 | Z10: =YEAR(Z11) -> 2027 | AA10: =YEAR(AA11) -> 2027 | AB10: =YEAR(AB11) -> 2027 | ... HB10: =YEAR(HB11) -> 2042
B11: Investment | C11: Current Face | D11: KRR Mark Px | E11: KKR Current Mark | F11: Cash & Receivables | G11: KKR Current NAV | H11: Weighted Avg. Hold Period | I11: Investor NAV | J11: Purch Px | K11: Purchase Price | L11: Gross Distros During Cutoff Period | M11: Fees/Expenses During Cutoff Period | N11: Net Distros During Cutoff Period | O11: Adjusted Price | Q11: Fwd. IRR(B)(D) | R11: Fwd. MOIC(C)(E) | T11: =$I$4 -> 46388 | U11: =EOMONTH(I4+1,0) -> 46418 | V11: =EOMONTH(U11,1) -> 46446 | W11: =EOMONTH(V11,1) -> 46477 | X11: =EOMONTH(W11,1) -> 46507 | Y11: =EOMONTH(X11,1) -> 46538 | Z11: =EOMONTH(Y11,1) -> 46568 | AA11: =EOMONTH(Z11,1) -> 46599 | AB11: =EOMONTH(AA11,1) -> 46630 | AC11: =EOMONTH(AB11,1) -> 46660 | ... HB11: =EOMONTH(HA11,1) -> 52170 | HD11: =TEXT($I$4,"m/d/yyyy")&" Acquisition" -> 1/1/2027 Acquisition | HE11: =YEAR(U11) -> 2027 | HF11: =HE11+1 -> 2028 | HG11: =HF11+1 -> 2029 | HH11: =HG11+1 -> 2030 | HI11: =HH11+1 -> 2031 | HJ11: =HI11+1 -> 2032 | HK11: Total
B12: Valuation | Q12: ="Projected Cash Flows ("&TEXT($I$8,"0.0%")&" stake acquired)" -> Projected Cash Flows (35.4% stake acquired)
A14: UBSCM 2017-C2 B-Piece Cashflows | B14: UBSCM 2017-C2 | C14: =OFFSET(Strats!$B$3,MATCH($B14,Strats!$B$4:$B$31,0),MATCH(C$10,Strats!$C$3:$BS$3,0)) -> 85566944 | D14: =OFFSET(Strats!$B$3,MATCH($B14,Strats!$B$4:$B$31,0),MATCH(D$10,Strats!$C$3:$BS$3,0)) -> 0.83725914 | E14: =C14*D14 -> 71641706 | F14: =$F$42*$E14/$E$42 -> 1171339.2 | G14: =F14+E14 -> 72813045 | H14: =IFERROR(SUMPRODUCT('HTM Output'!$K73:$GS73,'HTM Output'!$K$6:$GS$6)/SUM('HTM Output'!$K73:$GS73),_xlfn.MAXIFS($U$11:$HB$11,$U$14:$HB$14,">"&0)) -> 47326.871 | I14: =G14*$I$8 -> 25774529 | J14: =$J$42 -> 0.5 | K14: =I14*J14 -> 12887265 | L14: =-SUMIFS('HTM Output'!$K9:$GS9,'HTM Output'!$K$6:$GS$6,">"&'HTM Output'!$G$2,'HTM Output'!$K$6:$GS$6,"<="&'HTM Output'!$G$3)*$I$8 -> -676020.86 | M14: =M$42*K14/$K$42 -> 36029.299 | N14: =L14+M14 -> -639991.56 | O14: =SUM(K14:M14) -> 12247273 | Q14: =IFERROR(XIRR($T14:$HB14,$T$11:$HB$11),"N/A") -> 0.47247028 | R14: =IFERROR((HK14+O14)/O14,"N/A") -> 2.522879 | T14: =IF(T$11>$I$4,SUMIFS('Pooled CF'!$E:$E,'Pooled CF'!$A:$A,$A14,'Pooled CF'!$G:$G,T$11),0)+IF(T$11=$I$4,-$O14) -> -12247273 | U14: =IFERROR(OFFSET('HTM Output'!$J$6,MATCH($B14,'HTM Output'!$B$7:$B$37,0),MATCH(U$11,'HTM Output'!$K$6:$GS$6,0)),0)*$I$8 -> 111958.62 | V14: =IFERROR(OFFSET('HTM Output'!$J$6,MATCH($B14,'HTM Output'!$B$7:$B$37,0),MATCH(V$11,'HTM Output'!$K$6:$GS$6,0)),0)*$I$8 -> 111945.12 | W14: =IFERROR(OFFSET('HTM Output'!$J$6,MATCH($B14,'HTM Output'!$B$7:$B$37,0),MATCH(W$11,'HTM Output'!$K$6:$GS$6,0)),0)*$I$8 -> 111857.09 | X14: =IFERROR(OFFSET('HTM Output'!$J$6,MATCH($B14,'HTM Output'!$B$7:$B$37,0),MATCH(X$11,'HTM Output'!$K$6:$GS$6,0)),0)*$I$8 -> 115063.6 | Y14: =IFERROR(OFFSET('HTM Output'!$J$6,MATCH($B14,'HTM Output'!$B$7:$B$37,0),MATCH(Y$11,'HTM Output'!$K$6:$GS$6,0)),0)*$I$8 -> 111338.41 | Z14: =IFERROR(OFFSET('HTM Output'!$J$6,MATCH($B14,'HTM Output'!$B$7:$B$37,0),MATCH(Z$11,'HTM Output'!$K$6:$GS$6,0)),0)*$I$8 -> 107229.35 | AA14: =IFERROR(OFFSET('HTM Output'!$J$6,MATCH($B14,'HTM Output'!$B$7:$B$37,0),MATCH(AA$11,'HTM Output'!$K$6:$GS$6,0)),0)*$I$8 -> 110115.03 | AB14: =IFERROR(OFFSET('HTM Output'!$J$6,MATCH($B14,'HTM Output'!$B$7:$B$37,0),MATCH(AB$11,'HTM Output'!$K$6:$GS$6,0)),0)*$I$8 -> 111175.12 | ... HB14: =IFERROR(OFFSET('HTM Output'!$J$6,MATCH($B14,'HTM Output'!$B$7:$B$37,0),MATCH(HB$11,'HTM Output'!$K$6:$GS$6,0)),0)*$I$8 -> 0 | HD14: =T14 -> -12247273 | HE14: =SUMIFS($T14:$HB14,$T$10:$HB$10,HE$11) -> 1290223.9 | HF14: =SUMIFS($T14:$HB14,$T$10:$HB$10,HF$11) -> 1180142.5 | HG14: =SUMIFS($T14:$HB14,$T$10:$HB$10,HG$11) -> 28428021 | HH14: =SUMIFS($T14:$HB14,$T$10:$HB$10,HH$11) -> 0 | HI14: =SUMIFS($T14:$HB14,$T$10:$HB$10,HI$11) -> 0 | HJ14: =SUMIFS($T14:$HB14,$T$10:$HB$10,HJ$11) -> 0 | HK14: =SUM(HD14:HJ14) -> 18651115
A15: CGCMT 2017-C4 B-Piece Cashflows | B15: CGCMT 2017-C4 | C15: =OFFSET(Strats!$B$3,MATCH($B15,Strats!$B$4:$B$31,0),MATCH(C$10,Strats!$C$3:$BS$3,0)) -> 105034893 | D15: =OFFSET(Strats!$B$3,MATCH($B15,Strats!$B$4:$B$31,0),MATCH(D$10,Strats!$C$3:$BS$3,0)) -> 0.65106574 | E15: =C15*D15 -> 68384620 | F15: =$F$42*$E15/$E$42 -> 1118086 | G15: =F15+E15 -> 69502706 | H15: =IFERROR(SUMPRODUCT('HTM Output'!$K74:$GS74,'HTM Output'!$K$6:$GS$6)/SUM('HTM Output'!$K74:$GS74),_xlfn.MAXIFS($U$11:$HB$11,$U$14:$HB$14,">"&0)) -> 47774.733 | I15: =G15*$I$8 -> 24602728 | J15: =$J$42 -> 0.5 | K15: =I15*J15 -> 12301364 | L15: =-SUMIFS('HTM Output'!$K10:$GS10,'HTM Output'!$K$6:$GS$6,">"&'HTM Output'!$G$2,'HTM Output'!$K$6:$GS$6,"<="&'HTM Output'!$G$3)*$I$8 -> -842771.53 | M15: =M$42*K15/$K$42 -> 34391.279 | N15: =L15+M15 -> -808380.25 | O15: =SUM(K15:M15) -> 11492984 | Q15: =IFERROR(XIRR($T15:$HB15,$T$11:$HB$11),"N/A") -> 0.23411383 | R15: =IFERROR((HK15+O15)/O15,"N/A") -> 2.0448715 | T15: =IF(T$11>$I$4,SUMIFS('Pooled CF'!$E:$E,'Pooled CF'!$A:$A,$A15,'Pooled CF'!$G:$G,T$11),0)+IF(T$11=$I$4,-$O15) -> -11492984 | U15: =IFERROR(OFFSET('HTM Output'!$J$6,MATCH($B15,'HTM Output'!$B$7:$B$37,0),MATCH(U$11,'HTM Output'!$K$6:$GS$6,0)),0)*$I$8 -> 135425.99 | V15: =IFERROR(OFFSET('HTM Output'!$J$6,MATCH($B15,'HTM Output'!$B$7:$B$37,0),MATCH(V$11,'HTM Output'!$K$6:$GS$6,0)),0)*$I$8 -> 135420.62 | W15: =IFERROR(OFFSET('HTM Output'!$J$6,MATCH($B15,'HTM Output'!$B$7:$B$37,0),MATCH(W$11,'HTM Output'!$K$6:$GS$6,0)),0)*$I$8 -> 126140.98 | X15: =IFERROR(OFFSET('HTM Output'!$J$6,MATCH($B15,'HTM Output'!$B$7:$B$37,0),MATCH(X$11,'HTM Output'!$K$6:$GS$6,0)),0)*$I$8 -> 129641.59 | Y15: =IFERROR(OFFSET('HTM Output'!$J$6,MATCH($B15,'HTM Output'!$B$7:$B$37,0),MATCH(Y$11,'HTM Output'!$K$6:$GS$6,0)),0)*$I$8 -> 125456.36 | Z15: =IFERROR(OFFSET('HTM Output'!$J$6,MATCH($B15,'HTM Output'!$B$7:$B$37,0),MATCH(Z$11,'HTM Output'!$K$6:$GS$6,0)),0)*$I$8 -> 129634.63 | AA15: =IFERROR(OFFSET('HTM Output'!$J$6,MATCH($B15,'HTM Output'!$B$7:$B$37,0),MATCH(AA$11,'HTM Output'!$K$6:$GS$6,0)),0)*$I$8 -> 126669.99 | AB15: =IFERROR(OFFSET('HTM Output'!$J$6,MATCH($B15,'HTM Output'!$B$7:$B$37,0),MATCH(AB$11,'HTM Output'!$K$6:$GS$6,0)),0)*$I$8 -> 131570.93 | ... HB15: =IFERROR(OFFSET('HTM Output'!$J$6,MATCH($B15,'HTM Output'!$B$7:$B$37,0),MATCH(HB$11,'HTM Output'!$K$6:$GS$6,0)),0)*$I$8 -> 0 | HD15: =T15 -> -11492984 | HE15: =SUMIFS($T15:$HB15,$T$10:$HB$10,HE$11) -> 1402180 | HF15: =SUMIFS($T15:$HB15,$T$10:$HB$10,HF$11) -> 782553.05 | HG15: =SUMIFS($T15:$HB15,$T$10:$HB$10,HG$11) -> 3445700.2 | HH15: =SUMIFS($T15:$HB15,$T$10:$HB$10,HH$11) -> 9225187.7 | HI15: =SUMIFS($T15:$HB15,$T$10:$HB$10,HI$11) -> 8646054.1 | HJ15: =SUMIFS($T15:$HB15,$T$10:$HB$10,HJ$11) -> 0 | HK15: =SUM(HD15:HJ15) -> 12008691
A16: WFCM 2018-C47 B-Piece Cashflows | B16: WFCM 2018-C47 | C16: =OFFSET(Strats!$B$3,MATCH($B16,Strats!$B$4:$B$31,0),MATCH(C$10,Strats!$C$3:$BS$3,0)) -> 91373439 | D16: =OFFSET(Strats!$B$3,MATCH($B16,Strats!$B$4:$B$31,0),MATCH(D$10,Strats!$C$3:$BS$3,0)) -> 0.57207853 | E16: =C16*D16 -> 52272783 | F16: =$F$42*$E16/$E$42 -> 854658.02 | G16: =F16+E16 -> 53127441 | H16: =IFERROR(SUMPRODUCT('HTM Output'!$K75:$GS75,'HTM Output'!$K$6:$GS$6)/SUM('HTM Output'!$K75:$GS75),_xlfn.MAXIFS($U$11:$HB$11,$U$14:$HB$14,">"&0)) -> 47781.407 | I16: =G16*$I$8 -> 18806174 | J16: =$J$42 -> 0.5 | K16: =I16*J16 -> 9403086.8 | L16: =-SUMIFS('HTM Output'!$K11:$GS11,'HTM Output'!$K$6:$GS$6,">"&'HTM Output'!$G$2,'HTM Output'!$K$6:$GS$6,"<="&'HTM Output'!$G$3)*$I$8 -> -759147.17 | M16: =M$42*K16/$K$42 -> 26288.482 | N16: =L16+M16 -> -732858.69 | O16: =SUM(K16:M16) -> 8670228.1 | Q16: =IFERROR(XIRR($T16:$HB16,$T$11:$HB$11),"N/A") -> 0.27767276 | R16: =IFERROR((HK16+O16)/O16,"N/A") -> 2.1959625 | T16: =IF(T$11>$I$4,SUMIFS('Pooled CF'!$E:$E,'Pooled CF'!$A:$A,$A16,'Pooled CF'!$G:$G,T$11),0)+IF(T$11=$I$4,-$O16) -> -8670228.1 | U16: =IFERROR(OFFSET('HTM Output'!$J$6,MATCH($B16,'HTM Output'!$B$7:$B$37,0),MATCH(U$11,'HTM Output'!$K$6:$GS$6,0)),0)*$I$8 -> 126386.91 | V16: =IFERROR(OFFSET('HTM Output'!$J$6,MATCH($B16,'HTM Output'!$B$7:$B$37,0),MATCH(V$11,'HTM Output'!$K$6:$GS$6,0)),0)*$I$8 -> 126384.38 | W16: =IFERROR(OFFSET('HTM Output'!$J$6,MATCH($B16,'HTM Output'!$B$7:$B$37,0),MATCH(W$11,'HTM Output'!$K$6:$GS$6,0)),0)*$I$8 -> 126979.72 | X16: =IFERROR(OFFSET('HTM Output'!$J$6,MATCH($B16,'HTM Output'!$B$7:$B$37,0),MATCH(X$11,'HTM Output'!$K$6:$GS$6,0)),0)*$I$8 -> 130793.04 | Y16: =IFERROR(OFFSET('HTM Output'!$J$6,MATCH($B16,'HTM Output'!$B$7:$B$37,0),MATCH(Y$11,'HTM Output'!$K$6:$GS$6,0)),0)*$I$8 -> 126571.32 | Z16: =IFERROR(OFFSET('HTM Output'!$J$6,MATCH($B16,'HTM Output'!$B$7:$B$37,0),MATCH(Z$11,'HTM Output'!$K$6:$GS$6,0)),0)*$I$8 -> 130787.46 | AA16: =IFERROR(OFFSET('HTM Output'!$J$6,MATCH($B16,'HTM Output'!$B$7:$B$37,0),MATCH(AA$11,'HTM Output'!$K$6:$GS$6,0)),0)*$I$8 -> 126565.88 | AB16: =IFERROR(OFFSET('HTM Output'!$J$6,MATCH($B16,'HTM Output'!$B$7:$B$37,0),MATCH(AB$11,'HTM Output'!$K$6:$GS$6,0)),0)*$I$8 -> 130781.79 | ... HB16: =IFERROR(OFFSET('HTM Output'!$J$6,MATCH($B16,'HTM Output'!$B$7:$B$37,0),MATCH(HB$11,'HTM Output'!$K$6:$GS$6,0)),0)*$I$8 -> 0 | HD16: =T16 -> -8670228.1 | HE16: =SUMIFS($T16:$HB16,$T$10:$HB$10,HE$11) -> 1520149.8 | HF16: =SUMIFS($T16:$HB16,$T$10:$HB$10,HF$11) -> 1087955.2 | HG16: =SUMIFS($T16:$HB16,$T$10:$HB$10,HG$11) -> 710415.19 | HH16: =SUMIFS($T16:$HB16,$T$10:$HB$10,HH$11) -> 15720976 | HI16: =SUMIFS($T16:$HB16,$T$10:$HB$10,HI$11) -> 0 | HJ16: =SUMIFS($T16:$HB16,$T$10:$HB$10,HJ$11) -> 0 | HK16: =SUM(HD16:HJ16) -> 10369268
A17: BBCMS 2019-C3 B-Piece Cashflows | B17: BBCMS 2019-C3 | C17: =OFFSET(Strats!$B$3,MATCH($B17,Strats!$B$4:$B$31,0),MATCH(C$10,Strats!$C$3:$BS$3,0)) -> 94541101 | D17: =OFFSET(Strats!$B$3,MATCH($B17,Strats!$B$4:$B$31,0),MATCH(D$10,Strats!$C$3:$BS$3,0)) -> 0.5321654 | E17: =C17*D17 -> 50311503 | F17: =$F$42*$E17/$E$42 -> 822591.17 | G17: =F17+E17 -> 51134094 | H17: =IFERROR(SUMPRODUCT('HTM Output'!$K76:$GS76,'HTM Output'!$K$6:$GS$6)/SUM('HTM Output'!$K76:$GS76),_xlfn.MAXIFS($U$11:$HB$11,$U$14:$HB$14,">"&0)) -> 48342.458 | I17: =G17*$I$8 -> 18100564 | J17: =$J$42 -> 0.5 | K17: =I17*J17 -> 9050282.1 | L17: =-SUMIFS('HTM Output'!$K12:$GS12,'HTM Output'!$K$6:$GS$6,">"&'HTM Output'!$G$2,'HTM Output'!$K$6:$GS$6,"<="&'HTM Output'!$G$3)*$I$8 -> -678276.99 | M17: =M$42*K17/$K$42 -> 25302.136 | N17: =L17+M17 -> -652974.86 | O17: =SUM(K17:M17) -> 8397307.3 | Q17: =IFERROR(XIRR($T17:$HB17,$T$11:$HB$11),"N/A") -> 0.2409211 | R17: =IFERROR((HK17+O17)/O17,"N/A") -> 2.4982331 | T17: =IF(T$11>$I$4,SUMIFS('Pooled CF'!$E:$E,'Pooled CF'!$A:$A,$A17,'Pooled CF'!$G:$G,T$11),0)+IF(T$11=$I$4,-$O17) -> -8397307.3 | U17: =IFERROR(OFFSET('HTM Output'!$J$6,MATCH($B17,'HTM Output'!$B$7:$B$37,0),MATCH(U$11,'HTM Output'!$K$6:$GS$6,0)),0)*$I$8 -> 111942.28 | V17: =IFERROR(OFFSET('HTM Output'!$J$6,MATCH($B17,'HTM Output'!$B$7:$B$37,0),MATCH(V$11,'HTM Output'!$K$6:$GS$6,0)),0)*$I$8 -> 111940.97 | W17: =IFERROR(OFFSET('HTM Output'!$J$6,MATCH($B17,'HTM Output'!$B$7:$B$37,0),MATCH(W$11,'HTM Output'!$K$6:$GS$6,0)),0)*$I$8 -> 113981.74 | X17: =IFERROR(OFFSET('HTM Output'!$J$6,MATCH($B17,'HTM Output'!$B$7:$B$37,0),MATCH(X$11,'HTM Output'!$K$6:$GS$6,0)),0)*$I$8 -> 116369.23 | Y17: =IFERROR(OFFSET('HTM Output'!$J$6,MATCH($B17,'HTM Output'!$B$7:$B$37,0),MATCH(Y$11,'HTM Output'!$K$6:$GS$6,0)),0)*$I$8 -> 112614.04 | Z17: =IFERROR(OFFSET('HTM Output'!$J$6,MATCH($B17,'HTM Output'!$B$7:$B$37,0),MATCH(Z$11,'HTM Output'!$K$6:$GS$6,0)),0)*$I$8 -> 116366.33 | AA17: =IFERROR(OFFSET('HTM Output'!$J$6,MATCH($B17,'HTM Output'!$B$7:$B$37,0),MATCH(AA$11,'HTM Output'!$K$6:$GS$6,0)),0)*$I$8 -> 112611.2 | AB17: =IFERROR(OFFSET('HTM Output'!$J$6,MATCH($B17,'HTM Output'!$B$7:$B$37,0),MATCH(AB$11,'HTM Output'!$K$6:$GS$6,0)),0)*$I$8 -> 116363.38 | ... HB17: =IFERROR(OFFSET('HTM Output'!$J$6,MATCH($B17,'HTM Output'!$B$7:$B$37,0),MATCH(HB$11,'HTM Output'!$K$6:$GS$6,0)),0)*$I$8 -> 0 | HD17: =T17 -> -8397307.3 | HE17: =SUMIFS($T17:$HB17,$T$10:$HB$10,HE$11) -> 1370121 | HF17: =SUMIFS($T17:$HB17,$T$10:$HB$10,HF$11) -> 1348993.2 | HG17: =SUMIFS($T17:$HB17,$T$10:$HB$10,HG$11) -> 993802.28 | HH17: =SUMIFS($T17:$HB17,$T$10:$HB$10,HH$11) -> 879672.54 | HI17: =SUMIFS($T17:$HB17,$T$10:$HB$10,HI$11) -> 2690784.1 | HJ17: =SUMIFS($T17:$HB17,$T$10:$HB$10,HJ$11) -> 13695058 | HK17: =SUM(HD17:HJ17) -> 12581124
A18: GSMS 2019-GC38 B-Piece Cashflow | B18: GSMS 2019-GC38 | C18: =OFFSET(Strats!$B$3,MATCH($B18,Strats!$B$4:$B$31,0),MATCH(C$10,Strats!$C$3:$BS$3,0)) -> 73640365 | D18: =OFFSET(Strats!$B$3,MATCH($B18,Strats!$B$4:$B$31,0),MATCH(D$10,Strats!$C$3:$BS$3,0)) -> 0.66377783 | E18: =C18*D18 -> 48880842 | F18: =$F$42*$E18/$E$42 -> 799199.92 | G18: =F18+E18 -> 49680042 | H18: =IFERROR(SUMPRODUCT('HTM Output'!$K77:$GS77,'HTM Output'!$K$6:$GS$6)/SUM('HTM Output'!$K77:$GS77),_xlfn.MAXIFS($U$11:$HB$11,$U$14:$HB$14,">"&0)) -> 48273 | I18: =G18*$I$8 -> 17585855 | J18: =$J$42 -> 0.5 | K18: =I18*J18 -> 8792927.7 | L18: =-SUMIFS('HTM Output'!$K13:$GS13,'HTM Output'!$K$6:$GS$6,">"&'HTM Output'!$G$2,'HTM Output'!$K$6:$GS$6,"<="&'HTM Output'!$G$3)*$I$8 -> -699234.32 | M18: =M$42*K18/$K$42 -> 24582.643 | N18: =L18+M18 -> -674651.68 | O18: =SUM(K18:M18) -> 8118276.1 | Q18: =IFERROR(XIRR($T18:$HB18,$T$11:$HB$11),"N/A") -> 0.18022459 | R18: =IFERROR((HK18+O18)/O18,"N/A") -> 1.9623536 | T18: =IF(T$11>$I$4,SUMIFS('Pooled CF'!$E:$E,'Pooled CF'!$A:$A,$A18,'Pooled CF'!$G:$G,T$11),0)+IF(T$11=$I$4,-$O18) -> -8118276.1 | U18: =IFERROR(OFFSET('HTM Output'!$J$6,MATCH($B18,'HTM Output'!$B$7:$B$37,0),MATCH(U$11,'HTM Output'!$K$6:$GS$6,0)),0)*$I$8 -> 106247.28 | V18: =IFERROR(OFFSET('HTM Output'!$J$6,MATCH($B18,'HTM Output'!$B$7:$B$37,0),MATCH(V$11,'HTM Output'!$K$6:$GS$6,0)),0)*$I$8 -> 106245.03 | W18: =IFERROR(OFFSET('HTM Output'!$J$6,MATCH($B18,'HTM Output'!$B$7:$B$37,0),MATCH(W$11,'HTM Output'!$K$6:$GS$6,0)),0)*$I$8 -> 106247.69 | X18: =IFERROR(OFFSET('HTM Output'!$J$6,MATCH($B18,'HTM Output'!$B$7:$B$37,0),MATCH(X$11,'HTM Output'!$K$6:$GS$6,0)),0)*$I$8 -> 109781.25 | Y18: =IFERROR(OFFSET('HTM Output'!$J$6,MATCH($B18,'HTM Output'!$B$7:$B$37,0),MATCH(Y$11,'HTM Output'!$K$6:$GS$6,0)),0)*$I$8 -> 106237.63 | Z18: =IFERROR(OFFSET('HTM Output'!$J$6,MATCH($B18,'HTM Output'!$B$7:$B$37,0),MATCH(Z$11,'HTM Output'!$K$6:$GS$6,0)),0)*$I$8 -> 109776.31 | AA18: =IFERROR(OFFSET('HTM Output'!$J$6,MATCH($B18,'HTM Output'!$B$7:$B$37,0),MATCH(AA$11,'HTM Output'!$K$6:$GS$6,0)),0)*$I$8 -> 106232.83 | AB18: =IFERROR(OFFSET('HTM Output'!$J$6,MATCH($B18,'HTM Output'!$B$7:$B$37,0),MATCH(AB$11,'HTM Output'!$K$6:$GS$6,0)),0)*$I$8 -> 109771.32 | ... HB18: =IFERROR(OFFSET('HTM Output'!$J$6,MATCH($B18,'HTM Output'!$B$7:$B$37,0),MATCH(HB$11,'HTM Output'!$K$6:$GS$6,0)),0)*$I$8 -> 0 | HD18: =T18 -> -8118276.1 | HE18: =SUMIFS($T18:$HB18,$T$10:$HB$10,HE$11) -> 1292518.4 | HF18: =SUMIFS($T18:$HB18,$T$10:$HB$10,HF$11) -> 1291264.7 | HG18: =SUMIFS($T18:$HB18,$T$10:$HB$10,HG$11) -> 889854.14 | HH18: =SUMIFS($T18:$HB18,$T$10:$HB$10,HH$11) -> 343646.55 | HI18: =SUMIFS($T18:$HB18,$T$10:$HB$10,HI$11) -> 7504.3841 | HJ18: =SUMIFS($T18:$HB18,$T$10:$HB$10,HJ$11) -> 12106140 | HK18: =SUM(HD18:HJ18) -> 7812652
A19: GSMS 2017-GS8 B-Piece Cashflow | B19: GSMS 2017-GS8 | C19: =OFFSET(Strats!$B$3,MATCH($B19,Strats!$B$4:$B$31,0),MATCH(C$10,Strats!$C$3:$BS$3,0)) -> 106223386 | D19: =OFFSET(Strats!$B$3,MATCH($B19,Strats!$B$4:$B$31,0),MATCH(D$10,Strats!$C$3:$BS$3,0)) -> 0.43273164 | E19: =C19*D19 -> 45966220 | F19: =$F$42*$E19/$E$42 -> 751545.96 | G19: =F19+E19 -> 46717766 | H19: =IFERROR(SUMPRODUCT('HTM Output'!$K78:$GS78,'HTM Output'!$K$6:$GS$6)/SUM('HTM Output'!$K78:$GS78),_xlfn.MAXIFS($U$11:$HB$11,$U$14:$HB$14,">"&0)) -> 47787 | I19: =G19*$I$8 -> 16537262 | J19: =$J$42 -> 0.5 | K19: =I19*J19 -> 8268631.1 | L19: =-SUMIFS('HTM Output'!$K14:$GS14,'HTM Output'!$K$6:$GS$6,">"&'HTM Output'!$G$2,'HTM Output'!$K$6:$GS$6,"<="&'HTM Output'!$G$3)*$I$8 -> -451077.88 | M19: =M$42*K19/$K$42 -> 23116.851 | N19: =L19+M19 -> -427961.03 | O19: =SUM(K19:M19) -> 7840670.1 | Q19: =IFERROR(XIRR($T19:$HB19,$T$11:$HB$11),"N/A") -> 0.25317426 | R19: =IFERROR((HK19+O19)/O19,"N/A") -> 2.1681846 | T19: =IF(T$11>$I$4,SUMIFS('Pooled CF'!$E:$E,'Pooled CF'!$A:$A,$A19,'Pooled CF'!$G:$G,T$11),0)+IF(T$11=$I$4,-$O19) -> -7840670.1 | U19: =IFERROR(OFFSET('HTM Output'!$J$6,MATCH($B19,'HTM Output'!$B$7:$B$37,0),MATCH(U$11,'HTM Output'!$K$6:$GS$6,0)),0)*$I$8 -> 69322.44 | V19: =IFERROR(OFFSET('HTM Output'!$J$6,MATCH($B19,'HTM Output'!$B$7:$B$37,0),MATCH(V$11,'HTM Output'!$K$6:$GS$6,0)),0)*$I$8 -> 69315.183 | W19: =IFERROR(OFFSET('HTM Output'!$J$6,MATCH($B19,'HTM Output'!$B$7:$B$37,0),MATCH(W$11,'HTM Output'!$K$6:$GS$6,0)),0)*$I$8 -> 75566.871 | X19: =IFERROR(OFFSET('HTM Output'!$J$6,MATCH($B19,'HTM Output'!$B$7:$B$37,0),MATCH(X$11,'HTM Output'!$K$6:$GS$6,0)),0)*$I$8 -> 73244.522 | Y19: =IFERROR(OFFSET('HTM Output'!$J$6,MATCH($B19,'HTM Output'!$B$7:$B$37,0),MATCH(Y$11,'HTM Output'!$K$6:$GS$6,0)),0)*$I$8 -> 79422.098 | Z19: =IFERROR(OFFSET('HTM Output'!$J$6,MATCH($B19,'HTM Output'!$B$7:$B$37,0),MATCH(Z$11,'HTM Output'!$K$6:$GS$6,0)),0)*$I$8 -> 81290.264 | AA19: =IFERROR(OFFSET('HTM Output'!$J$6,MATCH($B19,'HTM Output'!$B$7:$B$37,0),MATCH(AA$11,'HTM Output'!$K$6:$GS$6,0)),0)*$I$8 -> 78885.804 | AB19: =IFERROR(OFFSET('HTM Output'!$J$6,MATCH($B19,'HTM Output'!$B$7:$B$37,0),MATCH(AB$11,'HTM Output'!$K$6:$GS$6,0)),0)*$I$8 -> 83044.242 | ... HB19: =IFERROR(OFFSET('HTM Output'!$J$6,MATCH($B19,'HTM Output'!$B$7:$B$37,0),MATCH(HB$11,'HTM Output'!$K$6:$GS$6,0)),0)*$I$8 -> 0 | HD19: =T19 -> -7840670.1 | HE19: =SUMIFS($T19:$HB19,$T$10:$HB$10,HE$11) -> 931572.49 | HF19: =SUMIFS($T19:$HB19,$T$10:$HB$10,HF$11) -> 760448.2 | HG19: =SUMIFS($T19:$HB19,$T$10:$HB$10,HG$11) -> 136501.51 | HH19: =SUMIFS($T19:$HB19,$T$10:$HB$10,HH$11) -> 15171498 | HI19: =SUMIFS($T19:$HB19,$T$10:$HB$10,HI$11) -> 0 | HJ19: =SUMIFS($T19:$HB19,$T$10:$HB$10,HJ$11) -> 0 | HK19: =SUM(HD19:HJ19) -> 9159349.9
A20: UBSCM 2018-C8 B-Piece Cashflows | B20: UBSCM 2018-C8 | C20: =OFFSET(Strats!$B$3,MATCH($B20,Strats!$B$4:$B$31,0),MATCH(C$10,Strats!$C$3:$BS$3,0)) -> 1.0628505e+08 | D20: =OFFSET(Strats!$B$3,MATCH($B20,Strats!$B$4:$B$31,0),MATCH(D$10,Strats!$C$3:$BS$3,0)) -> 0.43494577 | E20: =C20*D20 -> 46228232 | F20: =$F$42*$E20/$E$42 -> 755829.85 | G20: =F20+E20 -> 46984062 | H20: =IFERROR(SUMPRODUCT('HTM Output'!$K79:$GS79,'HTM Output'!$K$6:$GS$6)/SUM('HTM Output'!$K79:$GS79),_xlfn.MAXIFS($U$11:$HB$11,$U$14:$HB$14,">"&0)) -> 47361 | I20: =G20*$I$8 -> 16631526 | J20: =$J$42 -> 0.5 | K20: =I20*J20 -> 8315763.2 | L20: =-SUMIFS('HTM Output'!$K15:$GS15,'HTM Output'!$K$6:$GS$6,">"&'HTM Output'!$G$2,'HTM Output'!$K$6:$GS$6,"<="&'HTM Output'!$G$3)*$I$8 -> -870312.17 | M20: =M$42*K20/$K$42 -> 23248.62 | N20: =L20+M20 -> -847063.55 | O20: =SUM(K20:M20) -> 7468699.7 | Q20: =IFERROR(XIRR($T20:$HB20,$T$11:$HB$11),"N/A") -> -0.74124408 | R20: =IFERROR((HK20+O20)/O20,"N/A") -> 0.31259237 | T20: =IF(T$11>$I$4,SUMIFS('Pooled CF'!$E:$E,'Pooled CF'!$A:$A,$A20,'Pooled CF'!$G:$G,T$11),0)+IF(T$11=$I$4,-$O20) -> -7468699.7 | U20: =IFERROR(OFFSET('HTM Output'!$J$6,MATCH($B20,'HTM Output'!$B$7:$B$37,0),MATCH(U$11,'HTM Output'!$K$6:$GS$6,0)),0)*$I$8 -> 146740.66 | V20: =IFERROR(OFFSET('HTM Output'!$J$6,MATCH($B20,'HTM Output'!$B$7:$B$37,0),MATCH(V$11,'HTM Output'!$K$6:$GS$6,0)),0)*$I$8 -> 146738.13 | W20: =IFERROR(OFFSET('HTM Output'!$J$6,MATCH($B20,'HTM Output'!$B$7:$B$37,0),MATCH(W$11,'HTM Output'!$K$6:$GS$6,0)),0)*$I$8 -> 146744.71 | X20: =IFERROR(OFFSET('HTM Output'!$J$6,MATCH($B20,'HTM Output'!$B$7:$B$37,0),MATCH(X$11,'HTM Output'!$K$6:$GS$6,0)),0)*$I$8 -> 151623.5 | Y20: =IFERROR(OFFSET('HTM Output'!$J$6,MATCH($B20,'HTM Output'!$B$7:$B$37,0),MATCH(Y$11,'HTM Output'!$K$6:$GS$6,0)),0)*$I$8 -> 146729.84 | Z20: =IFERROR(OFFSET('HTM Output'!$J$6,MATCH($B20,'HTM Output'!$B$7:$B$37,0),MATCH(Z$11,'HTM Output'!$K$6:$GS$6,0)),0)*$I$8 -> 151617.95 | AA20: =IFERROR(OFFSET('HTM Output'!$J$6,MATCH($B20,'HTM Output'!$B$7:$B$37,0),MATCH(AA$11,'HTM Output'!$K$6:$GS$6,0)),0)*$I$8 -> 146657.13 | AB20: =IFERROR(OFFSET('HTM Output'!$J$6,MATCH($B20,'HTM Output'!$B$7:$B$37,0),MATCH(AB$11,'HTM Output'!$K$6:$GS$6,0)),0)*$I$8 -> 151542.89 | ... HB20: =IFERROR(OFFSET('HTM Output'!$J$6,MATCH($B20,'HTM Output'!$B$7:$B$37,0),MATCH(HB$11,'HTM Output'!$K$6:$GS$6,0)),0)*$I$8 -> 0 | HD20: =T20 -> -7468699.7 | HE20: =SUMIFS($T20:$HB20,$T$10:$HB$10,HE$11) -> 1784723.1 | HF20: =SUMIFS($T20:$HB20,$T$10:$HB$10,HF$11) -> 549935.49 | HG20: =SUMIFS($T20:$HB20,$T$10:$HB$10,HG$11) -> 0 | HH20: =SUMIFS($T20:$HB20,$T$10:$HB$10,HH$11) -> 0 | HI20: =SUMIFS($T20:$HB20,$T$10:$HB$10,HI$11) -> 0 | HJ20: =SUMIFS($T20:$HB20,$T$10:$HB$10,HJ$11) -> 0 | HK20: =SUM(HD20:HJ20) -> -5134041.1
A21: UBSCM 2017-C3 B-Piece Cashflows | B21: UBSCM 2017-C3 | C21: =OFFSET(Strats!$B$3,MATCH($B21,Strats!$B$4:$B$31,0),MATCH(C$10,Strats!$C$3:$BS$3,0)) -> 67393694 | D21: =OFFSET(Strats!$B$3,MATCH($B21,Strats!$B$4:$B$31,0),MATCH(D$10,Strats!$C$3:$BS$3,0)) -> 0.65732392 | E21: =C21*D21 -> 44299487 | F21: =$F$42*$E21/$E$42 -> 724294.94 | G21: =F21+E21 -> 45023782 | H21: =IFERROR(SUMPRODUCT('HTM Output'!$K80:$GS80,'HTM Output'!$K$6:$GS$6)/SUM('HTM Output'!$K80:$GS80),_xlfn.MAXIFS($U$11:$HB$11,$U$14:$HB$14,">"&0)) -> 47813.309 | I21: =G21*$I$8 -> 15937622 | J21: =$J$42 -> 0.5 | K21: =I21*J21 -> 7968811 | L21: =-SUMIFS('HTM Output'!$K16:$GS16,'HTM Output'!$K$6:$GS$6,">"&'HTM Output'!$G$2,'HTM Output'!$K$6:$GS$6,"<="&'HTM Output'!$G$3)*$I$8 -> -385067.49 | M21: =M$42*K21/$K$42 -> 22278.636 | N21: =L21+M21 -> -362788.85 | O21: =SUM(K21:M21) -> 7606022.1 | Q21: =IFERROR(XIRR($T21:$HB21,$T$11:$HB$11),"N/A") -> 0.18671796 | R21: =IFERROR((HK21+O21)/O21,"N/A") -> 1.7637253 | T21: =IF(T$11>$I$4,SUMIFS('Pooled CF'!$E:$E,'Pooled CF'!$A:$A,$A21,'Pooled CF'!$G:$G,T$11),0)+IF(T$11=$I$4,-$O21) -> -7606022.1 | U21: =IFERROR(OFFSET('HTM Output'!$J$6,MATCH($B21,'HTM Output'!$B$7:$B$37,0),MATCH(U$11,'HTM Output'!$K$6:$GS$6,0)),0)*$I$8 -> 66984.399 | V21: =IFERROR(OFFSET('HTM Output'!$J$6,MATCH($B21,'HTM Output'!$B$7:$B$37,0),MATCH(V$11,'HTM Output'!$K$6:$GS$6,0)),0)*$I$8 -> 66998.324 | W21: =IFERROR(OFFSET('HTM Output'!$J$6,MATCH($B21,'HTM Output'!$B$7:$B$37,0),MATCH(W$11,'HTM Output'!$K$6:$GS$6,0)),0)*$I$8 -> 68879.226 | X21: =IFERROR(OFFSET('HTM Output'!$J$6,MATCH($B21,'HTM Output'!$B$7:$B$37,0),MATCH(X$11,'HTM Output'!$K$6:$GS$6,0)),0)*$I$8 -> 69903.119 | Y21: =IFERROR(OFFSET('HTM Output'!$J$6,MATCH($B21,'HTM Output'!$B$7:$B$37,0),MATCH(Y$11,'HTM Output'!$K$6:$GS$6,0)),0)*$I$8 -> 67661.331 | Z21: =IFERROR(OFFSET('HTM Output'!$J$6,MATCH($B21,'HTM Output'!$B$7:$B$37,0),MATCH(Z$11,'HTM Output'!$K$6:$GS$6,0)),0)*$I$8 -> 69779.897 | AA21: =IFERROR(OFFSET('HTM Output'!$J$6,MATCH($B21,'HTM Output'!$B$7:$B$37,0),MATCH(AA$11,'HTM Output'!$K$6:$GS$6,0)),0)*$I$8 -> 70378.865 | AB21: =IFERROR(OFFSET('HTM Output'!$J$6,MATCH($B21,'HTM Output'!$B$7:$B$37,0),MATCH(AB$11,'HTM Output'!$K$6:$GS$6,0)),0)*$I$8 -> 63969.085 | ... HB21: =IFERROR(OFFSET('HTM Output'!$J$6,MATCH($B21,'HTM Output'!$B$7:$B$37,0),MATCH(HB$11,'HTM Output'!$K$6:$GS$6,0)),0)*$I$8 -> 0 | HD21: =T21 -> -7606022.1 | HE21: =SUMIFS($T21:$HB21,$T$10:$HB$10,HE$11) -> 884860.63 | HF21: =SUMIFS($T21:$HB21,$T$10:$HB$10,HF$11) -> 908213.75 | HG21: =SUMIFS($T21:$HB21,$T$10:$HB$10,HG$11) -> 731450.57 | HH21: =SUMIFS($T21:$HB21,$T$10:$HB$10,HH$11) -> 6445286.3 | HI21: =SUMIFS($T21:$HB21,$T$10:$HB$10,HI$11) -> 4445122.4 | HJ21: =SUMIFS($T21:$HB21,$T$10:$HB$10,HJ$11) -> 0 | HK21: =SUM(HD21:HJ21) -> 5808911.6
A22: UBSCM 2017-C5 B-Piece Cashflows | B22: UBSCM 2017-C5 | C22: =OFFSET(Strats!$B$3,MATCH($B22,Strats!$B$4:$B$31,0),MATCH(C$10,Strats!$C$3:$BS$3,0)) -> 63221086 | D22: =OFFSET(Strats!$B$3,MATCH($B22,Strats!$B$4:$B$31,0),MATCH(D$10,Strats!$C$3:$BS$3,0)) -> 0.69324 | E22: =C22*D22 -> 43827385 | F22: =$F$42*$E22/$E$42 -> 716576.1 | G22: =F22+E22 -> 44543962 | H22: =IFERROR(SUMPRODUCT('HTM Output'!$K81:$GS81,'HTM Output'!$K$6:$GS$6)/SUM('HTM Output'!$K81:$GS81),_xlfn.MAXIFS($U$11:$HB$11,$U$14:$HB$14,">"&0)) -> 47647.709 | I22: =G22*$I$8 -> 15767774 | J22: =$J$42 -> 0.5 | K22: =I22*J22 -> 7883887 | L22: =-SUMIFS('HTM Output'!$K17:$GS17,'HTM Output'!$K$6:$GS$6,">"&'HTM Output'!$G$2,'HTM Output'!$K$6:$GS$6,"<="&'HTM Output'!$G$3)*$I$8 -> -457325.32 | M22: =M$42*K22/$K$42 -> 22041.211 | N22: =L22+M22 -> -435284.11 | O22: =SUM(K22:M22) -> 7448602.8 | Q22: =IFERROR(XIRR($T22:$HB22,$T$11:$HB$11),"N/A") -> 0.17445292 | R22: =IFERROR((HK22+O22)/O22,"N/A") -> 1.6531662 | T22: =IF(T$11>$I$4,SUMIFS('Pooled CF'!$E:$E,'Pooled CF'!$A:$A,$A22,'Pooled CF'!$G:$G,T$11),0)+IF(T$11=$I$4,-$O22) -> -7448602.8 | U22: =IFERROR(OFFSET('HTM Output'!$J$6,MATCH($B22,'HTM Output'!$B$7:$B$37,0),MATCH(U$11,'HTM Output'!$K$6:$GS$6,0)),0)*$I$8 -> 67832.056 | V22: =IFERROR(OFFSET('HTM Output'!$J$6,MATCH($B22,'HTM Output'!$B$7:$B$37,0),MATCH(V$11,'HTM Output'!$K$6:$GS$6,0)),0)*$I$8 -> 67827.072 | W22: =IFERROR(OFFSET('HTM Output'!$J$6,MATCH($B22,'HTM Output'!$B$7:$B$37,0),MATCH(W$11,'HTM Output'!$K$6:$GS$6,0)),0)*$I$8 -> 69324.621 | X22: =IFERROR(OFFSET('HTM Output'!$J$6,MATCH($B22,'HTM Output'!$B$7:$B$37,0),MATCH(X$11,'HTM Output'!$K$6:$GS$6,0)),0)*$I$8 -> 70590.536 | Y22: =IFERROR(OFFSET('HTM Output'!$J$6,MATCH($B22,'HTM Output'!$B$7:$B$37,0),MATCH(Y$11,'HTM Output'!$K$6:$GS$6,0)),0)*$I$8 -> 68308.324 | Z22: =IFERROR(OFFSET('HTM Output'!$J$6,MATCH($B22,'HTM Output'!$B$7:$B$37,0),MATCH(Z$11,'HTM Output'!$K$6:$GS$6,0)),0)*$I$8 -> 70579.613 | AA22: =IFERROR(OFFSET('HTM Output'!$J$6,MATCH($B22,'HTM Output'!$B$7:$B$37,0),MATCH(AA$11,'HTM Output'!$K$6:$GS$6,0)),0)*$I$8 -> 68648.638 | AB22: =IFERROR(OFFSET('HTM Output'!$J$6,MATCH($B22,'HTM Output'!$B$7:$B$37,0),MATCH(AB$11,'HTM Output'!$K$6:$GS$6,0)),0)*$I$8 -> 70930.411 | ... HB22: =IFERROR(OFFSET('HTM Output'!$J$6,MATCH($B22,'HTM Output'!$B$7:$B$37,0),MATCH(HB$11,'HTM Output'!$K$6:$GS$6,0)),0)*$I$8 -> 0 | HD22: =T22 -> -7448602.8 | HE22: =SUMIFS($T22:$HB22,$T$10:$HB$10,HE$11) -> 673575.85 | HF22: =SUMIFS($T22:$HB22,$T$10:$HB$10,HF$11) -> 298629.78 | HG22: =SUMIFS($T22:$HB22,$T$10:$HB$10,HG$11) -> 6924619.6 | HH22: =SUMIFS($T22:$HB22,$T$10:$HB$10,HH$11) -> 121145.21 | HI22: =SUMIFS($T22:$HB22,$T$10:$HB$10,HI$11) -> 4295807.7 | HJ22: =SUMIFS($T22:$HB22,$T$10:$HB$10,HJ$11) -> 0 | HK22: =SUM(HD22:HJ22) -> 4865175.3
A23: MSC 2019-H6 B-Piece Cashflows | B23: MSC 2019-H6 | C23: =OFFSET(Strats!$B$3,MATCH($B23,Strats!$B$4:$B$31,0),MATCH(C$10,Strats!$C$3:$BS$3,0)) -> 62736698 | D23: =OFFSET(Strats!$B$3,MATCH($B23,Strats!$B$4:$B$31,0),MATCH(D$10,Strats!$C$3:$BS$3,0)) -> 0.69759483 | E23: =C23*D23 -> 43764796 | F23: =$F$42*$E23/$E$42 -> 715552.76 | G23: =F23+E23 -> 44480348 | H23: =IFERROR(SUMPRODUCT('HTM Output'!$K82:$GS82,'HTM Output'!$K$6:$GS$6)/SUM('HTM Output'!$K82:$GS82),_xlfn.MAXIFS($U$11:$HB$11,$U$14:$HB$14,">"&0)) -> 48008.549 | I23: =G23*$I$8 -> 15745256 | J23: =$J$42 -> 0.5 | K23: =I23*J23 -> 7872628 | L23: =-SUMIFS('HTM Output'!$K18:$GS18,'HTM Output'!$K$6:$GS$6,">"&'HTM Output'!$G$2,'HTM Output'!$K$6:$GS$6,"<="&'HTM Output'!$G$3)*$I$8 -> -470124.49 | M23: =M$42*K23/$K$42 -> 22009.734 | N23: =L23+M23 -> -448114.76 | O23: =SUM(K23:M23) -> 7424513.3 | Q23: =IFERROR(XIRR($T23:$HB23,$T$11:$HB$11),"N/A") -> 0.31284388 | R23: =IFERROR((HK23+O23)/O23,"N/A") -> 2.8239946 | T23: =IF(T$11>$I$4,SUMIFS('Pooled CF'!$E:$E,'Pooled CF'!$A:$A,$A23,'Pooled CF'!$G:$G,T$11),0)+IF(T$11=$I$4,-$O23) -> -7424513.3 | U23: =IFERROR(OFFSET('HTM Output'!$J$6,MATCH($B23,'HTM Output'!$B$7:$B$37,0),MATCH(U$11,'HTM Output'!$K$6:$GS$6,0)),0)*$I$8 -> 81021.367 | V23: =IFERROR(OFFSET('HTM Output'!$J$6,MATCH($B23,'HTM Output'!$B$7:$B$37,0),MATCH(V$11,'HTM Output'!$K$6:$GS$6,0)),0)*$I$8 -> 81018.839 | W23: =IFERROR(OFFSET('HTM Output'!$J$6,MATCH($B23,'HTM Output'!$B$7:$B$37,0),MATCH(W$11,'HTM Output'!$K$6:$GS$6,0)),0)*$I$8 -> 81298.144 | X23: =IFERROR(OFFSET('HTM Output'!$J$6,MATCH($B23,'HTM Output'!$B$7:$B$37,0),MATCH(X$11,'HTM Output'!$K$6:$GS$6,0)),0)*$I$8 -> 83808.115 | Y23: =IFERROR(OFFSET('HTM Output'!$J$6,MATCH($B23,'HTM Output'!$B$7:$B$37,0),MATCH(Y$11,'HTM Output'!$K$6:$GS$6,0)),0)*$I$8 -> 81102.017 | Z23: =IFERROR(OFFSET('HTM Output'!$J$6,MATCH($B23,'HTM Output'!$B$7:$B$37,0),MATCH(Z$11,'HTM Output'!$K$6:$GS$6,0)),0)*$I$8 -> 83802.45 | AA23: =IFERROR(OFFSET('HTM Output'!$J$6,MATCH($B23,'HTM Output'!$B$7:$B$37,0),MATCH(AA$11,'HTM Output'!$K$6:$GS$6,0)),0)*$I$8 -> 81096.499 | AB23: =IFERROR(OFFSET('HTM Output'!$J$6,MATCH($B23,'HTM Output'!$B$7:$B$37,0),MATCH(AB$11,'HTM Output'!$K$6:$GS$6,0)),0)*$I$8 -> 83796.71 | ... HB23: =IFERROR(OFFSET('HTM Output'!$J$6,MATCH($B23,'HTM Output'!$B$7:$B$37,0),MATCH(HB$11,'HTM Output'!$K$6:$GS$6,0)),0)*$I$8 -> 0 | HD23: =T23 -> -7424513.3 | HE23: =SUMIFS($T23:$HB23,$T$10:$HB$10,HE$11) -> 986696.87 | HF23: =SUMIFS($T23:$HB23,$T$10:$HB$10,HF$11) -> 965189.39 | HG23: =SUMIFS($T23:$HB23,$T$10:$HB$10,HG$11) -> 864238.05 | HH23: =SUMIFS($T23:$HB23,$T$10:$HB$10,HH$11) -> 845319.98 | HI23: =SUMIFS($T23:$HB23,$T$10:$HB$10,HI$11) -> 17305341 | HJ23: =SUMIFS($T23:$HB23,$T$10:$HB$10,HJ$11) -> 0 | HK23: =SUM(HD23:HJ23) -> 13542272
A24: WFCM 2019-C49 B-Piece Cashflows | B24: WFCM 2019-C49 | C24: =OFFSET(Strats!$B$3,MATCH($B24,Strats!$B$4:$B$31,0),MATCH(C$10,Strats!$C$3:$BS$3,0)) -> 72155021 | D24: =OFFSET(Strats!$B$3,MATCH($B24,Strats!$B$4:$B$31,0),MATCH(D$10,Strats!$C$3:$BS$3,0)) -> 0.59472576 | E24: =C24*D24 -> 42912450 | F24: =$F$42*$E24/$E$42 -> 701616.93 | G24: =F24+E24 -> 43614067 | H24: =IFERROR(SUMPRODUCT('HTM Output'!$K83:$GS83,'HTM Output'!$K$6:$GS$6)/SUM('HTM Output'!$K83:$GS83),_xlfn.MAXIFS($U$11:$HB$11,$U$14:$HB$14,">"&0)) -> 47962.226 | I24: =G24*$I$8 -> 15438608 | J24: =$J$42 -> 0.5 | K24: =I24*J24 -> 7719303.8 | L24: =-SUMIFS('HTM Output'!$K19:$GS19,'HTM Output'!$K$6:$GS$6,">"&'HTM Output'!$G$2,'HTM Output'!$K$6:$GS$6,"<="&'HTM Output'!$G$3)*$I$8 -> -617437.33 | M24: =M$42*K24/$K$42 -> 21581.081 | N24: =L24+M24 -> -595856.25 | O24: =SUM(K24:M24) -> 7123447.6 | Q24: =IFERROR(XIRR($T24:$HB24,$T$11:$HB$11),"N/A") -> 0.25744733 | R24: =IFERROR((HK24+O24)/O24,"N/A") -> 2.2735136 | T24: =IF(T$11>$I$4,SUMIFS('Pooled CF'!$E:$E,'Pooled CF'!$A:$A,$A24,'Pooled CF'!$G:$G,T$11),0)+IF(T$11=$I$4,-$O24) -> -7123447.6 | U24: =IFERROR(OFFSET('HTM Output'!$J$6,MATCH($B24,'HTM Output'!$B$7:$B$37,0),MATCH(U$11,'HTM Output'!$K$6:$GS$6,0)),0)*$I$8 -> 97610.002 | V24: =IFERROR(OFFSET('HTM Output'!$J$6,MATCH($B24,'HTM Output'!$B$7:$B$37,0),MATCH(V$11,'HTM Output'!$K$6:$GS$6,0)),0)*$I$8 -> 97607.829 | W24: =IFERROR(OFFSET('HTM Output'!$J$6,MATCH($B24,'HTM Output'!$B$7:$B$37,0),MATCH(W$11,'HTM Output'!$K$6:$GS$6,0)),0)*$I$8 -> 98727.373 | X24: =IFERROR(OFFSET('HTM Output'!$J$6,MATCH($B24,'HTM Output'!$B$7:$B$37,0),MATCH(X$11,'HTM Output'!$K$6:$GS$6,0)),0)*$I$8 -> 101239.6 | Y24: =IFERROR(OFFSET('HTM Output'!$J$6,MATCH($B24,'HTM Output'!$B$7:$B$37,0),MATCH(Y$11,'HTM Output'!$K$6:$GS$6,0)),0)*$I$8 -> 97971.583 | Z24: =IFERROR(OFFSET('HTM Output'!$J$6,MATCH($B24,'HTM Output'!$B$7:$B$37,0),MATCH(Z$11,'HTM Output'!$K$6:$GS$6,0)),0)*$I$8 -> 101234.81 | AA24: =IFERROR(OFFSET('HTM Output'!$J$6,MATCH($B24,'HTM Output'!$B$7:$B$37,0),MATCH(AA$11,'HTM Output'!$K$6:$GS$6,0)),0)*$I$8 -> 97966.914 | AB24: =IFERROR(OFFSET('HTM Output'!$J$6,MATCH($B24,'HTM Output'!$B$7:$B$37,0),MATCH(AB$11,'HTM Output'!$K$6:$GS$6,0)),0)*$I$8 -> 101229.95 | ... HB24: =IFERROR(OFFSET('HTM Output'!$J$6,MATCH($B24,'HTM Output'!$B$7:$B$37,0),MATCH(HB$11,'HTM Output'!$K$6:$GS$6,0)),0)*$I$8 -> 0 | HD24: =T24 -> -7123447.6 | HE24: =SUMIFS($T24:$HB24,$T$10:$HB$10,HE$11) -> 1191953.2 | HF24: =SUMIFS($T24:$HB24,$T$10:$HB$10,HF$11) -> 1194762.7 | HG24: =SUMIFS($T24:$HB24,$T$10:$HB$10,HG$11) -> 406393.64 | HH24: =SUMIFS($T24:$HB24,$T$10:$HB$10,HH$11) -> 322193.64 | HI24: =SUMIFS($T24:$HB24,$T$10:$HB$10,HI$11) -> 10509971 | HJ24: =SUMIFS($T24:$HB24,$T$10:$HB$10,HJ$11) -> 2569980.8 | HK24: =SUM(HD24:HJ24) -> 9071807.5
A25: UBSCM 2018-C13 B-Piece Cashflow | B25: UBSCM 2018-C13 | C25: =OFFSET(Strats!$B$3,MATCH($B25,Strats!$B$4:$B$31,0),MATCH(C$10,Strats!$C$3:$BS$3,0)) -> 69343649 | D25: =OFFSET(Strats!$B$3,MATCH($B25,Strats!$B$4:$B$31,0),MATCH(D$10,Strats!$C$3:$BS$3,0)) -> 0.58764012 | E25: =C25*D25 -> 40749110 | F25: =$F$42*$E25/$E$42 -> 666246.41 | G25: =F25+E25 -> 41415356 | H25: =IFERROR(SUMPRODUCT('HTM Output'!$K84:$GS84,'HTM Output'!$K$6:$GS$6)/SUM('HTM Output'!$K84:$GS84),_xlfn.MAXIFS($U$11:$HB$11,$U$14:$HB$14,">"&0)) -> 47787 | I25: =G25*$I$8 -> 14660303 | J25: =$J$42 -> 0.5 | K25: =I25*J25 -> 7330151.5 | L25: =-SUMIFS('HTM Output'!$K20:$GS20,'HTM Output'!$K$6:$GS$6,">"&'HTM Output'!$G$2,'HTM Output'!$K$6:$GS$6,"<="&'HTM Output'!$G$3)*$I$8 -> -517850.17 | M25: =M$42*K25/$K$42 -> 20493.117 | N25: =L25+M25 -> -497357.05 | O25: =SUM(K25:M25) -> 6832794.5 | Q25: =IFERROR(XIRR($T25:$HB25,$T$11:$HB$11),"N/A") -> 0.24700417 | R25: =IFERROR((HK25+O25)/O25,"N/A") -> 2.066532 | T25: =IF(T$11>$I$4,SUMIFS('Pooled CF'!$E:$E,'Pooled CF'!$A:$A,$A25,'Pooled CF'!$G:$G,T$11),0)+IF(T$11=$I$4,-$O25) -> -6832794.5 | U25: =IFERROR(OFFSET('HTM Output'!$J$6,MATCH($B25,'HTM Output'!$B$7:$B$37,0),MATCH(U$11,'HTM Output'!$K$6:$GS$6,0)),0)*$I$8 -> 85690.165 | V25: =IFERROR(OFFSET('HTM Output'!$J$6,MATCH($B25,'HTM Output'!$B$7:$B$37,0),MATCH(V$11,'HTM Output'!$K$6:$GS$6,0)),0)*$I$8 -> 85687.798 | W25: =IFERROR(OFFSET('HTM Output'!$J$6,MATCH($B25,'HTM Output'!$B$7:$B$37,0),MATCH(W$11,'HTM Output'!$K$6:$GS$6,0)),0)*$I$8 -> 87448.044 | X25: =IFERROR(OFFSET('HTM Output'!$J$6,MATCH($B25,'HTM Output'!$B$7:$B$37,0),MATCH(X$11,'HTM Output'!$K$6:$GS$6,0)),0)*$I$8 -> 89142.154 | Y25: =IFERROR(OFFSET('HTM Output'!$J$6,MATCH($B25,'HTM Output'!$B$7:$B$37,0),MATCH(Y$11,'HTM Output'!$K$6:$GS$6,0)),0)*$I$8 -> 86264.177 | Z25: =IFERROR(OFFSET('HTM Output'!$J$6,MATCH($B25,'HTM Output'!$B$7:$B$37,0),MATCH(Z$11,'HTM Output'!$K$6:$GS$6,0)),0)*$I$8 -> 89136.944 | AA25: =IFERROR(OFFSET('HTM Output'!$J$6,MATCH($B25,'HTM Output'!$B$7:$B$37,0),MATCH(AA$11,'HTM Output'!$K$6:$GS$6,0)),0)*$I$8 -> 86259.098 | AB25: =IFERROR(OFFSET('HTM Output'!$J$6,MATCH($B25,'HTM Output'!$B$7:$B$37,0),MATCH(AB$11,'HTM Output'!$K$6:$GS$6,0)),0)*$I$8 -> 89131.657 | ... HB25: =IFERROR(OFFSET('HTM Output'!$J$6,MATCH($B25,'HTM Output'!$B$7:$B$37,0),MATCH(HB$11,'HTM Output'!$K$6:$GS$6,0)),0)*$I$8 -> 0 | HD25: =T25 -> -6832794.5 | HE25: =SUMIFS($T25:$HB25,$T$10:$HB$10,HE$11) -> 1012512.1 | HF25: =SUMIFS($T25:$HB25,$T$10:$HB$10,HF$11) -> 769495.65 | HG25: =SUMIFS($T25:$HB25,$T$10:$HB$10,HG$11) -> 459343.46 | HH25: =SUMIFS($T25:$HB25,$T$10:$HB$10,HH$11) -> 11878837 | HI25: =SUMIFS($T25:$HB25,$T$10:$HB$10,HI$11) -> 0 | HJ25: =SUMIFS($T25:$HB25,$T$10:$HB$10,HJ$11) -> 0 | HK25: =SUM(HD25:HJ25) -> 7287394
... A40: CD 2017-CD3 B-Piece Hist Cashfl | B40: CD 2017-CD3 | C40: =OFFSET(Strats!$B$3,MATCH($B40,Strats!$B$4:$B$31,0),MATCH(C$10,Strats!$C$3:$BS$3,0)) -> 0 | D40: =OFFSET(Strats!$B$3,MATCH($B40,Strats!$B$4:$B$31,0),MATCH(D$10,Strats!$C$3:$BS$3,0)) -> 0 | E40: =C40*D40 -> 0 | F40: =$F$42*$E40/$E$42 -> 0 | G40: =F40+E40 -> 0 | H40: =IFERROR(SUMPRODUCT('HTM Output'!$K99:$GS99,'HTM Output'!$K$6:$GS$6)/SUM('HTM Output'!$K99:$GS99),_xlfn.MAXIFS($U$11:$HB$11,$U$14:$HB$14,">"&0)) -> 47361 | I40: =G40*$I$8 -> 0 | J40: =$J$42 -> 0.5 | K40: =I40*J40 -> 0 | L40: =-SUMIFS('HTM Output'!$K35:$GS35,'HTM Output'!$K$6:$GS$6,">"&'HTM Output'!$G$2,'HTM Output'!$K$6:$GS$6,"<="&'HTM Output'!$G$3)*$I$8 -> 0 | M40: =M$42*K40/$K$42 -> 0 | N40: =L40+M40 -> 0 | O40: =SUM(K40:M40) -> 0 | Q40: =IFERROR(XIRR($T40:$HB40,$T$11:$HB$11),"N/A") -> N/A | R40: =IFERROR((HK40+O40)/O40,"N/A") -> N/A | T40: =IF(T$11>$I$4,SUMIFS('Pooled CF'!$E:$E,'Pooled CF'!$A:$A,$A40,'Pooled CF'!$G:$G,T$11),0)+IF(T$11=$I$4,-$O40) -> 0 | U40: =IFERROR(OFFSET('HTM Output'!$J$6,MATCH($B40,'HTM Output'!$B$7:$B$37,0),MATCH(U$11,'HTM Output'!$K$6:$GS$6,0)),0)*$I$8 -> 0 | V40: =IFERROR(OFFSET('HTM Output'!$J$6,MATCH($B40,'HTM Output'!$B$7:$B$37,0),MATCH(V$11,'HTM Output'!$K$6:$GS$6,0)),0)*$I$8 -> 0 | W40: =IFERROR(OFFSET('HTM Output'!$J$6,MATCH($B40,'HTM Output'!$B$7:$B$37,0),MATCH(W$11,'HTM Output'!$K$6:$GS$6,0)),0)*$I$8 -> 0 | X40: =IFERROR(OFFSET('HTM Output'!$J$6,MATCH($B40,'HTM Output'!$B$7:$B$37,0),MATCH(X$11,'HTM Output'!$K$6:$GS$6,0)),0)*$I$8 -> 0 | Y40: =IFERROR(OFFSET('HTM Output'!$J$6,MATCH($B40,'HTM Output'!$B$7:$B$37,0),MATCH(Y$11,'HTM Output'!$K$6:$GS$6,0)),0)*$I$8 -> 0 | Z40: =IFERROR(OFFSET('HTM Output'!$J$6,MATCH($B40,'HTM Output'!$B$7:$B$37,0),MATCH(Z$11,'HTM Output'!$K$6:$GS$6,0)),0)*$I$8 -> 0 | AA40: =IFERROR(OFFSET('HTM Output'!$J$6,MATCH($B40,'HTM Output'!$B$7:$B$37,0),MATCH(AA$11,'HTM Output'!$K$6:$GS$6,0)),0)*$I$8 -> 0 | AB40: =IFERROR(OFFSET('HTM Output'!$J$6,MATCH($B40,'HTM Output'!$B$7:$B$37,0),MATCH(AB$11,'HTM Output'!$K$6:$GS$6,0)),0)*$I$8 -> 0 | ... HB40: =IFERROR(OFFSET('HTM Output'!$J$6,MATCH($B40,'HTM Output'!$B$7:$B$37,0),MATCH(HB$11,'HTM Output'!$K$6:$GS$6,0)),0)*$I$8 -> 0 | HD40: =T40 -> 0 | HE40: =SUMIFS($T40:$HB40,$T$10:$HB$10,HE$11) -> 0 | HF40: =SUMIFS($T40:$HB40,$T$10:$HB$10,HF$11) -> 0 | HG40: =SUMIFS($T40:$HB40,$T$10:$HB$10,HG$11) -> 0 | HH40: =SUMIFS($T40:$HB40,$T$10:$HB$10,HH$11) -> 0 | HI40: =SUMIFS($T40:$HB40,$T$10:$HB$10,HI$11) -> 0 | HJ40: =SUMIFS($T40:$HB40,$T$10:$HB$10,HJ$11) -> 0 | HK40: =SUM(HD40:HJ40) -> 0
B42: RECOP I Opportunity | C42: =SUM(C13:C41) -> 1.8620571e+09 | D42: =E42/C42 -> 0.50362429 | E42: =SUM(E13:E41) -> 9.377772e+08 | F42: =Assumptions!$D$32 -> 15332622 | G42: =SUM(G13:G41) -> 9.5310983e+08 | H42: =IFERROR(SUMPRODUCT('HTM Output'!$K101:$GS101,'HTM Output'!$K$6:$GS$6)/SUM('HTM Output'!$K101:$GS101),_xlfn.MAXIFS($U$11:$HB$11,$U$14:$HB$14,">"&0)) -> 47792.681 | I42: =SUM(I13:I41) -> 3.3738401e+08 | J42: =HD50 -> 0.5 | K42: =SUM(K13:K41) -> 1.68692e+08 | L42: =SUM(L13:L41) -> -12348779 | M42: =-SUMIFS('HTM Output'!$K216:$GS216,'HTM Output'!$K$6:$GS$6,">"&'HTM Output'!$G$2,'HTM Output'!$K$6:$GS$6,"<="&'HTM Output'!$G$3)*$I$8 -> 471617.12 | N42: =L42+M42 -> -11877162 | O42: =SUM(O13:O41) -> 1.5681484e+08 | Q42: =IFERROR(XIRR($T42:$HB42,$T$11:$HB$11),"N/A") -> 0.17426575 | R42: =IFERROR((HK42+O42)/O42,"N/A") -> 1.6843486 | T42: =SUM(T13:T41) -> -1.5681484e+08 | U42: =SUM(U13:U41) -> 1959220.2 | V42: =SUM(V13:V41) -> 1959533.8 | W42: =SUM(W13:W41) -> 1889089.8 | X42: =SUM(X13:X41) -> 1887977.7 | Y42: =SUM(Y13:Y41) -> 1826362.4 | Z42: =SUM(Z13:Z41) -> 1835149.9 | AA42: =SUM(AA13:AA41) -> 1789431.1 | ... HB42: =SUM(HB13:HB41) -> 0 | HD42: =T42 -> -1.5681484e+08 | HE42: =SUMIFS($T42:$HB42,$T$10:$HB$10,HE$11) -> 21516084 | HF42: =SUMIFS($T42:$HB42,$T$10:$HB$10,HF$11) -> 15728410 | HG42: =SUMIFS($T42:$HB42,$T$10:$HB$10,HG$11) -> 62289110 | HH42: =SUMIFS($T42:$HB42,$T$10:$HB$10,HH$11) -> 76755499 | HI42: =SUMIFS($T42:$HB42,$T$10:$HB$10,HI$11) -> 59470579 | HJ42: =SUMIFS($T42:$HB42,$T$10:$HB$10,HJ$11) -> 28371179 | HK42: =SUM(HD42:HJ42) -> 1.0731602e+08
N44: Purchase Price Calculation
N46: Asset Fair Value | T46: =$E$42*$I$8 -> 3.3195653e+08 | HD46: =T46 -> 3.3195653e+08
N47: Cash & Receivables | T47: =$F$42*$I$8 -> 5427476.7 | HD47: =T47 -> 5427476.7
N48: Investor NAV | T48: =SUM(T46:T47) -> 3.3738401e+08 | HD48: =T48 -> 3.3738401e+08
N50: Purch Px | T50: =$J$42 -> 0.5 | HD50: 0.5
N51: Purchase Price | T51: =T48*T50 -> 1.68692e+08 | HD51: =T51 -> 1.68692e+08
N52: Net Distros During Cutoff Period | T52: =N42 -> -11877162 | HD52: =T52 -> -11877162
N53: Adjusted Price | T53: =T51+T52 -> 1.5681484e+08 | HD53: =T53 -> 1.5681484e+08
Q55: Fwd. IRR(B)(D) | R55: Fwd. MOIC(C)(E) | T55: =$I$4 -> 46388 | U55: =EOMONTH(T55,1) -> 46446 | V55: =EOMONTH(U55,1) -> 46477 | W55: =EOMONTH(V55,1) -> 46507 | X55: =EOMONTH(W55,1) -> 46538 | Y55: =EOMONTH(X55,1) -> 46568 | Z55: =EOMONTH(Y55,1) -> 46599 | AA55: =EOMONTH(Z55,1) -> 46630 | AB55: =EOMONTH(AA55,1) -> 46660 | ... HB55: =EOMONTH(HA55,1) -> 52200 | HD55: =TEXT($I$4,"m/d/yyyy")&" Acquisition" -> 1/1/2027 Acquisition | HE55: =YEAR(U55) -> 2027 | HF55: =HE55+1 -> 2028 | HG55: =HF55+1 -> 2029 | HH55: =HG55+1 -> 2030 | HI55: =HH55+1 -> 2031 | HJ55: =HI55+1 -> 2032 | HK55: Total
N56: Gross Cash Flows
N58: Interest Collections | U58: =IFERROR(OFFSET('HTM Output'!$J$169,0,MATCH(U$11,'HTM Output'!$K$6:$GS$6,0)),0)*$I$8 -> 1959220.2 | V58: =IFERROR(OFFSET('HTM Output'!$J$169,0,MATCH(V$11,'HTM Output'!$K$6:$GS$6,0)),0)*$I$8 -> 1959533.8 | W58: =IFERROR(OFFSET('HTM Output'!$J$169,0,MATCH(W$11,'HTM Output'!$K$6:$GS$6,0)),0)*$I$8 -> 1889089.8 | X58: =IFERROR(OFFSET('HTM Output'!$J$169,0,MATCH(X$11,'HTM Output'!$K$6:$GS$6,0)),0)*$I$8 -> 1887977.7 | Y58: =IFERROR(OFFSET('HTM Output'!$J$169,0,MATCH(Y$11,'HTM Output'!$K$6:$GS$6,0)),0)*$I$8 -> 1826362.4 | Z58: =IFERROR(OFFSET('HTM Output'!$J$169,0,MATCH(Z$11,'HTM Output'!$K$6:$GS$6,0)),0)*$I$8 -> 1835149.9 | AA58: =IFERROR(OFFSET('HTM Output'!$J$169,0,MATCH(AA$11,'HTM Output'!$K$6:$GS$6,0)),0)*$I$8 -> 1789431.1 | AB58: =IFERROR(OFFSET('HTM Output'!$J$169,0,MATCH(AB$11,'HTM Output'!$K$6:$GS$6,0)),0)*$I$8 -> 1819182.7 | ... HB58: =IFERROR(OFFSET('HTM Output'!$J$169,0,MATCH(HB$11,'HTM Output'!$K$6:$GS$6,0)),0)*$I$8 -> 0 | HD58: =T58 -> 0 | HE58: =SUMIFS($T58:$HB58,$T$10:$HB$10,HE$11) -> 21516084 | HF58: =SUMIFS($T58:$HB58,$T$10:$HB$10,HF$11) -> 15728410 | HG58: =SUMIFS($T58:$HB58,$T$10:$HB$10,HG$11) -> 10119095 | HH58: =SUMIFS($T58:$HB58,$T$10:$HB$10,HH$11) -> 8757548.1 | HI58: =SUMIFS($T58:$HB58,$T$10:$HB$10,HI$11) -> 3398347.8 | HJ58: =SUMIFS($T58:$HB58,$T$10:$HB$10,HJ$11) -> 967349.52 | HK58: =SUM(HD58:HJ58) -> 60486835
N59: Principal Collections | U59: =IFERROR(OFFSET('HTM Output'!$J$170,0,MATCH(U$11,'HTM Output'!$K$6:$GS$6,0)),0)*$I$8 -> 0 | V59: =IFERROR(OFFSET('HTM Output'!$J$170,0,MATCH(V$11,'HTM Output'!$K$6:$GS$6,0)),0)*$I$8 -> 0 | W59: =IFERROR(OFFSET('HTM Output'!$J$170,0,MATCH(W$11,'HTM Output'!$K$6:$GS$6,0)),0)*$I$8 -> 0 | X59: =IFERROR(OFFSET('HTM Output'!$J$170,0,MATCH(X$11,'HTM Output'!$K$6:$GS$6,0)),0)*$I$8 -> 0 | Y59: =IFERROR(OFFSET('HTM Output'!$J$170,0,MATCH(Y$11,'HTM Output'!$K$6:$GS$6,0)),0)*$I$8 -> 0 | Z59: =IFERROR(OFFSET('HTM Output'!$J$170,0,MATCH(Z$11,'HTM Output'!$K$6:$GS$6,0)),0)*$I$8 -> 0 | AA59: =IFERROR(OFFSET('HTM Output'!$J$170,0,MATCH(AA$11,'HTM Output'!$K$6:$GS$6,0)),0)*$I$8 -> 0 | AB59: =IFERROR(OFFSET('HTM Output'!$J$170,0,MATCH(AB$11,'HTM Output'!$K$6:$GS$6,0)),0)*$I$8 -> 0 | ... HB59: =IFERROR(OFFSET('HTM Output'!$J$170,0,MATCH(HB$11,'HTM Output'!$K$6:$GS$6,0)),0)*$I$8 -> 0 | HD59: =T59 -> 0 | HE59: =SUMIFS($T59:$HB59,$T$10:$HB$10,HE$11) -> 0 | HF59: =SUMIFS($T59:$HB59,$T$10:$HB$10,HF$11) -> 0 | HG59: =SUMIFS($T59:$HB59,$T$10:$HB$10,HG$11) -> 52170016 | HH59: =SUMIFS($T59:$HB59,$T$10:$HB$10,HH$11) -> 67997950 | HI59: =SUMIFS($T59:$HB59,$T$10:$HB$10,HI$11) -> 56072231 | HJ59: =SUMIFS($T59:$HB59,$T$10:$HB$10,HJ$11) -> 27403829 | HK59: =SUM(HD59:HJ59) -> 2.0364403e+08
N60: Distribution of Fund Cash & Receivables | U60: =IFERROR(OFFSET('HTM Output'!$J$225,0,MATCH(U$11,'HTM Output'!$K$6:$GS$6,0))-OFFSET('HTM Output'!$J$224,0,MATCH(U$11,'HTM Output'!$K$6:$GS$6,0)),0)*$I$8 -> -1888151.2 | V60: =IFERROR(OFFSET('HTM Output'!$J$225,0,MATCH(V$11,'HTM Output'!$K$6:$GS$6,0))-OFFSET('HTM Output'!$J$224,0,MATCH(V$11,'HTM Output'!$K$6:$GS$6,0)),0)*$I$8 -> -1888754.8 | W60: =IFERROR(OFFSET('HTM Output'!$J$225,0,MATCH(W$11,'HTM Output'!$K$6:$GS$6,0))-OFFSET('HTM Output'!$J$224,0,MATCH(W$11,'HTM Output'!$K$6:$GS$6,0)),0)*$I$8 -> 4131816.3 | X60: =IFERROR(OFFSET('HTM Output'!$J$225,0,MATCH(X$11,'HTM Output'!$K$6:$GS$6,0))-OFFSET('HTM Output'!$J$224,0,MATCH(X$11,'HTM Output'!$K$6:$GS$6,0)),0)*$I$8 -> -1818963.1 | Y60: =IFERROR(OFFSET('HTM Output'!$J$225,0,MATCH(Y$11,'HTM Output'!$K$6:$GS$6,0))-OFFSET('HTM Output'!$J$224,0,MATCH(Y$11,'HTM Output'!$K$6:$GS$6,0)),0)*$I$8 -> -1757347.8 | Z60: =IFERROR(OFFSET('HTM Output'!$J$225,0,MATCH(Z$11,'HTM Output'!$K$6:$GS$6,0))-OFFSET('HTM Output'!$J$224,0,MATCH(Z$11,'HTM Output'!$K$6:$GS$6,0)),0)*$I$8 -> 3583390.6 | AA60: =IFERROR(OFFSET('HTM Output'!$J$225,0,MATCH(AA$11,'HTM Output'!$K$6:$GS$6,0))-OFFSET('HTM Output'!$J$224,0,MATCH(AA$11,'HTM Output'!$K$6:$GS$6,0)),0)*$I$8 -> -1720416.5 | AB60: =IFERROR(OFFSET('HTM Output'!$J$225,0,MATCH(AB$11,'HTM Output'!$K$6:$GS$6,0))-OFFSET('HTM Output'!$J$224,0,MATCH(AB$11,'HTM Output'!$K$6:$GS$6,0)),0)*$I$8 -> -1750168 | ... HB60: =IFERROR(OFFSET('HTM Output'!$J$225,0,MATCH(HB$11,'HTM Output'!$K$6:$GS$6,0))-OFFSET('HTM Output'!$J$224,0,MATCH(HB$11,'HTM Output'!$K$6:$GS$6,0)),0)*$I$8 -> 0 | HD60: =T60 -> 0 | HE60: =SUMIFS($T60:$HB60,$T$10:$HB$10,HE$11) -> 524821.9 | HF60: =SUMIFS($T60:$HB60,$T$10:$HB$10,HF$11) -> 1341592.9 | HG60: =SUMIFS($T60:$HB60,$T$10:$HB$10,HG$11) -> 1235398.2 | HH60: =SUMIFS($T60:$HB60,$T$10:$HB$10,HH$11) -> 1196460.2 | HI60: =SUMIFS($T60:$HB60,$T$10:$HB$10,HI$11) -> 821238.93 | HJ60: =SUMIFS($T60:$HB60,$T$10:$HB$10,HJ$11) -> 307964.6 | HK60: =SUM(HD60:HJ60) -> 5427476.7
N61: Gross Distributions | U61: =SUM(U58:U60) -> 71069.076 | V61: =SUM(V58:V60) -> 70779.08 | W61: =SUM(W58:W60) -> 6020906.1 | X61: =SUM(X58:X60) -> 69014.62 | Y61: =SUM(Y58:Y60) -> 69014.62 | Z61: =SUM(Z58:Z60) -> 5418540.5 | AA61: =SUM(AA58:AA60) -> 69014.62 | AB61: =SUM(AB58:AB60) -> 69014.62 | ... HB61: =SUM(HB58:HB60) -> 0 | HD61: =T61 -> 0 | HE61: =SUMIFS($T61:$HB61,$T$10:$HB$10,HE$11) -> 22040906 | HF61: =SUMIFS($T61:$HB61,$T$10:$HB$10,HF$11) -> 17070003 | HG61: =SUMIFS($T61:$HB61,$T$10:$HB$10,HG$11) -> 63524509 | HH61: =SUMIFS($T61:$HB61,$T$10:$HB$10,HH$11) -> 77951959 | HI61: =SUMIFS($T61:$HB61,$T$10:$HB$10,HI$11) -> 60291818 | HJ61: =SUMIFS($T61:$HB61,$T$10:$HB$10,HJ$11) -> 28679143 | HK61: =SUM(HD61:HJ61) -> 2.6955834e+08
N63: Gross B-Piece Cash Flows | Q63: =IFERROR(XIRR($T63:$HB63,$T$11:$HB$11),"N/A") -> 0.17801564 | R63: =-HK61/HD63 -> 1.7189593 | T63: =-T53 -> -1.5681484e+08 | U63: =U61 -> 71069.076 | V63: =V61 -> 70779.08 | W63: =W61 -> 6020906.1 | X63: =X61 -> 69014.62 | Y63: =Y61 -> 69014.62 | Z63: =Z61 -> 5418540.5 | AA63: =AA61 -> 69014.62 | AB63: =AB61 -> 69014.62 | ... HB63: =HB61 -> 0 | HD63: =T63 -> -1.5681484e+08 | HE63: =SUMIFS($T63:$HB63,$T$10:$HB$10,HE$11) -> 22040906 | HF63: =SUMIFS($T63:$HB63,$T$10:$HB$10,HF$11) -> 17070003 | HG63: =SUMIFS($T63:$HB63,$T$10:$HB$10,HG$11) -> 63524509 | HH63: =SUMIFS($T63:$HB63,$T$10:$HB$10,HH$11) -> 77951959 | HI63: =SUMIFS($T63:$HB63,$T$10:$HB$10,HI$11) -> 60291818 | HJ63: =SUMIFS($T63:$HB63,$T$10:$HB$10,HJ$11) -> 28679143 | HK63: =SUM(HD63:HJ63) -> 1.127435e+08
N65: Fees & Expenses | T65: Fees & Expenses
...

Sheet Assumptions
C1: Selling Investor Contributions | D1: 358713131
C2: Net of Capital Returned | D2: -1956490
C3: Selling Investor Net Capital | D3: =SUM(D1:D2) -> 356756641
C4: Total Capital Called | D4: 1.0078375e+09
C5: % of total | D5: =D3/D4 -> 0.3539823
C7: Fee Assumptions | D7: Historical | E7: Forward
C8: Investment Management Fee | D8: 0 | E8: 0
C9: Fund Admin. Expense | D9: 0 | E9: 0
C10: Fund G&A Expenses | D10: 0 | E10: 0
C11: Fund Org. Costs | D11: 0
C14: SS Curve Offset
C15: 42794 | D15: 0
C16: 43830 | D16: 0
C17: =EOMONTH(C16,12) -> 44196 | D17: 0.1
C18: =EOMONTH(C17,12) -> 44561 | D18: 0.2
C19: =EOMONTH(C18,12) -> 44926 | D19: 0.3
C20: =EOMONTH(C19,12) -> 45291 | D20: 0.4
C21: =EOMONTH(C20,12) -> 45657 | D21: 0.5
C22: =EOMONTH(C21,12) -> 46022 | D22: 0.9
C23: =EOMONTH(C22,12) -> 46387 | D23: 0.9
C24: =EOMONTH(C23,12) -> 46752 | D24: 0.9
C25: =EOMONTH(C24,12) -> 47118 | D25: 0.9
C26: =EOMONTH(C25,12) -> 47483 | D26: 0.9
C27: =EOMONTH(C26,12) -> 47848 | D27: 0.9
C28: =EOMONTH(C27,12) -> 48213 | D28: 0.9
C29: =EOMONTH(C28,12) -> 48579 | D29: 0.9
C32: Cash on Hand at Cutoff Month | D32: 15332622
C33: Running Cash Bal. (% of Rem. Eq.) | D33: 0.0175
C35: DD Fee | D35: 0
C36: IHPS Fee | D36: 0

Sheet Endnotes and Disclaimers
B1: Private and Confidential
B3: Endnotes
B5: (A) | C5: Any targets, forecasts, and projections contained herein have been prepared and are set out for illustrative purposes only and are based on hypothetical assumptions and current intentions with respect to the intended operation of the portfolio. The assumptions, forecasts and estimates used to generate this illustrative data are not all described herein, but include assumptions, forecasts and estimates currently deemed reasonable by Rialto relating to existing leases and contracts in place, anticipated collection of rental payments, absorption pace, leasing costs and concessions, operating expenses, development and capital costs, potential capital structures, debt financing, capitalization rates, sales proceeds, timing of dispositions, transaction costs, hold periods, credit of sponsor and borrower recourse, loss and default assumptions with respect to CMBS, current income, and legal risks, costs and timing. No representation or warranty is made as to the reasonableness of such assumptions or that such illustrations are accurate of completer or do not contain errors, or that alternative modeling techniques would not be more appropriate or would not produce significantly different results. None of the targets, assumptions, forecasts or estimates is meant to be a historical description or a prediction of future performance, and each has inherent limitations. Target returns are aspirational only. The forecasts are subject to uncertainties, changes (including changes in economic, operational, political, or other circumstances) and other risks, including broad trends in business and finance, legislation and regulation, interest rates, inflation, currency values, real estate market conditions, the availability and cost of short-term or long term funding and capital, all of which are beyond Rialto’s control and any of which may cause the relevant actual, financial and other results to be materially different from the results expressed or implied by such forecasts or projections. Industry experts may disagree with the forecasts, the estimations and assumptions used in preparing the targets. Different assumptions may also be reasonable and would yield different returns. No assurance, representation or warranty is made by any person that any targets, forecasts and projections will be achieved, and no prospective investor should rely on such targets, forecasts or projections. Projections are based on (a) capital funded by (and reinvested proceeds) and distributed to investors (for portfolio level returns) or the portfolio (for asset level returns) through the stated as of date, (b) projected cash to be distributed to investors (for portfolio level returns) or the portfolio (for asset level returns) during the remaining term, and (c) estimated investment expenses, management and service costs (including for property services and due diligence and asset management services) and capital expenditures (collectively, “Component Cash Flows”). The assumptions and projected returns may have under- or over-compensated for the effect, if any, of certain market factors and other events, including but not limited to the availability of suitable investments. Projected returns may be based in whole or in part on unaudited data that is subject to adjustment.
B6: (B) | C6: “Projected Gross IRR” is the projected compound internal rate of return (on a leveraged basis, if applicable) using a standard formula (XIRR), based on Component Cash Flows from the portfolio through the stated as of date. Project Gross IRR is calculated before deductions for portfolio level costs, investment management fees and incentive allocation, which would reduce returns if taken into account.
B7: (C) | C7: “Projected Gross Equity Multiple (MOIC)” or “Gross MOIC” is calculated by dividing (a) the sum of the (i) actual distributions to investors through the stated as of date, net of recalled capital, through the stated as of date, and (ii) the projected cash to be distributed to investors during the remaining term, by (b) capital funded by investors through the stated as of date. Project Gross MOIC is calculated before deductions for portfolio level costs, investment management fees and incentive allocation, which would reduce returns if taken into account.
B8: (D) | C8: “Projected Net IRR” is the projected compound internal rate of return, on a leveraged basis, if applicable, using a standard formula (XIRR) based on Component Cash Flows from the portfolio through the stated as of date and after taking into account estimated portfolio level costs, investment management fees and incentive allocation.
B9: (E) | C9: “Projected Net Equity Multiple (MOIC)” or “Net MOIC” is calculated by dividing (a) the sum of the (i) actual distributions to investors, net of recalled capital, through the stated as of date, and (ii) the projected cash to be distributed to investors during the remaining term, assuming the current invested portfolio, in each case, net of estimated investment expenses, management and service costs (including for due diligence and asset level accounting, legal and tax services), fund level costs, investment management fees and incentive allocation, and after adjustments for fund level indebtedness, if applicable, by (b) capital funded by investors through the stated as of date.
B11: Disclaimers and Risk Factors
C12: This presentation is for discussion purposes only and does not constitute an offer to sell or the solicitation of an offer to purchase any security or investment product described herein. Any offer or solicitation to purchase an interest in a fund managed by Rialto (a “Fund”) may only be made by means of delivery of an approved confidential offering memorandum, which must be received and reviewed prior to investing. You may not rely on this presentation as the basis upon which to make an investment decision. This presentation does not purport to be complete on any topic addressed. The information, opinions and estimates provided in this presentation are provided to you as of the dates indicated and Rialto does not undertake to update the information after its distribution. These materials are not intended for distribution to, or use by, any person or entity in any jurisdiction or country where such distribution or use would be contrary to applicable law or regulations. If there is any inconsistency between this presentation and the terms and disclosures in a Fund’s offering documents, the offering documents will govern. Certain information in this document might constitute material non-public information and therefore, potentially could impose certain trading restrictions on the recipient.
C13: An investment with Rialto is highly speculative, and there can be no assurance that a Fund’s investment objective will be achieved. Investors must be prepared to bear the risk of a total loss of their investment. An investment in a Fund is suitable only for certain financially sophisticated investors who meet applicable eligibility requirements, have no need for immediate liquidity in their investment and can bear the risk of an investment for an extended period of time. Before deciding to invest, prospective investors should carefully read the Fund’s offering memorandum and pay particular attention to the risk factors and conflicts of interest described therein. Some or all alternative investment programs may not be suitable for certain investors. Investors in a Fund may lose all or a significant portion of their investment. This presentation is not intended to provide, and should not be relied upon for, tax, legal, accounting or investment advice.
C14: PAST PERFORMANCE IS NOT INDICATIVE OF FUTURE RESULTS. Performance data is net of fees and assumes reinvestment of income and dividends except to the extent otherwise indicated. The performance data for certain periods has not been audited. There can be no assurance that a Fund will achieve results that are referenced in this presentation. There is no guarantee that a Fund or future offerings by Rialto will have access to similar types of investments or opportunities to achieve comparable results. Calculations of returns are based on the payment date of investors’ capital contributions. Returns of any individual investor may vary from the returns shown due to the timing of capital transactions and other items. Portfolio level performance reflects the reinvestment of a portion of the investment income and investment proceeds as a result of recycling (to the extent permitted under a portfolio’s governing documents, which is the case for each of Rialto’s flagship Funds). Internal Rate of Return (“IRR”) calculations may be favorably impacted by the short-term use of a line of credit facility to bridge capital calls, into which certain Funds and accounts have entered. Under the terms of the applicable line of credit facilities agreements, Rialto typically has the discretion to carry an investment on the line of credit facilities for an extended period. There are instances where the Fund utilizes borrowings under its subscription-based credit facility in advance of or in lieu of receiving investors’ capital contributions. The use of a subscription-based credit facility will result in higher or lower reported returns than if investors’ capital had been contributed at the inception of an investment. In addition, the Fund pays all related expenses, including interest, on its subscription-based credit facility and investors will bear such costs.
C15: Gross returns are presented before deduction for investment management fees and performance compensation but are net of all operating expenses. Actual net returns to investors are reduced by such investment management fees and performance compensation.
