Workbook
Name rcEntity: 'RECOP Tape'!$C$11:$C$129
Name rcIssuer: 'RECOP Tape'!$D$11:$D$129
Name rcBook: 'RECOP Tape'!$M$11:$M$129
Name rcFV: 'RECOP Tape'!$N$11:$N$129
Name mapPTCode: Mappings!$B$7:$B$16
Name mapPTGroup: Mappings!$C$7:$C$16
Name mapRegion: Mappings!$E$7:$E$16
Name lstDeal: Mappings!$G$7:$G$34
Name lstEntity: Mappings!$G$37:$G$40
Name lstPType: Mappings!$G$43:$G$52
Name lstDefeased: Mappings!$G$55:$G$56
Name stList: Mappings!$I$7:$I$60
Name stKey: Mappings!$K$7:$K$60
Name mMatWindow: Mappings!$N$7
Name mTieBreak: Mappings!$N$8
Name dmID: 'Deal Map'!$B$8:$B$34
Name dmName: 'Deal Map'!$C$8:$C$34
Name dmEntity: 'Deal Map'!$E$8:$E$34
Name dmVintage: 'Deal Map'!$F$8:$F$34
Name dmInclude: 'Deal Map'!$G$8:$G$34
Name dmBook: 'Deal Map'!$I$8:$I$34
Name dmFV: 'Deal Map'!$J$8:$J$34
Name dmInFilter: 'Deal Map'!$Q$8:$Q$34
Name dmFiltUPB: 'Deal Map'!$S$8:$S$34
Name tDealID: 'Collat Tape'!$C$8:$C$1600
Name tName: 'Collat Tape'!$E$8:$E$1600
Name tUID: 'Collat Tape'!$F$8:$F$1600
Name tOrigBal: 'Collat Tape'!$H$8:$H$1600
Name tUPB: 'Collat Tape'!$I$8:$I$1600
Name tAge: 'Collat Tape'!$Q$8:$Q$1600
Name tMatDate: 'Collat Tape'!$CQ$8:$CQ$1600
Name tARA: 'Collat Tape'!$BH$8:$BH$1600
Name tAdv: 'Collat Tape'!$BI$8:$BI$1600
Name tRptDate: 'Collat Tape'!$BS$8:$BS$1600
Name tDeal: 'Collat Tape'!$BU$8:$BU$1600
Name tEntity: 'Collat Tape'!$BV$8:$BV$1600
Name tVint: 'Collat Tape'!$BW$8:$BW$1600
Name tActive: 'Collat Tape'!$BY$8:$BY$1600
Name tPType: 'Collat Tape'!$BZ$8:$BZ$1600
Name tState: 'Collat Tape'!$CA$8:$CA$1600
Name tRegion: 'Collat Tape'!$CB$8:$CB$1600
Name tPay: 'Collat Tape'!$CC$8:$CC$1600
Name tDQ: 'Collat Tape'!$CD$8:$CD$1600
Name tSS: 'Collat Tape'!$CE$8:$CE$1600
Name tSSF: 'Collat Tape'!$CF$8:$CF$1600
Name tWL: 'Collat Tape'!$CG$8:$CG$1600
Name tWLF: 'Collat Tape'!$CH$8:$CH$1600
Name tDef: 'Collat Tape'!$CI$8:$CI$1600
Name tDefF: 'Collat Tape'!$CJ$8:$CJ$1600
Name tAmort: 'Collat Tape'!$CK$8:$CK$1600
Name tFIO: 'Collat Tape'!$CL$8:$CL$1600
Name tPIO: 'Collat Tape'!$CM$8:$CM$1600
Name tPari: 'Collat Tape'!$CN$8:$CN$1600
Name tPP: 'Collat Tape'!$CO$8:$CO$1600
Name tOrigYr: 'Collat Tape'!$CP$8:$CP$1600
Name tMatYr: 'Collat Tape'!$CR$8:$CR$1600
Name tRem: 'Collat Tape'!$CS$8:$CS$1600
Name tMat12: 'Collat Tape'!$CT$8:$CT$1600
Name tCpn: 'Collat Tape'!$CU$8:$CU$1600
Name tUWDSCR: 'Collat Tape'!$CV$8:$CV$1600

Sheet Strats
B2: KKR TRANSACTION (RECOP I CMBS B-PIECES): COLLATERAL POOL STRATIFICATIONS
B4: POOL OVERVIEW
B5: Data As Of (Intex Remit) | C5: =MAX(tRptDate) | E5: Wtd. Avg. Gross Coupon | I5: =IFERROR(SUMPRODUCT(tFlag*(1),tUPBf,tCpn)/SUMPRODUCT(tFlag*(1)*ISNUMBER(tCpn),tUPBf),0) | K5: % Full IO | P5: =IFERROR(SUMPRODUCT(tFlag*(1),tUPBf,tFIO)/SUMPRODUCT(tFlag*(1),tUPBf),0)
B6: Deal Filter | C6: All Deals | E6: Wtd. Avg. UW NCF DSCR | I6: =IFERROR(SUMPRODUCT(tFlag*(1),tUPBf,tUWDSCR)/SUMPRODUCT(tFlag*(1)*ISNUMBER(tUWDSCR),tUPBf),0) | K6: % Partial IO | P6: =IFERROR(SUMPRODUCT(tFlag*(1),tUPBf,tPIO)/SUMPRODUCT(tFlag*(1),tUPBf),0)
B7: Holding Entity Filter | C7: All Entities | E7: Wtd. Avg. Current NCF DSCR | I7: =IFERROR(SUMPRODUCT(tFlag*(1),tUPBf,tCurDSCR)/SUMPRODUCT(tFlag*(1)*ISNUMBER(tCurDSCR),tUPBf),0) | K7: % Fully Defeased | P7: =IFERROR(SUMPRODUCT(tFlag*(1),tUPBf,tDefF)/SUMPRODUCT(tFlag*(1),tUPBf),0)
B8: Property Type Filter | C8: All Property Types | E8: Wtd. Avg. UW (Cut-Off) LTV | I8: =IFERROR(SUMPRODUCT(tFlag*(1),tUPBf,tUWLTV)/SUMPRODUCT(tFlag*(1)*ISNUMBER(tUWLTV),tUPBf),0) | K8: % Currently Specially Serviced | P8: =IFERROR(SUMPRODUCT(tFlag*(1),tUPBf,tSSF)/SUMPRODUCT(tFlag*(1),tUPBf),0)
B9: Defeased Loans | C9: Include | E9: Wtd. Avg. Current LTV (Latest Appraisal) | I9: =IFERROR(SUMPRODUCT(tFlag*(1),tUPBf,tCurLTV)/SUMPRODUCT(tFlag*(1)*ISNUMBER(tCurLTV),tUPBf),0) | K9: % 30+ Delinq. / FC / REO / NP Matured | P9: =IFERROR(SUMPRODUCT(tFlag*(1),tUPBf,tDQ)/SUMPRODUCT(tFlag*(1),tUPBf),0)
B10: Number of Deals | C10: =SUMPRODUCT((dmFiltUPB>0)*1) | E10: Wtd. Avg. UW LTV at Maturity | I10: =IFERROR(SUMPRODUCT(tFlag*(1),tUPBf,tMatLTV)/SUMPRODUCT(tFlag*(1)*ISNUMBER(tMatLTV),tUPBf),0) | K10: % REO | P10: =IFERROR(SUMPRODUCT(tFlag*(tPay="REO"),tUPBf)/sUPB,0)
B11: Number of Loans (Trust Notes) | C11: =SUM(tFlag) | E11: Wtd. Avg. UW NCF Debt Yield | I11: =IFERROR(SUMPRODUCT(tFlag*(1),tUPBf,tUWDY)/SUMPRODUCT(tFlag*(1)*ISNUMBER(tUWDY),tUPBf),0) | K11: % On Watchlist | P11: =IFERROR(SUMPRODUCT(tFlag*(1),tUPBf,tWLF)/SUMPRODUCT(tFlag*(1),tUPBf),0)
B12: Unique Loans (Pari Passu Consolidated) | C12: =SUM(tFirst) | E12: Wtd. Avg. Current NCF Debt Yield | I12: =IFERROR(SUMPRODUCT(tFlag*(1),tUPBf,tCurDY)/SUMPRODUCT(tFlag*(1)*ISNUMBER(tCurDY),tUPBf),0) | K12: % Pari Passu Split Loans | P12: =IFERROR(SUMPRODUCT(tFlag*(1),tUPBf,tPP)/SUMPRODUCT(tFlag*(1),tUPBf),0)
B13: Current UPB | C13: =SUM(tUPBf) | E13: Wtd. Avg. Current Occupancy | I13: =IFERROR(SUMPRODUCT(tFlag*(1),tUPBf,tOcc)/SUMPRODUCT(tFlag*(1)*ISNUMBER(tOcc),tUPBf),0) | K13: ="% Maturing Within "&mMatWindow&" Months" | P13: =IFERROR(SUMPRODUCT(tFlag*(1),tUPBf,tMat12)/SUMPRODUCT(tFlag*(1),tUPBf),0)
B14: Original Balance (Same Loans) | C14: =SUMPRODUCT(tFlag,tOrigBal) | E14: Wtd. Avg. Rem. Term to Maturity (Mo.) | I14: =IFERROR(SUMPRODUCT(tFlag*(1),tUPBf,tRem)/SUMPRODUCT(tFlag*(1)*ISNUMBER(tRem),tUPBf),0) | K14: % Top 10 Loan Exposures | P14: =IFERROR(SUM($F$27:$F$36)/sUPB,0)
B15: Average Loan Size | C15: =IFERROR(C13/C11,0) | E15: Wtd. Avg. Seasoning (Mo.) | I15: =IFERROR(SUMPRODUCT(tFlag*(1),tUPBf,tAge)/SUMPRODUCT(tFlag*(1)*ISNUMBER(tAge),tUPBf),0) | K15: Active Appraisal Reductions | P15: =SUMPRODUCT(tFlag,tARA)
B16: Largest Loan Exposure | C16: =MAX(tGrpUPB) | E16: Pool Factor (Current / Original) | I16: =IFERROR(C13/C14,0) | K16: Outstanding P&I Advances | P16: =SUMPRODUCT(tFlag,tAdv)
B17: RECOP Book Value (Deals in Filter) | C17: =SUMPRODUCT(dmInFilter,dmBook)
B18: RECOP Fair Value (Deals in Filter) | C18: =SUMPRODUCT(dmInFilter,dmFV)
B20: ="(1) Source: KKR Transaction Intex Collateral Export (Collat Tape tab), remit data as of "&TEXT(C5,"mm/dd/yyyy")&"; RECOP I book and fair values per the Q2 2026 Combined Schedule of Investments (RECOP Tape tab)."
B21: (2) Strats cover active loans only (Current Balance above zero) in deals flagged Include in Pool on the Deal Map tab, after the four toggles above. Use the dropdowns in C6:C9 to filter by deal, RECOP holding entity, property type or defeasance.
B22: (3) Loan counts are trust notes; a pari passu loan held by several trusts counts once per trust. Unique Loans and the Top 10 table consolidate notes by Intex Unique ID. All weighted averages are weighted by Current UPB and exclude loans missing the metric.
B23: (4) UW metrics are at securitization (Intex Underwritten / Cut-Off fields). Current DSCR and Debt Yield use the most recent reported NCF; Current LTV uses the latest appraisal value in Intex. Delinquency uses Intex Delinq (Consolidated), then CREFC payment status.
B25: TEN LARGEST LOAN EXPOSURES (NOTES CONSOLIDATED ACROSS DEALS)
B26: Loan / Property Name | C26: Notes in Filter (#) | D26: Property Type | E26: State | F26: Current UPB (All Notes) | G26: % of UPB | H26: Gross Coupon | I26: UW NCF DSCR | J26: Current NCF DSCR | K26: UW LTV | L26: Current LTV | M26: UW NCF Debt Yield | N26: Current NCF Debt Yield | O26: Current Occupancy | P26: Rem. Term (Mo.) | Q26: Maturity (ARD if Any) | R26: Payment Status | S26: Servicing Status | T26: Watchlist Status | U26: Defeased | W26: Tape Row Index
B27: =IF($W27="","",INDEX(tName,$W27)) | C27: =IF($W27="","",INDEX(tGrpDeals,$W27)) | D27: =IF($W27="","",INDEX(tPType,$W27)) | E27: =IF($W27="","",INDEX(tState,$W27)) | F27: =IF($W27="","",INDEX(tGrpUPB,$W27)) | G27: =IFERROR(F27/sUPB,0) | H27: =IF($W27="","",INDEX(tCpn,$W27)) | I27: =IF($W27="","",INDEX(tUWDSCR,$W27)) | J27: =IF($W27="","",INDEX(tCurDSCR,$W27)) | K27: =IF($W27="","",INDEX(tUWLTV,$W27)) | L27: =IF($W27="","",INDEX(tCurLTV,$W27)) | M27: =IF($W27="","",INDEX(tUWDY,$W27)) | N27: =IF($W27="","",INDEX(tCurDY,$W27)) | O27: =IF($W27="","",INDEX(tOcc,$W27)) | P27: =IF($W27="","",INDEX(tRem,$W27)) | Q27: =IF($W27="","",INDEX(tMatDate,$W27)) | R27: =IF($W27="","",INDEX(tPay,$W27)) | S27: =IF($W27="","",IF(INDEX(tSSF,$W27)=1,"Current SS",IF(INDEX(tSS,$W27)="Previously Specially Serviced","Prior SS","Never SS"))) | T27: =IF($W27="","",IF(INDEX(tWLF,$W27)=1,"Current",IF(INDEX(tWL,$W27)="Previously on Watchlist","Prior","Never"))) | U27: =IF($W27="","",IF(INDEX(tDefF,$W27)=1,"Defeased","")) | W27: =IF(LARGE(tGrpKey,1)=0,"",MATCH(LARGE(tGrpKey,1),tGrpKey,0))
B28: =IF($W28="","",INDEX(tName,$W28)) | C28: =IF($W28="","",INDEX(tGrpDeals,$W28)) | D28: =IF($W28="","",INDEX(tPType,$W28)) | E28: =IF($W28="","",INDEX(tState,$W28)) | F28: =IF($W28="","",INDEX(tGrpUPB,$W28)) | G28: =IFERROR(F28/sUPB,0) | H28: =IF($W28="","",INDEX(tCpn,$W28)) | I28: =IF($W28="","",INDEX(tUWDSCR,$W28)) | J28: =IF($W28="","",INDEX(tCurDSCR,$W28)) | K28: =IF($W28="","",INDEX(tUWLTV,$W28)) | L28: =IF($W28="","",INDEX(tCurLTV,$W28)) | M28: =IF($W28="","",INDEX(tUWDY,$W28)) | N28: =IF($W28="","",INDEX(tCurDY,$W28)) | O28: =IF($W28="","",INDEX(tOcc,$W28)) | P28: =IF($W28="","",INDEX(tRem,$W28)) | Q28: =IF($W28="","",INDEX(tMatDate,$W28)) | R28: =IF($W28="","",INDEX(tPay,$W28)) | S28: =IF($W28="","",IF(INDEX(tSSF,$W28)=1,"Current SS",IF(INDEX(tSS,$W28)="Previously Specially Serviced","Prior SS","Never SS"))) | T28: =IF($W28="","",IF(INDEX(tWLF,$W28)=1,"Current",IF(INDEX(tWL,$W28)="Previously on Watchlist","Prior","Never"))) | U28: =IF($W28="","",IF(INDEX(tDefF,$W28)=1,"Defeased","")) | W28: =IF(LARGE(tGrpKey,2)=0,"",MATCH(LARGE(tGrpKey,2),tGrpKey,0))
B29: =IF($W29="","",INDEX(tName,$W29)) | C29: =IF($W29="","",INDEX(tGrpDeals,$W29)) | D29: =IF($W29="","",INDEX(tPType,$W29)) | E29: =IF($W29="","",INDEX(tState,$W29)) | F29: =IF($W29="","",INDEX(tGrpUPB,$W29)) | G29: =IFERROR(F29/sUPB,0) | H29: =IF($W29="","",INDEX(tCpn,$W29)) | I29: =IF($W29="","",INDEX(tUWDSCR,$W29)) | J29: =IF($W29="","",INDEX(tCurDSCR,$W29)) | K29: =IF($W29="","",INDEX(tUWLTV,$W29)) | L29: =IF($W29="","",INDEX(tCurLTV,$W29)) | M29: =IF($W29="","",INDEX(tUWDY,$W29)) | N29: =IF($W29="","",INDEX(tCurDY,$W29)) | O29: =IF($W29="","",INDEX(tOcc,$W29)) | P29: =IF($W29="","",INDEX(tRem,$W29)) | Q29: =IF($W29="","",INDEX(tMatDate,$W29)) | R29: =IF($W29="","",INDEX(tPay,$W29)) | S29: =IF($W29="","",IF(INDEX(tSSF,$W29)=1,"Current SS",IF(INDEX(tSS,$W29)="Previously Specially Serviced","Prior SS","Never SS"))) | T29: =IF($W29="","",IF(INDEX(tWLF,$W29)=1,"Current",IF(INDEX(tWL,$W29)="Previously on Watchlist","Prior","Never"))) | U29: =IF($W29="","",IF(INDEX(tDefF,$W29)=1,"Defeased","")) | W29: =IF(LARGE(tGrpKey,3)=0,"",MATCH(LARGE(tGrpKey,3),tGrpKey,0))
B30: =IF($W30="","",INDEX(tName,$W30)) | C30: =IF($W30="","",INDEX(tGrpDeals,$W30)) | D30: =IF($W30="","",INDEX(tPType,$W30)) | E30: =IF($W30="","",INDEX(tState,$W30)) | F30: =IF($W30="","",INDEX(tGrpUPB,$W30)) | G30: =IFERROR(F30/sUPB,0) | H30: =IF($W30="","",INDEX(tCpn,$W30)) | I30: =IF($W30="","",INDEX(tUWDSCR,$W30)) | J30: =IF($W30="","",INDEX(tCurDSCR,$W30)) | K30: =IF($W30="","",INDEX(tUWLTV,$W30)) | L30: =IF($W30="","",INDEX(tCurLTV,$W30)) | M30: =IF($W30="","",INDEX(tUWDY,$W30)) | N30: =IF($W30="","",INDEX(tCurDY,$W30)) | O30: =IF($W30="","",INDEX(tOcc,$W30)) | P30: =IF($W30="","",INDEX(tRem,$W30)) | Q30: =IF($W30="","",INDEX(tMatDate,$W30)) | R30: =IF($W30="","",INDEX(tPay,$W30)) | S30: =IF($W30="","",IF(INDEX(tSSF,$W30)=1,"Current SS",IF(INDEX(tSS,$W30)="Previously Specially Serviced","Prior SS","Never SS"))) | T30: =IF($W30="","",IF(INDEX(tWLF,$W30)=1,"Current",IF(INDEX(tWL,$W30)="Previously on Watchlist","Prior","Never"))) | U30: =IF($W30="","",IF(INDEX(tDefF,$W30)=1,"Defeased","")) | W30: =IF(LARGE(tGrpKey,4)=0,"",MATCH(LARGE(tGrpKey,4),tGrpKey,0))
B31: =IF($W31="","",INDEX(tName,$W31)) | C31: =IF($W31="","",INDEX(tGrpDeals,$W31)) | D31: =IF($W31="","",INDEX(tPType,$W31)) | E31: =IF($W31="","",INDEX(tState,$W31)) | F31: =IF($W31="","",INDEX(tGrpUPB,$W31)) | G31: =IFERROR(F31/sUPB,0) | H31: =IF($W31="","",INDEX(tCpn,$W31)) | I31: =IF($W31="","",INDEX(tUWDSCR,$W31)) | J31: =IF($W31="","",INDEX(tCurDSCR,$W31)) | K31: =IF($W31="","",INDEX(tUWLTV,$W31)) | L31: =IF($W31="","",INDEX(tCurLTV,$W31)) | M31: =IF($W31="","",INDEX(tUWDY,$W31)) | N31: =IF($W31="","",INDEX(tCurDY,$W31)) | O31: =IF($W31="","",INDEX(tOcc,$W31)) | P31: =IF($W31="","",INDEX(tRem,$W31)) | Q31: =IF($W31="","",INDEX(tMatDate,$W31)) | R31: =IF($W31="","",INDEX(tPay,$W31)) | S31: =IF($W31="","",IF(INDEX(tSSF,$W31)=1,"Current SS",IF(INDEX(tSS,$W31)="Previously Specially Serviced","Prior SS","Never SS"))) | T31: =IF($W31="","",IF(INDEX(tWLF,$W31)=1,"Current",IF(INDEX(tWL,$W31)="Previously on Watchlist","Prior","Never"))) | U31: =IF($W31="","",IF(INDEX(tDefF,$W31)=1,"Defeased","")) | W31: =IF(LARGE(tGrpKey,5)=0,"",MATCH(LARGE(tGrpKey,5),tGrpKey,0))
B32: =IF($W32="","",INDEX(tName,$W32)) | C32: =IF($W32="","",INDEX(tGrpDeals,$W32)) | D32: =IF($W32="","",INDEX(tPType,$W32)) | E32: =IF($W32="","",INDEX(tState,$W32)) | F32: =IF($W32="","",INDEX(tGrpUPB,$W32)) | G32: =IFERROR(F32/sUPB,0) | H32: =IF($W32="","",INDEX(tCpn,$W32)) | I32: =IF($W32="","",INDEX(tUWDSCR,$W32)) | J32: =IF($W32="","",INDEX(tCurDSCR,$W32)) | K32: =IF($W32="","",INDEX(tUWLTV,$W32)) | L32: =IF($W32="","",INDEX(tCurLTV,$W32)) | M32: =IF($W32="","",INDEX(tUWDY,$W32)) | N32: =IF($W32="","",INDEX(tCurDY,$W32)) | O32: =IF($W32="","",INDEX(tOcc,$W32)) | P32: =IF($W32="","",INDEX(tRem,$W32)) | Q32: =IF($W32="","",INDEX(tMatDate,$W32)) | R32: =IF($W32="","",INDEX(tPay,$W32)) | S32: =IF($W32="","",IF(INDEX(tSSF,$W32)=1,"Current SS",IF(INDEX(tSS,$W32)="Previously Specially Serviced","Prior SS","Never SS"))) | T32: =IF($W32="","",IF(INDEX(tWLF,$W32)=1,"Current",IF(INDEX(tWL,$W32)="Previously on Watchlist","Prior","Never"))) | U32: =IF($W32="","",IF(INDEX(tDefF,$W32)=1,"Defeased","")) | W32: =IF(LARGE(tGrpKey,6)=0,"",MATCH(LARGE(tGrpKey,6),tGrpKey,0))
B33: =IF($W33="","",INDEX(tName,$W33)) | C33: =IF($W33="","",INDEX(tGrpDeals,$W33)) | D33: =IF($W33="","",INDEX(tPType,$W33)) | E33: =IF($W33="","",INDEX(tState,$W33)) | F33: =IF($W33="","",INDEX(tGrpUPB,$W33)) | G33: =IFERROR(F33/sUPB,0) | H33: =IF($W33="","",INDEX(tCpn,$W33)) | I33: =IF($W33="","",INDEX(tUWDSCR,$W33)) | J33: =IF($W33="","",INDEX(tCurDSCR,$W33)) | K33: =IF($W33="","",INDEX(tUWLTV,$W33)) | L33: =IF($W33="","",INDEX(tCurLTV,$W33)) | M33: =IF($W33="","",INDEX(tUWDY,$W33)) | N33: =IF($W33="","",INDEX(tCurDY,$W33)) | O33: =IF($W33="","",INDEX(tOcc,$W33)) | P33: =IF($W33="","",INDEX(tRem,$W33)) | Q33: =IF($W33="","",INDEX(tMatDate,$W33)) | R33: =IF($W33="","",INDEX(tPay,$W33)) | S33: =IF($W33="","",IF(INDEX(tSSF,$W33)=1,"Current SS",IF(INDEX(tSS,$W33)="Previously Specially Serviced","Prior SS","Never SS"))) | T33: =IF($W33="","",IF(INDEX(tWLF,$W33)=1,"Current",IF(INDEX(tWL,$W33)="Previously on Watchlist","Prior","Never"))) | U33: =IF($W33="","",IF(INDEX(tDefF,$W33)=1,"Defeased","")) | W33: =IF(LARGE(tGrpKey,7)=0,"",MATCH(LARGE(tGrpKey,7),tGrpKey,0))
B34: =IF($W34="","",INDEX(tName,$W34)) | C34: =IF($W34="","",INDEX(tGrpDeals,$W34)) | D34: =IF($W34="","",INDEX(tPType,$W34)) | E34: =IF($W34="","",INDEX(tState,$W34)) | F34: =IF($W34="","",INDEX(tGrpUPB,$W34)) | G34: =IFERROR(F34/sUPB,0) | H34: =IF($W34="","",INDEX(tCpn,$W34)) | I34: =IF($W34="","",INDEX(tUWDSCR,$W34)) | J34: =IF($W34="","",INDEX(tCurDSCR,$W34)) | K34: =IF($W34="","",INDEX(tUWLTV,$W34)) | L34: =IF($W34="","",INDEX(tCurLTV,$W34)) | M34: =IF($W34="","",INDEX(tUWDY,$W34)) | N34: =IF($W34="","",INDEX(tCurDY,$W34)) | O34: =IF($W34="","",INDEX(tOcc,$W34)) | P34: =IF($W34="","",INDEX(tRem,$W34)) | Q34: =IF($W34="","",INDEX(tMatDate,$W34)) | R34: =IF($W34="","",INDEX(tPay,$W34)) | S34: =IF($W34="","",IF(INDEX(tSSF,$W34)=1,"Current SS",IF(INDEX(tSS,$W34)="Previously Specially Serviced","Prior SS","Never SS"))) | T34: =IF($W34="","",IF(INDEX(tWLF,$W34)=1,"Current",IF(INDEX(tWL,$W34)="Previously on Watchlist","Prior","Never"))) | U34: =IF($W34="","",IF(INDEX(tDefF,$W34)=1,"Defeased","")) | W34: =IF(LARGE(tGrpKey,8)=0,"",MATCH(LARGE(tGrpKey,8),tGrpKey,0))
B35: =IF($W35="","",INDEX(tName,$W35)) | C35: =IF($W35="","",INDEX(tGrpDeals,$W35)) | D35: =IF($W35="","",INDEX(tPType,$W35)) | E35: =IF($W35="","",INDEX(tState,$W35)) | F35: =IF($W35="","",INDEX(tGrpUPB,$W35)) | G35: =IFERROR(F35/sUPB,0) | H35: =IF($W35="","",INDEX(tCpn,$W35)) | I35: =IF($W35="","",INDEX(tUWDSCR,$W35)) | J35: =IF($W35="","",INDEX(tCurDSCR,$W35)) | K35: =IF($W35="","",INDEX(tUWLTV,$W35)) | L35: =IF($W35="","",INDEX(tCurLTV,$W35)) | M35: =IF($W35="","",INDEX(tUWDY,$W35)) | N35: =IF($W35="","",INDEX(tCurDY,$W35)) | O35: =IF($W35="","",INDEX(tOcc,$W35)) | P35: =IF($W35="","",INDEX(tRem,$W35)) | Q35: =IF($W35="","",INDEX(tMatDate,$W35)) | R35: =IF($W35="","",INDEX(tPay,$W35)) | S35: =IF($W35="","",IF(INDEX(tSSF,$W35)=1,"Current SS",IF(INDEX(tSS,$W35)="Previously Specially Serviced","Prior SS","Never SS"))) | T35: =IF($W35="","",IF(INDEX(tWLF,$W35)=1,"Current",IF(INDEX(tWL,$W35)="Previously on Watchlist","Prior","Never"))) | U35: =IF($W35="","",IF(INDEX(tDefF,$W35)=1,"Defeased","")) | W35: =IF(LARGE(tGrpKey,9)=0,"",MATCH(LARGE(tGrpKey,9),tGrpKey,0))
B36: =IF($W36="","",INDEX(tName,$W36)) | C36: =IF($W36="","",INDEX(tGrpDeals,$W36)) | D36: =IF($W36="","",INDEX(tPType,$W36)) | E36: =IF($W36="","",INDEX(tState,$W36)) | F36: =IF($W36="","",INDEX(tGrpUPB,$W36)) | G36: =IFERROR(F36/sUPB,0) | H36: =IF($W36="","",INDEX(tCpn,$W36)) | I36: =IF($W36="","",INDEX(tUWDSCR,$W36)) | J36: =IF($W36="","",INDEX(tCurDSCR,$W36)) | K36: =IF($W36="","",INDEX(tUWLTV,$W36)) | L36: =IF($W36="","",INDEX(tCurLTV,$W36)) | M36: =IF($W36="","",INDEX(tUWDY,$W36)) | N36: =IF($W36="","",INDEX(tCurDY,$W36)) | O36: =IF($W36="","",INDEX(tOcc,$W36)) | P36: =IF($W36="","",INDEX(tRem,$W36)) | Q36: =IF($W36="","",INDEX(tMatDate,$W36)) | R36: =IF($W36="","",INDEX(tPay,$W36)) | S36: =IF($W36="","",IF(INDEX(tSSF,$W36)=1,"Current SS",IF(INDEX(tSS,$W36)="Previously Specially Serviced","Prior SS","Never SS"))) | T36: =IF($W36="","",IF(INDEX(tWLF,$W36)=1,"Current",IF(INDEX(tWL,$W36)="Previously on Watchlist","Prior","Never"))) | U36: =IF($W36="","",IF(INDEX(tDefF,$W36)=1,"Defeased","")) | W36: =IF(LARGE(tGrpKey,10)=0,"",MATCH(LARGE(tGrpKey,10),tGrpKey,0))
B37: Top 10 Total / Wtd. Avg. | C37: =SUM(C27:C36) | F37: =SUM(F27:F36) | G37: =SUM(G27:G36) | H37: =IFERROR(SUMPRODUCT($F$27:$F$36,H27:H36)/SUMPRODUCT($F$27:$F$36*ISNUMBER(H27:H36)),0) | I37: =IFERROR(SUMPRODUCT($F$27:$F$36,I27:I36)/SUMPRODUCT($F$27:$F$36*ISNUMBER(I27:I36)),0) | J37: =IFERROR(SUMPRODUCT($F$27:$F$36,J27:J36)/SUMPRODUCT($F$27:$F$36*ISNUMBER(J27:J36)),0) | K37: =IFERROR(SUMPRODUCT($F$27:$F$36,K27:K36)/SUMPRODUCT($F$27:$F$36*ISNUMBER(K27:K36)),0) | L37: =IFERROR(SUMPRODUCT($F$27:$F$36,L27:L36)/SUMPRODUCT($F$27:$F$36*ISNUMBER(L27:L36)),0) | M37: =IFERROR(SUMPRODUCT($F$27:$F$36,M27:M36)/SUMPRODUCT($F$27:$F$36*ISNUMBER(M27:M36)),0) | N37: =IFERROR(SUMPRODUCT($F$27:$F$36,N27:N36)/SUMPRODUCT($F$27:$F$36*ISNUMBER(N27:N36)),0) | O37: =IFERROR(SUMPRODUCT($F$27:$F$36,O27:O36)/SUMPRODUCT($F$27:$F$36*ISNUMBER(O27:O36)),0) | P37: =IFERROR(SUMPRODUCT($F$27:$F$36,P27:P36)/SUMPRODUCT($F$27:$F$36*ISNUMBER(P27:P36)),0)
B38: Ranked by combined Current UPB of all notes of the loan inside the active filter. Loan metrics are loan level and identical across pari passu notes. Tape Row Index helper sits in column W.
B40: CMBS TRUST (DEAL)
B41: Category | C41: Number of Loans | D41: % of Loans | E41: Current UPB | F41: % of UPB | G41: Average Loan Size | H41: Wtd. Avg. Gross Coupon | I41: Wtd. Avg. UW NCF DSCR | J41: Wtd. Avg. Current NCF DSCR | K41: Wtd. Avg. UW LTV | L41: Wtd. Avg. Current LTV | M41: Wtd. Avg. UW NCF Debt Yield | N41: Wtd. Avg. Current NCF Debt Yield | O41: Wtd. Avg. Current Occupancy | P41: Wtd. Avg. Rem. Term (Mo.) | Q41: % Full IO | R41: % Defeased | S41: % Currently Specially Serviced | T41: % 30+ Delinq. / FC / REO | U41: % On Watchlist | W41: Category Label
B42: =IF(W42="","",W42&"") | C42: =SUMPRODUCT(tFlag*(tDeal=$W42)) | D42: =IFERROR(C42/sLoans,0) | E42: =SUMPRODUCT(tFlag*(tDeal=$W42),tUPBf) | F42: =IFERROR(E42/sUPB,0) | G42: =IFERROR(E42/C42,0) | H42: =IFERROR(SUMPRODUCT(tFlag*(tDeal=$W42),tUPBf,tCpn)/SUMPRODUCT(tFlag*(tDeal=$W42)*ISNUMBER(tCpn),tUPBf),0) | I42: =IFERROR(SUMPRODUCT(tFlag*(tDeal=$W42),tUPBf,tUWDSCR)/SUMPRODUCT(tFlag*(tDeal=$W42)*ISNUMBER(tUWDSCR),tUPBf),0) | J42: =IFERROR(SUMPRODUCT(tFlag*(tDeal=$W42),tUPBf,tCurDSCR)/SUMPRODUCT(tFlag*(tDeal=$W42)*ISNUMBER(tCurDSCR),tUPBf),0) | K42: =IFERROR(SUMPRODUCT(tFlag*(tDeal=$W42),tUPBf,tUWLTV)/SUMPRODUCT(tFlag*(tDeal=$W42)*ISNUMBER(tUWLTV),tUPBf),0) | L42: =IFERROR(SUMPRODUCT(tFlag*(tDeal=$W42),tUPBf,tCurLTV)/SUMPRODUCT(tFlag*(tDeal=$W42)*ISNUMBER(tCurLTV),tUPBf),0) | M42: =IFERROR(SUMPRODUCT(tFlag*(tDeal=$W42),tUPBf,tUWDY)/SUMPRODUCT(tFlag*(tDeal=$W42)*ISNUMBER(tUWDY),tUPBf),0) | N42: =IFERROR(SUMPRODUCT(tFlag*(tDeal=$W42),tUPBf,tCurDY)/SUMPRODUCT(tFlag*(tDeal=$W42)*ISNUMBER(tCurDY),tUPBf),0) | O42: =IFERROR(SUMPRODUCT(tFlag*(tDeal=$W42),tUPBf,tOcc)/SUMPRODUCT(tFlag*(tDeal=$W42)*ISNUMBER(tOcc),tUPBf),0) | P42: =IFERROR(SUMPRODUCT(tFlag*(tDeal=$W42),tUPBf,tRem)/SUMPRODUCT(tFlag*(tDeal=$W42)*ISNUMBER(tRem),tUPBf),0) | Q42: =IFERROR(SUMPRODUCT(tFlag*(tDeal=$W42),tUPBf,tFIO)/$E42,0) | R42: =IFERROR(SUMPRODUCT(tFlag*(tDeal=$W42),tUPBf,tDefF)/$E42,0) | S42: =IFERROR(SUMPRODUCT(tFlag*(tDeal=$W42),tUPBf,tSSF)/$E42,0) | T42: =IFERROR(SUMPRODUCT(tFlag*(tDeal=$W42),tUPBf,tDQ)/$E42,0) | U42: =IFERROR(SUMPRODUCT(tFlag*(tDeal=$W42),tUPBf,tWLF)/$E42,0) | W42: ='Deal Map'!C8
B43: =IF(W43="","",W43&"") | C43: =SUMPRODUCT(tFlag*(tDeal=$W43)) | D43: =IFERROR(C43/sLoans,0) | E43: =SUMPRODUCT(tFlag*(tDeal=$W43),tUPBf) | F43: =IFERROR(E43/sUPB,0) | G43: =IFERROR(E43/C43,0) | H43: =IFERROR(SUMPRODUCT(tFlag*(tDeal=$W43),tUPBf,tCpn)/SUMPRODUCT(tFlag*(tDeal=$W43)*ISNUMBER(tCpn),tUPBf),0) | I43: =IFERROR(SUMPRODUCT(tFlag*(tDeal=$W43),tUPBf,tUWDSCR)/SUMPRODUCT(tFlag*(tDeal=$W43)*ISNUMBER(tUWDSCR),tUPBf),0) | J43: =IFERROR(SUMPRODUCT(tFlag*(tDeal=$W43),tUPBf,tCurDSCR)/SUMPRODUCT(tFlag*(tDeal=$W43)*ISNUMBER(tCurDSCR),tUPBf),0) | K43: =IFERROR(SUMPRODUCT(tFlag*(tDeal=$W43),tUPBf,tUWLTV)/SUMPRODUCT(tFlag*(tDeal=$W43)*ISNUMBER(tUWLTV),tUPBf),0) | L43: =IFERROR(SUMPRODUCT(tFlag*(tDeal=$W43),tUPBf,tCurLTV)/SUMPRODUCT(tFlag*(tDeal=$W43)*ISNUMBER(tCurLTV),tUPBf),0) | M43: =IFERROR(SUMPRODUCT(tFlag*(tDeal=$W43),tUPBf,tUWDY)/SUMPRODUCT(tFlag*(tDeal=$W43)*ISNUMBER(tUWDY),tUPBf),0) | N43: =IFERROR(SUMPRODUCT(tFlag*(tDeal=$W43),tUPBf,tCurDY)/SUMPRODUCT(tFlag*(tDeal=$W43)*ISNUMBER(tCurDY),tUPBf),0) | O43: =IFERROR(SUMPRODUCT(tFlag*(tDeal=$W43),tUPBf,tOcc)/SUMPRODUCT(tFlag*(tDeal=$W43)*ISNUMBER(tOcc),tUPBf),0) | P43: =IFERROR(SUMPRODUCT(tFlag*(tDeal=$W43),tUPBf,tRem)/SUMPRODUCT(tFlag*(tDeal=$W43)*ISNUMBER(tRem),tUPBf),0) | Q43: =IFERROR(SUMPRODUCT(tFlag*(tDeal=$W43),tUPBf,tFIO)/$E43,0) | R43: =IFERROR(SUMPRODUCT(tFlag*(tDeal=$W43),tUPBf,tDefF)/$E43,0) | S43: =IFERROR(SUMPRODUCT(tFlag*(tDeal=$W43),tUPBf,tSSF)/$E43,0) | T43: =IFERROR(SUMPRODUCT(tFlag*(tDeal=$W43),tUPBf,tDQ)/$E43,0) | U43: =IFERROR(SUMPRODUCT(tFlag*(tDeal=$W43),tUPBf,tWLF)/$E43,0) | W43: ='Deal Map'!C9
B44: =IF(W44="","",W44&"") | C44: =SUMPRODUCT(tFlag*(tDeal=$W44)) | D44: =IFERROR(C44/sLoans,0) | E44: =SUMPRODUCT(tFlag*(tDeal=$W44),tUPBf) | F44: =IFERROR(E44/sUPB,0) | G44: =IFERROR(E44/C44,0) | H44: =IFERROR(SUMPRODUCT(tFlag*(tDeal=$W44),tUPBf,tCpn)/SUMPRODUCT(tFlag*(tDeal=$W44)*ISNUMBER(tCpn),tUPBf),0) | I44: =IFERROR(SUMPRODUCT(tFlag*(tDeal=$W44),tUPBf,tUWDSCR)/SUMPRODUCT(tFlag*(tDeal=$W44)*ISNUMBER(tUWDSCR),tUPBf),0) | J44: =IFERROR(SUMPRODUCT(tFlag*(tDeal=$W44),tUPBf,tCurDSCR)/SUMPRODUCT(tFlag*(tDeal=$W44)*ISNUMBER(tCurDSCR),tUPBf),0) | K44: =IFERROR(SUMPRODUCT(tFlag*(tDeal=$W44),tUPBf,tUWLTV)/SUMPRODUCT(tFlag*(tDeal=$W44)*ISNUMBER(tUWLTV),tUPBf),0) | L44: =IFERROR(SUMPRODUCT(tFlag*(tDeal=$W44),tUPBf,tCurLTV)/SUMPRODUCT(tFlag*(tDeal=$W44)*ISNUMBER(tCurLTV),tUPBf),0) | M44: =IFERROR(SUMPRODUCT(tFlag*(tDeal=$W44),tUPBf,tUWDY)/SUMPRODUCT(tFlag*(tDeal=$W44)*ISNUMBER(tUWDY),tUPBf),0) | N44: =IFERROR(SUMPRODUCT(tFlag*(tDeal=$W44),tUPBf,tCurDY)/SUMPRODUCT(tFlag*(tDeal=$W44)*ISNUMBER(tCurDY),tUPBf),0) | O44: =IFERROR(SUMPRODUCT(tFlag*(tDeal=$W44),tUPBf,tOcc)/SUMPRODUCT(tFlag*(tDeal=$W44)*ISNUMBER(tOcc),tUPBf),0) | P44: =IFERROR(SUMPRODUCT(tFlag*(tDeal=$W44),tUPBf,tRem)/SUMPRODUCT(tFlag*(tDeal=$W44)*ISNUMBER(tRem),tUPBf),0) | Q44: =IFERROR(SUMPRODUCT(tFlag*(tDeal=$W44),tUPBf,tFIO)/$E44,0) | R44: =IFERROR(SUMPRODUCT(tFlag*(tDeal=$W44),tUPBf,tDefF)/$E44,0) | S44: =IFERROR(SUMPRODUCT(tFlag*(tDeal=$W44),tUPBf,tSSF)/$E44,0) | T44: =IFERROR(SUMPRODUCT(tFlag*(tDeal=$W44),tUPBf,tDQ)/$E44,0) | U44: =IFERROR(SUMPRODUCT(tFlag*(tDeal=$W44),tUPBf,tWLF)/$E44,0) | W44: ='Deal Map'!C10
B45: =IF(W45="","",W45&"") | C45: =SUMPRODUCT(tFlag*(tDeal=$W45)) | D45: =IFERROR(C45/sLoans,0) | E45: =SUMPRODUCT(tFlag*(tDeal=$W45),tUPBf) | F45: =IFERROR(E45/sUPB,0) | G45: =IFERROR(E45/C45,0) | H45: =IFERROR(SUMPRODUCT(tFlag*(tDeal=$W45),tUPBf,tCpn)/SUMPRODUCT(tFlag*(tDeal=$W45)*ISNUMBER(tCpn),tUPBf),0) | I45: =IFERROR(SUMPRODUCT(tFlag*(tDeal=$W45),tUPBf,tUWDSCR)/SUMPRODUCT(tFlag*(tDeal=$W45)*ISNUMBER(tUWDSCR),tUPBf),0) | J45: =IFERROR(SUMPRODUCT(tFlag*(tDeal=$W45),tUPBf,tCurDSCR)/SUMPRODUCT(tFlag*(tDeal=$W45)*ISNUMBER(tCurDSCR),tUPBf),0) | K45: =IFERROR(SUMPRODUCT(tFlag*(tDeal=$W45),tUPBf,tUWLTV)/SUMPRODUCT(tFlag*(tDeal=$W45)*ISNUMBER(tUWLTV),tUPBf),0) | L45: =IFERROR(SUMPRODUCT(tFlag*(tDeal=$W45),tUPBf,tCurLTV)/SUMPRODUCT(tFlag*(tDeal=$W45)*ISNUMBER(tCurLTV),tUPBf),0) | M45: =IFERROR(SUMPRODUCT(tFlag*(tDeal=$W45),tUPBf,tUWDY)/SUMPRODUCT(tFlag*(tDeal=$W45)*ISNUMBER(tUWDY),tUPBf),0) | N45: =IFERROR(SUMPRODUCT(tFlag*(tDeal=$W45),tUPBf,tCurDY)/SUMPRODUCT(tFlag*(tDeal=$W45)*ISNUMBER(tCurDY),tUPBf),0) | O45: =IFERROR(SUMPRODUCT(tFlag*(tDeal=$W45),tUPBf,tOcc)/SUMPRODUCT(tFlag*(tDeal=$W45)*ISNUMBER(tOcc),tUPBf),0) | P45: =IFERROR(SUMPRODUCT(tFlag*(tDeal=$W45),tUPBf,tRem)/SUMPRODUCT(tFlag*(tDeal=$W45)*ISNUMBER(tRem),tUPBf),0) | Q45: =IFERROR(SUMPRODUCT(tFlag*(tDeal=$W45),tUPBf,tFIO)/$E45,0) | R45: =IFERROR(SUMPRODUCT(tFlag*(tDeal=$W45),tUPBf,tDefF)/$E45,0) | S45: =IFERROR(SUMPRODUCT(tFlag*(tDeal=$W45),tUPBf,tSSF)/$E45,0) | T45: =IFERROR(SUMPRODUCT(tFlag*(tDeal=$W45),tUPBf,tDQ)/$E45,0) | U45: =IFERROR(SUMPRODUCT(tFlag*(tDeal=$W45),tUPBf,tWLF)/$E45,0) | W45: ='Deal Map'!C11
...

Sheet Deal Map
B2: KKR TRANSACTION: CMBS DEAL MAP AND RECOP I POSITION TIE-OUT
B3: Blue font denotes hardcoded inputs, green font denotes links to other tabs and black font denotes formulas. Set Include in Pool to 0 to drop a deal from every strat.
B5: DEAL MAP
B7: Intex Deal ID | C7: Deal Name | D7: RECOP Issuer (Per Q2 2026 Tape) | E7: Holding Entity | F7: Deal Vintage | G7: Include in Pool (1 = Yes) | H7: RECOP Positions (#) | I7: RECOP Book Value ($) | J7: RECOP Fair Value ($) | K7: FV % of Book | L7: Intex Loans (Total #) | M7: Paid Off / Liquidated (#) | N7: Active Loans (#) | O7: Original Balance, Active ($) | P7: Current UPB, Active ($) | Q7: Deal In Filter (1 = Yes) | R7: Filtered Loans (#) | S7: Filtered UPB ($) | T7: % of Filtered UPB
B8: BCMK18B6 | C8: BMARK 2018-B6 | D8: Benchmark 2018-B6 Mortgage Trust | E8: =IFERROR(INDEX(rcEntity,MATCH(D8,rcIssuer,0)),"Not on RECOP Tape") | F8: 2018 | G8: 1 | H8: =COUNTIF(rcIssuer,D8) | I8: =SUMIFS(rcBook,rcIssuer,D8) | J8: =SUMIFS(rcFV,rcIssuer,D8) | K8: =IFERROR(J8/I8,0) | L8: =COUNTIF(tDealID,B8) | M8: =L8-N8 | N8: =COUNTIFS(tDealID,B8,tActive,1) | O8: =SUMIFS(tOrigBal,tDealID,B8,tActive,1) | P8: =SUMIFS(tUPB,tDealID,B8,tActive,1) | Q8: =IF(AND(G8=1,OR(fDeal="All Deals",C8=fDeal),OR(fEntity="All Entities",E8=fEntity)),1,0) | R8: =COUNTIFS(tDealID,B8,tFlag,1) | S8: =SUMIFS(tUPBf,tDealID,B8) | T8: =IFERROR(S8/sUPB,0)
B9: CTG17C04 | C9: CGCMT 2017-C4 | D9: Citigroup Commercial Mortgage Trust 2017-C4 | E9: =IFERROR(INDEX(rcEntity,MATCH(D9,rcIssuer,0)),"Not on RECOP Tape") | F9: 2017 | G9: 1 | H9: =COUNTIF(rcIssuer,D9) | I9: =SUMIFS(rcBook,rcIssuer,D9) | J9: =SUMIFS(rcFV,rcIssuer,D9) | K9: =IFERROR(J9/I9,0) | L9: =COUNTIF(tDealID,B9) | M9: =L9-N9 | N9: =COUNTIFS(tDealID,B9,tActive,1) | O9: =SUMIFS(tOrigBal,tDealID,B9,tActive,1) | P9: =SUMIFS(tUPB,tDealID,B9,tActive,1) | Q9: =IF(AND(G9=1,OR(fDeal="All Deals",C9=fDeal),OR(fEntity="All Entities",E9=fEntity)),1,0) | R9: =COUNTIFS(tDealID,B9,tFlag,1) | S9: =SUMIFS(tUPBf,tDealID,B9) | T9: =IFERROR(S9/sUPB,0)
B10: CTG18C06 | C10: CGCMT 2018-C6 | D10: Citigroup Commercial Mortgage Trust 2018-C6 | E10: =IFERROR(INDEX(rcEntity,MATCH(D10,rcIssuer,0)),"Not on RECOP Tape") | F10: 2018 | G10: 1 | H10: =COUNTIF(rcIssuer,D10) | I10: =SUMIFS(rcBook,rcIssuer,D10) | J10: =SUMIFS(rcFV,rcIssuer,D10) | K10: =IFERROR(J10/I10,0) | L10: =COUNTIF(tDealID,B10) | M10: =L10-N10 | N10: =COUNTIFS(tDealID,B10,tActive,1) | O10: =SUMIFS(tOrigBal,tDealID,B10,tActive,1) | P10: =SUMIFS(tUPB,tDealID,B10,tActive,1) | Q10: =IF(AND(G10=1,OR(fDeal="All Deals",C10=fDeal),OR(fEntity="All Entities",E10=fEntity)),1,0) | R10: =COUNTIFS(tDealID,B10,tFlag,1) | S10: =SUMIFS(tUPBf,tDealID,B10) | T10: =IFERROR(S10/sUPB,0)
B11: DBJ17C06 | C11: DBJPM 2017-C6 | D11: DBJPM 2017-C6 Mortgage Trust | E11: =IFERROR(INDEX(rcEntity,MATCH(D11,rcIssuer,0)),"Not on RECOP Tape") | F11: 2017 | G11: 1 | H11: =COUNTIF(rcIssuer,D11) | I11: =SUMIFS(rcBook,rcIssuer,D11) | J11: =SUMIFS(rcFV,rcIssuer,D11) | K11: =IFERROR(J11/I11,0) | L11: =COUNTIF(tDealID,B11) | M11: =L11-N11 | N11: =COUNTIFS(tDealID,B11,tActive,1) | O11: =SUMIFS(tOrigBal,tDealID,B11,tActive,1) | P11: =SUMIFS(tUPB,tDealID,B11,tActive,1) | Q11: =IF(AND(G11=1,OR(fDeal="All Deals",C11=fDeal),OR(fEntity="All Entities",E11=fEntity)),1,0) | R11: =COUNTIFS(tDealID,B11,tFlag,1) | S11: =SUMIFS(tUPBf,tDealID,B11) | T11: =IFERROR(S11/sUPB,0)
B12: GS217GS6 | C12: GSMS 2017-GS6 | D12: Goldman Sachs Mortgage Securities Trust 2017-GS6 | E12: =IFERROR(INDEX(rcEntity,MATCH(D12,rcIssuer,0)),"Not on RECOP Tape") | F12: 2017 | G12: 1 | H12: =COUNTIF(rcIssuer,D12) | I12: =SUMIFS(rcBook,rcIssuer,D12) | J12: =SUMIFS(rcFV,rcIssuer,D12) | K12: =IFERROR(J12/I12,0) | L12: =COUNTIF(tDealID,B12) | M12: =L12-N12 | N12: =COUNTIFS(tDealID,B12,tActive,1) | O12: =SUMIFS(tOrigBal,tDealID,B12,tActive,1) | P12: =SUMIFS(tUPB,tDealID,B12,tActive,1) | Q12: =IF(AND(G12=1,OR(fDeal="All Deals",C12=fDeal),OR(fEntity="All Entities",E12=fEntity)),1,0) | R12: =COUNTIFS(tDealID,B12,tFlag,1) | S12: =SUMIFS(tUPBf,tDealID,B12) | T12: =IFERROR(S12/sUPB,0)
B13: GS217GS8 | C13: GSMS 2017-GS8 | D13: GS Mortgage Securities Trust 2017-GS8 | E13: =IFERROR(INDEX(rcEntity,MATCH(D13,rcIssuer,0)),"Not on RECOP Tape") | F13: 2017 | G13: 1 | H13: =COUNTIF(rcIssuer,D13) | I13: =SUMIFS(rcBook,rcIssuer,D13) | J13: =SUMIFS(rcFV,rcIssuer,D13) | K13: =IFERROR(J13/I13,0) | L13: =COUNTIF(tDealID,B13) | M13: =L13-N13 | N13: =COUNTIFS(tDealID,B13,tActive,1) | O13: =SUMIFS(tOrigBal,tDealID,B13,tActive,1) | P13: =SUMIFS(tUPB,tDealID,B13,tActive,1) | Q13: =IF(AND(G13=1,OR(fDeal="All Deals",C13=fDeal),OR(fEntity="All Entities",E13=fEntity)),1,0) | R13: =COUNTIFS(tDealID,B13,tFlag,1) | S13: =SUMIFS(tUPBf,tDealID,B13) | T13: =IFERROR(S13/sUPB,0)
B14: JPD17C7 | C14: JPMDB 2017-C7 | D14: JPMDB Commercial Mortgage Securities Trust 2017-C7 | E14: =IFERROR(INDEX(rcEntity,MATCH(D14,rcIssuer,0)),"Not on RECOP Tape") | F14: 2017 | G14: 1 | H14: =COUNTIF(rcIssuer,D14) | I14: =SUMIFS(rcBook,rcIssuer,D14) | J14: =SUMIFS(rcFV,rcIssuer,D14) | K14: =IFERROR(J14/I14,0) | L14: =COUNTIF(tDealID,B14) | M14: =L14-N14 | N14: =COUNTIFS(tDealID,B14,tActive,1) | O14: =SUMIFS(tOrigBal,tDealID,B14,tActive,1) | P14: =SUMIFS(tUPB,tDealID,B14,tActive,1) | Q14: =IF(AND(G14=1,OR(fDeal="All Deals",C14=fDeal),OR(fEntity="All Entities",E14=fEntity)),1,0) | R14: =COUNTIFS(tDealID,B14,tFlag,1) | S14: =SUMIFS(tUPBf,tDealID,B14) | T14: =IFERROR(S14/sUPB,0)
B15: LCC17L26 | C15: LCCM 2017-LC26 | D15: LCCM 2017-LC26 | E15: =IFERROR(INDEX(rcEntity,MATCH(D15,rcIssuer,0)),"Not on RECOP Tape") | F15: 2017 | G15: 1 | H15: =COUNTIF(rcIssuer,D15) | I15: =SUMIFS(rcBook,rcIssuer,D15) | J15: =SUMIFS(rcFV,rcIssuer,D15) | K15: =IFERROR(J15/I15,0) | L15: =COUNTIF(tDealID,B15) | M15: =L15-N15 | N15: =COUNTIFS(tDealID,B15,tActive,1) | O15: =SUMIFS(tOrigBal,tDealID,B15,tActive,1) | P15: =SUMIFS(tUPB,tDealID,B15,tActive,1) | Q15: =IF(AND(G15=1,OR(fDeal="All Deals",C15=fDeal),OR(fEntity="All Entities",E15=fEntity)),1,0) | R15: =COUNTIFS(tDealID,B15,tFlag,1) | S15: =SUMIFS(tUPBf,tDealID,B15) | T15: =IFERROR(S15/sUPB,0)
B16: MSB17C33 | C16: MSBAM 2017-C33 | D16: Morgan Stanley Bank of America Merrill Lynch Trust 2017-C33 | E16: =IFERROR(INDEX(rcEntity,MATCH(D16,rcIssuer,0)),"Not on RECOP Tape") | F16: 2017 | G16: 1 | H16: =COUNTIF(rcIssuer,D16) | I16: =SUMIFS(rcBook,rcIssuer,D16) | J16: =SUMIFS(rcFV,rcIssuer,D16) | K16: =IFERROR(J16/I16,0) | L16: =COUNTIF(tDealID,B16) | M16: =L16-N16 | N16: =COUNTIFS(tDealID,B16,tActive,1) | O16: =SUMIFS(tOrigBal,tDealID,B16,tActive,1) | P16: =SUMIFS(tUPB,tDealID,B16,tActive,1) | Q16: =IF(AND(G16=1,OR(fDeal="All Deals",C16=fDeal),OR(fEntity="All Entities",E16=fEntity)),1,0) | R16: =COUNTIFS(tDealID,B16,tFlag,1) | S16: =SUMIFS(tUPBf,tDealID,B16) | T16: =IFERROR(S16/sUPB,0)
B17: MSC18L1 | C17: MSC 2018-L1 | D17: Morgan Stanley Capital I Trust 2018-L1 | E17: =IFERROR(INDEX(rcEntity,MATCH(D17,rcIssuer,0)),"Not on RECOP Tape") | F17: 2018 | G17: 1 | H17: =COUNTIF(rcIssuer,D17) | I17: =SUMIFS(rcBook,rcIssuer,D17) | J17: =SUMIFS(rcFV,rcIssuer,D17) | K17: =IFERROR(J17/I17,0) | L17: =COUNTIF(tDealID,B17) | M17: =L17-N17 | N17: =COUNTIFS(tDealID,B17,tActive,1) | O17: =SUMIFS(tOrigBal,tDealID,B17,tActive,1) | P17: =SUMIFS(tUPB,tDealID,B17,tActive,1) | Q17: =IF(AND(G17=1,OR(fDeal="All Deals",C17=fDeal),OR(fEntity="All Entities",E17=fEntity)),1,0) | R17: =COUNTIFS(tDealID,B17,tFlag,1) | S17: =SUMIFS(tUPBf,tDealID,B17) | T17: =IFERROR(S17/sUPB,0)
B18: UBS17C02 | C18: UBSCM 2017-C2 | D18: UBS Commercial Mortgage Trust 2017-C2 | E18: =IFERROR(INDEX(rcEntity,MATCH(D18,rcIssuer,0)),"Not on RECOP Tape") | F18: 2017 | G18: 1 | H18: =COUNTIF(rcIssuer,D18) | I18: =SUMIFS(rcBook,rcIssuer,D18) | J18: =SUMIFS(rcFV,rcIssuer,D18) | K18: =IFERROR(J18/I18,0) | L18: =COUNTIF(tDealID,B18) | M18: =L18-N18 | N18: =COUNTIFS(tDealID,B18,tActive,1) | O18: =SUMIFS(tOrigBal,tDealID,B18,tActive,1) | P18: =SUMIFS(tUPB,tDealID,B18,tActive,1) | Q18: =IF(AND(G18=1,OR(fDeal="All Deals",C18=fDeal),OR(fEntity="All Entities",E18=fEntity)),1,0) | R18: =COUNTIFS(tDealID,B18,tFlag,1) | S18: =SUMIFS(tUPBf,tDealID,B18) | T18: =IFERROR(S18/sUPB,0)
B19: UBS17C03 | C19: UBSCM 2017-C3 | D19: UBS Commercial Mortgage Trust 2017-C3 | E19: =IFERROR(INDEX(rcEntity,MATCH(D19,rcIssuer,0)),"Not on RECOP Tape") | F19: 2017 | G19: 1 | H19: =COUNTIF(rcIssuer,D19) | I19: =SUMIFS(rcBook,rcIssuer,D19) | J19: =SUMIFS(rcFV,rcIssuer,D19) | K19: =IFERROR(J19/I19,0) | L19: =COUNTIF(tDealID,B19) | M19: =L19-N19 | N19: =COUNTIFS(tDealID,B19,tActive,1) | O19: =SUMIFS(tOrigBal,tDealID,B19,tActive,1) | P19: =SUMIFS(tUPB,tDealID,B19,tActive,1) | Q19: =IF(AND(G19=1,OR(fDeal="All Deals",C19=fDeal),OR(fEntity="All Entities",E19=fEntity)),1,0) | R19: =COUNTIFS(tDealID,B19,tFlag,1) | S19: =SUMIFS(tUPBf,tDealID,B19) | T19: =IFERROR(S19/sUPB,0)
... B34: CD17CD3 | C34: CD 2017-CD3 | D34: Not on RECOP Tape | E34: =IFERROR(INDEX(rcEntity,MATCH(D34,rcIssuer,0)),"Not on RECOP Tape") | F34: 2017 | G34: 1 | H34: =COUNTIF(rcIssuer,D34) | I34: =SUMIFS(rcBook,rcIssuer,D34) | J34: =SUMIFS(rcFV,rcIssuer,D34) | K34: =IFERROR(J34/I34,0) | L34: =COUNTIF(tDealID,B34) | M34: =L34-N34 | N34: =COUNTIFS(tDealID,B34,tActive,1) | O34: =SUMIFS(tOrigBal,tDealID,B34,tActive,1) | P34: =SUMIFS(tUPB,tDealID,B34,tActive,1) | Q34: =IF(AND(G34=1,OR(fDeal="All Deals",C34=fDeal),OR(fEntity="All Entities",E34=fEntity)),1,0) | R34: =COUNTIFS(tDealID,B34,tFlag,1) | S34: =SUMIFS(tUPBf,tDealID,B34) | T34: =IFERROR(S34/sUPB,0)
B35: Total | G35: =SUM(G8:G34) | H35: =SUM(H8:H34) | I35: =SUM(I8:I34) | J35: =SUM(J8:J34) | K35: =IFERROR(J35/I35,0) | L35: =SUM(L8:L34) | M35: =SUM(M8:M34) | N35: =SUM(N8:N34) | O35: =SUM(O8:O34) | P35: =SUM(P8:P34) | Q35: =SUM(Q8:Q34) | R35: =SUM(R8:R34) | S35: =SUM(S8:S34) | T35: =SUM(T8:T34)
B37: RECOP I TIE-OUT
B38: Check | E38: Deal Map | F38: RECOP Tape | G38: Variance | H38: Status
B39: RECOP positions mapped to a deal | E39: =H35 | F39: =COUNT('RECOP Tape'!$B$11:$B$129) | G39: =E39-F39 | H39: =IF(ABS(G39)<1,"PASS","FAIL")
B40: RECOP book value mapped ($) | E40: =I35 | F40: ='RECOP Tape'!$E$7 | G40: =E40-F40 | H40: =IF(ABS(G40)<1,"PASS","FAIL")
B41: RECOP fair value mapped ($) | E41: =J35 | F41: ='RECOP Tape'!$F$7 | G41: =E41-F41 | H41: =IF(ABS(G41)<1,"PASS","FAIL")
B43: (1) Deal names follow the RECOP schedule naming. RECOP Issuer strings are matched exactly to the RECOP Tape tab (the source spells WFCM 2018-C43 as "Commerical").
B44: (2) CD 2017-CD3 (Intex CD17CD3) is in the KKR Intex collateral export but carries no position on the RECOP I Q2 2026 schedule; it is included by default and can be excluded with the Include in Pool toggle.
B45: (3) Active loans carry a Current Balance above zero in the Intex export; paid off and liquidated loans remain on the Collat Tape tab for reference but are excluded from every strat.

Sheet Collat Tape
B2: KKR TRANSACTION: INTEX CMBS COLLATERAL TAPE
B3: Source: KKR Transaction Intex Collateral Export (1,343 loans across 27 CMBS trusts). Columns B through BS are pasted from the export with the Intex field names as headers; re-paste the same fields to refresh.
B4: Blue font denotes hardcoded export values and black font denotes formulas. Helper columns to the right drive every strat on the Strats tab.
B6: INTEX EXPORT FIELDS (HARDCODED) | BU6: CALCULATED HELPERS
B7: Item | C7: Deal ID | D7: ID Number | E7: Asset Name | F7: Unique ID | G7: Split Loan ID | H7: Original Balance | I7: Current Balance | J7: Gross Coupon | K7: Rate Type | L7: Orig Maturity Term | M7: Rem Term | N7: Orig Amort Term | O7: Orig IO Term | P7: Rem IO Term | Q7: Age | R7: Amort Type | S7: Currently IO | T7: Issue Date | U7: Maturity Date | V7: Hyper Amortizing Date or ARD | W7: Delinq (Consolidated) | X7: CREFC Payment Status of Loan (Translated) | Y7: Months Delinq | Z7: Defeasance Status (Translated) | AA7: On the Watchlist (Translated) | AB7: Specially Serviced | AC7: Currently Special Serviced | AD7: Reason for SS Transfer (Translated) | AE7: Workout Strategy Code (Translated) | AF7: State | AG7: City | AH7: MSA | AI7: Region | AJ7: Property Type | AK7: Property Subtype | AL7: Number of Properties - Modeled | AM7: Number of Units | AN7: GLA | AO7: Date Built | AP7: Later of Date Built and Date Renovated | AQ7: Underwritten NCF DSCR | AR7: Most Recent NCF DSCR | AS7: Cut-Off LTV | AT7: Appraisal LTV | AU7: LTV at Maturity | AV7: Underwritten NCF Debt Yield | AW7: NCF Debt Yield | AX7: Most Recent Occupancy % | AY7: Underwritten Appraisal Value | AZ7: Appraisal Value | BA7: Underwritten NCF | BB7: Most Recent NCF | BC7: Loan Purpose | BD7: Ground Lease | BE7: Loan Balance - Pari Passu | BF7: Loan Balance - Junior | BG7: Mezzanine Debt Balance | BH7: Active Appraisal Reduction Amount | BI7: Outstanding P&I Advances | BJ7: Modification Indicator | BK7: Largest Tenant | BL7: Largest Tenant % | BM7: Largest Tenant Exp. Date | BN7: Sponsor | BO7: Originator | BP7: Master Servicer (Translated) | BQ7: Special Servicer (Translated) | BR7: Liquidation / Prepayment Code (Translated) | BS7: Reporting Period End Date | BU7: Deal Name | BV7: Holding Entity | BW7: Deal Vintage | BX7: Deal Included (1 = Yes) | BY7: Active (1 = Yes) | BZ7: Property Type Group | CA7: Primary State | CB7: Region (Primary) | CC7: Payment Status | CD7: 30+ Delinq / FC / REO (1 = Yes) | CE7: Special Servicing Status | CF7: Currently SS (1 = Yes) | CG7: Watchlist Status | CH7: On Watchlist (1 = Yes) | CI7: Defeasance Status | CJ7: Fully Defeased (1 = Yes) | CK7: Amortization Type | CL7: Full IO (1 = Yes) | CM7: Partial IO (1 = Yes) | CN7: Pari Passu Status | CO7: Pari Passu (1 = Yes) | CP7: Origination Year | CQ7: Anticipated Maturity (ARD if Any) | CR7: Maturity Year (ARD if Any) | CS7: Rem. Term (Mo.) | CT7: Matures in Window (1 = Yes) | CU7: Gross Coupon | CV7: UW NCF DSCR | CW7: Current NCF DSCR | CX7: UW (Cut-Off) LTV | CY7: Current LTV (Latest Appraisal) | CZ7: UW LTV at Maturity | DA7: UW NCF Debt Yield | DB7: Current NCF Debt Yield | DC7: Current Occupancy | DD7: Year Built (Earliest) | DE7: In Filter (1 = Yes) | DF7: Filtered UPB | DG7: First Note of Loan in Filter (1 = Yes) | DH7: Loan Exposure UPB (All Notes in Filter) | DI7: Notes / Deals in Filter (#) | DJ7: Exposure Rank Key
B8: 1 | C8: UBS17C02 | D8: 1.TR | E8: General Motors Building - Trust | F8: SPLIT_LOAN_01024 | G8: 1024 | H8: 50000000 | I8: 50000000 | J8: 3.43 | K8: Fixed rate | L8: 120 | M8: 9 | N8: 120 | O8: 120 | P8: 9 | Q8: 111 | R8: IO | S8: Yes | T8: 42887 | U8: 46547 | X8: Current | Z8: No Defeasance Occurred | AA8: Yes | AB8: Never special serv | AF8: NY | AG8: New York | AH8: New York-Newark-Jersey City, NY-NJ | AI8: Northeast / Mid-Atlantic | AJ8: MX | AK8: Office/Retail | AL8: 1 | AN8: 1989983 | AO8: 1968 | AP8: 2017 | AQ8: 4.33 | AR8: 3.93 | AS8: 30.6 | AT8: 30.62 | AU8: 30.6 | AV8: 15.071074 | AW8: 12.954029 | AX8: 99 | AY8: 4800000000 | AZ8: 4800000000 | BA8: 2.2154479e+08 | BB8: 1.998371e+08 | BC8: Refinance | BD8: N | BE8: 1420000000 | BF8: 830000000 | BH8: 0 | BI8: 0 | BJ8: N | BK8: Weil, Gotshal & Manges, LLP | BL8: 20.58 | BM8: 49187 | BN8: Boston Properties Limited Partnership; 767 LLC; Sungate Fifth Avenue LLC | BO8: Morgan Stanley / Citi Group Global Markets / GACC / Wells Fargo | BP8: Midland Loan Services | BQ8: Aegon USA Realty | BS8: 46276 | BU8: =IF($C8="","",IFERROR(INDEX(dmName,MATCH($C8,dmID,0)),"Unmapped")) | BV8: =IF($C8="","",IFERROR(INDEX(dmEntity,MATCH($C8,dmID,0)),"Unmapped")) | BW8: =IF($C8="","",IFERROR(INDEX(dmVintage,MATCH($C8,dmID,0)),"")) | BX8: =IFERROR(INDEX(dmInclude,MATCH($C8,dmID,0)),0) | BY8: =IF(N($I8)>0,1,0) | BZ8: =IF($AJ8="","Other / Leased Fee",IFERROR(INDEX(mapPTGroup,MATCH(LEFT(TRIM($AJ8),2),mapPTCode,0)),"Other / Leased Fee")) | CA8: =IF(TRIM($AF8&"")="","NR",LEFT(TRIM($AF8),2)) | CB8: =IFERROR(LOOKUP(2,1/(LEFT(TRIM($AI8&""),LEN(mapRegion))=mapRegion),mapRegion),"Not Reported") | CC8: =IF($BY8=0,"",IF(TRIM($W8&"")="REO","REO",IF(TRIM($W8&"")="FC","Foreclosure",IF(TRIM($W8&"")="90+","90+ Days Delinquent",IF(TRIM($W8&"")="60","60 Days Delinquent",IF(TRIM($W8&"")="30","30 Days Delinquent",IF($X8="Non-Performing Matured Balloon","Non-Performing Matured Balloon",IF(OR($X8="Late Payment But Less Than 30 Days Delinquent",LEFT($X8&"",20)="Payment Not Received"),"Late / In Grace (<30 Days)",IF($X8="Performing Matured Balloon","Performing Matured Balloon","Current"))))))))) | CD8: =IF(OR($CC8="REO",$CC8="Foreclosure",$CC8="90+ Days Delinquent",$CC8="60 Days Delinquent",$CC8="30 Days Delinquent",$CC8="Non-Performing Matured Balloon"),1,0) | CE8: =IF($AB8="Currently special serv","Currently Specially Serviced",IF($AB8="Returned to master serv","Previously Specially Serviced","Never Specially Serviced")) | CF8: =IF($CE8="Currently Specially Serviced",1,0) | CG8: =IF($AA8="Yes","Currently on Watchlist",IF($AA8="Previously","Previously on Watchlist","Never on Watchlist")) | CH8: =IF($CG8="Currently on Watchlist",1,0) | CI8: =IF($Z8="Full Defeasance","Fully Defeased",IF($Z8="Portion Of Loan Previously Defeased","Partially Defeased",IF($Z8="Defeasance Not Allowable","Not Defeased (Not Permitted)","Not Defeased"))) | CJ8: =IF($CI8="Fully Defeased",1,0) | CK8: =IF($R8="IO","Full IO",IF(LEFT($R8&"",7)="IO then","Partial IO","Amortizing")) | CL8: =IF($CK8="Full IO",1,0) | CM8: =IF($CK8="Partial IO",1,0) | CN8: =IF(LEFT($F8&"",10)="SPLIT_LOAN","Pari Passu Split","Standalone") | CO8: =IF($CN8="Pari Passu Split",1,0) | CP8: =IF(ISNUMBER($T8),YEAR($T8),"") | CQ8: =IF(ISNUMBER($V8),$V8,IF(ISNUMBER($U8),$U8,"")) | CR8: =IF(ISNUMBER($CQ8),YEAR($CQ8),"") | CS8: =IF(ISNUMBER($M8),MAX(0,$M8),IF(TRIM($M8&"")="matured",0,"")) | CT8: =IF(AND(ISNUMBER($CS8),N($CS8)<=mMatWindow),1,0) | CU8: =IF(ISNUMBER($J8),$J8/100,"") | CV8: =IF(ISNUMBER($AQ8),$AQ8,"") | CW8: =IF(ISNUMBER($AR8),$AR8,"") | CX8: =IF(ISNUMBER($AS8),$AS8/100,"") | CY8: =IF(ISNUMBER($AT8),$AT8/100,"") | CZ8: =IF(ISNUMBER($AU8),$AU8/100,"") | DA8: =IF(ISNUMBER($AV8),$AV8/100,"") | DB8: =IF(ISNUMBER($AW8),$AW8/100,"") | DC8: =IF(ISNUMBER($AX8),$AX8/100,"") | DD8: =IFERROR(VALUE(LEFT(TRIM($AO8&""),4)),"") | DE8: =IF(AND($BY8=1,$BX8=1,OR(fDeal="All Deals",$BU8=fDeal),OR(fEntity="All Entities",$BV8=fEntity),OR(fPType="All Property Types",$BZ8=fPType),OR(fDefeased="Include",$CJ8=0)),1,0) | DF8: =$DE8*N($I8) | DG8: =IF($DE8=1,IF(COUNTIFS($F$8:$F8,$F8,$DE$8:$DE8,1)=1,1,0),0) | DH8: =IF($DG8=1,SUMIFS($DF$8:$DF$1600,$F$8:$F$1600,$F8),0) | DI8: =IF($DG8=1,COUNTIFS($F$8:$F$1600,$F8,$DE$8:$DE$1600,1),0) | DJ8: =IF($DG8=1,$DH8+(100000-ROW())/mTieBreak,0)
B9: 2 | C9: UBS17C02 | D9: 2.000 | E9: Park West Village | F9: SPLIT_LOAN_01045 | G9: 1045 | H9: 50000000 | I9: 0 | J9: 2.62 | K9: Fixed rate | L9: 60 | N9: 60 | O9: 60 | R9: IO | S9: Yes | T9: 42979 | U9: 44779 | X9: Current | Z9: Defeasance Not Allowable | AA9: Previously | AB9: Never special serv | AF9: NY | AG9: New York | AH9: New York-Newark-Jersey City, NY-NJ | AI9: Northeast / Mid-Atlantic | AJ9: MF | AK9: High Rise | AL9: 1 | AM9: 852 | AO9: 1950, 1958, 1963 | AP9: 2017 | AQ9: 4.46 | AR9: 3.5 | AS9: 20 | AU9: 20 | AV9: 11.84893 | AX9: 83 | AY9: 600000000 | AZ9: 600000000 | BA9: 14218716 | BB9: 11148308 | BC9: Refinance | BD9: N | BE9: 0 | BF9: 0 | BG9: 186250000 | BH9: 0 | BI9: 0 | BJ9: N | BN9: The Chetrit Group LLC; Stellar Management LLC | BO9: UBS / Athene | BP9: Midland Loan Services | BQ9: Midland Loan Services | BR9: Full Payoff At Maturity | BS9: 44784 | BU9: =IF($C9="","",IFERROR(INDEX(dmName,MATCH($C9,dmID,0)),"Unmapped")) | BV9: =IF($C9="","",IFERROR(INDEX(dmEntity,MATCH($C9,dmID,0)),"Unmapped")) | BW9: =IF($C9="","",IFERROR(INDEX(dmVintage,MATCH($C9,dmID,0)),"")) | BX9: =IFERROR(INDEX(dmInclude,MATCH($C9,dmID,0)),0) | BY9: =IF(N($I9)>0,1,0) | BZ9: =IF($AJ9="","Other / Leased Fee",IFERROR(INDEX(mapPTGroup,MATCH(LEFT(TRIM($AJ9),2),mapPTCode,0)),"Other / Leased Fee")) | CA9: =IF(TRIM($AF9&"")="","NR",LEFT(TRIM($AF9),2)) | CB9: =IFERROR(LOOKUP(2,1/(LEFT(TRIM($AI9&""),LEN(mapRegion))=mapRegion),mapRegion),"Not Reported") | CC9: =IF($BY9=0,"",IF(TRIM($W9&"")="REO","REO",IF(TRIM($W9&"")="FC","Foreclosure",IF(TRIM($W9&"")="90+","90+ Days Delinquent",IF(TRIM($W9&"")="60","60 Days Delinquent",IF(TRIM($W9&"")="30","30 Days Delinquent",IF($X9="Non-Performing Matured Balloon","Non-Performing Matured Balloon",IF(OR($X9="Late Payment But Less Than 30 Days Delinquent",LEFT($X9&"",20)="Payment Not Received"),"Late / In Grace (<30 Days)",IF($X9="Performing Matured Balloon","Performing Matured Balloon","Current"))))))))) | CD9: =IF(OR($CC9="REO",$CC9="Foreclosure",$CC9="90+ Days Delinquent",$CC9="60 Days Delinquent",$CC9="30 Days Delinquent",$CC9="Non-Performing Matured Balloon"),1,0) | CE9: =IF($AB9="Currently special serv","Currently Specially Serviced",IF($AB9="Returned to master serv","Previously Specially Serviced","Never Specially Serviced")) | CF9: =IF($CE9="Currently Specially Serviced",1,0) | CG9: =IF($AA9="Yes","Currently on Watchlist",IF($AA9="Previously","Previously on Watchlist","Never on Watchlist")) | CH9: =IF($CG9="Currently on Watchlist",1,0) | CI9: =IF($Z9="Full Defeasance","Fully Defeased",IF($Z9="Portion Of Loan Previously Defeased","Partially Defeased",IF($Z9="Defeasance Not Allowable","Not Defeased (Not Permitted)","Not Defeased"))) | CJ9: =IF($CI9="Fully Defeased",1,0) | CK9: =IF($R9="IO","Full IO",IF(LEFT($R9&"",7)="IO then","Partial IO","Amortizing")) | CL9: =IF($CK9="Full IO",1,0) | CM9: =IF($CK9="Partial IO",1,0) | CN9: =IF(LEFT($F9&"",10)="SPLIT_LOAN","Pari Passu Split","Standalone") | CO9: =IF($CN9="Pari Passu Split",1,0) | CP9: =IF(ISNUMBER($T9),YEAR($T9),"") | CQ9: =IF(ISNUMBER($V9),$V9,IF(ISNUMBER($U9),$U9,"")) | CR9: =IF(ISNUMBER($CQ9),YEAR($CQ9),"") | CS9: =IF(ISNUMBER($M9),MAX(0,$M9),IF(TRIM($M9&"")="matured",0,"")) | CT9: =IF(AND(ISNUMBER($CS9),N($CS9)<=mMatWindow),1,0) | CU9: =IF(ISNUMBER($J9),$J9/100,"") | CV9: =IF(ISNUMBER($AQ9),$AQ9,"") | CW9: =IF(ISNUMBER($AR9),$AR9,"") | CX9: =IF(ISNUMBER($AS9),$AS9/100,"") | CY9: =IF(ISNUMBER($AT9),$AT9/100,"") | CZ9: =IF(ISNUMBER($AU9),$AU9/100,"") | DA9: =IF(ISNUMBER($AV9),$AV9/100,"") | DB9: =IF(ISNUMBER($AW9),$AW9/100,"") | DC9: =IF(ISNUMBER($AX9),$AX9/100,"") | DD9: =IFERROR(VALUE(LEFT(TRIM($AO9&""),4)),"") | DE9: =IF(AND($BY9=1,$BX9=1,OR(fDeal="All Deals",$BU9=fDeal),OR(fEntity="All Entities",$BV9=fEntity),OR(fPType="All Property Types",$BZ9=fPType),OR(fDefeased="Include",$CJ9=0)),1,0) | DF9: =$DE9*N($I9) | DG9: =IF($DE9=1,IF(COUNTIFS($F$8:$F9,$F9,$DE$8:$DE9,1)=1,1,0),0) | DH9: =IF($DG9=1,SUMIFS($DF$8:$DF$1600,$F$8:$F$1600,$F9),0) | DI9: =IF($DG9=1,COUNTIFS($F$8:$F$1600,$F9,$DE$8:$DE$1600,1),0) | DJ9: =IF($DG9=1,$DH9+(100000-ROW())/mTieBreak,0)
B10: 3 | C10: UBS17C02 | D10: 3.000 | E10: TZA Multifamily Portfolio I | F10: SPLIT_LOAN_01046 | G10: 1046 | H10: 50000000 | I10: 45018528 | J10: 4.95 | K10: Fixed rate | L10: 120 | M10: 10 | N10: 396 | O10: 36 | P10: 0 | Q10: 110 | R10: IO then Amort | S10: No | T10: 42917 | U10: 46569 | X10: Current | Z10: Full Defeasance | AA10: Previously | AB10: Returned to master serv | AD10: Other | AE10: Resolved | AF10: FL | AH10: Orlando-Kissimmee-Sanford, FL | AI10: South / Atlantic | AJ10: MF | AK10: Garden | AL10: 14 | AM10: 2382 | AP10: 2017 | AQ10: 1.55 | AR10: 1.28 | AS10: 73.7 | AT10: 55.49 | AU10: 65.1 | AV10: 9.9301061 | AW10: 9.0084393 | AX10: 97 | AY10: 146630000 | AZ10: 175230000 | BA10: 10724515 | BB10: 8759808.2 | BC10: Refinance | BD10: N | BE10: 52221492 | BH10: 0 | BI10: 0 | BJ10: Y | BN10: Adam Hendry | BO10: Societe Generale | BP10: Midland Loan Services | BQ10: Midland Loan Services | BS10: 46276 | BU10: =IF($C10="","",IFERROR(INDEX(dmName,MATCH($C10,dmID,0)),"Unmapped")) | BV10: =IF($C10="","",IFERROR(INDEX(dmEntity,MATCH($C10,dmID,0)),"Unmapped")) | BW10: =IF($C10="","",IFERROR(INDEX(dmVintage,MATCH($C10,dmID,0)),"")) | BX10: =IFERROR(INDEX(dmInclude,MATCH($C10,dmID,0)),0) | BY10: =IF(N($I10)>0,1,0) | BZ10: =IF($AJ10="","Other / Leased Fee",IFERROR(INDEX(mapPTGroup,MATCH(LEFT(TRIM($AJ10),2),mapPTCode,0)),"Other / Leased Fee")) | CA10: =IF(TRIM($AF10&"")="","NR",LEFT(TRIM($AF10),2)) | CB10: =IFERROR(LOOKUP(2,1/(LEFT(TRIM($AI10&""),LEN(mapRegion))=mapRegion),mapRegion),"Not Reported") | CC10: =IF($BY10=0,"",IF(TRIM($W10&"")="REO","REO",IF(TRIM($W10&"")="FC","Foreclosure",IF(TRIM($W10&"")="90+","90+ Days Delinquent",IF(TRIM($W10&"")="60","60 Days Delinquent",IF(TRIM($W10&"")="30","30 Days Delinquent",IF($X10="Non-Performing Matured Balloon","Non-Performing Matured Balloon",IF(OR($X10="Late Payment But Less Than 30 Days Delinquent",LEFT($X10&"",20)="Payment Not Received"),"Late / In Grace (<30 Days)",IF($X10="Performing Matured Balloon","Performing Matured Balloon","Current"))))))))) | CD10: =IF(OR($CC10="REO",$CC10="Foreclosure",$CC10="90+ Days Delinquent",$CC10="60 Days Delinquent",$CC10="30 Days Delinquent",$CC10="Non-Performing Matured Balloon"),1,0) | CE10: =IF($AB10="Currently special serv","Currently Specially Serviced",IF($AB10="Returned to master serv","Previously Specially Serviced","Never Specially Serviced")) | CF10: =IF($CE10="Currently Specially Serviced",1,0) | CG10: =IF($AA10="Yes","Currently on Watchlist",IF($AA10="Previously","Previously on Watchlist","Never on Watchlist")) | CH10: =IF($CG10="Currently on Watchlist",1,0) | CI10: =IF($Z10="Full Defeasance","Fully Defeased",IF($Z10="Portion Of Loan Previously Defeased","Partially Defeased",IF($Z10="Defeasance Not Allowable","Not Defeased (Not Permitted)","Not Defeased"))) | CJ10: =IF($CI10="Fully Defeased",1,0) | CK10: =IF($R10="IO","Full IO",IF(LEFT($R10&"",7)="IO then","Partial IO","Amortizing")) | CL10: =IF($CK10="Full IO",1,0) | CM10: =IF($CK10="Partial IO",1,0) | CN10: =IF(LEFT($F10&"",10)="SPLIT_LOAN","Pari Passu Split","Standalone") | CO10: =IF($CN10="Pari Passu Split",1,0) | CP10: =IF(ISNUMBER($T10),YEAR($T10),"") | CQ10: =IF(ISNUMBER($V10),$V10,IF(ISNUMBER($U10),$U10,"")) | CR10: =IF(ISNUMBER($CQ10),YEAR($CQ10),"") | CS10: =IF(ISNUMBER($M10),MAX(0,$M10),IF(TRIM($M10&"")="matured",0,"")) | CT10: =IF(AND(ISNUMBER($CS10),N($CS10)<=mMatWindow),1,0) | CU10: =IF(ISNUMBER($J10),$J10/100,"") | CV10: =IF(ISNUMBER($AQ10),$AQ10,"") | CW10: =IF(ISNUMBER($AR10),$AR10,"") | CX10: =IF(ISNUMBER($AS10),$AS10/100,"") | CY10: =IF(ISNUMBER($AT10),$AT10/100,"") | CZ10: =IF(ISNUMBER($AU10),$AU10/100,"") | DA10: =IF(ISNUMBER($AV10),$AV10/100,"") | DB10: =IF(ISNUMBER($AW10),$AW10/100,"") | DC10: =IF(ISNUMBER($AX10),$AX10/100,"") | DD10: =IFERROR(VALUE(LEFT(TRIM($AO10&""),4)),"") | DE10: =IF(AND($BY10=1,$BX10=1,OR(fDeal="All Deals",$BU10=fDeal),OR(fEntity="All Entities",$BV10=fEntity),OR(fPType="All Property Types",$BZ10=fPType),OR(fDefeased="Include",$CJ10=0)),1,0) | DF10: =$DE10*N($I10) | DG10: =IF($DE10=1,IF(COUNTIFS($F$8:$F10,$F10,$DE$8:$DE10,1)=1,1,0),0) | DH10: =IF($DG10=1,SUMIFS($DF$8:$DF$1600,$F$8:$F$1600,$F10),0) | DI10: =IF($DG10=1,COUNTIFS($F$8:$F$1600,$F10,$DE$8:$DE$1600,1),0) | DJ10: =IF($DG10=1,$DH10+(100000-ROW())/mTieBreak,0)
B11: 4 | C11: UBS17C02 | D11: 4.TR | E11: Del Amo Fashion Center - Trust | F11: SPLIT_LOAN_00999 | G11: 999 | H11: 45000000 | I11: 45000000 | J11: 3.6575 | K11: Fixed rate | L11: 120 | M11: 9 | N11: 120 | O11: 120 | P11: 9 | Q11: 111 | R11: IO | S11: Yes | T11: 42887 | U11: 46539 | X11: Current | Z11: No Defeasance Occurred | AA11: Previously | AB11: Never special serv | AF11: CA | AG11: Torrance | AH11: Los Angeles-Long Beach-Anaheim, CA | AI11: West / Pacific South | AJ11: RT | AK11: Super Regional Mall | AL11: 1 | AN11: 1769525 | AO11: 1961 | AP11: 2017 | AQ11: 3.34 | AR11: 4.31 | AS11: 39.8 | AT11: 39.77 | AU11: 39.8 | AV11: 12.402664 | AW11: 12.76047 | AX11: 84 | AY11: 1155000000 | AZ11: 1155000000 | BA11: 56965434 | BB11: 58137588 | BC11: Refinance | BD11: N | BE11: 414300000 | BF11: 125700000 | BH11: 0 | BI11: 0 | BJ11: N | BK11: JC Penney | BL11: 9.23 | BM11: 47118 | BN11: Simon Property Group, L.P.; Commingled Pension Trust Fund (Strategic Property) of JPMorgan Chase Bank, N.A. | BO11: Bank of America / Societe Generale / Wells Fargo / Barclays | BP11: Midland Loan Services | BQ11: Cohen Financial | BS11: 46276 | BU11: =IF($C11="","",IFERROR(INDEX(dmName,MATCH($C11,dmID,0)),"Unmapped")) | BV11: =IF($C11="","",IFERROR(INDEX(dmEntity,MATCH($C11,dmID,0)),"Unmapped")) | BW11: =IF($C11="","",IFERROR(INDEX(dmVintage,MATCH($C11,dmID,0)),"")) | BX11: =IFERROR(INDEX(dmInclude,MATCH($C11,dmID,0)),0) | BY11: =IF(N($I11)>0,1,0) | BZ11: =IF($AJ11="","Other / Leased Fee",IFERROR(INDEX(mapPTGroup,MATCH(LEFT(TRIM($AJ11),2),mapPTCode,0)),"Other / Leased Fee")) | CA11: =IF(TRIM($AF11&"")="","NR",LEFT(TRIM($AF11),2)) | CB11: =IFERROR(LOOKUP(2,1/(LEFT(TRIM($AI11&""),LEN(mapRegion))=mapRegion),mapRegion),"Not Reported") | CC11: =IF($BY11=0,"",IF(TRIM($W11&"")="REO","REO",IF(TRIM($W11&"")="FC","Foreclosure",IF(TRIM($W11&"")="90+","90+ Days Delinquent",IF(TRIM($W11&"")="60","60 Days Delinquent",IF(TRIM($W11&"")="30","30 Days Delinquent",IF($X11="Non-Performing Matured Balloon","Non-Performing Matured Balloon",IF(OR($X11="Late Payment But Less Than 30 Days Delinquent",LEFT($X11&"",20)="Payment Not Received"),"Late / In Grace (<30 Days)",IF($X11="Performing Matured Balloon","Performing Matured Balloon","Current"))))))))) | CD11: =IF(OR($CC11="REO",$CC11="Foreclosure",$CC11="90+ Days Delinquent",$CC11="60 Days Delinquent",$CC11="30 Days Delinquent",$CC11="Non-Performing Matured Balloon"),1,0) | CE11: =IF($AB11="Currently special serv","Currently Specially Serviced",IF($AB11="Returned to master serv","Previously Specially Serviced","Never Specially Serviced")) | CF11: =IF($CE11="Currently Specially Serviced",1,0) | CG11: =IF($AA11="Yes","Currently on Watchlist",IF($AA11="Previously","Previously on Watchlist","Never on Watchlist")) | CH11: =IF($CG11="Currently on Watchlist",1,0) | CI11: =IF($Z11="Full Defeasance","Fully Defeased",IF($Z11="Portion Of Loan Previously Defeased","Partially Defeased",IF($Z11="Defeasance Not Allowable","Not Defeased (Not Permitted)","Not Defeased"))) | CJ11: =IF($CI11="Fully Defeased",1,0) | CK11: =IF($R11="IO","Full IO",IF(LEFT($R11&"",7)="IO then","Partial IO","Amortizing")) | CL11: =IF($CK11="Full IO",1,0) | CM11: =IF($CK11="Partial IO",1,0) | CN11: =IF(LEFT($F11&"",10)="SPLIT_LOAN","Pari Passu Split","Standalone") | CO11: =IF($CN11="Pari Passu Split",1,0) | CP11: =IF(ISNUMBER($T11),YEAR($T11),"") | CQ11: =IF(ISNUMBER($V11),$V11,IF(ISNUMBER($U11),$U11,"")) | CR11: =IF(ISNUMBER($CQ11),YEAR($CQ11),"") | CS11: =IF(ISNUMBER($M11),MAX(0,$M11),IF(TRIM($M11&"")="matured",0,"")) | CT11: =IF(AND(ISNUMBER($CS11),N($CS11)<=mMatWindow),1,0) | CU11: =IF(ISNUMBER($J11),$J11/100,"") | CV11: =IF(ISNUMBER($AQ11),$AQ11,"") | CW11: =IF(ISNUMBER($AR11),$AR11,"") | CX11: =IF(ISNUMBER($AS11),$AS11/100,"") | CY11: =IF(ISNUMBER($AT11),$AT11/100,"") | CZ11: =IF(ISNUMBER($AU11),$AU11/100,"") | DA11: =IF(ISNUMBER($AV11),$AV11/100,"") | DB11: =IF(ISNUMBER($AW11),$AW11/100,"") | DC11: =IF(ISNUMBER($AX11),$AX11/100,"") | DD11: =IFERROR(VALUE(LEFT(TRIM($AO11&""),4)),"") | DE11: =IF(AND($BY11=1,$BX11=1,OR(fDeal="All Deals",$BU11=fDeal),OR(fEntity="All Entities",$BV11=fEntity),OR(fPType="All Property Types",$BZ11=fPType),OR(fDefeased="Include",$CJ11=0)),1,0) | DF11: =$DE11*N($I11) | DG11: =IF($DE11=1,IF(COUNTIFS($F$8:$F11,$F11,$DE$8:$DE11,1)=1,1,0),0) | DH11: =IF($DG11=1,SUMIFS($DF$8:$DF$1600,$F$8:$F$1600,$F11),0) | DI11: =IF($DG11=1,COUNTIFS($F$8:$F$1600,$F11,$DE$8:$DE$1600,1),0) | DJ11: =IF($DG11=1,$DH11+(100000-ROW())/mTieBreak,0)
