Workbook

Sheet Instructions
B2: TEMPLATE INSTRUCTIONS
B4: STEP | C4: WHAT TO DO
B5: 1. Tape | C5: Paste the lender data tape into Tape!B7:ME36 (one asset per row, up to 30 assets). Keep the column order of the header rows 2 to 5.
C6: Set the nine period labels once in Tape!T5:AB5 (years must be numbers, e.g. 2025). Every other period block, the asset tabs and the Rollup pick them up automatically.
C7: Row labels in Tape row 2 must match the line item labels in column C of the asset tabs. Do not rename them.
B8: 2. Cap Stack | C8: Enter the class, rating, size and spread (bps) for each tranche in 'Cap Stack Control'!F15:S22, the index rate in I28, and the IG / Non-IG tag in K28:K35.
C9: Enter deal name (D4), estimated appraised value (D9) and PIP reserve (D12). SSP hold amounts go in column U.
B10: 3. UW Drivers | C10: Asset names and history populate from the Tape. Set Sixth Street occupancy in P (defaults to TTM), cap rate in AA, as-is capex / key in AC, franchise fee in AH, and any override NOI margin in X. Set V to No to use the in-place NOI.
B11: 4. Capex | C11: Optional: paste historical capex by year in Capex!E6:N35. Start year is set in Capex!E5; Rollup!AB1 sets which year is matched to the TTM column.
B12: 5. S&U | C12: Mortgage loan links to the cap stack total. Enter the uses and sponsor equity; M10 checks that sources equal uses.
B13: Asset tabs | C13: Tabs 1 to 30 sit between START and END and pull their asset from the Tape by row order. Unused tabs show dashes and add nothing to the Rollup; they can be deleted. To add assets beyond 30, copy tab 1, rename it with the next number, place it before END, and change the row number inside the formula in C3.
B14: Colour key | C14: Blue font = input. Black font = formula. Blank slots show "-" because division formulas are wrapped in IFERROR.

Sheet Cap Stack Control
C3: Deal / Property Info
C4: Deal Name | D4: [Deal Name]
C5: Keys | D5: =Rollup!$AN$4 -> 0
C6: TTM NOI | D6: =Rollup!$AB$53 -> 0
C7: SSP IP NOI | D7: ='SSP UW Summary'!$O$36 -> 0
C8: SSP Stresed NOI | D8: =SUM('UW Drivers'!$W$9:$W$38) -> 0
C9: Est. Appraised Value
C10: SSP Stressed Value | D10: ='UW Drivers'!AE40+D12 -> 0
C11: SSP IP Value | D11: ='UW Drivers'!AD40+D12 -> 0
C12: PIP Reserve | F12: =$D$4&" - Capital Stack" -> [Deal Name] - Capital Stack
S13: Pricing | U13: SSP Order
F14: Class | G14: Rating (M / KBRA) | H14: Size | I14: % of Deal | J14: Cum. | K14: % CE | L14: $ / Key | M14: =Tape!$Z$5&" DY" -> TTM DY | N14: SSP In-Place DY | O14: SSP Stressed DY | P14: Est. Appr.LTV | Q14: SSP In-Place LTV | R14: SSP Stressed LTV | S14: DM | T14: Cum. DM | U14: SSP Hold | V14: % of Class | W14: Blended DM
C15: IG Bifurcation | F15: A | I15: =IFERROR(H15/$H$23,0) -> 0 | J15: =SUM(H$15:H15) -> 0 | K15: =IFERROR(SUM(H16:H$22)/$H$23,0) -> 0 | L15: =IFERROR(J15/$D$5,0) -> 0 | M15: =IFERROR($D$6/J15,0) -> 0 | N15: =IFERROR($D$7/J15,0) -> 0 | O15: =IFERROR($D$8/J15,0) -> 0 | P15: =IFERROR(J15/$D$9,0) -> 0 | Q15: =IFERROR(J15/$D$11,0) -> 0 | R15: =IFERROR(J15/$D$10,0) -> 0 | T15: =IFERROR(SUMPRODUCT(S$15:S15,H$15:H15)/J15,0) -> 0 | V15: =IFERROR(U15/$H15,0) -> 0 | W15: =IF(U15=0,"-",IFERROR(SUMPRODUCT($S$15:$S15,U$15:U15)/SUM(U$15:U15),"-")) -> -
C16: Portion | D16: Size | F16: B | I16: =IFERROR(H16/$H$23,0) -> 0 | J16: =SUM(H$15:H16) -> 0 | K16: =IFERROR(SUM(H17:H$22)/$H$23,0) -> 0 | L16: =IFERROR(J16/$D$5,0) -> 0 | M16: =IFERROR($D$6/J16,0) -> 0 | N16: =IFERROR($D$7/J16,0) -> 0 | O16: =IFERROR($D$8/J16,0) -> 0 | P16: =IFERROR(J16/$D$9,0) -> 0 | Q16: =IFERROR(J16/$D$11,0) -> 0 | R16: =IFERROR(J16/$D$10,0) -> 0 | T16: =IFERROR(SUMPRODUCT(S$15:S16,H$15:H16)/J16,0) -> 0 | V16: =IFERROR(U16/$H16,0) -> 0 | W16: =IF(U16=0,"-",IFERROR(SUMPRODUCT($S$15:$S16,U$15:U16)/SUM(U$15:U16),"-")) -> -
C17: IG | D17: =SUMIFS($G$28:$G$35,$K$28:$K$35,C17) -> 0 | F17: C | I17: =IFERROR(H17/$H$23,0) -> 0 | J17: =SUM(H$15:H17) -> 0 | K17: =IFERROR(SUM(H18:H$22)/$H$23,0) -> 0 | L17: =IFERROR(J17/$D$5,0) -> 0 | M17: =IFERROR($D$6/J17,0) -> 0 | N17: =IFERROR($D$7/J17,0) -> 0 | O17: =IFERROR($D$8/J17,0) -> 0 | P17: =IFERROR(J17/$D$9,0) -> 0 | Q17: =IFERROR(J17/$D$11,0) -> 0 | R17: =IFERROR(J17/$D$10,0) -> 0 | T17: =IFERROR(SUMPRODUCT(S$15:S17,H$15:H17)/J17,0) -> 0 | V17: =IFERROR(U17/$H17,0) -> 0 | W17: =IF(U17=0,"-",IFERROR(SUMPRODUCT($S$15:$S17,U$15:U17)/SUM(U$15:U17),"-")) -> -
C18: Non-IG | D18: =SUMIFS($G$28:$G$35,$K$28:$K$35,C18) -> 0 | F18: D | I18: =IFERROR(H18/$H$23,0) -> 0 | J18: =SUM(H$15:H18) -> 0 | K18: =IFERROR(SUM(H19:H$22)/$H$23,0) -> 0 | L18: =IFERROR(J18/$D$5,0) -> 0 | M18: =IFERROR($D$6/J18,0) -> 0 | N18: =IFERROR($D$7/J18,0) -> 0 | O18: =IFERROR($D$8/J18,0) -> 0 | P18: =IFERROR(J18/$D$9,0) -> 0 | Q18: =IFERROR(J18/$D$11,0) -> 0 | R18: =IFERROR(J18/$D$10,0) -> 0 | T18: =IFERROR(SUMPRODUCT(S$15:S18,H$15:H18)/J18,0) -> 0 | V18: =IFERROR(U18/$H18,0) -> 0 | W18: =IF(U18=0,"-",IFERROR(SUMPRODUCT($S$15:$S18,U$15:U18)/SUM(U$15:U18),"-")) -> -
C19: Total | D19: =SUM(D17:D18) -> 0 | F19: E | I19: =IFERROR(H19/$H$23,0) -> 0 | J19: =SUM(H$15:H19) -> 0 | K19: =IFERROR(SUM(H20:H$22)/$H$23,0) -> 0 | L19: =IFERROR(J19/$D$5,0) -> 0 | M19: =IFERROR($D$6/J19,0) -> 0 | N19: =IFERROR($D$7/J19,0) -> 0 | O19: =IFERROR($D$8/J19,0) -> 0 | P19: =IFERROR(J19/$D$9,0) -> 0 | Q19: =IFERROR(J19/$D$11,0) -> 0 | R19: =IFERROR(J19/$D$10,0) -> 0 | T19: =IFERROR(SUMPRODUCT(S$15:S19,H$15:H19)/J19,0) -> 0 | V19: =IFERROR(U19/$H19,0) -> 0 | W19: =IF(U19=0,"-",IFERROR(SUMPRODUCT($S$15:$S19,U$15:U19)/SUM(U$15:U19),"-")) -> -
F20: F | I20: =IFERROR(H20/$H$23,0) -> 0 | J20: =SUM(H$15:H20) -> 0 | K20: =IFERROR(SUM(H21:H$22)/$H$23,0) -> 0 | L20: =IFERROR(J20/$D$5,0) -> 0 | M20: =IFERROR($D$6/J20,0) -> 0 | N20: =IFERROR($D$7/J20,0) -> 0 | O20: =IFERROR($D$8/J20,0) -> 0 | P20: =IFERROR(J20/$D$9,0) -> 0 | Q20: =IFERROR(J20/$D$11,0) -> 0 | R20: =IFERROR(J20/$D$10,0) -> 0 | T20: =IFERROR(SUMPRODUCT(S$15:S20,H$15:H20)/J20,0) -> 0 | V20: =IFERROR(U20/$H20,0) -> 0 | W20: =IF(U20=0,"-",IFERROR(SUMPRODUCT($S$15:$S20,U$15:U20)/SUM(U$15:U20),"-")) -> -
F21: G | I21: =IFERROR(H21/$H$23,0) -> 0 | J21: =SUM(H$15:H21) -> 0 | K21: =IFERROR(SUM(H22:H$22)/$H$23,0) -> 0 | L21: =IFERROR(J21/$D$5,0) -> 0 | M21: =IFERROR($D$6/J21,0) -> 0 | N21: =IFERROR($D$7/J21,0) -> 0 | O21: =IFERROR($D$8/J21,0) -> 0 | P21: =IFERROR(J21/$D$9,0) -> 0 | Q21: =IFERROR(J21/$D$11,0) -> 0 | R21: =IFERROR(J21/$D$10,0) -> 0 | T21: =IFERROR(SUMPRODUCT(S$15:S21,H$15:H21)/J21,0) -> 0 | V21: =IFERROR(U21/$H21,0) -> 0 | W21: =IF(U21=0,"-",IFERROR(SUMPRODUCT($S$15:$S21,U$15:U21)/SUM(U$15:U21),"-")) -> -
F22: HRR | I22: =IFERROR(H22/$H$23,0) -> 0 | J22: =SUM(H$15:H22) -> 0 | K22: - | L22: =IFERROR(J22/$D$5,0) -> 0 | M22: =IFERROR($D$6/J22,0) -> 0 | N22: =IFERROR($D$7/J22,0) -> 0 | O22: =IFERROR($D$8/J22,0) -> 0 | P22: =IFERROR(J22/$D$9,0) -> 0 | Q22: =IFERROR(J22/$D$11,0) -> 0 | R22: =IFERROR(J22/$D$10,0) -> 0 | T22: =IFERROR(SUMPRODUCT(S$15:S22,H$15:H22)/J22,0) -> 0 | V22: =IFERROR(U22/$H22,0) -> 0 | W22: =IF(U22=0,"-",IFERROR(SUMPRODUCT($S$15:$S22,U$15:U22)/SUM(U$15:U22),"-")) -> -
F23: Total SASB | H23: =SUM(H15:H22) -> 0 | I23: =IFERROR(H23/$H$23,0) -> 0 | J23: =J22 -> 0 | K23: - | L23: =IFERROR(J23/$D$5,0) -> 0 | M23: =IFERROR($D$6/J23,0) -> 0 | N23: =IFERROR($D$7/J23,0) -> 0 | O23: =IFERROR($D$8/J23,0) -> 0 | P23: =IFERROR(J23/$D$9,0) -> 0 | Q23: =IFERROR(J23/$D$11,0) -> 0 | R23: =IFERROR(J23/$D$10,0) -> 0 | S23: =IFERROR(SUMPRODUCT(S15:S22,$H$15:$H$22)/SUM(H15:H22),0) -> 0 | T23: =T22 -> 0 | U23: =SUM(U15:U22) -> 0 | V23: =IFERROR(U23/$H23,0) -> 0 | W23: =IF(U23=0,"-",IFERROR(SUMPRODUCT($S$15:$S$22,U$15:U$22)/U23,"-")) -> -
F26: Debt Service Calculations
F27: Class | G27: Size | H27: Spread | I27: Index | J27: Debt Service | K27: IG Tag
F28: =F15 -> A | G28: =H15 -> 0 | H28: =IFERROR(S15/10000,0) -> 0 | J28: =IFERROR(G28*(H28+I28)*365/360,0) -> 0 | K28: IG
F29: =F16 -> B | G29: =H16 -> 0 | H29: =IFERROR(S16/10000,0) -> 0 | I29: =$I$28 -> 0 | J29: =IFERROR(G29*(H29+I29)*365/360,0) -> 0 | K29: IG
F30: =F17 -> C | G30: =H17 -> 0 | H30: =IFERROR(S17/10000,0) -> 0 | I30: =$I$28 -> 0 | J30: =IFERROR(G30*(H30+I30)*365/360,0) -> 0 | K30: IG
F31: =F18 -> D | G31: =H18 -> 0 | H31: =IFERROR(S18/10000,0) -> 0 | I31: =$I$28 -> 0 | J31: =IFERROR(G31*(H31+I31)*365/360,0) -> 0 | K31: IG
F32: =F19 -> E | G32: =H19 -> 0 | H32: =IFERROR(S19/10000,0) -> 0 | I32: =$I$28 -> 0 | J32: =IFERROR(G32*(H32+I32)*365/360,0) -> 0 | K32: Non-IG
F33: =F20 -> F | G33: =H20 -> 0 | H33: =IFERROR(S20/10000,0) -> 0 | I33: =$I$28 -> 0 | J33: =IFERROR(G33*(H33+I33)*365/360,0) -> 0 | K33: Non-IG
F34: =F21 -> G | G34: =H21 -> 0 | H34: =IFERROR(S21/10000,0) -> 0 | I34: =$I$28 -> 0 | J34: =IFERROR(G34*(H34+I34)*365/360,0) -> 0 | K34: Non-IG
F35: =F22 -> HRR | G35: =H22 -> 0 | H35: =IFERROR(S22/10000,0) -> 0 | I35: =$I$28 -> 0 | J35: =IFERROR(G35*(H35+I35)*365/360,0) -> 0 | K35: Non-IG

Sheet S&U
C1: Keys | D1: ='Cap Stack Control'!$D$5 -> 0
C3: Project Capitalization
C4: Sources | D4: $ | E4: $ / Key | F4: % | H4: Uses | I4: $ | J4: $ / Key | K4: %
C5: Mortgage Loan | D5: ='Cap Stack Control'!$H$23 -> 0 | E5: =IFERROR(SUM(D$5:D5)/$D$1,0) -> 0 | F5: =IFERROR(SUM(D$5:D5)/$D$10,0) -> 0 | H5: Refinance Existing Debt | J5: =IFERROR(I5/$D$1,0) -> 0 | K5: =IFERROR(I5/$I$10,0) -> 0
C6: Sponsor Equity | E6: =IFERROR(SUM(D$5:D6)/$D$1,0) -> 0 | F6: =IFERROR(SUM(D$5:D6)/$D$10,0) -> 0 | H6: Upfront PIP Reserve | J6: =IFERROR(I6/$D$1,0) -> 0 | K6: =IFERROR(I6/$I$10,0) -> 0
H7: Estimated Closing Costs | J7: =IFERROR(I7/$D$1,0) -> 0 | K7: =IFERROR(I7/$I$10,0) -> 0
H8: Return of Equity to Sponsor | J8: =IFERROR(I8/$D$1,0) -> 0 | K8: =IFERROR(I8/$I$10,0) -> 0
C10: Total Sources | D10: =SUM(D5:D8) -> 0 | E10: =IFERROR(D10/D1,0) -> 0 | F10: =IFERROR(D10/D10,0) -> 0 | H10: Total Uses | I10: =SUM(I5:I8) -> 0 | J10: =IFERROR(I10/$D$1,0) -> 0 | K10: =IFERROR(I10/$I$10,0) -> 0 | M10: =I10=D10 -> TRUE

Sheet UW Drivers
F1: AN6 | G1: X9 | H1: X10 | I1: X11 | J1: AB9 | K1: AB10 | L1: AB11 | M1: AF9 | N1: AF10 | O1: AF11 | S1: AN19 | T1: AN55 | U1: AO55 | W1: AN55
D3: Franchise Fee Floor | E3: 0.06
D4: CapEx Hit / Key | E4: 15000
D5: Normalized NOI Margin | E5: 0.25
G7: =Tape!$Y$5 -> 2025 | J7: =Tape!$Z$5 -> TTM | M7: =Tape!$AA$5 -> Reforecast | P7: Sixth Street UW
C8: No. | D8: Asset | E8: Year Built | F8: Keys | G8: Occ | H8: ADR | I8: RevPAR | J8: Occ | K8: ADR | L8: RevPAR | M8: Occ | N8: ADR | O8: RevPAR | P8: Occ | Q8: ADR | R8: RevPAR | S8: Total Revenue | T8: In-Place NOI | U8: Natural NOI Margin | V8: Normalize NOI Margin | W8: Stressed NOI | X8: Override NOI Margin | Y8: UW NOI Margin | Z8: Check | AA8: Cap Rate | AB8: Gross Value (Inc. Capex) | AC8: As-Is Capex ($ / Key) | AD8: Base Case Property Value | AE8: Stressed Value | AF8: $ / Key | AH8: Franchise Fee | AJ8: NOI per Key | AK8: Valuation Commentary
C9: 1 | D9: =IF(INDEX(Tape!$C$7:$C$36,$C9)="","",INDEX(Tape!$C$7:$C$36,$C9)) | E9: =IFERROR(INDEX(Tape!$O$7:$O$36,MATCH('UW Drivers'!$D9,Tape!$C$7:$C$36,0)),0) -> 0 | F9: =IFERROR(INDIRECT("'" & $C9 & "'!" & F$1),0) -> 0 | G9: =IFERROR(INDIRECT("'" & $C9 & "'!" & G$1),0) -> 0 | H9: =IFERROR(INDIRECT("'" & $C9 & "'!" & H$1),0) -> 0 | I9: =IFERROR(INDIRECT("'" & $C9 & "'!" & I$1),0) -> 0 | J9: =IFERROR(INDIRECT("'" & $C9 & "'!" & J$1),0) -> 0 | K9: =IFERROR(INDIRECT("'" & $C9 & "'!" & K$1),0) -> 0 | L9: =IFERROR(INDIRECT("'" & $C9 & "'!" & L$1),0) -> 0 | M9: =IFERROR(INDIRECT("'" & $C9 & "'!" & M$1),0) -> 0 | ... O9: =IFERROR(INDIRECT("'" & $C9 & "'!" & O$1),0) -> 0 | P9: =J9 -> 0 | Q9: =K9 -> 0 | R9: =P9*Q9 -> 0 | S9: =IFERROR(INDIRECT("'" & $C9 & "'!" & S$1),0) -> 0 | T9: =IFERROR(INDIRECT("'" & $C9 & "'!" & T$1),0) -> 0 | U9: =IFERROR(INDIRECT("'" & $C9 & "'!" & U$1),0) -> 0 | V9: Yes | W9: =IFERROR(IF(V9="No",INDIRECT("'"&$C9&"'!"&W$1),S9*Y9),0) -> 0 | Y9: =IF(X9>0,X9,U9) -> 0 | Z9: =IFERROR(W9/S9,0) -> 0 | AB9: =IFERROR(ROUND(T9/AA9,-5),0) -> 0 | AD9: =AB9-(AC9*F9) -> 0 | AE9: =IFERROR(ROUND(W9/AA9,-5)-(AC9*F9),0) -> 0 | AF9: =IFERROR(AE9/F9,0) -> 0 | AI9: =AC9*F9 -> 0 | AJ9: =IFERROR(+W9/$F9,0) -> 0
C10: =C9+1 -> 2 | D10: =IF(INDEX(Tape!$C$7:$C$36,$C10)="","",INDEX(Tape!$C$7:$C$36,$C10)) | E10: =IFERROR(INDEX(Tape!$O$7:$O$36,MATCH('UW Drivers'!$D10,Tape!$C$7:$C$36,0)),0) -> 0 | F10: =IFERROR(INDIRECT("'" & $C10 & "'!" & F$1),0) -> 0 | G10: =IFERROR(INDIRECT("'" & $C10 & "'!" & G$1),0) -> 0 | H10: =IFERROR(INDIRECT("'" & $C10 & "'!" & H$1),0) -> 0 | I10: =IFERROR(INDIRECT("'" & $C10 & "'!" & I$1),0) -> 0 | J10: =IFERROR(INDIRECT("'" & $C10 & "'!" & J$1),0) -> 0 | K10: =IFERROR(INDIRECT("'" & $C10 & "'!" & K$1),0) -> 0 | L10: =IFERROR(INDIRECT("'" & $C10 & "'!" & L$1),0) -> 0 | M10: =IFERROR(INDIRECT("'" & $C10 & "'!" & M$1),0) -> 0 | ... O10: =IFERROR(INDIRECT("'" & $C10 & "'!" & O$1),0) -> 0 | P10: =J10 -> 0 | Q10: =K10 -> 0 | R10: =P10*Q10 -> 0 | S10: =IFERROR(INDIRECT("'" & $C10 & "'!" & S$1),0) -> 0 | T10: =IFERROR(INDIRECT("'" & $C10 & "'!" & T$1),0) -> 0 | U10: =IFERROR(INDIRECT("'" & $C10 & "'!" & U$1),0) -> 0 | V10: Yes | W10: =IFERROR(IF(V10="No",INDIRECT("'"&$C10&"'!"&W$1),S10*Y10),0) -> 0 | Y10: =IF(X10>0,X10,U10) -> 0 | Z10: =IFERROR(W10/S10,0) -> 0 | AB10: =IFERROR(ROUND(T10/AA10,-5),0) -> 0 | AD10: =AB10-(AC10*F10) -> 0 | AE10: =IFERROR(ROUND(W10/AA10,-5)-(AC10*F10),0) -> 0 | AF10: =IFERROR(AE10/F10,0) -> 0 | AI10: =AC10*F10 -> 0 | AJ10: =IFERROR(+W10/$F10,0) -> 0
C11: =C10+1 -> 3 | D11: =IF(INDEX(Tape!$C$7:$C$36,$C11)="","",INDEX(Tape!$C$7:$C$36,$C11)) | E11: =IFERROR(INDEX(Tape!$O$7:$O$36,MATCH('UW Drivers'!$D11,Tape!$C$7:$C$36,0)),0) -> 0 | F11: =IFERROR(INDIRECT("'" & $C11 & "'!" & F$1),0) -> 0 | G11: =IFERROR(INDIRECT("'" & $C11 & "'!" & G$1),0) -> 0 | H11: =IFERROR(INDIRECT("'" & $C11 & "'!" & H$1),0) -> 0 | I11: =IFERROR(INDIRECT("'" & $C11 & "'!" & I$1),0) -> 0 | J11: =IFERROR(INDIRECT("'" & $C11 & "'!" & J$1),0) -> 0 | K11: =IFERROR(INDIRECT("'" & $C11 & "'!" & K$1),0) -> 0 | L11: =IFERROR(INDIRECT("'" & $C11 & "'!" & L$1),0) -> 0 | M11: =IFERROR(INDIRECT("'" & $C11 & "'!" & M$1),0) -> 0 | ... O11: =IFERROR(INDIRECT("'" & $C11 & "'!" & O$1),0) -> 0 | P11: =J11 -> 0 | Q11: =K11 -> 0 | R11: =P11*Q11 -> 0 | S11: =IFERROR(INDIRECT("'" & $C11 & "'!" & S$1),0) -> 0 | T11: =IFERROR(INDIRECT("'" & $C11 & "'!" & T$1),0) -> 0 | U11: =IFERROR(INDIRECT("'" & $C11 & "'!" & U$1),0) -> 0 | V11: Yes | W11: =IFERROR(IF(V11="No",INDIRECT("'"&$C11&"'!"&W$1),S11*Y11),0) -> 0 | Y11: =IF(X11>0,X11,U11) -> 0 | Z11: =IFERROR(W11/S11,0) -> 0 | AB11: =IFERROR(ROUND(T11/AA11,-5),0) -> 0 | AD11: =AB11-(AC11*F11) -> 0 | AE11: =IFERROR(ROUND(W11/AA11,-5)-(AC11*F11),0) -> 0 | AF11: =IFERROR(AE11/F11,0) -> 0 | AI11: =AC11*F11 -> 0 | AJ11: =IFERROR(+W11/$F11,0) -> 0
C12: =C11+1 -> 4 | D12: =IF(INDEX(Tape!$C$7:$C$36,$C12)="","",INDEX(Tape!$C$7:$C$36,$C12)) | E12: =IFERROR(INDEX(Tape!$O$7:$O$36,MATCH('UW Drivers'!$D12,Tape!$C$7:$C$36,0)),0) -> 0 | F12: =IFERROR(INDIRECT("'" & $C12 & "'!" & F$1),0) -> 0 | G12: =IFERROR(INDIRECT("'" & $C12 & "'!" & G$1),0) -> 0 | H12: =IFERROR(INDIRECT("'" & $C12 & "'!" & H$1),0) -> 0 | I12: =IFERROR(INDIRECT("'" & $C12 & "'!" & I$1),0) -> 0 | J12: =IFERROR(INDIRECT("'" & $C12 & "'!" & J$1),0) -> 0 | K12: =IFERROR(INDIRECT("'" & $C12 & "'!" & K$1),0) -> 0 | L12: =IFERROR(INDIRECT("'" & $C12 & "'!" & L$1),0) -> 0 | M12: =IFERROR(INDIRECT("'" & $C12 & "'!" & M$1),0) -> 0 | ... O12: =IFERROR(INDIRECT("'" & $C12 & "'!" & O$1),0) -> 0 | P12: =J12 -> 0 | Q12: =K12 -> 0 | R12: =P12*Q12 -> 0 | S12: =IFERROR(INDIRECT("'" & $C12 & "'!" & S$1),0) -> 0 | T12: =IFERROR(INDIRECT("'" & $C12 & "'!" & T$1),0) -> 0 | U12: =IFERROR(INDIRECT("'" & $C12 & "'!" & U$1),0) -> 0 | V12: Yes | W12: =IFERROR(IF(V12="No",INDIRECT("'"&$C12&"'!"&W$1),S12*Y12),0) -> 0 | Y12: =IF(X12>0,X12,U12) -> 0 | Z12: =IFERROR(W12/S12,0) -> 0 | AB12: =IFERROR(ROUND(T12/AA12,-5),0) -> 0 | AD12: =AB12-(AC12*F12) -> 0 | AE12: =IFERROR(ROUND(W12/AA12,-5)-(AC12*F12),0) -> 0 | AF12: =IFERROR(AE12/F12,0) -> 0 | AI12: =AC12*F12 -> 0 | AJ12: =IFERROR(+W12/$F12,0) -> 0
C13: =C12+1 -> 5 | D13: =IF(INDEX(Tape!$C$7:$C$36,$C13)="","",INDEX(Tape!$C$7:$C$36,$C13)) | E13: =IFERROR(INDEX(Tape!$O$7:$O$36,MATCH('UW Drivers'!$D13,Tape!$C$7:$C$36,0)),0) -> 0 | F13: =IFERROR(INDIRECT("'" & $C13 & "'!" & F$1),0) -> 0 | G13: =IFERROR(INDIRECT("'" & $C13 & "'!" & G$1),0) -> 0 | H13: =IFERROR(INDIRECT("'" & $C13 & "'!" & H$1),0) -> 0 | I13: =IFERROR(INDIRECT("'" & $C13 & "'!" & I$1),0) -> 0 | J13: =IFERROR(INDIRECT("'" & $C13 & "'!" & J$1),0) -> 0 | K13: =IFERROR(INDIRECT("'" & $C13 & "'!" & K$1),0) -> 0 | L13: =IFERROR(INDIRECT("'" & $C13 & "'!" & L$1),0) -> 0 | M13: =IFERROR(INDIRECT("'" & $C13 & "'!" & M$1),0) -> 0 | ... O13: =IFERROR(INDIRECT("'" & $C13 & "'!" & O$1),0) -> 0 | P13: =J13 -> 0 | Q13: =K13 -> 0 | R13: =P13*Q13 -> 0 | S13: =IFERROR(INDIRECT("'" & $C13 & "'!" & S$1),0) -> 0 | T13: =IFERROR(INDIRECT("'" & $C13 & "'!" & T$1),0) -> 0 | U13: =IFERROR(INDIRECT("'" & $C13 & "'!" & U$1),0) -> 0 | V13: Yes | W13: =IFERROR(IF(V13="No",INDIRECT("'"&$C13&"'!"&W$1),S13*Y13),0) -> 0 | Y13: =IF(X13>0,X13,U13) -> 0 | Z13: =IFERROR(W13/S13,0) -> 0 | AB13: =IFERROR(ROUND(T13/AA13,-5),0) -> 0 | AD13: =AB13-(AC13*F13) -> 0 | AE13: =IFERROR(ROUND(W13/AA13,-5)-(AC13*F13),0) -> 0 | AF13: =IFERROR(AE13/F13,0) -> 0 | AI13: =AC13*F13 -> 0 | AJ13: =IFERROR(+W13/$F13,0) -> 0
C14: =C13+1 -> 6 | D14: =IF(INDEX(Tape!$C$7:$C$36,$C14)="","",INDEX(Tape!$C$7:$C$36,$C14)) | E14: =IFERROR(INDEX(Tape!$O$7:$O$36,MATCH('UW Drivers'!$D14,Tape!$C$7:$C$36,0)),0) -> 0 | F14: =IFERROR(INDIRECT("'" & $C14 & "'!" & F$1),0) -> 0 | G14: =IFERROR(INDIRECT("'" & $C14 & "'!" & G$1),0) -> 0 | H14: =IFERROR(INDIRECT("'" & $C14 & "'!" & H$1),0) -> 0 | I14: =IFERROR(INDIRECT("'" & $C14 & "'!" & I$1),0) -> 0 | J14: =IFERROR(INDIRECT("'" & $C14 & "'!" & J$1),0) -> 0 | K14: =IFERROR(INDIRECT("'" & $C14 & "'!" & K$1),0) -> 0 | L14: =IFERROR(INDIRECT("'" & $C14 & "'!" & L$1),0) -> 0 | M14: =IFERROR(INDIRECT("'" & $C14 & "'!" & M$1),0) -> 0 | ... O14: =IFERROR(INDIRECT("'" & $C14 & "'!" & O$1),0) -> 0 | P14: =J14 -> 0 | Q14: =K14 -> 0 | R14: =P14*Q14 -> 0 | S14: =IFERROR(INDIRECT("'" & $C14 & "'!" & S$1),0) -> 0 | T14: =IFERROR(INDIRECT("'" & $C14 & "'!" & T$1),0) -> 0 | U14: =IFERROR(INDIRECT("'" & $C14 & "'!" & U$1),0) -> 0 | V14: Yes | W14: =IFERROR(IF(V14="No",INDIRECT("'"&$C14&"'!"&W$1),S14*Y14),0) -> 0 | Y14: =IF(X14>0,X14,U14) -> 0 | Z14: =IFERROR(W14/S14,0) -> 0 | AB14: =IFERROR(ROUND(T14/AA14,-5),0) -> 0 | AD14: =AB14-(AC14*F14) -> 0 | AE14: =IFERROR(ROUND(W14/AA14,-5)-(AC14*F14),0) -> 0 | AF14: =IFERROR(AE14/F14,0) -> 0 | AI14: =AC14*F14 -> 0 | AJ14: =IFERROR(+W14/$F14,0) -> 0
C15: =C14+1 -> 7 | D15: =IF(INDEX(Tape!$C$7:$C$36,$C15)="","",INDEX(Tape!$C$7:$C$36,$C15)) | E15: =IFERROR(INDEX(Tape!$O$7:$O$36,MATCH('UW Drivers'!$D15,Tape!$C$7:$C$36,0)),0) -> 0 | F15: =IFERROR(INDIRECT("'" & $C15 & "'!" & F$1),0) -> 0 | G15: =IFERROR(INDIRECT("'" & $C15 & "'!" & G$1),0) -> 0 | H15: =IFERROR(INDIRECT("'" & $C15 & "'!" & H$1),0) -> 0 | I15: =IFERROR(INDIRECT("'" & $C15 & "'!" & I$1),0) -> 0 | J15: =IFERROR(INDIRECT("'" & $C15 & "'!" & J$1),0) -> 0 | K15: =IFERROR(INDIRECT("'" & $C15 & "'!" & K$1),0) -> 0 | L15: =IFERROR(INDIRECT("'" & $C15 & "'!" & L$1),0) -> 0 | M15: =IFERROR(INDIRECT("'" & $C15 & "'!" & M$1),0) -> 0 | ... O15: =IFERROR(INDIRECT("'" & $C15 & "'!" & O$1),0) -> 0 | P15: =J15 -> 0 | Q15: =K15 -> 0 | R15: =P15*Q15 -> 0 | S15: =IFERROR(INDIRECT("'" & $C15 & "'!" & S$1),0) -> 0 | T15: =IFERROR(INDIRECT("'" & $C15 & "'!" & T$1),0) -> 0 | U15: =IFERROR(INDIRECT("'" & $C15 & "'!" & U$1),0) -> 0 | V15: Yes | W15: =IFERROR(IF(V15="No",INDIRECT("'"&$C15&"'!"&W$1),S15*Y15),0) -> 0 | Y15: =IF(X15>0,X15,U15) -> 0 | Z15: =IFERROR(W15/S15,0) -> 0 | AB15: =IFERROR(ROUND(T15/AA15,-5),0) -> 0 | AD15: =AB15-(AC15*F15) -> 0 | AE15: =IFERROR(ROUND(W15/AA15,-5)-(AC15*F15),0) -> 0 | AF15: =IFERROR(AE15/F15,0) -> 0 | AI15: =AC15*F15 -> 0 | AJ15: =IFERROR(+W15/$F15,0) -> 0
C16: =C15+1 -> 8 | D16: =IF(INDEX(Tape!$C$7:$C$36,$C16)="","",INDEX(Tape!$C$7:$C$36,$C16)) | E16: =IFERROR(INDEX(Tape!$O$7:$O$36,MATCH('UW Drivers'!$D16,Tape!$C$7:$C$36,0)),0) -> 0 | F16: =IFERROR(INDIRECT("'" & $C16 & "'!" & F$1),0) -> 0 | G16: =IFERROR(INDIRECT("'" & $C16 & "'!" & G$1),0) -> 0 | H16: =IFERROR(INDIRECT("'" & $C16 & "'!" & H$1),0) -> 0 | I16: =IFERROR(INDIRECT("'" & $C16 & "'!" & I$1),0) -> 0 | J16: =IFERROR(INDIRECT("'" & $C16 & "'!" & J$1),0) -> 0 | K16: =IFERROR(INDIRECT("'" & $C16 & "'!" & K$1),0) -> 0 | L16: =IFERROR(INDIRECT("'" & $C16 & "'!" & L$1),0) -> 0 | M16: =IFERROR(INDIRECT("'" & $C16 & "'!" & M$1),0) -> 0 | ... O16: =IFERROR(INDIRECT("'" & $C16 & "'!" & O$1),0) -> 0 | P16: =J16 -> 0 | Q16: =K16 -> 0 | R16: =P16*Q16 -> 0 | S16: =IFERROR(INDIRECT("'" & $C16 & "'!" & S$1),0) -> 0 | T16: =IFERROR(INDIRECT("'" & $C16 & "'!" & T$1),0) -> 0 | U16: =IFERROR(INDIRECT("'" & $C16 & "'!" & U$1),0) -> 0 | V16: Yes | W16: =IFERROR(IF(V16="No",INDIRECT("'"&$C16&"'!"&W$1),S16*Y16),0) -> 0 | Y16: =IF(X16>0,X16,U16) -> 0 | Z16: =IFERROR(W16/S16,0) -> 0 | AB16: =IFERROR(ROUND(T16/AA16,-5),0) -> 0 | AD16: =AB16-(AC16*F16) -> 0 | AE16: =IFERROR(ROUND(W16/AA16,-5)-(AC16*F16),0) -> 0 | AF16: =IFERROR(AE16/F16,0) -> 0 | AI16: =AC16*F16 -> 0 | AJ16: =IFERROR(+W16/$F16,0) -> 0
C17: =C16+1 -> 9 | D17: =IF(INDEX(Tape!$C$7:$C$36,$C17)="","",INDEX(Tape!$C$7:$C$36,$C17)) | E17: =IFERROR(INDEX(Tape!$O$7:$O$36,MATCH('UW Drivers'!$D17,Tape!$C$7:$C$36,0)),0) -> 0 | F17: =IFERROR(INDIRECT("'" & $C17 & "'!" & F$1),0) -> 0 | G17: =IFERROR(INDIRECT("'" & $C17 & "'!" & G$1),0) -> 0 | H17: =IFERROR(INDIRECT("'" & $C17 & "'!" & H$1),0) -> 0 | I17: =IFERROR(INDIRECT("'" & $C17 & "'!" & I$1),0) -> 0 | J17: =IFERROR(INDIRECT("'" & $C17 & "'!" & J$1),0) -> 0 | K17: =IFERROR(INDIRECT("'" & $C17 & "'!" & K$1),0) -> 0 | L17: =IFERROR(INDIRECT("'" & $C17 & "'!" & L$1),0) -> 0 | M17: =IFERROR(INDIRECT("'" & $C17 & "'!" & M$1),0) -> 0 | ... O17: =IFERROR(INDIRECT("'" & $C17 & "'!" & O$1),0) -> 0 | P17: =J17 -> 0 | Q17: =K17 -> 0 | R17: =P17*Q17 -> 0 | S17: =IFERROR(INDIRECT("'" & $C17 & "'!" & S$1),0) -> 0 | T17: =IFERROR(INDIRECT("'" & $C17 & "'!" & T$1),0) -> 0 | U17: =IFERROR(INDIRECT("'" & $C17 & "'!" & U$1),0) -> 0 | V17: Yes | W17: =IFERROR(IF(V17="No",INDIRECT("'"&$C17&"'!"&W$1),S17*Y17),0) -> 0 | Y17: =IF(X17>0,X17,U17) -> 0 | Z17: =IFERROR(W17/S17,0) -> 0 | AB17: =IFERROR(ROUND(T17/AA17,-5),0) -> 0 | AD17: =AB17-(AC17*F17) -> 0 | AE17: =IFERROR(ROUND(W17/AA17,-5)-(AC17*F17),0) -> 0 | AF17: =IFERROR(AE17/F17,0) -> 0 | AI17: =AC17*F17 -> 0 | AJ17: =IFERROR(+W17/$F17,0) -> 0
C18: =C17+1 -> 10 | D18: =IF(INDEX(Tape!$C$7:$C$36,$C18)="","",INDEX(Tape!$C$7:$C$36,$C18)) | E18: =IFERROR(INDEX(Tape!$O$7:$O$36,MATCH('UW Drivers'!$D18,Tape!$C$7:$C$36,0)),0) -> 0 | F18: =IFERROR(INDIRECT("'" & $C18 & "'!" & F$1),0) -> 0 | G18: =IFERROR(INDIRECT("'" & $C18 & "'!" & G$1),0) -> 0 | H18: =IFERROR(INDIRECT("'" & $C18 & "'!" & H$1),0) -> 0 | I18: =IFERROR(INDIRECT("'" & $C18 & "'!" & I$1),0) -> 0 | J18: =IFERROR(INDIRECT("'" & $C18 & "'!" & J$1),0) -> 0 | K18: =IFERROR(INDIRECT("'" & $C18 & "'!" & K$1),0) -> 0 | L18: =IFERROR(INDIRECT("'" & $C18 & "'!" & L$1),0) -> 0 | M18: =IFERROR(INDIRECT("'" & $C18 & "'!" & M$1),0) -> 0 | ... O18: =IFERROR(INDIRECT("'" & $C18 & "'!" & O$1),0) -> 0 | P18: =J18 -> 0 | Q18: =K18 -> 0 | R18: =P18*Q18 -> 0 | S18: =IFERROR(INDIRECT("'" & $C18 & "'!" & S$1),0) -> 0 | T18: =IFERROR(INDIRECT("'" & $C18 & "'!" & T$1),0) -> 0 | U18: =IFERROR(INDIRECT("'" & $C18 & "'!" & U$1),0) -> 0 | V18: Yes | W18: =IFERROR(IF(V18="No",INDIRECT("'"&$C18&"'!"&W$1),S18*Y18),0) -> 0 | Y18: =IF(X18>0,X18,U18) -> 0 | Z18: =IFERROR(W18/S18,0) -> 0 | AB18: =IFERROR(ROUND(T18/AA18,-5),0) -> 0 | AD18: =AB18-(AC18*F18) -> 0 | AE18: =IFERROR(ROUND(W18/AA18,-5)-(AC18*F18),0) -> 0 | AF18: =IFERROR(AE18/F18,0) -> 0 | AI18: =AC18*F18 -> 0 | AJ18: =IFERROR(+W18/$F18,0) -> 0
C19: =C18+1 -> 11 | D19: =IF(INDEX(Tape!$C$7:$C$36,$C19)="","",INDEX(Tape!$C$7:$C$36,$C19)) | E19: =IFERROR(INDEX(Tape!$O$7:$O$36,MATCH('UW Drivers'!$D19,Tape!$C$7:$C$36,0)),0) -> 0 | F19: =IFERROR(INDIRECT("'" & $C19 & "'!" & F$1),0) -> 0 | G19: =IFERROR(INDIRECT("'" & $C19 & "'!" & G$1),0) -> 0 | H19: =IFERROR(INDIRECT("'" & $C19 & "'!" & H$1),0) -> 0 | I19: =IFERROR(INDIRECT("'" & $C19 & "'!" & I$1),0) -> 0 | J19: =IFERROR(INDIRECT("'" & $C19 & "'!" & J$1),0) -> 0 | K19: =IFERROR(INDIRECT("'" & $C19 & "'!" & K$1),0) -> 0 | L19: =IFERROR(INDIRECT("'" & $C19 & "'!" & L$1),0) -> 0 | M19: =IFERROR(INDIRECT("'" & $C19 & "'!" & M$1),0) -> 0 | ... O19: =IFERROR(INDIRECT("'" & $C19 & "'!" & O$1),0) -> 0 | P19: =J19 -> 0 | Q19: =K19 -> 0 | R19: =P19*Q19 -> 0 | S19: =IFERROR(INDIRECT("'" & $C19 & "'!" & S$1),0) -> 0 | T19: =IFERROR(INDIRECT("'" & $C19 & "'!" & T$1),0) -> 0 | U19: =IFERROR(INDIRECT("'" & $C19 & "'!" & U$1),0) -> 0 | V19: Yes | W19: =IFERROR(IF(V19="No",INDIRECT("'"&$C19&"'!"&W$1),S19*Y19),0) -> 0 | Y19: =IF(X19>0,X19,U19) -> 0 | Z19: =IFERROR(W19/S19,0) -> 0 | AB19: =IFERROR(ROUND(T19/AA19,-5),0) -> 0 | AD19: =AB19-(AC19*F19) -> 0 | AE19: =IFERROR(ROUND(W19/AA19,-5)-(AC19*F19),0) -> 0 | AF19: =IFERROR(AE19/F19,0) -> 0 | AI19: =AC19*F19 -> 0 | AJ19: =IFERROR(+W19/$F19,0) -> 0
C20: =C19+1 -> 12 | D20: =IF(INDEX(Tape!$C$7:$C$36,$C20)="","",INDEX(Tape!$C$7:$C$36,$C20)) | E20: =IFERROR(INDEX(Tape!$O$7:$O$36,MATCH('UW Drivers'!$D20,Tape!$C$7:$C$36,0)),0) -> 0 | F20: =IFERROR(INDIRECT("'" & $C20 & "'!" & F$1),0) -> 0 | G20: =IFERROR(INDIRECT("'" & $C20 & "'!" & G$1),0) -> 0 | H20: =IFERROR(INDIRECT("'" & $C20 & "'!" & H$1),0) -> 0 | I20: =IFERROR(INDIRECT("'" & $C20 & "'!" & I$1),0) -> 0 | J20: =IFERROR(INDIRECT("'" & $C20 & "'!" & J$1),0) -> 0 | K20: =IFERROR(INDIRECT("'" & $C20 & "'!" & K$1),0) -> 0 | L20: =IFERROR(INDIRECT("'" & $C20 & "'!" & L$1),0) -> 0 | M20: =IFERROR(INDIRECT("'" & $C20 & "'!" & M$1),0) -> 0 | ... O20: =IFERROR(INDIRECT("'" & $C20 & "'!" & O$1),0) -> 0 | P20: =J20 -> 0 | Q20: =K20 -> 0 | R20: =P20*Q20 -> 0 | S20: =IFERROR(INDIRECT("'" & $C20 & "'!" & S$1),0) -> 0 | T20: =IFERROR(INDIRECT("'" & $C20 & "'!" & T$1),0) -> 0 | U20: =IFERROR(INDIRECT("'" & $C20 & "'!" & U$1),0) -> 0 | V20: Yes | W20: =IFERROR(IF(V20="No",INDIRECT("'"&$C20&"'!"&W$1),S20*Y20),0) -> 0 | Y20: =IF(X20>0,X20,U20) -> 0 | Z20: =IFERROR(W20/S20,0) -> 0 | AB20: =IFERROR(ROUND(T20/AA20,-5),0) -> 0 | AD20: =AB20-(AC20*F20) -> 0 | AE20: =IFERROR(ROUND(W20/AA20,-5)-(AC20*F20),0) -> 0 | AF20: =IFERROR(AE20/F20,0) -> 0 | AI20: =AC20*F20 -> 0 | AJ20: =IFERROR(+W20/$F20,0) -> 0
C21: =C20+1 -> 13 | D21: =IF(INDEX(Tape!$C$7:$C$36,$C21)="","",INDEX(Tape!$C$7:$C$36,$C21)) | E21: =IFERROR(INDEX(Tape!$O$7:$O$36,MATCH('UW Drivers'!$D21,Tape!$C$7:$C$36,0)),0) -> 0 | F21: =IFERROR(INDIRECT("'" & $C21 & "'!" & F$1),0) -> 0 | G21: =IFERROR(INDIRECT("'" & $C21 & "'!" & G$1),0) -> 0 | H21: =IFERROR(INDIRECT("'" & $C21 & "'!" & H$1),0) -> 0 | I21: =IFERROR(INDIRECT("'" & $C21 & "'!" & I$1),0) -> 0 | J21: =IFERROR(INDIRECT("'" & $C21 & "'!" & J$1),0) -> 0 | K21: =IFERROR(INDIRECT("'" & $C21 & "'!" & K$1),0) -> 0 | L21: =IFERROR(INDIRECT("'" & $C21 & "'!" & L$1),0) -> 0 | M21: =IFERROR(INDIRECT("'" & $C21 & "'!" & M$1),0) -> 0 | ... O21: =IFERROR(INDIRECT("'" & $C21 & "'!" & O$1),0) -> 0 | P21: =J21 -> 0 | Q21: =K21 -> 0 | R21: =P21*Q21 -> 0 | S21: =IFERROR(INDIRECT("'" & $C21 & "'!" & S$1),0) -> 0 | T21: =IFERROR(INDIRECT("'" & $C21 & "'!" & T$1),0) -> 0 | U21: =IFERROR(INDIRECT("'" & $C21 & "'!" & U$1),0) -> 0 | V21: Yes | W21: =IFERROR(IF(V21="No",INDIRECT("'"&$C21&"'!"&W$1),S21*Y21),0) -> 0 | Y21: =IF(X21>0,X21,U21) -> 0 | Z21: =IFERROR(W21/S21,0) -> 0 | AB21: =IFERROR(ROUND(T21/AA21,-5),0) -> 0 | AD21: =AB21-(AC21*F21) -> 0 | AE21: =IFERROR(ROUND(W21/AA21,-5)-(AC21*F21),0) -> 0 | AF21: =IFERROR(AE21/F21,0) -> 0 | AI21: =AC21*F21 -> 0 | AJ21: =IFERROR(+W21/$F21,0) -> 0
... C38: =C37+1 -> 30 | D38: =IF(INDEX(Tape!$C$7:$C$36,$C38)="","",INDEX(Tape!$C$7:$C$36,$C38)) | E38: =IFERROR(INDEX(Tape!$O$7:$O$36,MATCH('UW Drivers'!$D38,Tape!$C$7:$C$36,0)),0) -> 0 | F38: =IFERROR(INDIRECT("'" & $C38 & "'!" & F$1),0) -> 0 | G38: =IFERROR(INDIRECT("'" & $C38 & "'!" & G$1),0) -> 0 | H38: =IFERROR(INDIRECT("'" & $C38 & "'!" & H$1),0) -> 0 | I38: =IFERROR(INDIRECT("'" & $C38 & "'!" & I$1),0) -> 0 | J38: =IFERROR(INDIRECT("'" & $C38 & "'!" & J$1),0) -> 0 | K38: =IFERROR(INDIRECT("'" & $C38 & "'!" & K$1),0) -> 0 | L38: =IFERROR(INDIRECT("'" & $C38 & "'!" & L$1),0) -> 0 | M38: =IFERROR(INDIRECT("'" & $C38 & "'!" & M$1),0) -> 0 | ... O38: =IFERROR(INDIRECT("'" & $C38 & "'!" & O$1),0) -> 0 | P38: =J38 -> 0 | Q38: =K38 -> 0 | R38: =P38*Q38 -> 0 | S38: =IFERROR(INDIRECT("'" & $C38 & "'!" & S$1),0) -> 0 | T38: =IFERROR(INDIRECT("'" & $C38 & "'!" & T$1),0) -> 0 | U38: =IFERROR(INDIRECT("'" & $C38 & "'!" & U$1),0) -> 0 | V38: Yes | W38: =IFERROR(IF(V38="No",INDIRECT("'"&$C38&"'!"&W$1),S38*Y38),0) -> 0 | Y38: =IF(X38>0,X38,U38) -> 0 | Z38: =IFERROR(W38/S38,0) -> 0 | AB38: =IFERROR(ROUND(T38/AA38,-5),0) -> 0 | AD38: =AB38-(AC38*F38) -> 0 | AE38: =IFERROR(ROUND(W38/AA38,-5)-(AC38*F38),0) -> 0 | AF38: =IFERROR(AE38/F38,0) -> 0 | AI38: =AC38*F38 -> 0 | AJ38: =IFERROR(+W38/$F38,0) -> 0
F40: =SUM(F9:F38) -> 0 | J40: =IFERROR(SUMPRODUCT(J9:J38,$F$9:$F$38)/SUM($F$9:$F$38),0) -> 0 | K40: =IFERROR(SUMPRODUCT(K9:K38,$F$9:$F$38)/SUM($F$9:$F$38),0) -> 0 | L40: =IFERROR(SUMPRODUCT(L9:L38,$F$9:$F$38)/SUM($F$9:$F$38),0) -> 0 | T40: =SUM(T9:T38) -> 0 | U40: =SUMPRODUCT(U9:U38,S9:S38) -> 0 | W40: =SUM(W9:W38) -> 0 | X40: Max | Y40: Max | Z40: Max | AA40: =MIN(AA9:AA38) -> 0 | AB40: =SUM(AB9:AB38) -> 0 | AD40: =SUM(AD9:AD38) -> 0 | AE40: =SUM(AE9:AE38) -> 0 | AI40: =SUM(AI9:AI38) -> 0
U41: =U40-W40 -> 0 | W41: =IFERROR('UW Drivers'!W40/'Cap Stack Control'!$D$17,0) -> 0 | X41: Min | Y41: Min | Z41: Min | AA41: =MAX(AA9:AA38) -> 0 | AB41: =IFERROR('Cap Stack Control'!$D$17/'UW Drivers'!AB40,0) -> 0 | AD41: =AD40+'Cap Stack Control'!$D$12 -> 0 | AE41: =IFERROR('Cap Stack Control'!$D$17/'UW Drivers'!AE40,0) -> 0
X42: WAVG | Y42: WAVG | Z42: WAVG | AA42: =IFERROR(SUMPRODUCT(AA9:AA38,AB9:AB38)/AB40,0) -> 0 | AD42: =IFERROR('Cap Stack Control'!$D$17/'UW Drivers'!AD41,0) -> 0
AE43: =AE40+'Cap Stack Control'!$D$12 -> 0
AE44: =IFERROR('Cap Stack Control'!$D$17/AE43,0) -> 0

Sheet Rollup
D1: =D3 -> 2019 | H1: =H3 -> 2021 | L1: =L3 -> 2022 | P1: =P3 -> 2023 | T1: =T3 -> 2024 | X1: =X3 -> 2025 | AB1: 2025 | AF1: 2026
D3: =Tape!$T$5 -> 2019 | H3: =Tape!$U$5 -> 2021 | L3: =Tape!$V$5 -> 2022 | P3: =Tape!$W$5 -> 2023 | T3: =Tape!$X$5 -> 2024 | X3: =Tape!$Y$5 -> 2025 | AB3: =Tape!$Z$5 -> TTM | AF3: =Tape!$AA$5 -> Reforecast | AJ3: =Tape!$AB$5 -> Lender UW | AN3: Sixth Street In-Place UW
C4: Keys | D4: =SUM(START:END!D6:D6) -> 0 | H4: =SUM(START:END!H6:H6) -> 0 | L4: =SUM(START:END!L6:L6) -> 0 | P4: =SUM(START:END!P6:P6) -> 0 | T4: =SUM(START:END!T6:T6) -> 0 | X4: =SUM(START:END!X6:X6) -> 0 | AB4: =SUM(START:END!AB6:AB6) -> 0 | AF4: =SUM(START:END!AF6:AF6) -> 0 | AJ4: =SUM(START:END!AJ6:AJ6) -> 0 | AN4: =SUM(START:END!AN6:AN6) -> 0
C5: Rooms Available | D5: =SUM(START:END!D7:D7) -> 0 | H5: =SUM(START:END!H7:H7) -> 0 | L5: =SUM(START:END!L7:L7) -> 0 | P5: =SUM(START:END!P7:P7) -> 0 | T5: =SUM(START:END!T7:T7) -> 0 | X5: =SUM(START:END!X7:X7) -> 0 | AB5: =SUM(START:END!AB7:AB7) -> 0 | AF5: =SUM(START:END!AF7:AF7) -> 0 | AJ5: =SUM(START:END!AJ7:AJ7) -> 0 | AN5: =SUM(START:END!AN7:AN7) -> 0
C6: Rooms Sold | D6: =SUM(START:END!D8:D8) -> 0 | H6: =SUM(START:END!H8:H8) -> 0 | L6: =SUM(START:END!L8:L8) -> 0 | P6: =SUM(START:END!P8:P8) -> 0 | T6: =SUM(START:END!T8:T8) -> 0 | X6: =SUM(START:END!X8:X8) -> 0 | AB6: =SUM(START:END!AB8:AB8) -> 0 | AF6: =SUM(START:END!AF8:AF8) -> 0 | AJ6: =SUM(START:END!AJ8:AJ8) -> 0 | AN6: =SUM(START:END!AN8:AN8) -> 0
C7: Occupancy | D7: =IFERROR(D6/D5,0) -> 0 | H7: =IFERROR(H6/H5,0) -> 0 | L7: =IFERROR(L6/L5,0) -> 0 | P7: =IFERROR(P6/P5,0) -> 0 | T7: =IFERROR(T6/T5,0) -> 0 | X7: =IFERROR(X6/X5,0) -> 0 | AB7: =IFERROR(AB6/AB5,0) -> 0 | AF7: =IFERROR(AF6/AF5,0) -> 0 | AJ7: =IFERROR(AJ6/AJ5,0) -> 0 | AN7: =IFERROR(AN6/AN5,0) -> 0
C8: ADR | D8: =IFERROR(D12/D6,0) -> 0 | H8: =IFERROR(H12/H6,0) -> 0 | L8: =IFERROR(L12/L6,0) -> 0 | P8: =IFERROR(P12/P6,0) -> 0 | T8: =IFERROR(T12/T6,0) -> 0 | X8: =IFERROR(X12/X6,0) -> 0 | AB8: =IFERROR(AB12/AB6,0) -> 0 | AF8: =IFERROR(AF12/AF6,0) -> 0 | AJ8: =IFERROR(AJ12/AJ6,0) -> 0 | AN8: =IFERROR(AN12/AN6,0) -> 0
C9: RevPAR | D9: =D7*D8 -> 0 | H9: =H7*H8 -> 0 | L9: =L7*L8 -> 0 | P9: =P7*P8 -> 0 | T9: =T7*T8 -> 0 | X9: =X7*X8 -> 0 | AB9: =AB7*AB8 -> 0 | AF9: =AF7*AF8 -> 0 | AJ9: =AJ7*AJ8 -> 0 | AN9: =AN7*AN8 -> 0
C11: REVENUES | D11: $ | E11: % Total Rev. | F11: POR | G11: PAR | H11: $ | I11: % Total Rev. | J11: POR | K11: PAR | L11: $ | M11: % Total Rev. | N11: POR | O11: PAR | P11: $ | Q11: % Total Rev. | R11: POR | S11: PAR | T11: $ | U11: % Total Rev. | V11: POR | W11: PAR | X11: $ | Y11: % Total Rev. | Z11: POR | AA11: PAR | AB11: $ | AC11: % Total Rev. | AD11: POR | AE11: PAR | AF11: $ | AG11: % Total Rev. | AH11: POR | AI11: PAR | AJ11: $ | AK11: % Total Rev. | AL11: POR | AM11: PAR | AN11: $ | AO11: % Total Rev. | AP11: POR | AQ11: PAR
C12: Rooms Revenue | D12: =SUM(START:END!D14:D14) -> 0 | E12: =IFERROR(D12/D$17,0) -> 0 | F12: =IFERROR(D12/D$6,0) -> 0 | G12: =IFERROR(D12/D$5,0) -> 0 | H12: =SUM(START:END!H14:H14) -> 0 | I12: =IFERROR(H12/H$17,0) -> 0 | J12: =IFERROR(H12/H$6,0) -> 0 | K12: =IFERROR(H12/H$5,0) -> 0 | L12: =SUM(START:END!L14:L14) -> 0 | M12: =IFERROR(L12/L$17,0) -> 0 | N12: =IFERROR(L12/L$6,0) -> 0 | O12: =IFERROR(L12/L$5,0) -> 0 | P12: =SUM(START:END!P14:P14) -> 0 | Q12: =IFERROR(P12/P$17,0) -> 0 | R12: =IFERROR(P12/P$6,0) -> 0 | S12: =IFERROR(P12/P$5,0) -> 0 | T12: =SUM(START:END!T14:T14) -> 0 | U12: =IFERROR(T12/T$17,0) -> 0 | V12: =IFERROR(T12/T$6,0) -> 0 | W12: =IFERROR(T12/T$5,0) -> 0 | X12: =SUM(START:END!X14:X14) -> 0 | Y12: =IFERROR(X12/X$17,0) -> 0 | Z12: =IFERROR(X12/X$6,0) -> 0 | AA12: =IFERROR(X12/X$5,0) -> 0 | AB12: =SUM(START:END!AB14:AB14) -> 0 | AC12: =IFERROR(AB12/AB$17,0) -> 0 | AD12: =IFERROR(AB12/AB$6,0) -> 0 | AE12: =IFERROR(AB12/AB$5,0) -> 0 | AF12: =SUM(START:END!AF14:AF14) -> 0 | AG12: =IFERROR(AF12/AF$17,0) -> 0 | AH12: =IFERROR(AF12/AF$6,0) -> 0 | AI12: =IFERROR(AF12/AF$5,0) -> 0 | AJ12: =SUM(START:END!AJ14:AJ14) -> 0 | AK12: =IFERROR(AJ12/AJ$17,0) -> 0 | AL12: =IFERROR(AJ12/AJ$6,0) -> 0 | AM12: =IFERROR(AJ12/AJ$5,0) -> 0 | AN12: =SUM(START:END!AN14:AN14) -> 0 | AO12: =IFERROR(AN12/AN$17,0) -> 0 | AP12: =IFERROR(AN12/AN$6,0) -> 0 | AQ12: =IFERROR(AN12/AN$5,0) -> 0
C13: Food & Beverage Revenue | D13: =SUM(START:END!D15:D15) -> 0 | E13: =IFERROR(D13/D$17,0) -> 0 | F13: =IFERROR(D13/D$6,0) -> 0 | G13: =IFERROR(D13/D$5,0) -> 0 | H13: =SUM(START:END!H15:H15) -> 0 | I13: =IFERROR(H13/H$17,0) -> 0 | J13: =IFERROR(H13/H$6,0) -> 0 | K13: =IFERROR(H13/H$5,0) -> 0 | L13: =SUM(START:END!L15:L15) -> 0 | M13: =IFERROR(L13/L$17,0) -> 0 | N13: =IFERROR(L13/L$6,0) -> 0 | O13: =IFERROR(L13/L$5,0) -> 0 | P13: =SUM(START:END!P15:P15) -> 0 | Q13: =IFERROR(P13/P$17,0) -> 0 | R13: =IFERROR(P13/P$6,0) -> 0 | S13: =IFERROR(P13/P$5,0) -> 0 | T13: =SUM(START:END!T15:T15) -> 0 | U13: =IFERROR(T13/T$17,0) -> 0 | V13: =IFERROR(T13/T$6,0) -> 0 | W13: =IFERROR(T13/T$5,0) -> 0 | X13: =SUM(START:END!X15:X15) -> 0 | Y13: =IFERROR(X13/X$17,0) -> 0 | Z13: =IFERROR(X13/X$6,0) -> 0 | AA13: =IFERROR(X13/X$5,0) -> 0 | AB13: =SUM(START:END!AB15:AB15) -> 0 | AC13: =IFERROR(AB13/AB$17,0) -> 0 | AD13: =IFERROR(AB13/AB$6,0) -> 0 | AE13: =IFERROR(AB13/AB$5,0) -> 0 | AF13: =SUM(START:END!AF15:AF15) -> 0 | AG13: =IFERROR(AF13/AF$17,0) -> 0 | AH13: =IFERROR(AF13/AF$6,0) -> 0 | AI13: =IFERROR(AF13/AF$5,0) -> 0 | AJ13: =SUM(START:END!AJ15:AJ15) -> 0 | AK13: =IFERROR(AJ13/AJ$17,0) -> 0 | AL13: =IFERROR(AJ13/AJ$6,0) -> 0 | AM13: =IFERROR(AJ13/AJ$5,0) -> 0 | AN13: =SUM(START:END!AN15:AN15) -> 0 | AO13: =IFERROR(AN13/AN$17,0) -> 0 | AP13: =IFERROR(AN13/AN$6,0) -> 0 | AQ13: =IFERROR(AN13/AN$5,0) -> 0
C14: Other Departmental Revenue | D14: =SUM(START:END!D16:D16) -> 0 | E14: =IFERROR(D14/D$17,0) -> 0 | F14: =IFERROR(D14/D$6,0) -> 0 | G14: =IFERROR(D14/D$5,0) -> 0 | H14: =SUM(START:END!H16:H16) -> 0 | I14: =IFERROR(H14/H$17,0) -> 0 | J14: =IFERROR(H14/H$6,0) -> 0 | K14: =IFERROR(H14/H$5,0) -> 0 | L14: =SUM(START:END!L16:L16) -> 0 | M14: =IFERROR(L14/L$17,0) -> 0 | N14: =IFERROR(L14/L$6,0) -> 0 | O14: =IFERROR(L14/L$5,0) -> 0 | P14: =SUM(START:END!P16:P16) -> 0 | Q14: =IFERROR(P14/P$17,0) -> 0 | R14: =IFERROR(P14/P$6,0) -> 0 | S14: =IFERROR(P14/P$5,0) -> 0 | T14: =SUM(START:END!T16:T16) -> 0 | U14: =IFERROR(T14/T$17,0) -> 0 | V14: =IFERROR(T14/T$6,0) -> 0 | W14: =IFERROR(T14/T$5,0) -> 0 | X14: =SUM(START:END!X16:X16) -> 0 | Y14: =IFERROR(X14/X$17,0) -> 0 | Z14: =IFERROR(X14/X$6,0) -> 0 | AA14: =IFERROR(X14/X$5,0) -> 0 | AB14: =SUM(START:END!AB16:AB16) -> 0 | AC14: =IFERROR(AB14/AB$17,0) -> 0 | AD14: =IFERROR(AB14/AB$6,0) -> 0 | AE14: =IFERROR(AB14/AB$5,0) -> 0 | AF14: =SUM(START:END!AF16:AF16) -> 0 | AG14: =IFERROR(AF14/AF$17,0) -> 0 | AH14: =IFERROR(AF14/AF$6,0) -> 0 | AI14: =IFERROR(AF14/AF$5,0) -> 0 | AJ14: =SUM(START:END!AJ16:AJ16) -> 0 | AK14: =IFERROR(AJ14/AJ$17,0) -> 0 | AL14: =IFERROR(AJ14/AJ$6,0) -> 0 | AM14: =IFERROR(AJ14/AJ$5,0) -> 0 | AN14: =SUM(START:END!AN16:AN16) -> 0 | AO14: =IFERROR(AN14/AN$17,0) -> 0 | AP14: =IFERROR(AN14/AN$6,0) -> 0 | AQ14: =IFERROR(AN14/AN$5,0) -> 0
C15: Parking Revenue | D15: =SUM(START:END!D17:D17) -> 0 | E15: =IFERROR(D15/D$17,0) -> 0 | F15: =IFERROR(D15/D$6,0) -> 0 | G15: =IFERROR(D15/D$5,0) -> 0 | H15: =SUM(START:END!H17:H17) -> 0 | I15: =IFERROR(H15/H$17,0) -> 0 | J15: =IFERROR(H15/H$6,0) -> 0 | K15: =IFERROR(H15/H$5,0) -> 0 | L15: =SUM(START:END!L17:L17) -> 0 | M15: =IFERROR(L15/L$17,0) -> 0 | N15: =IFERROR(L15/L$6,0) -> 0 | O15: =IFERROR(L15/L$5,0) -> 0 | P15: =SUM(START:END!P17:P17) -> 0 | Q15: =IFERROR(P15/P$17,0) -> 0 | R15: =IFERROR(P15/P$6,0) -> 0 | S15: =IFERROR(P15/P$5,0) -> 0 | T15: =SUM(START:END!T17:T17) -> 0 | U15: =IFERROR(T15/T$17,0) -> 0 | V15: =IFERROR(T15/T$6,0) -> 0 | W15: =IFERROR(T15/T$5,0) -> 0 | X15: =SUM(START:END!X17:X17) -> 0 | Y15: =IFERROR(X15/X$17,0) -> 0 | Z15: =IFERROR(X15/X$6,0) -> 0 | AA15: =IFERROR(X15/X$5,0) -> 0 | AB15: =SUM(START:END!AB17:AB17) -> 0 | AC15: =IFERROR(AB15/AB$17,0) -> 0 | AD15: =IFERROR(AB15/AB$6,0) -> 0 | AE15: =IFERROR(AB15/AB$5,0) -> 0 | AF15: =SUM(START:END!AF17:AF17) -> 0 | AG15: =IFERROR(AF15/AF$17,0) -> 0 | AH15: =IFERROR(AF15/AF$6,0) -> 0 | AI15: =IFERROR(AF15/AF$5,0) -> 0 | AJ15: =SUM(START:END!AJ17:AJ17) -> 0 | AK15: =IFERROR(AJ15/AJ$17,0) -> 0 | AL15: =IFERROR(AJ15/AJ$6,0) -> 0 | AM15: =IFERROR(AJ15/AJ$5,0) -> 0 | AN15: =SUM(START:END!AN17:AN17) -> 0 | AO15: =IFERROR(AN15/AN$17,0) -> 0 | AP15: =IFERROR(AN15/AN$6,0) -> 0 | AQ15: =IFERROR(AN15/AN$5,0) -> 0
C16: Miscellaneous | D16: =SUM(START:END!D18:D18) -> 0 | E16: =IFERROR(D16/D$17,0) -> 0 | F16: =IFERROR(D16/D$6,0) -> 0 | G16: =IFERROR(D16/D$5,0) -> 0 | H16: =SUM(START:END!H18:H18) -> 0 | I16: =IFERROR(H16/H$17,0) -> 0 | J16: =IFERROR(H16/H$6,0) -> 0 | K16: =IFERROR(H16/H$5,0) -> 0 | L16: =SUM(START:END!L18:L18) -> 0 | M16: =IFERROR(L16/L$17,0) -> 0 | N16: =IFERROR(L16/L$6,0) -> 0 | O16: =IFERROR(L16/L$5,0) -> 0 | P16: =SUM(START:END!P18:P18) -> 0 | Q16: =IFERROR(P16/P$17,0) -> 0 | R16: =IFERROR(P16/P$6,0) -> 0 | S16: =IFERROR(P16/P$5,0) -> 0 | T16: =SUM(START:END!T18:T18) -> 0 | U16: =IFERROR(T16/T$17,0) -> 0 | V16: =IFERROR(T16/T$6,0) -> 0 | W16: =IFERROR(T16/T$5,0) -> 0 | X16: =SUM(START:END!X18:X18) -> 0 | Y16: =IFERROR(X16/X$17,0) -> 0 | Z16: =IFERROR(X16/X$6,0) -> 0 | AA16: =IFERROR(X16/X$5,0) -> 0 | AB16: =SUM(START:END!AB18:AB18) -> 0 | AC16: =IFERROR(AB16/AB$17,0) -> 0 | AD16: =IFERROR(AB16/AB$6,0) -> 0 | AE16: =IFERROR(AB16/AB$5,0) -> 0 | AF16: =SUM(START:END!AF18:AF18) -> 0 | AG16: =IFERROR(AF16/AF$17,0) -> 0 | AH16: =IFERROR(AF16/AF$6,0) -> 0 | AI16: =IFERROR(AF16/AF$5,0) -> 0 | AJ16: =SUM(START:END!AJ18:AJ18) -> 0 | AK16: =IFERROR(AJ16/AJ$17,0) -> 0 | AL16: =IFERROR(AJ16/AJ$6,0) -> 0 | AM16: =IFERROR(AJ16/AJ$5,0) -> 0 | AN16: =SUM(START:END!AN18:AN18) -> 0 | AO16: =IFERROR(AN16/AN$17,0) -> 0 | AP16: =IFERROR(AN16/AN$6,0) -> 0 | AQ16: =IFERROR(AN16/AN$5,0) -> 0
C17: TOTAL REVENUES | D17: =SUM(D12:D16) -> 0 | E17: =IFERROR(D17/D$17,0) -> 0 | F17: =IFERROR(D17/D$6,0) -> 0 | G17: =IFERROR(D17/D$5,0) -> 0 | H17: =SUM(H12:H16) -> 0 | I17: =IFERROR(H17/H$17,0) -> 0 | J17: =IFERROR(H17/H$6,0) -> 0 | K17: =IFERROR(H17/H$5,0) -> 0 | L17: =SUM(L12:L16) -> 0 | M17: =IFERROR(L17/L$17,0) -> 0 | N17: =IFERROR(L17/L$6,0) -> 0 | O17: =IFERROR(L17/L$5,0) -> 0 | P17: =SUM(P12:P16) -> 0 | Q17: =IFERROR(P17/P$17,0) -> 0 | R17: =IFERROR(P17/P$6,0) -> 0 | S17: =IFERROR(P17/P$5,0) -> 0 | T17: =SUM(T12:T16) -> 0 | U17: =IFERROR(T17/T$17,0) -> 0 | V17: =IFERROR(T17/T$6,0) -> 0 | W17: =IFERROR(T17/T$5,0) -> 0 | X17: =SUM(X12:X16) -> 0 | Y17: =IFERROR(X17/X$17,0) -> 0 | Z17: =IFERROR(X17/X$6,0) -> 0 | AA17: =IFERROR(X17/X$5,0) -> 0 | AB17: =SUM(AB12:AB16) -> 0 | AC17: =IFERROR(AB17/AB$17,0) -> 0 | AD17: =IFERROR(AB17/AB$6,0) -> 0 | AE17: =IFERROR(AB17/AB$5,0) -> 0 | AF17: =SUM(AF12:AF16) -> 0 | AG17: =IFERROR(AF17/AF$17,0) -> 0 | AH17: =IFERROR(AF17/AF$6,0) -> 0 | AI17: =IFERROR(AF17/AF$5,0) -> 0 | AJ17: =SUM(AJ12:AJ16) -> 0 | AK17: =IFERROR(AJ17/AJ$17,0) -> 0 | AL17: =IFERROR(AJ17/AJ$6,0) -> 0 | AM17: =IFERROR(AJ17/AJ$5,0) -> 0 | AN17: =SUM(AN12:AN16) -> 0 | AO17: =IFERROR(AN17/AN$17,0) -> 0 | AP17: =IFERROR(AN17/AN$6,0) -> 0 | AQ17: =IFERROR(AN17/AN$5,0) -> 0
C19: DEPARTMENTAL EXPENSES
C20: Rooms Expense | D20: =SUM(START:END!D22:D22) -> 0 | E20: =IFERROR(D20/D12,0) -> 0 | F20: =IFERROR(D20/D$6,0) -> 0 | G20: =IFERROR(D20/D$5,0) -> 0 | H20: =SUM(START:END!H22:H22) -> 0 | I20: =IFERROR(H20/H12,0) -> 0 | J20: =IFERROR(H20/H$6,0) -> 0 | K20: =IFERROR(H20/H$5,0) -> 0 | L20: =SUM(START:END!L22:L22) -> 0 | M20: =IFERROR(L20/L12,0) -> 0 | N20: =IFERROR(L20/L$6,0) -> 0 | O20: =IFERROR(L20/L$5,0) -> 0 | P20: =SUM(START:END!P22:P22) -> 0 | Q20: =IFERROR(P20/P12,0) -> 0 | R20: =IFERROR(P20/P$6,0) -> 0 | S20: =IFERROR(P20/P$5,0) -> 0 | T20: =SUM(START:END!T22:T22) -> 0 | U20: =IFERROR(T20/T12,0) -> 0 | V20: =IFERROR(T20/T$6,0) -> 0 | W20: =IFERROR(T20/T$5,0) -> 0 | X20: =SUM(START:END!X22:X22) -> 0 | Y20: =IFERROR(X20/X12,0) -> 0 | Z20: =IFERROR(X20/X$6,0) -> 0 | AA20: =IFERROR(X20/X$5,0) -> 0 | AB20: =SUM(START:END!AB22:AB22) -> 0 | AC20: =IFERROR(AB20/AB12,0) -> 0 | AD20: =IFERROR(AB20/AB$6,0) -> 0 | AE20: =IFERROR(AB20/AB$5,0) -> 0 | AF20: =SUM(START:END!AF22:AF22) -> 0 | AG20: =IFERROR(AF20/AF12,0) -> 0 | AH20: =IFERROR(AF20/AF$6,0) -> 0 | AI20: =IFERROR(AF20/AF$5,0) -> 0 | AJ20: =SUM(START:END!AJ22:AJ22) -> 0 | AK20: =IFERROR(AJ20/AJ12,0) -> 0 | AL20: =IFERROR(AJ20/AJ$6,0) -> 0 | AM20: =IFERROR(AJ20/AJ$5,0) -> 0 | AN20: =SUM(START:END!AN22:AN22) -> 0 | AO20: =IFERROR(AN20/AN12,0) -> 0 | AP20: =IFERROR(AN20/AN$6,0) -> 0 | AQ20: =IFERROR(AN20/AN$5,0) -> 0
C21: Food & Beverage Expense | D21: =SUM(START:END!D23:D23) -> 0 | E21: =IFERROR(D21/D13,0) -> 0 | F21: =IFERROR(D21/D$6,0) -> 0 | G21: =IFERROR(D21/D$5,0) -> 0 | H21: =SUM(START:END!H23:H23) -> 0 | I21: =IFERROR(H21/H13,0) -> 0 | J21: =IFERROR(H21/H$6,0) -> 0 | K21: =IFERROR(H21/H$5,0) -> 0 | L21: =SUM(START:END!L23:L23) -> 0 | M21: =IFERROR(L21/L13,0) -> 0 | N21: =IFERROR(L21/L$6,0) -> 0 | O21: =IFERROR(L21/L$5,0) -> 0 | P21: =SUM(START:END!P23:P23) -> 0 | Q21: =IFERROR(P21/P13,0) -> 0 | R21: =IFERROR(P21/P$6,0) -> 0 | S21: =IFERROR(P21/P$5,0) -> 0 | T21: =SUM(START:END!T23:T23) -> 0 | U21: =IFERROR(T21/T13,0) -> 0 | V21: =IFERROR(T21/T$6,0) -> 0 | W21: =IFERROR(T21/T$5,0) -> 0 | X21: =SUM(START:END!X23:X23) -> 0 | Y21: =IFERROR(X21/X13,0) -> 0 | Z21: =IFERROR(X21/X$6,0) -> 0 | AA21: =IFERROR(X21/X$5,0) -> 0 | AB21: =SUM(START:END!AB23:AB23) -> 0 | AC21: =IFERROR(AB21/AB13,0) -> 0 | AD21: =IFERROR(AB21/AB$6,0) -> 0 | AE21: =IFERROR(AB21/AB$5,0) -> 0 | AF21: =SUM(START:END!AF23:AF23) -> 0 | AG21: =IFERROR(AF21/AF13,0) -> 0 | AH21: =IFERROR(AF21/AF$6,0) -> 0 | AI21: =IFERROR(AF21/AF$5,0) -> 0 | AJ21: =SUM(START:END!AJ23:AJ23) -> 0 | AK21: =IFERROR(AJ21/AJ13,0) -> 0 | AL21: =IFERROR(AJ21/AJ$6,0) -> 0 | AM21: =IFERROR(AJ21/AJ$5,0) -> 0 | AN21: =SUM(START:END!AN23:AN23) -> 0 | AO21: =IFERROR(AN21/AN13,0) -> 0 | AP21: =IFERROR(AN21/AN$6,0) -> 0 | AQ21: =IFERROR(AN21/AN$5,0) -> 0
C22: Other Departmental Expense | D22: =SUM(START:END!D24:D24) -> 0 | E22: =IFERROR(D22/D14,0) -> 0 | F22: =IFERROR(D22/D$6,0) -> 0 | G22: =IFERROR(D22/D$5,0) -> 0 | H22: =SUM(START:END!H24:H24) -> 0 | I22: =IFERROR(H22/H14,0) -> 0 | J22: =IFERROR(H22/H$6,0) -> 0 | K22: =IFERROR(H22/H$5,0) -> 0 | L22: =SUM(START:END!L24:L24) -> 0 | M22: =IFERROR(L22/L14,0) -> 0 | N22: =IFERROR(L22/L$6,0) -> 0 | O22: =IFERROR(L22/L$5,0) -> 0 | P22: =SUM(START:END!P24:P24) -> 0 | Q22: =IFERROR(P22/P14,0) -> 0 | R22: =IFERROR(P22/P$6,0) -> 0 | S22: =IFERROR(P22/P$5,0) -> 0 | T22: =SUM(START:END!T24:T24) -> 0 | U22: =IFERROR(T22/T14,0) -> 0 | V22: =IFERROR(T22/T$6,0) -> 0 | W22: =IFERROR(T22/T$5,0) -> 0 | X22: =SUM(START:END!X24:X24) -> 0 | Y22: =IFERROR(X22/X14,0) -> 0 | Z22: =IFERROR(X22/X$6,0) -> 0 | AA22: =IFERROR(X22/X$5,0) -> 0 | AB22: =SUM(START:END!AB24:AB24) -> 0 | AC22: =IFERROR(AB22/AB14,0) -> 0 | AD22: =IFERROR(AB22/AB$6,0) -> 0 | AE22: =IFERROR(AB22/AB$5,0) -> 0 | AF22: =SUM(START:END!AF24:AF24) -> 0 | AG22: =IFERROR(AF22/AF14,0) -> 0 | AH22: =IFERROR(AF22/AF$6,0) -> 0 | AI22: =IFERROR(AF22/AF$5,0) -> 0 | AJ22: =SUM(START:END!AJ24:AJ24) -> 0 | AK22: =IFERROR(AJ22/AJ14,0) -> 0 | AL22: =IFERROR(AJ22/AJ$6,0) -> 0 | AM22: =IFERROR(AJ22/AJ$5,0) -> 0 | AN22: =SUM(START:END!AN24:AN24) -> 0 | AO22: =IFERROR(AN22/AN14,0) -> 0 | AP22: =IFERROR(AN22/AN$6,0) -> 0 | AQ22: =IFERROR(AN22/AN$5,0) -> 0
C23: TOTAL DEPARTMENTAL EXPENSES | D23: =SUM(D20:D22) -> 0 | E23: =IFERROR(D23/D$17,0) -> 0 | F23: =IFERROR(D23/D$6,0) -> 0 | G23: =IFERROR(D23/D$5,0) -> 0 | H23: =SUM(H20:H22) -> 0 | I23: =IFERROR(H23/H$17,0) -> 0 | J23: =IFERROR(H23/H$6,0) -> 0 | K23: =IFERROR(H23/H$5,0) -> 0 | L23: =SUM(L20:L22) -> 0 | M23: =IFERROR(L23/L$17,0) -> 0 | N23: =IFERROR(L23/L$6,0) -> 0 | O23: =IFERROR(L23/L$5,0) -> 0 | P23: =SUM(P20:P22) -> 0 | Q23: =IFERROR(P23/P$17,0) -> 0 | R23: =IFERROR(P23/P$6,0) -> 0 | S23: =IFERROR(P23/P$5,0) -> 0 | T23: =SUM(T20:T22) -> 0 | U23: =IFERROR(T23/T$17,0) -> 0 | V23: =IFERROR(T23/T$6,0) -> 0 | W23: =IFERROR(T23/T$5,0) -> 0 | X23: =SUM(X20:X22) -> 0 | Y23: =IFERROR(X23/X$17,0) -> 0 | Z23: =IFERROR(X23/X$6,0) -> 0 | AA23: =IFERROR(X23/X$5,0) -> 0 | AB23: =SUM(AB20:AB22) -> 0 | AC23: =IFERROR(AB23/AB$17,0) -> 0 | AD23: =IFERROR(AB23/AB$6,0) -> 0 | AE23: =IFERROR(AB23/AB$5,0) -> 0 | AF23: =SUM(AF20:AF22) -> 0 | AG23: =IFERROR(AF23/AF$17,0) -> 0 | AH23: =IFERROR(AF23/AF$6,0) -> 0 | AI23: =IFERROR(AF23/AF$5,0) -> 0 | AJ23: =SUM(AJ20:AJ22) -> 0 | AK23: =IFERROR(AJ23/AJ$17,0) -> 0 | AL23: =IFERROR(AJ23/AJ$6,0) -> 0 | AM23: =IFERROR(AJ23/AJ$5,0) -> 0 | AN23: =SUM(AN20:AN22) -> 0 | AO23: =IFERROR(AN23/AN$17,0) -> 0 | AP23: =IFERROR(AN23/AN$6,0) -> 0 | AQ23: =IFERROR(AN23/AN$5,0) -> 0
C25: GROSS OPERATING INCOME | D25: =D17-D23 -> 0 | E25: =IFERROR(D25/D$17,0) -> 0 | F25: =IFERROR(D25/D$6,0) -> 0 | G25: =IFERROR(D25/D$5,0) -> 0 | H25: =H17-H23 -> 0 | I25: =IFERROR(H25/H$17,0) -> 0 | J25: =IFERROR(H25/H$6,0) -> 0 | K25: =IFERROR(H25/H$5,0) -> 0 | L25: =L17-L23 -> 0 | M25: =IFERROR(L25/L$17,0) -> 0 | N25: =IFERROR(L25/L$6,0) -> 0 | O25: =IFERROR(L25/L$5,0) -> 0 | P25: =P17-P23 -> 0 | Q25: =IFERROR(P25/P$17,0) -> 0 | R25: =IFERROR(P25/P$6,0) -> 0 | S25: =IFERROR(P25/P$5,0) -> 0 | T25: =T17-T23 -> 0 | U25: =IFERROR(T25/T$17,0) -> 0 | V25: =IFERROR(T25/T$6,0) -> 0 | W25: =IFERROR(T25/T$5,0) -> 0 | X25: =X17-X23 -> 0 | Y25: =IFERROR(X25/X$17,0) -> 0 | Z25: =IFERROR(X25/X$6,0) -> 0 | AA25: =IFERROR(X25/X$5,0) -> 0 | AB25: =AB17-AB23 -> 0 | AC25: =IFERROR(AB25/AB$17,0) -> 0 | AD25: =IFERROR(AB25/AB$6,0) -> 0 | AE25: =IFERROR(AB25/AB$5,0) -> 0 | AF25: =AF17-AF23 -> 0 | AG25: =IFERROR(AF25/AF$17,0) -> 0 | AH25: =IFERROR(AF25/AF$6,0) -> 0 | AI25: =IFERROR(AF25/AF$5,0) -> 0 | AJ25: =AJ17-AJ23 -> 0 | AK25: =IFERROR(AJ25/AJ$17,0) -> 0 | AL25: =IFERROR(AJ25/AJ$6,0) -> 0 | AM25: =IFERROR(AJ25/AJ$5,0) -> 0 | AN25: =AN17-AN23 -> 0 | AO25: =IFERROR(AN25/AN$17,0) -> 0 | AP25: =IFERROR(AN25/AN$6,0) -> 0 | AQ25: =IFERROR(AN25/AN$5,0) -> 0
C27: UNDISTRIBUTED EXPENSES
C28: General and Administrative | D28: =SUM(START:END!D30:D30) -> 0 | E28: =IFERROR(D28/D$17,0) -> 0 | F28: =IFERROR(D28/D$6,0) -> 0 | G28: =IFERROR(D28/D$5,0) -> 0 | H28: =SUM(START:END!H30:H30) -> 0 | I28: =IFERROR(H28/H$17,0) -> 0 | J28: =IFERROR(H28/H$6,0) -> 0 | K28: =IFERROR(H28/H$5,0) -> 0 | L28: =SUM(START:END!L30:L30) -> 0 | M28: =IFERROR(L28/L$17,0) -> 0 | N28: =IFERROR(L28/L$6,0) -> 0 | O28: =IFERROR(L28/L$5,0) -> 0 | P28: =SUM(START:END!P30:P30) -> 0 | Q28: =IFERROR(P28/P$17,0) -> 0 | R28: =IFERROR(P28/P$6,0) -> 0 | S28: =IFERROR(P28/P$5,0) -> 0 | T28: =SUM(START:END!T30:T30) -> 0 | U28: =IFERROR(T28/T$17,0) -> 0 | V28: =IFERROR(T28/T$6,0) -> 0 | W28: =IFERROR(T28/T$5,0) -> 0 | X28: =SUM(START:END!X30:X30) -> 0 | Y28: =IFERROR(X28/X$17,0) -> 0 | Z28: =IFERROR(X28/X$6,0) -> 0 | AA28: =IFERROR(X28/X$5,0) -> 0 | AB28: =SUM(START:END!AB30:AB30) -> 0 | AC28: =IFERROR(AB28/AB$17,0) -> 0 | AD28: =IFERROR(AB28/AB$6,0) -> 0 | AE28: =IFERROR(AB28/AB$5,0) -> 0 | AF28: =SUM(START:END!AF30:AF30) -> 0 | AG28: =IFERROR(AF28/AF$17,0) -> 0 | AH28: =IFERROR(AF28/AF$6,0) -> 0 | AI28: =IFERROR(AF28/AF$5,0) -> 0 | AJ28: =SUM(START:END!AJ30:AJ30) -> 0 | AK28: =IFERROR(AJ28/AJ$17,0) -> 0 | AL28: =IFERROR(AJ28/AJ$6,0) -> 0 | AM28: =IFERROR(AJ28/AJ$5,0) -> 0 | AN28: =SUM(START:END!AN30:AN30) -> 0 | AO28: =IFERROR(AN28/AN$17,0) -> 0 | AP28: =IFERROR(AN28/AN$6,0) -> 0 | AQ28: =IFERROR(AN28/AN$5,0) -> 0
C29: Credit Card Commissions | D29: =SUM(START:END!D31:D31) -> 0 | E29: =IFERROR(D29/D$17,0) -> 0 | F29: =IFERROR(D29/D$6,0) -> 0 | G29: =IFERROR(D29/D$5,0) -> 0 | H29: =SUM(START:END!H31:H31) -> 0 | I29: =IFERROR(H29/H$17,0) -> 0 | J29: =IFERROR(H29/H$6,0) -> 0 | K29: =IFERROR(H29/H$5,0) -> 0 | L29: =SUM(START:END!L31:L31) -> 0 | M29: =IFERROR(L29/L$17,0) -> 0 | N29: =IFERROR(L29/L$6,0) -> 0 | O29: =IFERROR(L29/L$5,0) -> 0 | P29: =SUM(START:END!P31:P31) -> 0 | Q29: =IFERROR(P29/P$17,0) -> 0 | R29: =IFERROR(P29/P$6,0) -> 0 | S29: =IFERROR(P29/P$5,0) -> 0 | T29: =SUM(START:END!T31:T31) -> 0 | U29: =IFERROR(T29/T$17,0) -> 0 | V29: =IFERROR(T29/T$6,0) -> 0 | W29: =IFERROR(T29/T$5,0) -> 0 | X29: =SUM(START:END!X31:X31) -> 0 | Y29: =IFERROR(X29/X$17,0) -> 0 | Z29: =IFERROR(X29/X$6,0) -> 0 | AA29: =IFERROR(X29/X$5,0) -> 0 | AB29: =SUM(START:END!AB31:AB31) -> 0 | AC29: =IFERROR(AB29/AB$17,0) -> 0 | AD29: =IFERROR(AB29/AB$6,0) -> 0 | AE29: =IFERROR(AB29/AB$5,0) -> 0 | AF29: =SUM(START:END!AF31:AF31) -> 0 | AG29: =IFERROR(AF29/AF$17,0) -> 0 | AH29: =IFERROR(AF29/AF$6,0) -> 0 | AI29: =IFERROR(AF29/AF$5,0) -> 0 | AJ29: =SUM(START:END!AJ31:AJ31) -> 0 | AK29: =IFERROR(AJ29/AJ$17,0) -> 0 | AL29: =IFERROR(AJ29/AJ$6,0) -> 0 | AM29: =IFERROR(AJ29/AJ$5,0) -> 0 | AN29: =SUM(START:END!AN31:AN31) -> 0 | AO29: =IFERROR(AN29/AN$17,0) -> 0 | AP29: =IFERROR(AN29/AN$6,0) -> 0 | AQ29: =IFERROR(AN29/AN$5,0) -> 0
C30: Information & Telecommunication | D30: =SUM(START:END!D32:D32) -> 0 | E30: =IFERROR(D30/D$17,0) -> 0 | F30: =IFERROR(D30/D$6,0) -> 0 | G30: =IFERROR(D30/D$5,0) -> 0 | H30: =SUM(START:END!H32:H32) -> 0 | I30: =IFERROR(H30/H$17,0) -> 0 | J30: =IFERROR(H30/H$6,0) -> 0 | K30: =IFERROR(H30/H$5,0) -> 0 | L30: =SUM(START:END!L32:L32) -> 0 | M30: =IFERROR(L30/L$17,0) -> 0 | N30: =IFERROR(L30/L$6,0) -> 0 | O30: =IFERROR(L30/L$5,0) -> 0 | P30: =SUM(START:END!P32:P32) -> 0 | Q30: =IFERROR(P30/P$17,0) -> 0 | R30: =IFERROR(P30/P$6,0) -> 0 | S30: =IFERROR(P30/P$5,0) -> 0 | T30: =SUM(START:END!T32:T32) -> 0 | U30: =IFERROR(T30/T$17,0) -> 0 | V30: =IFERROR(T30/T$6,0) -> 0 | W30: =IFERROR(T30/T$5,0) -> 0 | X30: =SUM(START:END!X32:X32) -> 0 | Y30: =IFERROR(X30/X$17,0) -> 0 | Z30: =IFERROR(X30/X$6,0) -> 0 | AA30: =IFERROR(X30/X$5,0) -> 0 | AB30: =SUM(START:END!AB32:AB32) -> 0 | AC30: =IFERROR(AB30/AB$17,0) -> 0 | AD30: =IFERROR(AB30/AB$6,0) -> 0 | AE30: =IFERROR(AB30/AB$5,0) -> 0 | AF30: =SUM(START:END!AF32:AF32) -> 0 | AG30: =IFERROR(AF30/AF$17,0) -> 0 | AH30: =IFERROR(AF30/AF$6,0) -> 0 | AI30: =IFERROR(AF30/AF$5,0) -> 0 | AJ30: =SUM(START:END!AJ32:AJ32) -> 0 | AK30: =IFERROR(AJ30/AJ$17,0) -> 0 | AL30: =IFERROR(AJ30/AJ$6,0) -> 0 | AM30: =IFERROR(AJ30/AJ$5,0) -> 0 | AN30: =SUM(START:END!AN32:AN32) -> 0 | AO30: =IFERROR(AN30/AN$17,0) -> 0 | AP30: =IFERROR(AN30/AN$6,0) -> 0 | AQ30: =IFERROR(AN30/AN$5,0) -> 0
C31: Sales & Marketing | D31: =SUM(START:END!D33:D33) -> 0 | E31: =IFERROR(D31/D$17,0) -> 0 | F31: =IFERROR(D31/D$6,0) -> 0 | G31: =IFERROR(D31/D$5,0) -> 0 | H31: =SUM(START:END!H33:H33) -> 0 | I31: =IFERROR(H31/H$17,0) -> 0 | J31: =IFERROR(H31/H$6,0) -> 0 | K31: =IFERROR(H31/H$5,0) -> 0 | L31: =SUM(START:END!L33:L33) -> 0 | M31: =IFERROR(L31/L$17,0) -> 0 | N31: =IFERROR(L31/L$6,0) -> 0 | O31: =IFERROR(L31/L$5,0) -> 0 | P31: =SUM(START:END!P33:P33) -> 0 | Q31: =IFERROR(P31/P$17,0) -> 0 | R31: =IFERROR(P31/P$6,0) -> 0 | S31: =IFERROR(P31/P$5,0) -> 0 | T31: =SUM(START:END!T33:T33) -> 0 | U31: =IFERROR(T31/T$17,0) -> 0 | V31: =IFERROR(T31/T$6,0) -> 0 | W31: =IFERROR(T31/T$5,0) -> 0 | X31: =SUM(START:END!X33:X33) -> 0 | Y31: =IFERROR(X31/X$17,0) -> 0 | Z31: =IFERROR(X31/X$6,0) -> 0 | AA31: =IFERROR(X31/X$5,0) -> 0 | AB31: =SUM(START:END!AB33:AB33) -> 0 | AC31: =IFERROR(AB31/AB$17,0) -> 0 | AD31: =IFERROR(AB31/AB$6,0) -> 0 | AE31: =IFERROR(AB31/AB$5,0) -> 0 | AF31: =SUM(START:END!AF33:AF33) -> 0 | AG31: =IFERROR(AF31/AF$17,0) -> 0 | AH31: =IFERROR(AF31/AF$6,0) -> 0 | AI31: =IFERROR(AF31/AF$5,0) -> 0 | AJ31: =SUM(START:END!AJ33:AJ33) -> 0 | AK31: =IFERROR(AJ31/AJ$17,0) -> 0 | AL31: =IFERROR(AJ31/AJ$6,0) -> 0 | AM31: =IFERROR(AJ31/AJ$5,0) -> 0 | AN31: =SUM(START:END!AN33:AN33) -> 0 | AO31: =IFERROR(AN31/AN$17,0) -> 0 | AP31: =IFERROR(AN31/AN$6,0) -> 0 | AQ31: =IFERROR(AN31/AN$5,0) -> 0
C32: Franchise Fees | D32: =SUM(START:END!D34:D34) -> 0 | E32: =IFERROR(D32/D$17,0) -> 0 | F32: =IFERROR(D32/D$6,0) -> 0 | G32: =IFERROR(D32/D$5,0) -> 0 | H32: =SUM(START:END!H34:H34) -> 0 | I32: =IFERROR(H32/H$17,0) -> 0 | J32: =IFERROR(H32/H$6,0) -> 0 | K32: =IFERROR(H32/H$5,0) -> 0 | L32: =SUM(START:END!L34:L34) -> 0 | M32: =IFERROR(L32/L$17,0) -> 0 | N32: =IFERROR(L32/L$6,0) -> 0 | O32: =IFERROR(L32/L$5,0) -> 0 | P32: =SUM(START:END!P34:P34) -> 0 | Q32: =IFERROR(P32/P$17,0) -> 0 | R32: =IFERROR(P32/P$6,0) -> 0 | S32: =IFERROR(P32/P$5,0) -> 0 | T32: =SUM(START:END!T34:T34) -> 0 | U32: =IFERROR(T32/T$17,0) -> 0 | V32: =IFERROR(T32/T$6,0) -> 0 | W32: =IFERROR(T32/T$5,0) -> 0 | X32: =SUM(START:END!X34:X34) -> 0 | Y32: =IFERROR(X32/X$17,0) -> 0 | Z32: =IFERROR(X32/X$6,0) -> 0 | AA32: =IFERROR(X32/X$5,0) -> 0 | AB32: =SUM(START:END!AB34:AB34) -> 0 | AC32: =IFERROR(AB32/AB$17,0) -> 0 | AD32: =IFERROR(AB32/AB$6,0) -> 0 | AE32: =IFERROR(AB32/AB$5,0) -> 0 | AF32: =SUM(START:END!AF34:AF34) -> 0 | AG32: =IFERROR(AF32/AF$17,0) -> 0 | AH32: =IFERROR(AF32/AF$6,0) -> 0 | AI32: =IFERROR(AF32/AF$5,0) -> 0 | AJ32: =SUM(START:END!AJ34:AJ34) -> 0 | AK32: =IFERROR(AJ32/AJ$17,0) -> 0 | AL32: =IFERROR(AJ32/AJ$6,0) -> 0 | AM32: =IFERROR(AJ32/AJ$5,0) -> 0 | AN32: =SUM(START:END!AN34:AN34) -> 0 | AO32: =IFERROR(AN32/AN$17,0) -> 0 | AP32: =IFERROR(AN32/AN$6,0) -> 0 | AQ32: =IFERROR(AN32/AN$5,0) -> 0
C33: Property Ops./R&M | D33: =SUM(START:END!D35:D35) -> 0 | E33: =IFERROR(D33/D$17,0) -> 0 | F33: =IFERROR(D33/D$6,0) -> 0 | G33: =IFERROR(D33/D$5,0) -> 0 | H33: =SUM(START:END!H35:H35) -> 0 | I33: =IFERROR(H33/H$17,0) -> 0 | J33: =IFERROR(H33/H$6,0) -> 0 | K33: =IFERROR(H33/H$5,0) -> 0 | L33: =SUM(START:END!L35:L35) -> 0 | M33: =IFERROR(L33/L$17,0) -> 0 | N33: =IFERROR(L33/L$6,0) -> 0 | O33: =IFERROR(L33/L$5,0) -> 0 | P33: =SUM(START:END!P35:P35) -> 0 | Q33: =IFERROR(P33/P$17,0) -> 0 | R33: =IFERROR(P33/P$6,0) -> 0 | S33: =IFERROR(P33/P$5,0) -> 0 | T33: =SUM(START:END!T35:T35) -> 0 | U33: =IFERROR(T33/T$17,0) -> 0 | V33: =IFERROR(T33/T$6,0) -> 0 | W33: =IFERROR(T33/T$5,0) -> 0 | X33: =SUM(START:END!X35:X35) -> 0 | Y33: =IFERROR(X33/X$17,0) -> 0 | Z33: =IFERROR(X33/X$6,0) -> 0 | AA33: =IFERROR(X33/X$5,0) -> 0 | AB33: =SUM(START:END!AB35:AB35) -> 0 | AC33: =IFERROR(AB33/AB$17,0) -> 0 | AD33: =IFERROR(AB33/AB$6,0) -> 0 | AE33: =IFERROR(AB33/AB$5,0) -> 0 | AF33: =SUM(START:END!AF35:AF35) -> 0 | AG33: =IFERROR(AF33/AF$17,0) -> 0 | AH33: =IFERROR(AF33/AF$6,0) -> 0 | AI33: =IFERROR(AF33/AF$5,0) -> 0 | AJ33: =SUM(START:END!AJ35:AJ35) -> 0 | AK33: =IFERROR(AJ33/AJ$17,0) -> 0 | AL33: =IFERROR(AJ33/AJ$6,0) -> 0 | AM33: =IFERROR(AJ33/AJ$5,0) -> 0 | AN33: =SUM(START:END!AN35:AN35) -> 0 | AO33: =IFERROR(AN33/AN$17,0) -> 0 | AP33: =IFERROR(AN33/AN$6,0) -> 0 | AQ33: =IFERROR(AN33/AN$5,0) -> 0
C34: Utilities | D34: =SUM(START:END!D36:D36) -> 0 | E34: =IFERROR(D34/D$17,0) -> 0 | F34: =IFERROR(D34/D$6,0) -> 0 | G34: =IFERROR(D34/D$5,0) -> 0 | H34: =SUM(START:END!H36:H36) -> 0 | I34: =IFERROR(H34/H$17,0) -> 0 | J34: =IFERROR(H34/H$6,0) -> 0 | K34: =IFERROR(H34/H$5,0) -> 0 | L34: =SUM(START:END!L36:L36) -> 0 | M34: =IFERROR(L34/L$17,0) -> 0 | N34: =IFERROR(L34/L$6,0) -> 0 | O34: =IFERROR(L34/L$5,0) -> 0 | P34: =SUM(START:END!P36:P36) -> 0 | Q34: =IFERROR(P34/P$17,0) -> 0 | R34: =IFERROR(P34/P$6,0) -> 0 | S34: =IFERROR(P34/P$5,0) -> 0 | T34: =SUM(START:END!T36:T36) -> 0 | U34: =IFERROR(T34/T$17,0) -> 0 | V34: =IFERROR(T34/T$6,0) -> 0 | W34: =IFERROR(T34/T$5,0) -> 0 | X34: =SUM(START:END!X36:X36) -> 0 | Y34: =IFERROR(X34/X$17,0) -> 0 | Z34: =IFERROR(X34/X$6,0) -> 0 | AA34: =IFERROR(X34/X$5,0) -> 0 | AB34: =SUM(START:END!AB36:AB36) -> 0 | AC34: =IFERROR(AB34/AB$17,0) -> 0 | AD34: =IFERROR(AB34/AB$6,0) -> 0 | AE34: =IFERROR(AB34/AB$5,0) -> 0 | AF34: =SUM(START:END!AF36:AF36) -> 0 | AG34: =IFERROR(AF34/AF$17,0) -> 0 | AH34: =IFERROR(AF34/AF$6,0) -> 0 | AI34: =IFERROR(AF34/AF$5,0) -> 0 | AJ34: =SUM(START:END!AJ36:AJ36) -> 0 | AK34: =IFERROR(AJ34/AJ$17,0) -> 0 | AL34: =IFERROR(AJ34/AJ$6,0) -> 0 | AM34: =IFERROR(AJ34/AJ$5,0) -> 0 | AN34: =SUM(START:END!AN36:AN36) -> 0 | AO34: =IFERROR(AN34/AN$17,0) -> 0 | AP34: =IFERROR(AN34/AN$6,0) -> 0 | AQ34: =IFERROR(AN34/AN$5,0) -> 0
C35: TOTAL UNDISTRIBUTED EXPENSES | D35: =SUM(D28:D34) -> 0 | E35: =IFERROR(D35/D$17,0) -> 0 | F35: =IFERROR(D35/D$6,0) -> 0 | G35: =IFERROR(D35/D$5,0) -> 0 | H35: =SUM(H28:H34) -> 0 | I35: =IFERROR(H35/H$17,0) -> 0 | J35: =IFERROR(H35/H$6,0) -> 0 | K35: =IFERROR(H35/H$5,0) -> 0 | L35: =SUM(L28:L34) -> 0 | M35: =IFERROR(L35/L$17,0) -> 0 | N35: =IFERROR(L35/L$6,0) -> 0 | O35: =IFERROR(L35/L$5,0) -> 0 | P35: =SUM(P28:P34) -> 0 | Q35: =IFERROR(P35/P$17,0) -> 0 | R35: =IFERROR(P35/P$6,0) -> 0 | S35: =IFERROR(P35/P$5,0) -> 0 | T35: =SUM(T28:T34) -> 0 | U35: =IFERROR(T35/T$17,0) -> 0 | V35: =IFERROR(T35/T$6,0) -> 0 | W35: =IFERROR(T35/T$5,0) -> 0 | X35: =SUM(X28:X34) -> 0 | Y35: =IFERROR(X35/X$17,0) -> 0 | Z35: =IFERROR(X35/X$6,0) -> 0 | AA35: =IFERROR(X35/X$5,0) -> 0 | AB35: =SUM(AB28:AB34) -> 0 | AC35: =IFERROR(AB35/AB$17,0) -> 0 | AD35: =IFERROR(AB35/AB$6,0) -> 0 | AE35: =IFERROR(AB35/AB$5,0) -> 0 | AF35: =SUM(AF28:AF34) -> 0 | AG35: =IFERROR(AF35/AF$17,0) -> 0 | AH35: =IFERROR(AF35/AF$6,0) -> 0 | AI35: =IFERROR(AF35/AF$5,0) -> 0 | AJ35: =SUM(AJ28:AJ34) -> 0 | AK35: =IFERROR(AJ35/AJ$17,0) -> 0 | AL35: =IFERROR(AJ35/AJ$6,0) -> 0 | AM35: =IFERROR(AJ35/AJ$5,0) -> 0 | AN35: =SUM(AN28:AN34) -> 0 | AO35: =IFERROR(AN35/AN$17,0) -> 0 | AP35: =IFERROR(AN35/AN$6,0) -> 0 | AQ35: =IFERROR(AN35/AN$5,0) -> 0
