Workbook

Sheet Cover
B4: SSP LOAN POOL MODEL
B6: Stratification package, individual loan runs and levered returns
B8: Illustrative sample loan tape. Replace with the live deal data.
B12: HOW THE MODEL WORKS
B13: • | C13: The Loan Tape is the single source of data. Nothing else on the model holds loan level hardcodes.
B14: • | C14: The Assumptions tab holds every lever. One scenario switch moves purchase price, advance rate, financing spread, credit, prepayment and the index curve together.
B15: • | C15: The Loan CF tab runs each loan on its own through an annual cash flow, so the pool result is the sum of the individual loan runs rather than a weighted average approximation.
B16: • | C16: The Loan Runs tab shows the outcome of each loan run side by side and aggregates them. The Pool Returns tab layers pool level fees and the financing facility on top to give the levered equity return.
B17: • | C17: Six tie out checks at the foot of the Pool Returns tab prove the aggregation, the sources and uses and the balance roll forward.
B19: CONTENTS
B20: Tab | D20: What it does | E20: Type
B21: Assumptions | D21: Every lever in one place. Scenario grid with a downside, base and upside column and a single switch that drives the whole model, plus the forward index curve. | E21: Input
B22: Loan Tape | D22: Loan level data for up to 300 loans. Columns A to AM are the strat feed. Columns AN to BE are the pricing and financing feed the returns engine reads. | E22: Input and calculation
B23: Strats | D23: Portfolio wide stratification package across 27 dimensions with tie out checks. Unchanged in structure from the original build. | E23: Output
B24: Deal Strat | D24: The same package filtered to one underlying deal, selected on that tab. | E24: Output
B25: Loan Runs | D25: One row per loan: purchase price, basis, collections, credit loss, unlevered and levered IRR and MOIC, with a total and weighted average row. Includes a single loan drill down. | E25: Output
B26: Loan CF | D26: The engine. Annual cash flows for every loan, one block per line item, from beginning balance through levered equity cash flow. | E26: Calculation
B27: Pool Returns | D27: Sources and uses at close, the aggregated pool cash flow, unlevered and levered returns, three sensitivity grids and six tie out checks. | E27: Output
B29: LEGEND, FONT COLOR SHOWS HOW A NUMBER GOT INTO A CELL
B30: Color | D30: Meaning
B31: Green text | C31: 1,234 | D31: Hardcoded input typed on that sheet. These are the only cells to change.
B32: Blue text | C32: 1,234 | D32: Link to another cell or another tab.
B33: Purple text | C33: 1,234 | D33: Hardcode carried in from another schedule.
B34: Black text | C34: 1,234 | D34: Calculated on that sheet.
B36: LEGEND, FILL COLOR
B37: Color | D37: Meaning
B38: Dark navy | D38: Header rows, banner bars and total or weighted average rows.
B39: Light blue | D39: Section labels, the active case column and the live cell in a sensitivity grid.
B40: Light gray | D40: Row banding and label columns.
B41: Light red | D41: Downside sensitivity cells and failed checks.
B42: Light green | D42: Upside sensitivity cells and passed checks.
B45: Source: loan level fields are the illustrative sample tape carried over from the original strats file. Purchase price, financing terms, credit and prepayment assumptions are user inputs and carry no external source. Replace the forward index curve on the Assumptions tab with the live curve at pricing.

Sheet Assumptions
B2: TRANSACTION, FINANCING AND RETURN ASSUMPTIONS
B4: Active Scenario (1 = Downside, 2 = Base, 3 = Upside) | C4: 2
B5: Active Scenario | C5: =CHOOSE(Scen,"Downside","Base","Upside") -> Base
B6: Green cells are inputs. Black cells are calculated. Blue cells link to another tab. Every assumption below feeds the loan level engine on the Loan CF tab.
B8: Assumption | C8: Downside | D8: Base | E8: Upside | F8: Active Case | H8: Basis and Note
B9: TRANSACTION AND POOL SCOPE
B10: As-Of / Settlement Date | C10: n/a | D10: 46295 | E10: n/a | F10: =D10 -> 46295 | H10: Drives seasoning, remaining term and the strat tie outs on the Strats tab.
B11: Deal Scope Purchased | C11: n/a | D11: All Deals | E11: n/a | F11: =D11 -> All Deals | H11: All Deals buys the entire tape. Selecting a single deal restricts the purchase to that deal and reprices the pool accordingly.
B12: Hold Period (Years, integer 1 to 10) | C12: 5 | D12: 5 | E12: 5 | F12: =CHOOSE(Scen,C12,D12,E12) -> 5 | H12: Sets the exit year. Residual balance is sold at the exit price in this year.
B13: Purchase Price (% of Par) | C13: 0.9 | D13: 0.94 | E13: 0.97 | F13: =CHOOSE(Scen,C13,D13,E13) -> 0.94 | H13: Applied to Current UPB on every loan in scope. Discount to par accretes through the hold period.
B14: Accrued Interest Purchased (% of Par) | C14: n/a | D14: 0.0015 | E14: n/a | F14: =D14 -> 0.0015 | H14: Day count accrual paid to the seller at settlement. Part of basis, not of purchase price.
B15: Acquisition and Diligence Costs (% of Purchase Price) | C15: n/a | D15: 0.0075 | E15: n/a | F15: =D15 -> 0.0075 | H15: Legal, third party reports, servicer onboarding and transfer costs.
B16: Exit Price (% of Par on Residual Balance) | C16: 0.93 | D16: 0.97 | E16: 1 | F16: =CHOOSE(Scen,C16,D16,E16) -> 0.97 | H16: Applied to the performing balance still outstanding at the end of the hold period.
B17: Exit / Disposition Costs (% of Exit Proceeds) | C17: n/a | D17: 0.005 | E17: n/a | F17: =D17 -> 0.005 | H17: Broker, legal and transfer costs on the residual sale.
B18: FINANCING STRUCTURE
B19: Financing Used (Yes / No) | C19: n/a | D19: Yes | E19: n/a | F19: =D19 -> Yes | H19: Set to No for an all equity purchase. Levered and unlevered returns converge when this is No.
B20: Financing Structure | C20: n/a | D20: Repo Facility | E20: n/a | F20: =D20 -> Repo Facility | H20: Label only. The economics are driven by advance rate, spread, fees and sweep below.
B21: Advance Rate (% of Purchase Price) | C21: 0.5 | D21: 0.6 | E21: 0.65 | F21: =CHOOSE(Scen,C21,D21,E21) -> 0.6 | H21: Facility size at close. Advance is struck off purchase price, not par.
B22: Financing Spread over Index (bps) | C22: 325 | D22: 250 | E22: 225 | F22: =CHOOSE(Scen,C22,D22,E22) -> 250 | H22: Added to the active index curve to give the all in cost of debt by year.
B23: Upfront Financing Fee (% of Facility) | C23: n/a | D23: 0.005 | E23: n/a | F23: =D23 -> 0.005 | H23: Structuring and commitment fee funded at close out of equity.
B24: Exit / Termination Fee (% of Facility) | C24: n/a | D24: 0.0025 | E24: n/a | F24: =D24 -> 0.0025 | H24: Charged on facility amounts as they are repaid, so the whole fee is paid by the time the facility is retired.
B25: Cash Sweep to Debt (% of Principal Collections) | C25: 1 | D25: 1 | E25: 0.85 | F25: =CHOOSE(Scen,C25,D25,E25) -> 1 | H25: Share of principal, payoff and recovery proceeds applied to the facility before equity is released.
B26: Financing Term (Years) | C26: n/a | D26: 5 | E26: n/a | F26: =D26 -> 5 | H26: Facility must be fully repaid by the earlier of this year and the hold period.
B27: Debt Repayment Year (Model) | C27: n/a | D27: n/a | E27: n/a | F27: =MIN(Hold_Yrs,Fin_Term) -> 5 | H27: The facility is swept to zero in this year and the exit fee is charged.
B28: All in Cost of Debt, Year 1 (%) | C28: n/a | D28: n/a | E28: n/a | F28: =IF(Fin_Flag="Yes",INDEX(Fin_Curve,1,1),0) -> 0.07 | H28: Active index curve in Year 1 plus the financing spread.
B29: FEES AND ONGOING COSTS
B30: Servicing and Special Servicing Fee (bps on Avg. Balance) | C30: n/a | D30: 15 | E30: n/a | F30: =D30 -> 15 | H30: Charged at the pool level on the average performing balance each year.
B31: Asset Management Fee (bps on Invested Equity) | C31: n/a | D31: 100 | E31: n/a | F31: =D31 -> 100 | H31: Charged at the pool level on equity funded at close for each year of the hold period.
B32: Annual Fixed and Administrative Costs ($) | C32: n/a | D32: 250000 | E32: n/a | F32: =D32 -> 250000 | H32: Audit, admin, custody and reporting. Charged at the pool level.
B33: CREDIT
B34: CDR, Annual Default Rate (% of Performing Balance) | C34: 0.04 | D34: 0.02 | E34: 0.01 | F34: =CHOOSE(Scen,C34,D34,E34) -> 0.02 | H34: Applied to the beginning performing balance of each loan each year.
B35: Loss Severity (% of Defaulted Balance) | C35: 0.45 | D35: 0.3 | E35: 0.2 | F35: =CHOOSE(Scen,C35,D35,E35) -> 0.3 | H35: One minus severity is recovered in cash after the recovery lag below.
B36: Recovery Lag (Years, integer) | C36: n/a | D36: 1 | E36: n/a | F36: =D36 -> 1 | H36: Whole years between default and receipt of recovery proceeds. Recoveries still in the pipeline at exit are valued in the exit proceeds.
B37: PREPAYMENT AND EXTENSION
B38: CPR, Annual Prepayment Rate (% of Performing Balance) | C38: 0.05 | D38: 0.1 | E38: 0.15 | F38: =CHOOSE(Scen,C38,D38,E38) -> 0.1 | H38: Voluntary prepayment on the performing balance in each year before maturity.
B39: Prepayment Penalty Captured (% of Prepaid Balance) | C39: n/a | D39: 0.01 | E39: n/a | F39: =D39 -> 0.01 | H39: Blended yield maintenance and exit fee capture across the tape.
B40: Assume Extension Options Exercised (Yes / No) | C40: n/a | D40: Yes | E40: n/a | F40: =D40 -> Yes | H40: When Yes, every loan flagged with an extension option in the tape gets the extension length added to its remaining term.
B41: Extension Length (Months) | C41: n/a | D41: 12 | E41: n/a | F41: =D41 -> 12 | H41: Added to remaining term for loans with an extension option.
B42: AMORTIZATION
B43: Assumed Amortization Term for Amortizing Loans (Years) | C43: n/a | D43: 30 | E43: n/a | F43: =D43 -> 30 | H43: Full amortizing and partial IO loans amortize on this schedule once the IO period rolls off.
...

Sheet Loan Tape
A1: LOAN TAPE — [NEW DEAL NAME] (illustrative sample data shown)
A2: Rows 4-53 below are 50 illustrative sample loans for demonstration only — replace with your new deal's actual loan-level data. Green cells are hardcoded inputs; black cells are formulas (Seasoning, Coupon (Current), IO Remaining, Coupon at Reset) — leave them as is. If a loan sits in more than one underlying deal, tag it in the Underlying Deal column, then relabel the placeholder deal names on the Strats tab. | AN2: Columns AN to BE are the pricing and financing engine feed. Every one is a formula driven by the Assumptions tab. Do not type over them.
A3: Loan ID | B3: Loan / Property Name | C3: State | D3: Property Type | E3: Underlying Deal | F3: Number of Units | G3: Origination Date | H3: Maturity Date | I3: Original Term (Months) | J3: IO Term (Months) | K3: Rate Type | L3: Fixed Coupon (if Fixed) | M3: Floating Rate Spread | N3: Reset Frequency | O3: Next Reset Date | P3: Rate Cap (if Floating) | Q3: Rate Floor (if Floating) | R3: Current UPB | S3: Occupancy | T3: NOI Debt Yield (Most Recent) | U3: DSCR (Most Recent) | V3: LTV (Most Recent) | W3: SSP / Underwritten LTV | X3: Year Built | Y3: Year Renovated | Z3: Amortization Type | AA3: Extension Option | AB3: Prepayment Protection | AC3: Lien Position | AD3: Sponsor Type | AE3: Loan Purpose | AF3: Delinquency Status | AG3: Ownership Interest | AH3: Seasoning (Months) | AI3: Coupon (Current) | AJ3: IO Remaining (Months) | AK3: Coupon at Reset (Stress) | AL3: Rank within Selected Deal | AM3: Rank (by UPB) | AN3: Include in Purchase (1 / 0) | AO3: Purchase Price (% of Par) | AP3: Remaining Term to Maturity (Mos) | AQ3: Extension Months Added | AR3: Effective Term (Mos) | AS3: Effective Term (Yrs) | AT3: IO Remaining (Yrs) | AU3: Amort. Term Remaining (Yrs) | AV3: Model End Year (Maturity vs. Hold) | AW3: Maturity Year (Model) | AX3: Matures within Hold (1 / 0) | AY3: Purchase Price ($) | AZ3: Accrued Interest ($) | BA3: Acquisition Costs ($) | BB3: Total Basis ($) | BC3: Debt Allocated ($) | BD3: Financing Fees ($) | BE3: Equity Allocated ($)
A4: L-001 | B4: Oceanview Plaza | C4: TX | D4: Retail | E4: Deal 4 | G4: 42826 | H4: 45383 | I4: 83 | J4: 24 | K4: Floating | M4: 0.0373 | N4: Monthly | O4: 46325 | P4: 0.0956 | R4: 8155000 | S4: 0.99 | T4: 0.0792 | U4: 1.38 | V4: 0.556 | W4: 0.574 | X4: 2013 | Y4: 2020 | Z4: Partial IO | AA4: Yes | AB4: Freely Prepayable | AC4: First Lien | AD4: PE Fund | AE4: Acquisition | AF4: Current | AG4: Fee Simple | AH4: =IF(G4="",0,ROUND((Strats!$C$4-G4)/30.4375,1)) -> 114 | AI4: =IF(K4="",0,IF(K4="Floating",Strats!$C$10+M4,L4)) -> 0.0823 | AJ4: =IF(OR(Z4="",Z4="Full Amortizing"),"",MAX(J4-AH4,0)) -> 0 | AK4: =IF(K4="",0,IF(K4="Floating",IF(P4<>"",MIN(IF(Q4<>"",MAX((Strats!$C$10+Strats!$C$11+M4),Q4),(Strats!$C$10+Strats!$C$11+M4)),P4),IF(Q4<>"",MAX((Strats!$C$10+Strats!$C$11+M4),Q4),(Strats!$C$10+Strats!$C$11+M4))),AI4)) -> 0.0956 | AL4: =IF(OR(E4="",E4<>'Deal Strat'!$C$12,R4=""),"",SUMPRODUCT((E$4:E$303='Deal Strat'!$C$12)*(R$4:R$303>R4))+1+SUMPRODUCT((E$4:E$303='Deal Strat'!$C$12)*(R$4:R$303=R4)*(ROW(R$4:R$303)<ROW(R4)))) | AM4: =IF(R4="","",RANK(R4,$R$4:$R$303,0)+COUNTIF($R$4:R4,R4)-1) -> 42 | AN4: =IF(OR($A4="",$R4=""),0,IF(Deal_Scope="All Deals",1,IF($E4=Deal_Scope,1,0))) -> 1 | AO4: =IF($AN4=0,0,Px_Par) -> 0.94 | AP4: =IF($H4="",0,MAX(0,($H4-Set_Date)/30.4375)) -> 0 | AQ4: =IF(AND(Ext_Flag="Yes",$AA4="Yes"),Ext_Months,0) -> 12 | AR4: =$AP4+$AQ4 -> 12 | AS4: =$AR4/12 -> 1 | AT4: =IF($AJ4="",0,MAX(0,$AJ4/12)) -> 0 | AU4: =MAX(Amort_Min,Amort_Term-$AH4/12) -> 20.5 | AV4: =MIN($AS4,Hold_Yrs) -> 1 | AW4: =IF($AN4=0,0,CEILING(MAX($AS4,0.0001),1)) -> 1 | AX4: =IF(AND($AN4=1,MAX($AS4,0.0001)<=Hold_Yrs),1,0) -> 1 | AY4: =$R4*$AO4 -> 7665700 | AZ4: =$R4*Acc_Int*$AN4 -> 12232.5 | BA4: =$AY4*Acq_Cost -> 57492.75 | BB4: =$AY4+$AZ4+$BA4 -> 7735425.2 | BC4: =IF(Fin_Flag="Yes",$AY4*Adv_Rate,0) -> 4599420 | BD4: =$BC4*Fin_UpFee -> 22997.1 | BE4: =$BB4-$BC4+$BD4 -> 3159002.4
A5: L-002 | B5: Chandler Resort | C5: FL | D5: Hotel | E5: Deal 6 | G5: 42917 | H5: 46569 | I5: 121 | J5: 36 | K5: Floating | M5: 0.0224 | N5: Monthly | O5: 46355 | P5: 0.1078 | R5: 10687000 | S5: 0.857 | T5: 0.0834 | U5: 1.21 | V5: 0.589 | W5: 0.618 | X5: 2005 | Z5: Partial IO | AA5: Yes | AB5: Prepayable with Penalty | AC5: First Lien | AD5: PE Fund | AE5: Refinance | AF5: Current | AG5: Fee Simple | AH5: =IF(G5="",0,ROUND((Strats!$C$4-G5)/30.4375,1)) -> 111 | AI5: =IF(K5="",0,IF(K5="Floating",Strats!$C$10+M5,L5)) -> 0.0674 | AJ5: =IF(OR(Z5="",Z5="Full Amortizing"),"",MAX(J5-AH5,0)) -> 0 | AK5: =IF(K5="",0,IF(K5="Floating",IF(P5<>"",MIN(IF(Q5<>"",MAX((Strats!$C$10+Strats!$C$11+M5),Q5),(Strats!$C$10+Strats!$C$11+M5)),P5),IF(Q5<>"",MAX((Strats!$C$10+Strats!$C$11+M5),Q5),(Strats!$C$10+Strats!$C$11+M5))),AI5)) -> 0.0824 | AL5: =IF(OR(E5="",E5<>'Deal Strat'!$C$12,R5=""),"",SUMPRODUCT((E$4:E$303='Deal Strat'!$C$12)*(R$4:R$303>R5))+1+SUMPRODUCT((E$4:E$303='Deal Strat'!$C$12)*(R$4:R$303=R5)*(ROW(R$4:R$303)<ROW(R5)))) | AM5: =IF(R5="","",RANK(R5,$R$4:$R$303,0)+COUNTIF($R$4:R5,R5)-1) -> 38 | AN5: =IF(OR($A5="",$R5=""),0,IF(Deal_Scope="All Deals",1,IF($E5=Deal_Scope,1,0))) -> 1 | AO5: =IF($AN5=0,0,Px_Par) -> 0.94 | AP5: =IF($H5="",0,MAX(0,($H5-Set_Date)/30.4375)) -> 9.0020534 | AQ5: =IF(AND(Ext_Flag="Yes",$AA5="Yes"),Ext_Months,0) -> 12 | AR5: =$AP5+$AQ5 -> 21.002053 | AS5: =$AR5/12 -> 1.7501711 | AT5: =IF($AJ5="",0,MAX(0,$AJ5/12)) -> 0 | AU5: =MAX(Amort_Min,Amort_Term-$AH5/12) -> 20.75 | AV5: =MIN($AS5,Hold_Yrs) -> 1.7501711 | AW5: =IF($AN5=0,0,CEILING(MAX($AS5,0.0001),1)) -> 2 | AX5: =IF(AND($AN5=1,MAX($AS5,0.0001)<=Hold_Yrs),1,0) -> 1 | AY5: =$R5*$AO5 -> 10045780 | AZ5: =$R5*Acc_Int*$AN5 -> 16030.5 | BA5: =$AY5*Acq_Cost -> 75343.35 | BB5: =$AY5+$AZ5+$BA5 -> 10137154 | BC5: =IF(Fin_Flag="Yes",$AY5*Adv_Rate,0) -> 6027468 | BD5: =$BC5*Fin_UpFee -> 30137.34 | BE5: =$BB5-$BC5+$BD5 -> 4139823.2
A6: L-003 | B6: Deerfield Terrace | C6: CO | D6: Multifamily | E6: Deal 7 | F6: 409 | G6: 44713 | H6: 47270 | I6: 84 | J6: 12 | K6: Floating | M6: 0.0384 | N6: Quarterly | O6: 46295 | R6: 119229000 | S6: 0.871 | T6: 0.036 | U6: 1.41 | V6: 0.931 | W6: 0.967 | X6: 2000 | Z6: Partial IO | AA6: Yes | AB6: Defeasance | AC6: First Lien | AD6: Institutional Owner/Operator | AE6: Acquisition | AF6: Current | AG6: Fee Simple | AH6: =IF(G6="",0,ROUND((Strats!$C$4-G6)/30.4375,1)) -> 52 | AI6: =IF(K6="",0,IF(K6="Floating",Strats!$C$10+M6,L6)) -> 0.0834 | AJ6: =IF(OR(Z6="",Z6="Full Amortizing"),"",MAX(J6-AH6,0)) -> 0 | AK6: =IF(K6="",0,IF(K6="Floating",IF(P6<>"",MIN(IF(Q6<>"",MAX((Strats!$C$10+Strats!$C$11+M6),Q6),(Strats!$C$10+Strats!$C$11+M6)),P6),IF(Q6<>"",MAX((Strats!$C$10+Strats!$C$11+M6),Q6),(Strats!$C$10+Strats!$C$11+M6))),AI6)) -> 0.0984 | AL6: =IF(OR(E6="",E6<>'Deal Strat'!$C$12,R6=""),"",SUMPRODUCT((E$4:E$303='Deal Strat'!$C$12)*(R$4:R$303>R6))+1+SUMPRODUCT((E$4:E$303='Deal Strat'!$C$12)*(R$4:R$303=R6)*(ROW(R$4:R$303)<ROW(R6)))) | AM6: =IF(R6="","",RANK(R6,$R$4:$R$303,0)+COUNTIF($R$4:R6,R6)-1) -> 5 | AN6: =IF(OR($A6="",$R6=""),0,IF(Deal_Scope="All Deals",1,IF($E6=Deal_Scope,1,0))) -> 1 | AO6: =IF($AN6=0,0,Px_Par) -> 0.94 | AP6: =IF($H6="",0,MAX(0,($H6-Set_Date)/30.4375)) -> 32.032854 | AQ6: =IF(AND(Ext_Flag="Yes",$AA6="Yes"),Ext_Months,0) -> 12 | AR6: =$AP6+$AQ6 -> 44.032854 | AS6: =$AR6/12 -> 3.6694045 | AT6: =IF($AJ6="",0,MAX(0,$AJ6/12)) -> 0 | AU6: =MAX(Amort_Min,Amort_Term-$AH6/12) -> 25.666667 | AV6: =MIN($AS6,Hold_Yrs) -> 3.6694045 | AW6: =IF($AN6=0,0,CEILING(MAX($AS6,0.0001),1)) -> 4 | AX6: =IF(AND($AN6=1,MAX($AS6,0.0001)<=Hold_Yrs),1,0) -> 1 | AY6: =$R6*$AO6 -> 112075260 | AZ6: =$R6*Acc_Int*$AN6 -> 178843.5 | BA6: =$AY6*Acq_Cost -> 840564.45 | BB6: =$AY6+$AZ6+$BA6 -> 1.1309467e+08 | BC6: =IF(Fin_Flag="Yes",$AY6*Adv_Rate,0) -> 67245156 | BD6: =$BC6*Fin_UpFee -> 336225.78 | BE6: =$BB6-$BC6+$BD6 -> 46185738
A7: L-004 | B7: Riverwalk Plaza | C7: NV | D7: Office | E7: Deal 3 | G7: 43344 | H7: 46997 | I7: 120 | J7: 60 | K7: Floating | M7: 0.0185 | N7: Quarterly | O7: 46325 | P7: 0.0834 | R7: 46042000 | S7: 0.99 | T7: 0.1073 | U7: 1.62 | V7: 0.357 | W7: 0.394 | X7: 1973 | Y7: 1993 | Z7: Partial IO | AA7: No | AB7: Prepayable with Penalty | AC7: First Lien | AD7: Institutional Owner/Operator | AE7: Recapitalization | AF7: Matured | AG7: Fee Simple | AH7: =IF(G7="",0,ROUND((Strats!$C$4-G7)/30.4375,1)) -> 97 | AI7: =IF(K7="",0,IF(K7="Floating",Strats!$C$10+M7,L7)) -> 0.0635 | AJ7: =IF(OR(Z7="",Z7="Full Amortizing"),"",MAX(J7-AH7,0)) -> 0 | AK7: =IF(K7="",0,IF(K7="Floating",IF(P7<>"",MIN(IF(Q7<>"",MAX((Strats!$C$10+Strats!$C$11+M7),Q7),(Strats!$C$10+Strats!$C$11+M7)),P7),IF(Q7<>"",MAX((Strats!$C$10+Strats!$C$11+M7),Q7),(Strats!$C$10+Strats!$C$11+M7))),AI7)) -> 0.0785 | AL7: =IF(OR(E7="",E7<>'Deal Strat'!$C$12,R7=""),"",SUMPRODUCT((E$4:E$303='Deal Strat'!$C$12)*(R$4:R$303>R7))+1+SUMPRODUCT((E$4:E$303='Deal Strat'!$C$12)*(R$4:R$303=R7)*(ROW(R$4:R$303)<ROW(R7)))) | AM7: =IF(R7="","",RANK(R7,$R$4:$R$303,0)+COUNTIF($R$4:R7,R7)-1) -> 23 | AN7: =IF(OR($A7="",$R7=""),0,IF(Deal_Scope="All Deals",1,IF($E7=Deal_Scope,1,0))) -> 1 | AO7: =IF($AN7=0,0,Px_Par) -> 0.94 | AP7: =IF($H7="",0,MAX(0,($H7-Set_Date)/30.4375)) -> 23.063655 | AQ7: =IF(AND(Ext_Flag="Yes",$AA7="Yes"),Ext_Months,0) -> 0 | AR7: =$AP7+$AQ7 -> 23.063655 | AS7: =$AR7/12 -> 1.9219713 | AT7: =IF($AJ7="",0,MAX(0,$AJ7/12)) -> 0 | AU7: =MAX(Amort_Min,Amort_Term-$AH7/12) -> 21.916667 | AV7: =MIN($AS7,Hold_Yrs) -> 1.9219713 | AW7: =IF($AN7=0,0,CEILING(MAX($AS7,0.0001),1)) -> 2 | AX7: =IF(AND($AN7=1,MAX($AS7,0.0001)<=Hold_Yrs),1,0) -> 1 | AY7: =$R7*$AO7 -> 43279480 | AZ7: =$R7*Acc_Int*$AN7 -> 69063 | BA7: =$AY7*Acq_Cost -> 324596.1 | BB7: =$AY7+$AZ7+$BA7 -> 43673139 | BC7: =IF(Fin_Flag="Yes",$AY7*Adv_Rate,0) -> 25967688 | BD7: =$BC7*Fin_UpFee -> 129838.44 | BE7: =$BB7-$BC7+$BD7 -> 17835290
A8: L-005 | B8: Pinehurst Plaza | C8: WA | D8: Retail | E8: Deal 8 | G8: 43466 | H8: 45292 | I8: 60 | J8: 12 | K8: Fixed | L8: 0.0648 | N8: N/A | R8: 117696000 | S8: 0.96 | T8: 0.0782 | U8: 1.46 | V8: 0.587 | W8: 0.604 | X8: 2021 | Z8: Interest Only | AA8: Yes | AB8: Defeasance | AC8: First Lien | AD8: PE Fund | AE8: Refinance | AF8: Current | AG8: Fee Simple | AH8: =IF(G8="",0,ROUND((Strats!$C$4-G8)/30.4375,1)) -> 92.9 | AI8: =IF(K8="",0,IF(K8="Floating",Strats!$C$10+M8,L8)) -> 0.0648 | AJ8: =IF(OR(Z8="",Z8="Full Amortizing"),"",MAX(J8-AH8,0)) -> 0 | AK8: =IF(K8="",0,IF(K8="Floating",IF(P8<>"",MIN(IF(Q8<>"",MAX((Strats!$C$10+Strats!$C$11+M8),Q8),(Strats!$C$10+Strats!$C$11+M8)),P8),IF(Q8<>"",MAX((Strats!$C$10+Strats!$C$11+M8),Q8),(Strats!$C$10+Strats!$C$11+M8))),AI8)) -> 0.0648 | AL8: =IF(OR(E8="",E8<>'Deal Strat'!$C$12,R8=""),"",SUMPRODUCT((E$4:E$303='Deal Strat'!$C$12)*(R$4:R$303>R8))+1+SUMPRODUCT((E$4:E$303='Deal Strat'!$C$12)*(R$4:R$303=R8)*(ROW(R$4:R$303)<ROW(R8)))) | AM8: =IF(R8="","",RANK(R8,$R$4:$R$303,0)+COUNTIF($R$4:R8,R8)-1) -> 6 | AN8: =IF(OR($A8="",$R8=""),0,IF(Deal_Scope="All Deals",1,IF($E8=Deal_Scope,1,0))) -> 1 | AO8: =IF($AN8=0,0,Px_Par) -> 0.94 | AP8: =IF($H8="",0,MAX(0,($H8-Set_Date)/30.4375)) -> 0 | AQ8: =IF(AND(Ext_Flag="Yes",$AA8="Yes"),Ext_Months,0) -> 12 | AR8: =$AP8+$AQ8 -> 12 | AS8: =$AR8/12 -> 1 | AT8: =IF($AJ8="",0,MAX(0,$AJ8/12)) -> 0 | AU8: =MAX(Amort_Min,Amort_Term-$AH8/12) -> 22.258333 | AV8: =MIN($AS8,Hold_Yrs) -> 1 | AW8: =IF($AN8=0,0,CEILING(MAX($AS8,0.0001),1)) -> 1 | AX8: =IF(AND($AN8=1,MAX($AS8,0.0001)<=Hold_Yrs),1,0) -> 1 | AY8: =$R8*$AO8 -> 110634240 | AZ8: =$R8*Acc_Int*$AN8 -> 176544 | BA8: =$AY8*Acq_Cost -> 829756.8 | BB8: =$AY8+$AZ8+$BA8 -> 1.1164054e+08 | BC8: =IF(Fin_Flag="Yes",$AY8*Adv_Rate,0) -> 66380544 | BD8: =$BC8*Fin_UpFee -> 331902.72 | BE8: =$BB8-$BC8+$BD8 -> 45591900
A9: L-006 | B9: Keystone Distribution Center | C9: CA | D9: Industrial | E9: Deal 1 | G9: 43221 | H9: 46874 | I9: 120 | J9: 0 | K9: Floating | M9: 0.02 | N9: Quarterly | O9: 46355 | P9: 0.0978 | R9: 57608000 | S9: 0.94 | T9: 0.0853 | U9: 1.36 | V9: 0.572 | W9: 0.602 | X9: 1995 | Y9: 2012 | Z9: Full Amortizing | AA9: No | AB9: Prepayable with Penalty | AC9: First Lien | AD9: Institutional Owner/Operator | AE9: Recapitalization | AF9: Current | AG9: Fee Simple | AH9: =IF(G9="",0,ROUND((Strats!$C$4-G9)/30.4375,1)) -> 101 | AI9: =IF(K9="",0,IF(K9="Floating",Strats!$C$10+M9,L9)) -> 0.065 | AJ9: =IF(OR(Z9="",Z9="Full Amortizing"),"",MAX(J9-AH9,0)) | AK9: =IF(K9="",0,IF(K9="Floating",IF(P9<>"",MIN(IF(Q9<>"",MAX((Strats!$C$10+Strats!$C$11+M9),Q9),(Strats!$C$10+Strats!$C$11+M9)),P9),IF(Q9<>"",MAX((Strats!$C$10+Strats!$C$11+M9),Q9),(Strats!$C$10+Strats!$C$11+M9))),AI9)) -> 0.08 | AL9: =IF(OR(E9="",E9<>'Deal Strat'!$C$12,R9=""),"",SUMPRODUCT((E$4:E$303='Deal Strat'!$C$12)*(R$4:R$303>R9))+1+SUMPRODUCT((E$4:E$303='Deal Strat'!$C$12)*(R$4:R$303=R9)*(ROW(R$4:R$303)<ROW(R9)))) -> 4 | AM9: =IF(R9="","",RANK(R9,$R$4:$R$303,0)+COUNTIF($R$4:R9,R9)-1) -> 19 | AN9: =IF(OR($A9="",$R9=""),0,IF(Deal_Scope="All Deals",1,IF($E9=Deal_Scope,1,0))) -> 1 | AO9: =IF($AN9=0,0,Px_Par) -> 0.94 | AP9: =IF($H9="",0,MAX(0,($H9-Set_Date)/30.4375)) -> 19.022587 | AQ9: =IF(AND(Ext_Flag="Yes",$AA9="Yes"),Ext_Months,0) -> 0 | AR9: =$AP9+$AQ9 -> 19.022587 | AS9: =$AR9/12 -> 1.5852156 | AT9: =IF($AJ9="",0,MAX(0,$AJ9/12)) -> 0 | AU9: =MAX(Amort_Min,Amort_Term-$AH9/12) -> 21.583333 | AV9: =MIN($AS9,Hold_Yrs) -> 1.5852156 | AW9: =IF($AN9=0,0,CEILING(MAX($AS9,0.0001),1)) -> 2 | AX9: =IF(AND($AN9=1,MAX($AS9,0.0001)<=Hold_Yrs),1,0) -> 1 | AY9: =$R9*$AO9 -> 54151520 | AZ9: =$R9*Acc_Int*$AN9 -> 86412 | BA9: =$AY9*Acq_Cost -> 406136.4 | BB9: =$AY9+$AZ9+$BA9 -> 54644068 | BC9: =IF(Fin_Flag="Yes",$AY9*Adv_Rate,0) -> 32490912 | BD9: =$BC9*Fin_UpFee -> 162454.56 | BE9: =$BB9-$BC9+$BD9 -> 22315611
A10: L-007 | B10: Jasper Retail Center | C10: MD | D10: Retail | E10: Deal 3 | G10: 45170 | H10: 48823 | I10: 120 | J10: 120 | K10: Floating | M10: 0.0202 | N10: Monthly | O10: 46355 | P10: 0.1052 | R10: 4524000 | S10: 0.99 | T10: 0.08 | U10: 1.19 | V10: 0.644 | W10: 0.658 | X10: 2007 | Z10: Interest Only | AA10: Yes | AB10: Prepayable with Penalty | AC10: First Lien | AD10: Institutional Owner/Operator | AE10: Acquisition | AF10: Current | AG10: Fee Simple | AH10: =IF(G10="",0,ROUND((Strats!$C$4-G10)/30.4375,1)) -> 37 | AI10: =IF(K10="",0,IF(K10="Floating",Strats!$C$10+M10,L10)) -> 0.0652 | AJ10: =IF(OR(Z10="",Z10="Full Amortizing"),"",MAX(J10-AH10,0)) -> 83 | AK10: =IF(K10="",0,IF(K10="Floating",IF(P10<>"",MIN(IF(Q10<>"",MAX((Strats!$C$10+Strats!$C$11+M10),Q10),(Strats!$C$10+Strats!$C$11+M10)),P10),IF(Q10<>"",MAX((Strats!$C$10+Strats!$C$11+M10),Q10),(Strats!$C$10+Strats!$C$11+M10))),AI10)) -> 0.0802 | AL10: =IF(OR(E10="",E10<>'Deal Strat'!$C$12,R10=""),"",SUMPRODUCT((E$4:E$303='Deal Strat'!$C$12)*(R$4:R$303>R10))+1+SUMPRODUCT((E$4:E$303='Deal Strat'!$C$12)*(R$4:R$303=R10)*(ROW(R$4:R$303)<ROW(R10)))) | AM10: =IF(R10="","",RANK(R10,$R$4:$R$303,0)+COUNTIF($R$4:R10,R10)-1) -> 49 | AN10: =IF(OR($A10="",$R10=""),0,IF(Deal_Scope="All Deals",1,IF($E10=Deal_Scope,1,0))) -> 1 | AO10: =IF($AN10=0,0,Px_Par) -> 0.94 | AP10: =IF($H10="",0,MAX(0,($H10-Set_Date)/30.4375)) -> 83.055441 | AQ10: =IF(AND(Ext_Flag="Yes",$AA10="Yes"),Ext_Months,0) -> 12 | AR10: =$AP10+$AQ10 -> 95.055441 | AS10: =$AR10/12 -> 7.9212868 | AT10: =IF($AJ10="",0,MAX(0,$AJ10/12)) -> 6.9166667 | AU10: =MAX(Amort_Min,Amort_Term-$AH10/12) -> 26.916667 | AV10: =MIN($AS10,Hold_Yrs) -> 5 | AW10: =IF($AN10=0,0,CEILING(MAX($AS10,0.0001),1)) -> 8 | AX10: =IF(AND($AN10=1,MAX($AS10,0.0001)<=Hold_Yrs),1,0) -> 0 | AY10: =$R10*$AO10 -> 4252560 | AZ10: =$R10*Acc_Int*$AN10 -> 6786 | BA10: =$AY10*Acq_Cost -> 31894.2 | BB10: =$AY10+$AZ10+$BA10 -> 4291240.2 | BC10: =IF(Fin_Flag="Yes",$AY10*Adv_Rate,0) -> 2551536 | BD10: =$BC10*Fin_UpFee -> 12757.68 | BE10: =$BB10-$BC10+$BD10 -> 1752461.9
A11: L-008 | B11: Riverwalk Business Park | C11: FL | D11: Office | E11: Deal 2 | G11: 43891 | H11: 47543 | I11: 119 | J11: 12 | K11: Floating | M11: 0.036 | N11: Monthly | O11: 46355 | P11: 0.1057 | R11: 48331000 | S11: 0.99 | T11: 0.0941 | U11: 0.98 | V11: 0.741 | W11: 0.762 | X11: 1986 | Y11: 2011 | Z11: Partial IO | AA11: No | AB11: Defeasance | AC11: First Lien | AD11: Private REIT | AE11: Acquisition | AF11: Current | AG11: Fee Simple | AH11: =IF(G11="",0,ROUND((Strats!$C$4-G11)/30.4375,1)) -> 79 | AI11: =IF(K11="",0,IF(K11="Floating",Strats!$C$10+M11,L11)) -> 0.081 | AJ11: =IF(OR(Z11="",Z11="Full Amortizing"),"",MAX(J11-AH11,0)) -> 0 | AK11: =IF(K11="",0,IF(K11="Floating",IF(P11<>"",MIN(IF(Q11<>"",MAX((Strats!$C$10+Strats!$C$11+M11),Q11),(Strats!$C$10+Strats!$C$11+M11)),P11),IF(Q11<>"",MAX((Strats!$C$10+Strats!$C$11+M11),Q11),(Strats!$C$10+Strats!$C$11+M11))),AI11)) -> 0.096 | AL11: =IF(OR(E11="",E11<>'Deal Strat'!$C$12,R11=""),"",SUMPRODUCT((E$4:E$303='Deal Strat'!$C$12)*(R$4:R$303>R11))+1+SUMPRODUCT((E$4:E$303='Deal Strat'!$C$12)*(R$4:R$303=R11)*(ROW(R$4:R$303)<ROW(R11)))) | AM11: =IF(R11="","",RANK(R11,$R$4:$R$303,0)+COUNTIF($R$4:R11,R11)-1) -> 22 | AN11: =IF(OR($A11="",$R11=""),0,IF(Deal_Scope="All Deals",1,IF($E11=Deal_Scope,1,0))) -> 1 | AO11: =IF($AN11=0,0,Px_Par) -> 0.94 | AP11: =IF($H11="",0,MAX(0,($H11-Set_Date)/30.4375)) -> 41.002053 | AQ11: =IF(AND(Ext_Flag="Yes",$AA11="Yes"),Ext_Months,0) -> 0 | AR11: =$AP11+$AQ11 -> 41.002053 | AS11: =$AR11/12 -> 3.4168378 | AT11: =IF($AJ11="",0,MAX(0,$AJ11/12)) -> 0 | AU11: =MAX(Amort_Min,Amort_Term-$AH11/12) -> 23.416667 | AV11: =MIN($AS11,Hold_Yrs) -> 3.4168378 | AW11: =IF($AN11=0,0,CEILING(MAX($AS11,0.0001),1)) -> 4 | AX11: =IF(AND($AN11=1,MAX($AS11,0.0001)<=Hold_Yrs),1,0) -> 1 | AY11: =$R11*$AO11 -> 45431140 | AZ11: =$R11*Acc_Int*$AN11 -> 72496.5 | BA11: =$AY11*Acq_Cost -> 340733.55 | BB11: =$AY11+$AZ11+$BA11 -> 45844370 | BC11: =IF(Fin_Flag="Yes",$AY11*Adv_Rate,0) -> 27258684 | BD11: =$BC11*Fin_UpFee -> 136293.42 | BE11: =$BB11-$BC11+$BD11 -> 18721979
A12: L-009 | B12: Quarry Commons | C12: CO | D12: Multifamily | E12: Deal 5 | F12: 162 | G12: 45292 | H12: 48945 | I12: 119 | J12: 60 | K12: Fixed | L12: 0.0479 | N12: N/A | R12: 16415000 | S12: 0.831 | T12: 0.0963 | U12: 2.05 | V12: 0.432 | W12: 0.487 | X12: 1978 | Z12: Partial IO | AA12: No | AB12: Freely Prepayable | AC12: First Lien | AD12: HNW Investors | AE12: Recapitalization | AF12: Current | AG12: Fee & Leasehold | AH12: =IF(G12="",0,ROUND((Strats!$C$4-G12)/30.4375,1)) -> 33 | AI12: =IF(K12="",0,IF(K12="Floating",Strats!$C$10+M12,L12)) -> 0.0479 | AJ12: =IF(OR(Z12="",Z12="Full Amortizing"),"",MAX(J12-AH12,0)) -> 27 | AK12: =IF(K12="",0,IF(K12="Floating",IF(P12<>"",MIN(IF(Q12<>"",MAX((Strats!$C$10+Strats!$C$11+M12),Q12),(Strats!$C$10+Strats!$C$11+M12)),P12),IF(Q12<>"",MAX((Strats!$C$10+Strats!$C$11+M12),Q12),(Strats!$C$10+Strats!$C$11+M12))),AI12)) -> 0.0479 | AL12: =IF(OR(E12="",E12<>'Deal Strat'!$C$12,R12=""),"",SUMPRODUCT((E$4:E$303='Deal Strat'!$C$12)*(R$4:R$303>R12))+1+SUMPRODUCT((E$4:E$303='Deal Strat'!$C$12)*(R$4:R$303=R12)*(ROW(R$4:R$303)<ROW(R12)))) | AM12: =IF(R12="","",RANK(R12,$R$4:$R$303,0)+COUNTIF($R$4:R12,R12)-1) -> 33 | AN12: =IF(OR($A12="",$R12=""),0,IF(Deal_Scope="All Deals",1,IF($E12=Deal_Scope,1,0))) -> 1 | AO12: =IF($AN12=0,0,Px_Par) -> 0.94 | AP12: =IF($H12="",0,MAX(0,($H12-Set_Date)/30.4375)) -> 87.063655 | AQ12: =IF(AND(Ext_Flag="Yes",$AA12="Yes"),Ext_Months,0) -> 0 | AR12: =$AP12+$AQ12 -> 87.063655 | AS12: =$AR12/12 -> 7.2553046 | AT12: =IF($AJ12="",0,MAX(0,$AJ12/12)) -> 2.25 | AU12: =MAX(Amort_Min,Amort_Term-$AH12/12) -> 27.25 | AV12: =MIN($AS12,Hold_Yrs) -> 5 | AW12: =IF($AN12=0,0,CEILING(MAX($AS12,0.0001),1)) -> 8 | AX12: =IF(AND($AN12=1,MAX($AS12,0.0001)<=Hold_Yrs),1,0) -> 0 | AY12: =$R12*$AO12 -> 15430100 | AZ12: =$R12*Acc_Int*$AN12 -> 24622.5 | BA12: =$AY12*Acq_Cost -> 115725.75 | BB12: =$AY12+$AZ12+$BA12 -> 15570448 | BC12: =IF(Fin_Flag="Yes",$AY12*Adv_Rate,0) -> 9258060 | BD12: =$BC12*Fin_UpFee -> 46290.3 | BE12: =$BB12-$BC12+$BD12 -> 6358678.5
A13: L-010 | B13: Brookstone Landing | C13: NC | D13: Multifamily | E13: Deal 1 | F13: 171 | G13: 43435 | H13: 45261 | I13: 61 | J13: 0 | K13: Fixed | L13: 0.0647 | N13: N/A | R13: 45056000 | S13: 0.929 | T13: 0.0685 | U13: 1.98 | V13: 0.685 | W13: 0.735 | X13: 1979 | Y13: 1990 | Z13: Full Amortizing | AA13: Yes | AB13: Prepayable with Penalty | AC13: First Lien | AD13: HNW Investors | AE13: Acquisition | AF13: Current | AG13: Fee Simple | AH13: =IF(G13="",0,ROUND((Strats!$C$4-G13)/30.4375,1)) -> 94 | AI13: =IF(K13="",0,IF(K13="Floating",Strats!$C$10+M13,L13)) -> 0.0647 | AJ13: =IF(OR(Z13="",Z13="Full Amortizing"),"",MAX(J13-AH13,0)) | AK13: =IF(K13="",0,IF(K13="Floating",IF(P13<>"",MIN(IF(Q13<>"",MAX((Strats!$C$10+Strats!$C$11+M13),Q13),(Strats!$C$10+Strats!$C$11+M13)),P13),IF(Q13<>"",MAX((Strats!$C$10+Strats!$C$11+M13),Q13),(Strats!$C$10+Strats!$C$11+M13))),AI13)) -> 0.0647 | AL13: =IF(OR(E13="",E13<>'Deal Strat'!$C$12,R13=""),"",SUMPRODUCT((E$4:E$303='Deal Strat'!$C$12)*(R$4:R$303>R13))+1+SUMPRODUCT((E$4:E$303='Deal Strat'!$C$12)*(R$4:R$303=R13)*(ROW(R$4:R$303)<ROW(R13)))) -> 5 | AM13: =IF(R13="","",RANK(R13,$R$4:$R$303,0)+COUNTIF($R$4:R13,R13)-1) -> 24 | AN13: =IF(OR($A13="",$R13=""),0,IF(Deal_Scope="All Deals",1,IF($E13=Deal_Scope,1,0))) -> 1 | AO13: =IF($AN13=0,0,Px_Par) -> 0.94 | AP13: =IF($H13="",0,MAX(0,($H13-Set_Date)/30.4375)) -> 0 | AQ13: =IF(AND(Ext_Flag="Yes",$AA13="Yes"),Ext_Months,0) -> 12 | AR13: =$AP13+$AQ13 -> 12 | AS13: =$AR13/12 -> 1 | AT13: =IF($AJ13="",0,MAX(0,$AJ13/12)) -> 0 | AU13: =MAX(Amort_Min,Amort_Term-$AH13/12) -> 22.166667 | AV13: =MIN($AS13,Hold_Yrs) -> 1 | AW13: =IF($AN13=0,0,CEILING(MAX($AS13,0.0001),1)) -> 1 | AX13: =IF(AND($AN13=1,MAX($AS13,0.0001)<=Hold_Yrs),1,0) -> 1 | AY13: =$R13*$AO13 -> 42352640 | AZ13: =$R13*Acc_Int*$AN13 -> 67584 | BA13: =$AY13*Acq_Cost -> 317644.8 | BB13: =$AY13+$AZ13+$BA13 -> 42737869 | BC13: =IF(Fin_Flag="Yes",$AY13*Adv_Rate,0) -> 25411584 | BD13: =$BC13*Fin_UpFee -> 127057.92 | BE13: =$BB13-$BC13+$BD13 -> 17453343
A14: L-011 | B14: Summit Distribution Center | C14: CO | D14: Industrial | E14: Deal 5 | G14: 44835 | H14: 48488 | I14: 120 | J14: 24 | K14: Floating | M14: 0.0249 | N14: Monthly | O14: 46295 | R14: 27710000 | S14: 0.817 | T14: 0.0839 | U14: 0.58 | V14: 0.581 | W14: 0.613 | X14: 2007 | Z14: Partial IO | AA14: No | AB14: Defeasance | AC14: First Lien | AD14: Private REIT | AE14: Acquisition | AF14: Current | AG14: Fee Simple | AH14: =IF(G14="",0,ROUND((Strats!$C$4-G14)/30.4375,1)) -> 48 | AI14: =IF(K14="",0,IF(K14="Floating",Strats!$C$10+M14,L14)) -> 0.0699 | AJ14: =IF(OR(Z14="",Z14="Full Amortizing"),"",MAX(J14-AH14,0)) -> 0 | AK14: =IF(K14="",0,IF(K14="Floating",IF(P14<>"",MIN(IF(Q14<>"",MAX((Strats!$C$10+Strats!$C$11+M14),Q14),(Strats!$C$10+Strats!$C$11+M14)),P14),IF(Q14<>"",MAX((Strats!$C$10+Strats!$C$11+M14),Q14),(Strats!$C$10+Strats!$C$11+M14))),AI14)) -> 0.0849 | AL14: =IF(OR(E14="",E14<>'Deal Strat'!$C$12,R14=""),"",SUMPRODUCT((E$4:E$303='Deal Strat'!$C$12)*(R$4:R$303>R14))+1+SUMPRODUCT((E$4:E$303='Deal Strat'!$C$12)*(R$4:R$303=R14)*(ROW(R$4:R$303)<ROW(R14)))) | AM14: =IF(R14="","",RANK(R14,$R$4:$R$303,0)+COUNTIF($R$4:R14,R14)-1) -> 31 | AN14: =IF(OR($A14="",$R14=""),0,IF(Deal_Scope="All Deals",1,IF($E14=Deal_Scope,1,0))) -> 1 | AO14: =IF($AN14=0,0,Px_Par) -> 0.94 | AP14: =IF($H14="",0,MAX(0,($H14-Set_Date)/30.4375)) -> 72.049281 | AQ14: =IF(AND(Ext_Flag="Yes",$AA14="Yes"),Ext_Months,0) -> 0 | AR14: =$AP14+$AQ14 -> 72.049281 | AS14: =$AR14/12 -> 6.0041068 | AT14: =IF($AJ14="",0,MAX(0,$AJ14/12)) -> 0 | AU14: =MAX(Amort_Min,Amort_Term-$AH14/12) -> 26 | AV14: =MIN($AS14,Hold_Yrs) -> 5 | AW14: =IF($AN14=0,0,CEILING(MAX($AS14,0.0001),1)) -> 7 | AX14: =IF(AND($AN14=1,MAX($AS14,0.0001)<=Hold_Yrs),1,0) -> 0 | AY14: =$R14*$AO14 -> 26047400 | AZ14: =$R14*Acc_Int*$AN14 -> 41565 | BA14: =$AY14*Acq_Cost -> 195355.5 | BB14: =$AY14+$AZ14+$BA14 -> 26284320 | BC14: =IF(Fin_Flag="Yes",$AY14*Adv_Rate,0) -> 15628440 | BD14: =$BC14*Fin_UpFee -> 78142.2 | BE14: =$BB14-$BC14+$BD14 -> 10734023
A15: L-012 | B15: Parkside Marketplace | C15: MD | D15: Retail | E15: Deal 7 | G15: 43952 | H15: 46508 | I15: 85 | J15: 36 | K15: Fixed | L15: 0.0557 | N15: N/A | R15: 5654000 | S15: 0.842 | T15: 0.0426 | U15: 1.44 | V15: 0.703 | W15: 0.753 | X15: 1975 | Z15: Partial IO | AA15: Yes | AB15: Defeasance | AC15: First Lien | AD15: PE Fund | AE15: Recapitalization | AF15: Current | AG15: Fee Simple | AH15: =IF(G15="",0,ROUND((Strats!$C$4-G15)/30.4375,1)) -> 77 | AI15: =IF(K15="",0,IF(K15="Floating",Strats!$C$10+M15,L15)) -> 0.0557 | AJ15: =IF(OR(Z15="",Z15="Full Amortizing"),"",MAX(J15-AH15,0)) -> 0 | AK15: =IF(K15="",0,IF(K15="Floating",IF(P15<>"",MIN(IF(Q15<>"",MAX((Strats!$C$10+Strats!$C$11+M15),Q15),(Strats!$C$10+Strats!$C$11+M15)),P15),IF(Q15<>"",MAX((Strats!$C$10+Strats!$C$11+M15),Q15),(Strats!$C$10+Strats!$C$11+M15))),AI15)) -> 0.0557 | AL15: =IF(OR(E15="",E15<>'Deal Strat'!$C$12,R15=""),"",SUMPRODUCT((E$4:E$303='Deal Strat'!$C$12)*(R$4:R$303>R15))+1+SUMPRODUCT((E$4:E$303='Deal Strat'!$C$12)*(R$4:R$303=R15)*(ROW(R$4:R$303)<ROW(R15)))) | AM15: =IF(R15="","",RANK(R15,$R$4:$R$303,0)+COUNTIF($R$4:R15,R15)-1) -> 44 | AN15: =IF(OR($A15="",$R15=""),0,IF(Deal_Scope="All Deals",1,IF($E15=Deal_Scope,1,0))) -> 1 | AO15: =IF($AN15=0,0,Px_Par) -> 0.94 | AP15: =IF($H15="",0,MAX(0,($H15-Set_Date)/30.4375)) -> 6.9979466 | AQ15: =IF(AND(Ext_Flag="Yes",$AA15="Yes"),Ext_Months,0) -> 12 | AR15: =$AP15+$AQ15 -> 18.997947 | AS15: =$AR15/12 -> 1.5831622 | AT15: =IF($AJ15="",0,MAX(0,$AJ15/12)) -> 0 | AU15: =MAX(Amort_Min,Amort_Term-$AH15/12) -> 23.583333 | AV15: =MIN($AS15,Hold_Yrs) -> 1.5831622 | AW15: =IF($AN15=0,0,CEILING(MAX($AS15,0.0001),1)) -> 2 | AX15: =IF(AND($AN15=1,MAX($AS15,0.0001)<=Hold_Yrs),1,0) -> 1 | AY15: =$R15*$AO15 -> 5314760 | AZ15: =$R15*Acc_Int*$AN15 -> 8481 | BA15: =$AY15*Acq_Cost -> 39860.7 | BB15: =$AY15+$AZ15+$BA15 -> 5363101.7 | BC15: =IF(Fin_Flag="Yes",$AY15*Adv_Rate,0) -> 3188856 | BD15: =$BC15*Fin_UpFee -> 15944.28 | BE15: =$BB15-$BC15+$BD15 -> 2190190
A16: L-013 | B16: Summit Distribution Center | C16: GA | D16: Industrial | E16: Deal 4 | G16: 45108 | H16: 47665 | I16: 84 | J16: 12 | K16: Fixed | L16: 0.0655 | N16: N/A | R16: 85445000 | S16: 0.99 | T16: 0.0875 | U16: 0.79 | V16: 0.577 | W16: 0.627 | X16: 2009 | Y16: 2015 | Z16: Partial IO | AA16: Yes | AB16: Yield Maintenance | AC16: First Lien | AD16: PE Fund | AE16: Acquisition | AF16: Current | AG16: Fee Simple | AH16: =IF(G16="",0,ROUND((Strats!$C$4-G16)/30.4375,1)) -> 39 | AI16: =IF(K16="",0,IF(K16="Floating",Strats!$C$10+M16,L16)) -> 0.0655 | AJ16: =IF(OR(Z16="",Z16="Full Amortizing"),"",MAX(J16-AH16,0)) -> 0 | AK16: =IF(K16="",0,IF(K16="Floating",IF(P16<>"",MIN(IF(Q16<>"",MAX((Strats!$C$10+Strats!$C$11+M16),Q16),(Strats!$C$10+Strats!$C$11+M16)),P16),IF(Q16<>"",MAX((Strats!$C$10+Strats!$C$11+M16),Q16),(Strats!$C$10+Strats!$C$11+M16))),AI16)) -> 0.0655 | AL16: =IF(OR(E16="",E16<>'Deal Strat'!$C$12,R16=""),"",SUMPRODUCT((E$4:E$303='Deal Strat'!$C$12)*(R$4:R$303>R16))+1+SUMPRODUCT((E$4:E$303='Deal Strat'!$C$12)*(R$4:R$303=R16)*(ROW(R$4:R$303)<ROW(R16)))) | AM16: =IF(R16="","",RANK(R16,$R$4:$R$303,0)+COUNTIF($R$4:R16,R16)-1) -> 12 | AN16: =IF(OR($A16="",$R16=""),0,IF(Deal_Scope="All Deals",1,IF($E16=Deal_Scope,1,0))) -> 1 | AO16: =IF($AN16=0,0,Px_Par) -> 0.94 | AP16: =IF($H16="",0,MAX(0,($H16-Set_Date)/30.4375)) -> 45.010267 | AQ16: =IF(AND(Ext_Flag="Yes",$AA16="Yes"),Ext_Months,0) -> 12 | AR16: =$AP16+$AQ16 -> 57.010267 | AS16: =$AR16/12 -> 4.7508556 | AT16: =IF($AJ16="",0,MAX(0,$AJ16/12)) -> 0 | AU16: =MAX(Amort_Min,Amort_Term-$AH16/12) -> 26.75 | AV16: =MIN($AS16,Hold_Yrs) -> 4.7508556 | AW16: =IF($AN16=0,0,CEILING(MAX($AS16,0.0001),1)) -> 5 | AX16: =IF(AND($AN16=1,MAX($AS16,0.0001)<=Hold_Yrs),1,0) -> 1 | AY16: =$R16*$AO16 -> 80318300 | AZ16: =$R16*Acc_Int*$AN16 -> 128167.5 | BA16: =$AY16*Acq_Cost -> 602387.25 | BB16: =$AY16+$AZ16+$BA16 -> 81048855 | BC16: =IF(Fin_Flag="Yes",$AY16*Adv_Rate,0) -> 48190980 | BD16: =$BC16*Fin_UpFee -> 240954.9 | BE16: =$BB16-$BC16+$BD16 -> 33098830
A17: L-014 | B17: Glenwood Landing | C17: NV | D17: Multifamily | E17: Deal 8 | F17: 161 | G17: 45231 | H17: 47788 | I17: 84 | J17: 36 | K17: Fixed | L17: 0.0504 | N17: N/A | R17: 128291000 | S17: 0.802 | T17: 0.095 | U17: 1.98 | V17: 0.693 | W17: 0.722 | X17: 1974 | Z17: Partial IO | AA17: Yes | AB17: Freely Prepayable | AC17: First Lien | AD17: Institutional Owner/Operator | AE17: Acquisition | AF17: Current | AG17: Fee & Leasehold | AH17: =IF(G17="",0,ROUND((Strats!$C$4-G17)/30.4375,1)) -> 35 | AI17: =IF(K17="",0,IF(K17="Floating",Strats!$C$10+M17,L17)) -> 0.0504 | AJ17: =IF(OR(Z17="",Z17="Full Amortizing"),"",MAX(J17-AH17,0)) -> 1 | AK17: =IF(K17="",0,IF(K17="Floating",IF(P17<>"",MIN(IF(Q17<>"",MAX((Strats!$C$10+Strats!$C$11+M17),Q17),(Strats!$C$10+Strats!$C$11+M17)),P17),IF(Q17<>"",MAX((Strats!$C$10+Strats!$C$11+M17),Q17),(Strats!$C$10+Strats!$C$11+M17))),AI17)) -> 0.0504 | AL17: =IF(OR(E17="",E17<>'Deal Strat'!$C$12,R17=""),"",SUMPRODUCT((E$4:E$303='Deal Strat'!$C$12)*(R$4:R$303>R17))+1+SUMPRODUCT((E$4:E$303='Deal Strat'!$C$12)*(R$4:R$303=R17)*(ROW(R$4:R$303)<ROW(R17)))) | AM17: =IF(R17="","",RANK(R17,$R$4:$R$303,0)+COUNTIF($R$4:R17,R17)-1) -> 3 | AN17: =IF(OR($A17="",$R17=""),0,IF(Deal_Scope="All Deals",1,IF($E17=Deal_Scope,1,0))) -> 1 | AO17: =IF($AN17=0,0,Px_Par) -> 0.94 | AP17: =IF($H17="",0,MAX(0,($H17-Set_Date)/30.4375)) -> 49.051335 | AQ17: =IF(AND(Ext_Flag="Yes",$AA17="Yes"),Ext_Months,0) -> 12 | AR17: =$AP17+$AQ17 -> 61.051335 | AS17: =$AR17/12 -> 5.0876112 | AT17: =IF($AJ17="",0,MAX(0,$AJ17/12)) -> 0.083333333 | AU17: =MAX(Amort_Min,Amort_Term-$AH17/12) -> 27.083333 | AV17: =MIN($AS17,Hold_Yrs) -> 5 | AW17: =IF($AN17=0,0,CEILING(MAX($AS17,0.0001),1)) -> 6 | AX17: =IF(AND($AN17=1,MAX($AS17,0.0001)<=Hold_Yrs),1,0) -> 0 | AY17: =$R17*$AO17 -> 120593540 | AZ17: =$R17*Acc_Int*$AN17 -> 192436.5 | BA17: =$AY17*Acq_Cost -> 904451.55 | BB17: =$AY17+$AZ17+$BA17 -> 1.2169043e+08 | BC17: =IF(Fin_Flag="Yes",$AY17*Adv_Rate,0) -> 72356124 | BD17: =$BC17*Fin_UpFee -> 361780.62 | BE17: =$BB17-$BC17+$BD17 -> 49696085
A18: L-015 | B18: Palisades Exchange | C18: TX | D18: Office | E18: Deal 7 | G18: 45566 | H18: 48122 | I18: 85 | J18: 60 | K18: Floating | M18: 0.0311 | N18: Monthly | O18: 46355 | R18: 131786000 | S18: 0.951 | T18: 0.1044 | U18: 1.69 | V18: 0.78 | W18: 0.791 | X18: 1990 | Y18: 1995 | Z18: Interest Only | AA18: Yes | AB18: Freely Prepayable | AC18: First Lien | AD18: PE Fund | AE18: Acquisition | AF18: Current | AG18: Fee Simple | AH18: =IF(G18="",0,ROUND((Strats!$C$4-G18)/30.4375,1)) -> 24 | AI18: =IF(K18="",0,IF(K18="Floating",Strats!$C$10+M18,L18)) -> 0.0761 | AJ18: =IF(OR(Z18="",Z18="Full Amortizing"),"",MAX(J18-AH18,0)) -> 36 | AK18: =IF(K18="",0,IF(K18="Floating",IF(P18<>"",MIN(IF(Q18<>"",MAX((Strats!$C$10+Strats!$C$11+M18),Q18),(Strats!$C$10+Strats!$C$11+M18)),P18),IF(Q18<>"",MAX((Strats!$C$10+Strats!$C$11+M18),Q18),(Strats!$C$10+Strats!$C$11+M18))),AI18)) -> 0.0911 | AL18: =IF(OR(E18="",E18<>'Deal Strat'!$C$12,R18=""),"",SUMPRODUCT((E$4:E$303='Deal Strat'!$C$12)*(R$4:R$303>R18))+1+SUMPRODUCT((E$4:E$303='Deal Strat'!$C$12)*(R$4:R$303=R18)*(ROW(R$4:R$303)<ROW(R18)))) | AM18: =IF(R18="","",RANK(R18,$R$4:$R$303,0)+COUNTIF($R$4:R18,R18)-1) -> 2 | AN18: =IF(OR($A18="",$R18=""),0,IF(Deal_Scope="All Deals",1,IF($E18=Deal_Scope,1,0))) -> 1 | AO18: =IF($AN18=0,0,Px_Par) -> 0.94 | AP18: =IF($H18="",0,MAX(0,($H18-Set_Date)/30.4375)) -> 60.024641 | AQ18: =IF(AND(Ext_Flag="Yes",$AA18="Yes"),Ext_Months,0) -> 12 | AR18: =$AP18+$AQ18 -> 72.024641 | AS18: =$AR18/12 -> 6.0020534 | AT18: =IF($AJ18="",0,MAX(0,$AJ18/12)) -> 3 | AU18: =MAX(Amort_Min,Amort_Term-$AH18/12) -> 28 | AV18: =MIN($AS18,Hold_Yrs) -> 5 | AW18: =IF($AN18=0,0,CEILING(MAX($AS18,0.0001),1)) -> 7 | AX18: =IF(AND($AN18=1,MAX($AS18,0.0001)<=Hold_Yrs),1,0) -> 0 | AY18: =$R18*$AO18 -> 123878840 | AZ18: =$R18*Acc_Int*$AN18 -> 197679 | BA18: =$AY18*Acq_Cost -> 929091.3 | BB18: =$AY18+$AZ18+$BA18 -> 1.2500561e+08 | BC18: =IF(Fin_Flag="Yes",$AY18*Adv_Rate,0) -> 74327304 | BD18: =$BC18*Fin_UpFee -> 371636.52 | BE18: =$BB18-$BC18+$BD18 -> 51049943
A19: L-016 | B19: Harborview Landing | C19: TN | D19: Multifamily | E19: Deal 5 | F19: 121 | G19: 42461 | H19: 45017 | I19: 84 | J19: 24 | K19: Floating | M19: 0.0214 | N19: Monthly | O19: 46355 | R19: 8243000 | S19: 0.897 | T19: 0.0445 | U19: 1.69 | V19: 0.469 | W19: 0.515 | X19: 2014 | Z19: Partial IO | AA19: No | AB19: Prepayable with Penalty | AC19: First Lien | AD19: Institutional Owner/Operator | AE19: Refinance | AF19: Matured | AG19: Fee Simple | AH19: =IF(G19="",0,ROUND((Strats!$C$4-G19)/30.4375,1)) -> 126 | AI19: =IF(K19="",0,IF(K19="Floating",Strats!$C$10+M19,L19)) -> 0.0664 | AJ19: =IF(OR(Z19="",Z19="Full Amortizing"),"",MAX(J19-AH19,0)) -> 0 | AK19: =IF(K19="",0,IF(K19="Floating",IF(P19<>"",MIN(IF(Q19<>"",MAX((Strats!$C$10+Strats!$C$11+M19),Q19),(Strats!$C$10+Strats!$C$11+M19)),P19),IF(Q19<>"",MAX((Strats!$C$10+Strats!$C$11+M19),Q19),(Strats!$C$10+Strats!$C$11+M19))),AI19)) -> 0.0814 | AL19: =IF(OR(E19="",E19<>'Deal Strat'!$C$12,R19=""),"",SUMPRODUCT((E$4:E$303='Deal Strat'!$C$12)*(R$4:R$303>R19))+1+SUMPRODUCT((E$4:E$303='Deal Strat'!$C$12)*(R$4:R$303=R19)*(ROW(R$4:R$303)<ROW(R19)))) | AM19: =IF(R19="","",RANK(R19,$R$4:$R$303,0)+COUNTIF($R$4:R19,R19)-1) -> 40 | AN19: =IF(OR($A19="",$R19=""),0,IF(Deal_Scope="All Deals",1,IF($E19=Deal_Scope,1,0))) -> 1 | AO19: =IF($AN19=0,0,Px_Par) -> 0.94 | AP19: =IF($H19="",0,MAX(0,($H19-Set_Date)/30.4375)) -> 0 | AQ19: =IF(AND(Ext_Flag="Yes",$AA19="Yes"),Ext_Months,0) -> 0 | AR19: =$AP19+$AQ19 -> 0 | AS19: =$AR19/12 -> 0 | AT19: =IF($AJ19="",0,MAX(0,$AJ19/12)) -> 0 | AU19: =MAX(Amort_Min,Amort_Term-$AH19/12) -> 19.5 | AV19: =MIN($AS19,Hold_Yrs) -> 0 | AW19: =IF($AN19=0,0,CEILING(MAX($AS19,0.0001),1)) -> 1 | AX19: =IF(AND($AN19=1,MAX($AS19,0.0001)<=Hold_Yrs),1,0) -> 1 | AY19: =$R19*$AO19 -> 7748420 | AZ19: =$R19*Acc_Int*$AN19 -> 12364.5 | BA19: =$AY19*Acq_Cost -> 58113.15 | BB19: =$AY19+$AZ19+$BA19 -> 7818897.7 | BC19: =IF(Fin_Flag="Yes",$AY19*Adv_Rate,0) -> 4649052 | BD19: =$BC19*Fin_UpFee -> 23245.26 | BE19: =$BB19-$BC19+$BD19 -> 3193090.9
A20: L-017 | B20: Emerson Marketplace | C20: FL | D20: Retail | E20: Deal 2 | G20: 44440 | H20: 48092 | I20: 120 | J20: 36 | K20: Fixed | L20: 0.0453 | N20: N/A | R20: 5111000 | S20: 0.808 | T20: 0.0677 | U20: 1.55 | V20: 0.706 | W20: 0.761 | X20: 1994 | Z20: Interest Only | AA20: Yes | AB20: Defeasance | AC20: Second Lien | AD20: PE Fund | AE20: Refinance | AF20: Current | AG20: Fee Simple | AH20: =IF(G20="",0,ROUND((Strats!$C$4-G20)/30.4375,1)) -> 60.9 | AI20: =IF(K20="",0,IF(K20="Floating",Strats!$C$10+M20,L20)) -> 0.0453 | AJ20: =IF(OR(Z20="",Z20="Full Amortizing"),"",MAX(J20-AH20,0)) -> 0 | AK20: =IF(K20="",0,IF(K20="Floating",IF(P20<>"",MIN(IF(Q20<>"",MAX((Strats!$C$10+Strats!$C$11+M20),Q20),(Strats!$C$10+Strats!$C$11+M20)),P20),IF(Q20<>"",MAX((Strats!$C$10+Strats!$C$11+M20),Q20),(Strats!$C$10+Strats!$C$11+M20))),AI20)) -> 0.0453 | AL20: =IF(OR(E20="",E20<>'Deal Strat'!$C$12,R20=""),"",SUMPRODUCT((E$4:E$303='Deal Strat'!$C$12)*(R$4:R$303>R20))+1+SUMPRODUCT((E$4:E$303='Deal Strat'!$C$12)*(R$4:R$303=R20)*(ROW(R$4:R$303)<ROW(R20)))) | AM20: =IF(R20="","",RANK(R20,$R$4:$R$303,0)+COUNTIF($R$4:R20,R20)-1) -> 47 | AN20: =IF(OR($A20="",$R20=""),0,IF(Deal_Scope="All Deals",1,IF($E20=Deal_Scope,1,0))) -> 1 | AO20: =IF($AN20=0,0,Px_Par) -> 0.94 | AP20: =IF($H20="",0,MAX(0,($H20-Set_Date)/30.4375)) -> 59.039014 | AQ20: =IF(AND(Ext_Flag="Yes",$AA20="Yes"),Ext_Months,0) -> 12 | AR20: =$AP20+$AQ20 -> 71.039014 | AS20: =$AR20/12 -> 5.9199179 | AT20: =IF($AJ20="",0,MAX(0,$AJ20/12)) -> 0 | AU20: =MAX(Amort_Min,Amort_Term-$AH20/12) -> 24.925 | AV20: =MIN($AS20,Hold_Yrs) -> 5 | AW20: =IF($AN20=0,0,CEILING(MAX($AS20,0.0001),1)) -> 6 | AX20: =IF(AND($AN20=1,MAX($AS20,0.0001)<=Hold_Yrs),1,0) -> 0 | AY20: =$R20*$AO20 -> 4804340 | AZ20: =$R20*Acc_Int*$AN20 -> 7666.5 | BA20: =$AY20*Acq_Cost -> 36032.55 | BB20: =$AY20+$AZ20+$BA20 -> 4848039 | BC20: =IF(Fin_Flag="Yes",$AY20*Adv_Rate,0) -> 2882604 | BD20: =$BC20*Fin_UpFee -> 14413.02 | BE20: =$BB20-$BC20+$BD20 -> 1979848.1
A21: L-018 | B21: Kingston Corporate Center | C21: IL | D21: Office | E21: Deal 2 | G21: 44256 | H21: 47908 | I21: 120 | J21: 36 | K21: Floating | M21: 0.0272 | N21: Quarterly | O21: 46355 | R21: 76728000 | S21: 0.842 | T21: 0.0861 | U21: 1.33 | V21: 0.782 | W21: 0.82 | X21: 1980 | Z21: Partial IO | AA21: No | AB21: Defeasance | AC21: First Lien | AD21: PE Fund | AE21: Acquisition | AF21: Current | AG21: Fee Simple | AH21: =IF(G21="",0,ROUND((Strats!$C$4-G21)/30.4375,1)) -> 67 | AI21: =IF(K21="",0,IF(K21="Floating",Strats!$C$10+M21,L21)) -> 0.0722 | AJ21: =IF(OR(Z21="",Z21="Full Amortizing"),"",MAX(J21-AH21,0)) -> 0 | AK21: =IF(K21="",0,IF(K21="Floating",IF(P21<>"",MIN(IF(Q21<>"",MAX((Strats!$C$10+Strats!$C$11+M21),Q21),(Strats!$C$10+Strats!$C$11+M21)),P21),IF(Q21<>"",MAX((Strats!$C$10+Strats!$C$11+M21),Q21),(Strats!$C$10+Strats!$C$11+M21))),AI21)) -> 0.0872 | AL21: =IF(OR(E21="",E21<>'Deal Strat'!$C$12,R21=""),"",SUMPRODUCT((E$4:E$303='Deal Strat'!$C$12)*(R$4:R$303>R21))+1+SUMPRODUCT((E$4:E$303='Deal Strat'!$C$12)*(R$4:R$303=R21)*(ROW(R$4:R$303)<ROW(R21)))) | AM21: =IF(R21="","",RANK(R21,$R$4:$R$303,0)+COUNTIF($R$4:R21,R21)-1) -> 15 | AN21: =IF(OR($A21="",$R21=""),0,IF(Deal_Scope="All Deals",1,IF($E21=Deal_Scope,1,0))) -> 1 | AO21: =IF($AN21=0,0,Px_Par) -> 0.94 | AP21: =IF($H21="",0,MAX(0,($H21-Set_Date)/30.4375)) -> 52.99384 | AQ21: =IF(AND(Ext_Flag="Yes",$AA21="Yes"),Ext_Months,0) -> 0 | AR21: =$AP21+$AQ21 -> 52.99384 | AS21: =$AR21/12 -> 4.4161533 | AT21: =IF($AJ21="",0,MAX(0,$AJ21/12)) -> 0 | AU21: =MAX(Amort_Min,Amort_Term-$AH21/12) -> 24.416667 | AV21: =MIN($AS21,Hold_Yrs) -> 4.4161533 | AW21: =IF($AN21=0,0,CEILING(MAX($AS21,0.0001),1)) -> 5 | AX21: =IF(AND($AN21=1,MAX($AS21,0.0001)<=Hold_Yrs),1,0) -> 1 | AY21: =$R21*$AO21 -> 72124320 | AZ21: =$R21*Acc_Int*$AN21 -> 115092 | BA21: =$AY21*Acq_Cost -> 540932.4 | BB21: =$AY21+$AZ21+$BA21 -> 72780344 | BC21: =IF(Fin_Flag="Yes",$AY21*Adv_Rate,0) -> 43274592 | BD21: =$BC21*Fin_UpFee -> 216372.96 | BE21: =$BB21-$BC21+$BD21 -> 29722125
A22: L-019 | B22: Chandler Exchange | C22: OR | D22: Office | E22: Deal 6 | G22: 43617 | H22: 45444 | I22: 59 | J22: 0 | K22: Floating | M22: 0.0366 | N22: Monthly | O22: 46355 | P22: 0.1004 | R22: 8222000 | S22: 0.827 | T22: 0.0956 | U22: 1.31 | V22: 0.707 | W22: 0.728 | X22: 1976 | Y22: 1998 | Z22: Full Amortizing | AA22: Yes | AB22: Prepayable with Penalty | AC22: First Lien | AD22: PE Fund | AE22: Recapitalization | AF22: Current | AG22: Fee Simple | AH22: =IF(G22="",0,ROUND((Strats!$C$4-G22)/30.4375,1)) -> 88 | AI22: =IF(K22="",0,IF(K22="Floating",Strats!$C$10+M22,L22)) -> 0.0816 | AJ22: =IF(OR(Z22="",Z22="Full Amortizing"),"",MAX(J22-AH22,0)) | AK22: =IF(K22="",0,IF(K22="Floating",IF(P22<>"",MIN(IF(Q22<>"",MAX((Strats!$C$10+Strats!$C$11+M22),Q22),(Strats!$C$10+Strats!$C$11+M22)),P22),IF(Q22<>"",MAX((Strats!$C$10+Strats!$C$11+M22),Q22),(Strats!$C$10+Strats!$C$11+M22))),AI22)) -> 0.0966 | AL22: =IF(OR(E22="",E22<>'Deal Strat'!$C$12,R22=""),"",SUMPRODUCT((E$4:E$303='Deal Strat'!$C$12)*(R$4:R$303>R22))+1+SUMPRODUCT((E$4:E$303='Deal Strat'!$C$12)*(R$4:R$303=R22)*(ROW(R$4:R$303)<ROW(R22)))) | AM22: =IF(R22="","",RANK(R22,$R$4:$R$303,0)+COUNTIF($R$4:R22,R22)-1) -> 41 | AN22: =IF(OR($A22="",$R22=""),0,IF(Deal_Scope="All Deals",1,IF($E22=Deal_Scope,1,0))) -> 1 | AO22: =IF($AN22=0,0,Px_Par) -> 0.94 | AP22: =IF($H22="",0,MAX(0,($H22-Set_Date)/30.4375)) -> 0 | AQ22: =IF(AND(Ext_Flag="Yes",$AA22="Yes"),Ext_Months,0) -> 12 | AR22: =$AP22+$AQ22 -> 12 | AS22: =$AR22/12 -> 1 | AT22: =IF($AJ22="",0,MAX(0,$AJ22/12)) -> 0 | AU22: =MAX(Amort_Min,Amort_Term-$AH22/12) -> 22.666667 | AV22: =MIN($AS22,Hold_Yrs) -> 1 | AW22: =IF($AN22=0,0,CEILING(MAX($AS22,0.0001),1)) -> 1 | AX22: =IF(AND($AN22=1,MAX($AS22,0.0001)<=Hold_Yrs),1,0) -> 1 | AY22: =$R22*$AO22 -> 7728680 | AZ22: =$R22*Acc_Int*$AN22 -> 12333 | BA22: =$AY22*Acq_Cost -> 57965.1 | BB22: =$AY22+$AZ22+$BA22 -> 7798978.1 | BC22: =IF(Fin_Flag="Yes",$AY22*Adv_Rate,0) -> 4637208 | BD22: =$BC22*Fin_UpFee -> 23186.04 | BE22: =$BB22-$BC22+$BD22 -> 3184956.1
A23: L-020 | B23: Dogwood Pointe | C23: TX | D23: Multifamily | E23: Deal 8 | F23: 325 | G23: 44958 | H23: 48611 | I23: 120 | J23: 120 | K23: Floating | M23: 0.0436 | N23: Monthly | O23: 46295 | P23: 0.1018 | R23: 69109000 | S23: 0.916 | T23: 0.0633 | U23: 1.11 | V23: 0.641 | W23: 0.673 | X23: 2020 | Z23: Interest Only | AA23: Yes | AB23: Defeasance | AC23: First Lien | AD23: Institutional Owner/Operator | AE23: Recapitalization | AF23: Current | AG23: Fee Simple | AH23: =IF(G23="",0,ROUND((Strats!$C$4-G23)/30.4375,1)) -> 43.9 | AI23: =IF(K23="",0,IF(K23="Floating",Strats!$C$10+M23,L23)) -> 0.0886 | AJ23: =IF(OR(Z23="",Z23="Full Amortizing"),"",MAX(J23-AH23,0)) -> 76.1 | AK23: =IF(K23="",0,IF(K23="Floating",IF(P23<>"",MIN(IF(Q23<>"",MAX((Strats!$C$10+Strats!$C$11+M23),Q23),(Strats!$C$10+Strats!$C$11+M23)),P23),IF(Q23<>"",MAX((Strats!$C$10+Strats!$C$11+M23),Q23),(Strats!$C$10+Strats!$C$11+M23))),AI23)) -> 0.1018 | AL23: =IF(OR(E23="",E23<>'Deal Strat'!$C$12,R23=""),"",SUMPRODUCT((E$4:E$303='Deal Strat'!$C$12)*(R$4:R$303>R23))+1+SUMPRODUCT((E$4:E$303='Deal Strat'!$C$12)*(R$4:R$303=R23)*(ROW(R$4:R$303)<ROW(R23)))) | AM23: =IF(R23="","",RANK(R23,$R$4:$R$303,0)+COUNTIF($R$4:R23,R23)-1) -> 17 | AN23: =IF(OR($A23="",$R23=""),0,IF(Deal_Scope="All Deals",1,IF($E23=Deal_Scope,1,0))) -> 1 | AO23: =IF($AN23=0,0,Px_Par) -> 0.94 | AP23: =IF($H23="",0,MAX(0,($H23-Set_Date)/30.4375)) -> 76.090349 | AQ23: =IF(AND(Ext_Flag="Yes",$AA23="Yes"),Ext_Months,0) -> 12 | AR23: =$AP23+$AQ23 -> 88.090349 | AS23: =$AR23/12 -> 7.3408624 | AT23: =IF($AJ23="",0,MAX(0,$AJ23/12)) -> 6.3416667 | AU23: =MAX(Amort_Min,Amort_Term-$AH23/12) -> 26.341667 | AV23: =MIN($AS23,Hold_Yrs) -> 5 | AW23: =IF($AN23=0,0,CEILING(MAX($AS23,0.0001),1)) -> 8 | AX23: =IF(AND($AN23=1,MAX($AS23,0.0001)<=Hold_Yrs),1,0) -> 0 | AY23: =$R23*$AO23 -> 64962460 | AZ23: =$R23*Acc_Int*$AN23 -> 103663.5 | BA23: =$AY23*Acq_Cost -> 487218.45 | BB23: =$AY23+$AZ23+$BA23 -> 65553342 | BC23: =IF(Fin_Flag="Yes",$AY23*Adv_Rate,0) -> 38977476 | BD23: =$BC23*Fin_UpFee -> 194887.38 | BE23: =$BB23-$BC23+$BD23 -> 26770753
A24: L-021 | B24: Fairhaven Marketplace | C24: NC | D24: Retail | E24: Deal 2 | G24: 44958 | H24: 47515 | I24: 84 | J24: 24 | K24: Floating | M24: 0.0295 | N24: Monthly | O24: 46355 | P24: 0.0843 | Q24: 0.0309 | R24: 36748000 | S24: 0.932 | T24: 0.1053 | U24: 0.9 | V24: 0.418 | W24: 0.45 | X24: 1994 | Z24: Partial IO | AA24: No | AB24: Yield Maintenance | AC24: First Lien | AD24: Institutional Owner/Operator | AE24: Acquisition | AF24: Current | AG24: Fee Simple | AH24: =IF(G24="",0,ROUND((Strats!$C$4-G24)/30.4375,1)) -> 43.9 | AI24: =IF(K24="",0,IF(K24="Floating",Strats!$C$10+M24,L24)) -> 0.0745 | AJ24: =IF(OR(Z24="",Z24="Full Amortizing"),"",MAX(J24-AH24,0)) -> 0 | AK24: =IF(K24="",0,IF(K24="Floating",IF(P24<>"",MIN(IF(Q24<>"",MAX((Strats!$C$10+Strats!$C$11+M24),Q24),(Strats!$C$10+Strats!$C$11+M24)),P24),IF(Q24<>"",MAX((Strats!$C$10+Strats!$C$11+M24),Q24),(Strats!$C$10+Strats!$C$11+M24))),AI24)) -> 0.0843 | AL24: =IF(OR(E24="",E24<>'Deal Strat'!$C$12,R24=""),"",SUMPRODUCT((E$4:E$303='Deal Strat'!$C$12)*(R$4:R$303>R24))+1+SUMPRODUCT((E$4:E$303='Deal Strat'!$C$12)*(R$4:R$303=R24)*(ROW(R$4:R$303)<ROW(R24)))) | AM24: =IF(R24="","",RANK(R24,$R$4:$R$303,0)+COUNTIF($R$4:R24,R24)-1) -> 28 | AN24: =IF(OR($A24="",$R24=""),0,IF(Deal_Scope="All Deals",1,IF($E24=Deal_Scope,1,0))) -> 1 | AO24: =IF($AN24=0,0,Px_Par) -> 0.94 | AP24: =IF($H24="",0,MAX(0,($H24-Set_Date)/30.4375)) -> 40.082136 | AQ24: =IF(AND(Ext_Flag="Yes",$AA24="Yes"),Ext_Months,0) -> 0 | AR24: =$AP24+$AQ24 -> 40.082136 | AS24: =$AR24/12 -> 3.340178 | AT24: =IF($AJ24="",0,MAX(0,$AJ24/12)) -> 0 | AU24: =MAX(Amort_Min,Amort_Term-$AH24/12) -> 26.341667 | AV24: =MIN($AS24,Hold_Yrs) -> 3.340178 | AW24: =IF($AN24=0,0,CEILING(MAX($AS24,0.0001),1)) -> 4 | AX24: =IF(AND($AN24=1,MAX($AS24,0.0001)<=Hold_Yrs),1,0) -> 1 | AY24: =$R24*$AO24 -> 34543120 | AZ24: =$R24*Acc_Int*$AN24 -> 55122 | BA24: =$AY24*Acq_Cost -> 259073.4 | BB24: =$AY24+$AZ24+$BA24 -> 34857315 | BC24: =IF(Fin_Flag="Yes",$AY24*Adv_Rate,0) -> 20725872 | BD24: =$BC24*Fin_UpFee -> 103629.36 | BE24: =$BB24-$BC24+$BD24 -> 14235073
A25: L-022 | B25: Summit Residences | C25: IL | D25: Multifamily | E25: Deal 4 | F25: 425 | G25: 43313 | H25: 46966 | I25: 121 | J25: 0 | K25: Fixed | L25: 0.0492 | N25: N/A | R25: 7026000 | S25: 0.79 | T25: 0.0763 | U25: 1.1 | V25: 0.663 | W25: 0.69 | X25: 1986 | Y25: 1994 | Z25: Full Amortizing | AA25: No | AB25: Prepayable with Penalty | AC25: First Lien | AD25: PE Fund | AE25: Recapitalization | AF25: Current | AG25: Fee Simple | AH25: =IF(G25="",0,ROUND((Strats!$C$4-G25)/30.4375,1)) -> 98 | AI25: =IF(K25="",0,IF(K25="Floating",Strats!$C$10+M25,L25)) -> 0.0492 | AJ25: =IF(OR(Z25="",Z25="Full Amortizing"),"",MAX(J25-AH25,0)) | AK25: =IF(K25="",0,IF(K25="Floating",IF(P25<>"",MIN(IF(Q25<>"",MAX((Strats!$C$10+Strats!$C$11+M25),Q25),(Strats!$C$10+Strats!$C$11+M25)),P25),IF(Q25<>"",MAX((Strats!$C$10+Strats!$C$11+M25),Q25),(Strats!$C$10+Strats!$C$11+M25))),AI25)) -> 0.0492 | AL25: =IF(OR(E25="",E25<>'Deal Strat'!$C$12,R25=""),"",SUMPRODUCT((E$4:E$303='Deal Strat'!$C$12)*(R$4:R$303>R25))+1+SUMPRODUCT((E$4:E$303='Deal Strat'!$C$12)*(R$4:R$303=R25)*(ROW(R$4:R$303)<ROW(R25)))) | AM25: =IF(R25="","",RANK(R25,$R$4:$R$303,0)+COUNTIF($R$4:R25,R25)-1) -> 43 | AN25: =IF(OR($A25="",$R25=""),0,IF(Deal_Scope="All Deals",1,IF($E25=Deal_Scope,1,0))) -> 1 | AO25: =IF($AN25=0,0,Px_Par) -> 0.94 | AP25: =IF($H25="",0,MAX(0,($H25-Set_Date)/30.4375)) -> 22.045175 | AQ25: =IF(AND(Ext_Flag="Yes",$AA25="Yes"),Ext_Months,0) -> 0 | AR25: =$AP25+$AQ25 -> 22.045175 | AS25: =$AR25/12 -> 1.8370979 | AT25: =IF($AJ25="",0,MAX(0,$AJ25/12)) -> 0 | AU25: =MAX(Amort_Min,Amort_Term-$AH25/12) -> 21.833333 | AV25: =MIN($AS25,Hold_Yrs) -> 1.8370979 | AW25: =IF($AN25=0,0,CEILING(MAX($AS25,0.0001),1)) -> 2 | AX25: =IF(AND($AN25=1,MAX($AS25,0.0001)<=Hold_Yrs),1,0) -> 1 | AY25: =$R25*$AO25 -> 6604440 | AZ25: =$R25*Acc_Int*$AN25 -> 10539 | BA25: =$AY25*Acq_Cost -> 49533.3 | BB25: =$AY25+$AZ25+$BA25 -> 6664512.3 | BC25: =IF(Fin_Flag="Yes",$AY25*Adv_Rate,0) -> 3962664 | BD25: =$BC25*Fin_UpFee -> 19813.32 | BE25: =$BB25-$BC25+$BD25 -> 2721661.6
A26: L-023 | B26: Grandview Plaza | C26: CO | D26: Office | E26: Deal 2 | G26: 42461 | H26: 46113 | I26: 120 | J26: 60 | K26: Fixed | L26: 0.0594 | N26: N/A | R26: 76306000 | S26: 0.904 | T26: 0.0413 | U26: 1.11 | V26: 0.576 | W26: 0.608 | X26: 2009 | Y26: 2014 | Z26: Partial IO | AA26: No | AB26: Defeasance | AC26: First Lien | AD26: PE Fund | AE26: Refinance | AF26: Current | AG26: Fee Simple | AH26: =IF(G26="",0,ROUND((Strats!$C$4-G26)/30.4375,1)) -> 126 | AI26: =IF(K26="",0,IF(K26="Floating",Strats!$C$10+M26,L26)) -> 0.0594 | AJ26: =IF(OR(Z26="",Z26="Full Amortizing"),"",MAX(J26-AH26,0)) -> 0 | AK26: =IF(K26="",0,IF(K26="Floating",IF(P26<>"",MIN(IF(Q26<>"",MAX((Strats!$C$10+Strats!$C$11+M26),Q26),(Strats!$C$10+Strats!$C$11+M26)),P26),IF(Q26<>"",MAX((Strats!$C$10+Strats!$C$11+M26),Q26),(Strats!$C$10+Strats!$C$11+M26))),AI26)) -> 0.0594 | AL26: =IF(OR(E26="",E26<>'Deal Strat'!$C$12,R26=""),"",SUMPRODUCT((E$4:E$303='Deal Strat'!$C$12)*(R$4:R$303>R26))+1+SUMPRODUCT((E$4:E$303='Deal Strat'!$C$12)*(R$4:R$303=R26)*(ROW(R$4:R$303)<ROW(R26)))) | AM26: =IF(R26="","",RANK(R26,$R$4:$R$303,0)+COUNTIF($R$4:R26,R26)-1) -> 16 | AN26: =IF(OR($A26="",$R26=""),0,IF(Deal_Scope="All Deals",1,IF($E26=Deal_Scope,1,0))) -> 1 | AO26: =IF($AN26=0,0,Px_Par) -> 0.94 | AP26: =IF($H26="",0,MAX(0,($H26-Set_Date)/30.4375)) -> 0 | AQ26: =IF(AND(Ext_Flag="Yes",$AA26="Yes"),Ext_Months,0) -> 0 | AR26: =$AP26+$AQ26 -> 0 | AS26: =$AR26/12 -> 0 | AT26: =IF($AJ26="",0,MAX(0,$AJ26/12)) -> 0 | AU26: =MAX(Amort_Min,Amort_Term-$AH26/12) -> 19.5 | AV26: =MIN($AS26,Hold_Yrs) -> 0 | AW26: =IF($AN26=0,0,CEILING(MAX($AS26,0.0001),1)) -> 1 | AX26: =IF(AND($AN26=1,MAX($AS26,0.0001)<=Hold_Yrs),1,0) -> 1 | AY26: =$R26*$AO26 -> 71727640 | AZ26: =$R26*Acc_Int*$AN26 -> 114459 | BA26: =$AY26*Acq_Cost -> 537957.3 | BB26: =$AY26+$AZ26+$BA26 -> 72380056 | BC26: =IF(Fin_Flag="Yes",$AY26*Adv_Rate,0) -> 43036584 | BD26: =$BC26*Fin_UpFee -> 215182.92 | BE26: =$BB26-$BC26+$BD26 -> 29558655
A27: L-024 | B27: Union Square Mixed-Use Development | C27: NY | D27: Mixed-Use | E27: Deal 3 | G27: 45170 | H27: 47727 | I27: 85 | J27: 120 | K27: Floating | M27: 0.0317 | N27: Quarterly | O27: 46295 | P27: 0.1027 | R27: 17633000 | S27: 0.99 | T27: 0.092 | U27: 1.18 | V27: 0.572 | W27: 0.597 | X27: 2002 | Y27: 2022 | Z27: Interest Only | AA27: No | AB27: Freely Prepayable | AC27: First Lien | AD27: Institutional Owner/Operator | AE27: Refinance | AF27: Current | AG27: Fee & Leasehold | AH27: =IF(G27="",0,ROUND((Strats!$C$4-G27)/30.4375,1)) -> 37 | AI27: =IF(K27="",0,IF(K27="Floating",Strats!$C$10+M27,L27)) -> 0.0767 | AJ27: =IF(OR(Z27="",Z27="Full Amortizing"),"",MAX(J27-AH27,0)) -> 83 | AK27: =IF(K27="",0,IF(K27="Floating",IF(P27<>"",MIN(IF(Q27<>"",MAX((Strats!$C$10+Strats!$C$11+M27),Q27),(Strats!$C$10+Strats!$C$11+M27)),P27),IF(Q27<>"",MAX((Strats!$C$10+Strats!$C$11+M27),Q27),(Strats!$C$10+Strats!$C$11+M27))),AI27)) -> 0.0917 | AL27: =IF(OR(E27="",E27<>'Deal Strat'!$C$12,R27=""),"",SUMPRODUCT((E$4:E$303='Deal Strat'!$C$12)*(R$4:R$303>R27))+1+SUMPRODUCT((E$4:E$303='Deal Strat'!$C$12)*(R$4:R$303=R27)*(ROW(R$4:R$303)<ROW(R27)))) | AM27: =IF(R27="","",RANK(R27,$R$4:$R$303,0)+COUNTIF($R$4:R27,R27)-1) -> 32 | AN27: =IF(OR($A27="",$R27=""),0,IF(Deal_Scope="All Deals",1,IF($E27=Deal_Scope,1,0))) -> 1 | AO27: =IF($AN27=0,0,Px_Par) -> 0.94 | AP27: =IF($H27="",0,MAX(0,($H27-Set_Date)/30.4375)) -> 47.047228 | AQ27: =IF(AND(Ext_Flag="Yes",$AA27="Yes"),Ext_Months,0) -> 0 | AR27: =$AP27+$AQ27 -> 47.047228 | AS27: =$AR27/12 -> 3.9206023 | AT27: =IF($AJ27="",0,MAX(0,$AJ27/12)) -> 6.9166667 | AU27: =MAX(Amort_Min,Amort_Term-$AH27/12) -> 26.916667 | AV27: =MIN($AS27,Hold_Yrs) -> 3.9206023 | AW27: =IF($AN27=0,0,CEILING(MAX($AS27,0.0001),1)) -> 4 | AX27: =IF(AND($AN27=1,MAX($AS27,0.0001)<=Hold_Yrs),1,0) -> 1 | AY27: =$R27*$AO27 -> 16575020 | AZ27: =$R27*Acc_Int*$AN27 -> 26449.5 | BA27: =$AY27*Acq_Cost -> 124312.65 | BB27: =$AY27+$AZ27+$BA27 -> 16725782 | BC27: =IF(Fin_Flag="Yes",$AY27*Adv_Rate,0) -> 9945012 | BD27: =$BC27*Fin_UpFee -> 49725.06 | BE27: =$BB27-$BC27+$BD27 -> 6830495.2
